package com.KMOD.WorldGens;

import com.KMOD.Main.KMOD_Main;
import java.util.Random;
import net.minecraft.init.Blocks;
import net.minecraft.item.ItemStack;
import net.minecraft.tileentity.TileEntityChest;
import net.minecraft.world.World;
import net.minecraft.world.gen.feature.WorldGenerator;

public class WorldGenDarkChamber extends WorldGenerator {
   public boolean LocationIsValidSpawn(World world, int i, int j, int k) {
      return world.getBlock(i, j, k) == Blocks.air;
   }

   public boolean generate(World world, Random rand, int i, int j, int k) {
      if (this.LocationIsValidSpawn(world, i, j, k) && this.LocationIsValidSpawn(world, i + 22, j, k) && this.LocationIsValidSpawn(world, i + 22, j, k + 27) && this.LocationIsValidSpawn(world, i, j, k + 27)) {
         world.setBlock(i + 0, j + 0, k + 10, KMOD_Main.KetherCloud);
         world.setBlock(i + 0, j + 0, k + 12, KMOD_Main.KetherCloud);
         world.setBlock(i + 0, j + 0, k + 13, KMOD_Main.KetherCloud);
         world.setBlock(i + 0, j + 1, k + 8, KMOD_Main.KetherCloud);
         world.setBlock(i + 0, j + 1, k + 9, KMOD_Main.KetherCloud);
         world.setBlock(i + 0, j + 1, k + 10, KMOD_Main.KetherCloud);
         world.setBlock(i + 0, j + 2, k + 8, KMOD_Main.KetherCloud);
         world.setBlock(i + 1, j + 0, k + 10, KMOD_Main.KetherCloud);
         world.setBlock(i + 1, j + 0, k + 11, KMOD_Main.KetherCloud);
         world.setBlock(i + 1, j + 0, k + 12, KMOD_Main.KetherCloud);
         world.setBlock(i + 1, j + 0, k + 13, KMOD_Main.KetherCloud);
         world.setBlock(i + 1, j + 0, k + 14, KMOD_Main.KetherCloud);
         world.setBlock(i + 1, j + 1, k + 13, KMOD_Main.KetherCloud);
         world.setBlock(i + 1, j + 1, k + 14, KMOD_Main.KetherCloud);
         world.setBlock(i + 2, j + 0, k + 9, KMOD_Main.KetherCloud);
         world.setBlock(i + 2, j + 0, k + 10, KMOD_Main.KetherCloud);
         world.setBlock(i + 2, j + 0, k + 11, KMOD_Main.KetherCloud);
         world.setBlock(i + 2, j + 0, k + 12, KMOD_Main.KetherCloud);
         world.setBlock(i + 2, j + 0, k + 13, KMOD_Main.KetherCloud);
         world.setBlock(i + 2, j + 1, k + 9, KMOD_Main.KetherCloud);
         world.setBlock(i + 2, j + 1, k + 12, KMOD_Main.CarvedScrapyBrick);
         world.setBlock(i + 2, j + 1, k + 16, KMOD_Main.KetherCloud);
         world.setBlock(i + 2, j + 2, k + 12, KMOD_Main.CarvedScrapyBrick);
         world.setBlock(i + 2, j + 2, k + 16, KMOD_Main.KetherCloud);
         world.setBlock(i + 2, j + 2, k + 17, KMOD_Main.KetherCloud);
         world.setBlock(i + 2, j + 3, k + 12, KMOD_Main.CarvedScrapyBrick);
         world.setBlock(i + 2, j + 4, k + 12, KMOD_Main.CarvedScrapyBrick);
         world.setBlock(i + 3, j + 0, k + 8, KMOD_Main.KetherCloud);
         world.setBlock(i + 3, j + 0, k + 9, KMOD_Main.KetherCloud);
         world.setBlock(i + 3, j + 0, k + 10, KMOD_Main.KetherCloud);
         world.setBlock(i + 3, j + 0, k + 11, KMOD_Main.KetherCloud);
         world.setBlock(i + 3, j + 0, k + 12, KMOD_Main.KetherCloud);
         world.setBlock(i + 3, j + 0, k + 13, KMOD_Main.KetherCloud);
         world.setBlock(i + 3, j + 0, k + 14, KMOD_Main.KetherCloud);
         world.setBlock(i + 3, j + 0, k + 15, KMOD_Main.KetherCloud);
         world.setBlock(i + 3, j + 0, k + 16, KMOD_Main.KetherCloud);
         world.setBlock(i + 3, j + 1, k + 8, KMOD_Main.KetherCloud);
         world.setBlock(i + 3, j + 1, k + 11, KMOD_Main.CarvedScrapyBrick);
         world.setBlock(i + 3, j + 1, k + 12, KMOD_Main.ScrapyBrick);
         world.setBlock(i + 3, j + 1, k + 13, KMOD_Main.CarvedScrapyBrick);
         world.setBlock(i + 3, j + 1, k + 16, KMOD_Main.KetherCloud);
         world.setBlock(i + 3, j + 2, k + 11, KMOD_Main.CarvedScrapyBrick);
         world.setBlock(i + 3, j + 2, k + 13, KMOD_Main.CarvedScrapyBrick);
         world.setBlock(i + 3, j + 3, k + 11, KMOD_Main.CarvedScrapyBrick);
         world.setBlock(i + 3, j + 3, k + 13, KMOD_Main.CarvedScrapyBrick);
         world.setBlock(i + 3, j + 4, k + 11, KMOD_Main.CarvedScrapyBrick);
         world.setBlock(i + 3, j + 4, k + 13, KMOD_Main.CarvedScrapyBrick);
         world.setBlock(i + 3, j + 5, k + 12, KMOD_Main.CarvedScrapyBrick);
         world.setBlock(i + 4, j + 0, k + 8, KMOD_Main.KetherCloud);
         world.setBlock(i + 4, j + 0, k + 9, KMOD_Main.KetherCloud);
         world.setBlock(i + 4, j + 0, k + 10, KMOD_Main.KetherCloud);
         world.setBlock(i + 4, j + 0, k + 11, KMOD_Main.KetherCloud);
         world.setBlock(i + 4, j + 0, k + 12, KMOD_Main.KetherCloud);
         world.setBlock(i + 4, j + 0, k + 13, KMOD_Main.KetherCloud);
         world.setBlock(i + 4, j + 0, k + 14, KMOD_Main.KetherCloud);
         world.setBlock(i + 4, j + 0, k + 15, KMOD_Main.KetherCloud);
         world.setBlock(i + 4, j + 0, k + 16, KMOD_Main.KetherCloud);
         world.setBlock(i + 4, j + 0, k + 17, KMOD_Main.KetherCloud);
         world.setBlock(i + 4, j + 1, k + 8, KMOD_Main.KetherCloud);
         world.setBlock(i + 4, j + 1, k + 10, KMOD_Main.CarvedScrapyBrick);
         world.setBlock(i + 4, j + 1, k + 11, KMOD_Main.ScrapyBrick);
         world.setBlock(i + 4, j + 1, k + 12, KMOD_Main.ScrapyBrick);
         world.setBlock(i + 4, j + 1, k + 13, KMOD_Main.ScrapyBrick);
         world.setBlock(i + 4, j + 1, k + 14, KMOD_Main.CarvedScrapyBrick);
         world.setBlock(i + 4, j + 1, k + 17, KMOD_Main.KetherCloud);
         world.setBlock(i + 4, j + 2, k + 10, KMOD_Main.CarvedScrapyBrick);
         world.setBlock(i + 4, j + 2, k + 14, KMOD_Main.CarvedScrapyBrick);
         world.setBlock(i + 4, j + 3, k + 10, KMOD_Main.CarvedScrapyBrick);
         world.setBlock(i + 4, j + 3, k + 14, KMOD_Main.CarvedScrapyBrick);
         world.setBlock(i + 4, j + 4, k + 10, KMOD_Main.CarvedScrapyBrick);
         world.setBlock(i + 4, j + 4, k + 14, KMOD_Main.CarvedScrapyBrick);
         world.setBlock(i + 4, j + 5, k + 11, KMOD_Main.CarvedScrapyBrick);
         world.setBlock(i + 4, j + 5, k + 13, KMOD_Main.CarvedScrapyBrick);
         world.setBlock(i + 4, j + 6, k + 12, KMOD_Main.CarvedScrapyBrick);
         world.setBlock(i + 5, j + 0, k + 7, KMOD_Main.KetherCloud);
         world.setBlock(i + 5, j + 0, k + 8, KMOD_Main.KetherCloud);
         world.setBlock(i + 5, j + 0, k + 9, KMOD_Main.KetherCloud);
         world.setBlock(i + 5, j + 0, k + 10, KMOD_Main.KetherCloud);
         world.setBlock(i + 5, j + 0, k + 11, KMOD_Main.KetherCloud);
         world.setBlock(i + 5, j + 0, k + 12, KMOD_Main.KetherCloud);
         world.setBlock(i + 5, j + 0, k + 13, KMOD_Main.KetherCloud);
         world.setBlock(i + 5, j + 0, k + 14, KMOD_Main.KetherCloud);
         world.setBlock(i + 5, j + 0, k + 15, KMOD_Main.KetherCloud);
         world.setBlock(i + 5, j + 0, k + 16, KMOD_Main.KetherCloud);
         world.setBlock(i + 5, j + 0, k + 17, KMOD_Main.KetherCloud);
         world.setBlock(i + 5, j + 1, k + 7, KMOD_Main.KetherCloud);
         world.setBlock(i + 5, j + 1, k + 9, KMOD_Main.CarvedScrapyBrick);
         world.setBlock(i + 5, j + 1, k + 10, KMOD_Main.ScrapyBrick);
         world.setBlock(i + 5, j + 1, k + 11, KMOD_Main.ScrapyBrick);
         world.setBlock(i + 5, j + 1, k + 12, KMOD_Main.KetherStone);
         world.setBlock(i + 5, j + 1, k + 13, KMOD_Main.ScrapyBrick);
         world.setBlock(i + 5, j + 1, k + 14, KMOD_Main.ScrapyBrick);
         world.setBlock(i + 5, j + 1, k + 15, KMOD_Main.CarvedScrapyBrick);
         world.setBlock(i + 5, j + 1, k + 17, KMOD_Main.KetherCloud);
         world.setBlock(i + 5, j + 1, k + 18, KMOD_Main.KetherCloud);
         world.setBlock(i + 5, j + 1, k + 19, KMOD_Main.KetherCloud);
         world.setBlock(i + 5, j + 1, k + 21, KMOD_Main.KetherCloud);
         world.setBlock(i + 5, j + 2, k + 9, KMOD_Main.CarvedScrapyBrick);
         world.setBlock(i + 5, j + 2, k + 15, KMOD_Main.CarvedScrapyBrick);
         world.setBlock(i + 5, j + 2, k + 19, KMOD_Main.KetherCloud);
         world.setBlock(i + 5, j + 2, k + 21, KMOD_Main.KetherCloud);
         world.setBlock(i + 5, j + 3, k + 9, KMOD_Main.CarvedScrapyBrick);
         world.setBlock(i + 5, j + 3, k + 15, KMOD_Main.CarvedScrapyBrick);
         world.setBlock(i + 5, j + 4, k + 9, KMOD_Main.CarvedScrapyBrick);
         world.setBlock(i + 5, j + 4, k + 15, KMOD_Main.CarvedScrapyBrick);
         world.setBlock(i + 5, j + 5, k + 10, KMOD_Main.CarvedScrapyBrick);
         world.setBlock(i + 5, j + 5, k + 14, KMOD_Main.CarvedScrapyBrick);
         world.setBlock(i + 5, j + 6, k + 11, KMOD_Main.CarvedScrapyBrick);
         world.setBlock(i + 5, j + 6, k + 13, KMOD_Main.CarvedScrapyBrick);
         world.setBlock(i + 5, j + 7, k + 12, KMOD_Main.CarvedScrapyBrick);
         world.setBlock(i + 6, j + 0, k + 6, KMOD_Main.KetherCloud);
         world.setBlock(i + 6, j + 0, k + 7, KMOD_Main.KetherCloud);
         world.setBlock(i + 6, j + 0, k + 8, KMOD_Main.KetherCloud);
         world.setBlock(i + 6, j + 0, k + 9, KMOD_Main.KetherCloud);
         world.setBlock(i + 6, j + 0, k + 10, KMOD_Main.KetherCloud);
         world.setBlock(i + 6, j + 0, k + 11, KMOD_Main.KetherCloud);
         world.setBlock(i + 6, j + 0, k + 12, KMOD_Main.KetherCloud);
         world.setBlock(i + 6, j + 0, k + 13, KMOD_Main.KetherCloud);
         world.setBlock(i + 6, j + 0, k + 14, KMOD_Main.KetherCloud);
         world.setBlock(i + 6, j + 0, k + 15, KMOD_Main.KetherCloud);
         world.setBlock(i + 6, j + 0, k + 16, KMOD_Main.KetherCloud);
         world.setBlock(i + 6, j + 0, k + 17, KMOD_Main.KetherCloud);
         world.setBlock(i + 6, j + 0, k + 18, KMOD_Main.KetherCloud);
         world.setBlock(i + 6, j + 0, k + 19, KMOD_Main.KetherCloud);
         world.setBlock(i + 6, j + 1, k + 4, KMOD_Main.KetherCloud);
         world.setBlock(i + 6, j + 1, k + 6, KMOD_Main.KetherCloud);
         world.setBlock(i + 6, j + 1, k + 8, KMOD_Main.CarvedScrapyBrick);
         world.setBlock(i + 6, j + 1, k + 9, KMOD_Main.ScrapyBrick);
         world.setBlock(i + 6, j + 1, k + 10, KMOD_Main.ScrapyBrick);
         world.setBlock(i + 6, j + 1, k + 11, KMOD_Main.KetherStone);
         world.setBlock(i + 6, j + 1, k + 12, KMOD_Main.KetherStone);
         world.setBlock(i + 6, j + 1, k + 13, KMOD_Main.KetherStone);
         world.setBlock(i + 6, j + 1, k + 14, KMOD_Main.ScrapyBrick);
         world.setBlock(i + 6, j + 1, k + 15, KMOD_Main.ScrapyBrick);
         world.setBlock(i + 6, j + 1, k + 16, KMOD_Main.CarvedScrapyBrick);
         world.setBlock(i + 6, j + 1, k + 19, KMOD_Main.KetherCloud);
         world.setBlock(i + 6, j + 1, k + 20, KMOD_Main.KetherCloud);
         world.setBlock(i + 6, j + 1, k + 21, KMOD_Main.KetherCloud);
         world.setBlock(i + 6, j + 1, k + 23, KMOD_Main.KetherCloud);
         world.setBlock(i + 6, j + 1, k + 24, KMOD_Main.KetherCloud);
         world.setBlock(i + 6, j + 1, k + 25, KMOD_Main.KetherCloud);
         world.setBlock(i + 6, j + 2, k + 8, KMOD_Main.CarvedScrapyBrick);
         world.setBlock(i + 6, j + 2, k + 16, KMOD_Main.CarvedScrapyBrick);
         world.setBlock(i + 6, j + 2, k + 20, KMOD_Main.KetherCloud);
         world.setBlock(i + 6, j + 2, k + 23, KMOD_Main.KetherCloud);
         world.setBlock(i + 6, j + 2, k + 25, KMOD_Main.KetherCloud);
         world.setBlock(i + 6, j + 3, k + 8, KMOD_Main.CarvedScrapyBrick);
         world.setBlock(i + 6, j + 3, k + 16, KMOD_Main.CarvedScrapyBrick);
         world.setBlock(i + 6, j + 4, k + 8, KMOD_Main.CarvedScrapyBrick);
         world.setBlock(i + 6, j + 4, k + 16, KMOD_Main.CarvedScrapyBrick);
         world.setBlock(i + 6, j + 5, k + 9, KMOD_Main.CarvedScrapyBrick);
         world.setBlock(i + 6, j + 5, k + 15, KMOD_Main.CarvedScrapyBrick);
         world.setBlock(i + 6, j + 6, k + 10, KMOD_Main.CarvedScrapyBrick);
         world.setBlock(i + 6, j + 6, k + 14, KMOD_Main.CarvedScrapyBrick);
         world.setBlock(i + 6, j + 7, k + 11, KMOD_Main.CarvedScrapyBrick);
         world.setBlock(i + 6, j + 7, k + 13, KMOD_Main.CarvedScrapyBrick);
         world.setBlock(i + 6, j + 8, k + 12, KMOD_Main.CarvedScrapyBrick);
         world.setBlock(i + 7, j + 0, k + 4, KMOD_Main.KetherCloud);
         world.setBlock(i + 7, j + 0, k + 6, KMOD_Main.KetherCloud);
         world.setBlock(i + 7, j + 0, k + 7, KMOD_Main.KetherCloud);
         world.setBlock(i + 7, j + 0, k + 8, KMOD_Main.KetherCloud);
         world.setBlock(i + 7, j + 0, k + 9, KMOD_Main.KetherCloud);
         world.setBlock(i + 7, j + 0, k + 10, KMOD_Main.KetherCloud);
         world.setBlock(i + 7, j + 0, k + 11, KMOD_Main.KetherCloud);
         world.setBlock(i + 7, j + 0, k + 12, KMOD_Main.KetherCloud);
         world.setBlock(i + 7, j + 0, k + 13, KMOD_Main.KetherCloud);
         world.setBlock(i + 7, j + 0, k + 14, KMOD_Main.KetherCloud);
         world.setBlock(i + 7, j + 0, k + 15, KMOD_Main.KetherCloud);
         world.setBlock(i + 7, j + 0, k + 16, KMOD_Main.KetherCloud);
         world.setBlock(i + 7, j + 0, k + 17, KMOD_Main.KetherCloud);
         world.setBlock(i + 7, j + 0, k + 18, KMOD_Main.KetherCloud);
         world.setBlock(i + 7, j + 0, k + 19, KMOD_Main.KetherCloud);
         world.setBlock(i + 7, j + 0, k + 21, KMOD_Main.KetherCloud);
         world.setBlock(i + 7, j + 0, k + 22, KMOD_Main.KetherCloud);
         world.setBlock(i + 7, j + 0, k + 23, KMOD_Main.KetherCloud);
         world.setBlock(i + 7, j + 0, k + 24, KMOD_Main.KetherCloud);
         world.setBlock(i + 7, j + 0, k + 25, KMOD_Main.KetherCloud);
         world.setBlock(i + 7, j + 1, k + 4, KMOD_Main.KetherCloud);
         world.setBlock(i + 7, j + 1, k + 7, KMOD_Main.CarvedScrapyBrick);
         world.setBlock(i + 7, j + 1, k + 8, KMOD_Main.ScrapyBrick);
         world.setBlock(i + 7, j + 1, k + 9, KMOD_Main.ScrapyBrick);
         world.setBlock(i + 7, j + 1, k + 10, KMOD_Main.KetherStone);
         world.setBlock(i + 7, j + 1, k + 11, KMOD_Main.KetherStone);
         world.setBlock(i + 7, j + 1, k + 12, KMOD_Main.KetherStone);
         world.setBlock(i + 7, j + 1, k + 13, KMOD_Main.KetherStone);
         world.setBlock(i + 7, j + 1, k + 14, KMOD_Main.KetherStone);
         world.setBlock(i + 7, j + 1, k + 15, KMOD_Main.ScrapyBrick);
         world.setBlock(i + 7, j + 1, k + 16, KMOD_Main.ScrapyBrick);
         world.setBlock(i + 7, j + 1, k + 17, KMOD_Main.CarvedScrapyBrick);
         world.setBlock(i + 7, j + 1, k + 21, KMOD_Main.KetherCloud);
         world.setBlock(i + 7, j + 1, k + 23, KMOD_Main.KetherCloud);
         world.setBlock(i + 7, j + 1, k + 24, KMOD_Main.KetherCloud);
         world.setBlock(i + 7, j + 1, k + 25, KMOD_Main.KetherCloud);
         world.setBlock(i + 7, j + 2, k + 7, KMOD_Main.CarvedScrapyBrick);
         world.setBlock(i + 7, j + 2, k + 17, KMOD_Main.CarvedScrapyBrick);
         world.setBlock(i + 7, j + 3, k + 7, KMOD_Main.CarvedScrapyBrick);
         world.setBlock(i + 7, j + 3, k + 17, KMOD_Main.CarvedScrapyBrick);
         world.setBlock(i + 7, j + 4, k + 7, KMOD_Main.CarvedScrapyBrick);
         world.setBlock(i + 7, j + 4, k + 17, KMOD_Main.CarvedScrapyBrick);
         world.setBlock(i + 7, j + 5, k + 8, KMOD_Main.CarvedScrapyBrick);
         world.setBlock(i + 7, j + 5, k + 16, KMOD_Main.CarvedScrapyBrick);
         world.setBlock(i + 7, j + 6, k + 9, KMOD_Main.CarvedScrapyBrick);
         world.setBlock(i + 7, j + 6, k + 15, KMOD_Main.CarvedScrapyBrick);
         world.setBlock(i + 7, j + 7, k + 10, KMOD_Main.CarvedScrapyBrick);
         world.setBlock(i + 7, j + 7, k + 14, KMOD_Main.CarvedScrapyBrick);
         world.setBlock(i + 7, j + 8, k + 11, KMOD_Main.CarvedScrapyBrick);
         world.setBlock(i + 7, j + 8, k + 13, KMOD_Main.CarvedScrapyBrick);
         world.setBlock(i + 7, j + 9, k + 12, KMOD_Main.CarvedScrapyBrick);
         world.setBlock(i + 8, j + 0, k + 3, KMOD_Main.KetherCloud);
         world.setBlock(i + 8, j + 0, k + 4, KMOD_Main.KetherCloud);
         world.setBlock(i + 8, j + 0, k + 5, KMOD_Main.KetherCloud);
         world.setBlock(i + 8, j + 0, k + 6, KMOD_Main.KetherCloud);
         world.setBlock(i + 8, j + 0, k + 7, KMOD_Main.KetherCloud);
         world.setBlock(i + 8, j + 0, k + 8, KMOD_Main.KetherCloud);
         world.setBlock(i + 8, j + 0, k + 9, KMOD_Main.KetherCloud);
         world.setBlock(i + 8, j + 0, k + 10, KMOD_Main.KetherCloud);
         world.setBlock(i + 8, j + 0, k + 11, KMOD_Main.KetherCloud);
         world.setBlock(i + 8, j + 0, k + 12, KMOD_Main.KetherCloud);
         world.setBlock(i + 8, j + 0, k + 13, KMOD_Main.KetherCloud);
         world.setBlock(i + 8, j + 0, k + 14, KMOD_Main.KetherCloud);
         world.setBlock(i + 8, j + 0, k + 15, KMOD_Main.KetherCloud);
         world.setBlock(i + 8, j + 0, k + 16, KMOD_Main.KetherCloud);
         world.setBlock(i + 8, j + 0, k + 17, KMOD_Main.KetherCloud);
         world.setBlock(i + 8, j + 0, k + 18, KMOD_Main.KetherCloud);
         world.setBlock(i + 8, j + 0, k + 19, KMOD_Main.KetherCloud);
         world.setBlock(i + 8, j + 0, k + 20, KMOD_Main.KetherCloud);
         world.setBlock(i + 8, j + 0, k + 21, KMOD_Main.KetherCloud);
         world.setBlock(i + 8, j + 0, k + 22, KMOD_Main.KetherCloud);
         world.setBlock(i + 8, j + 0, k + 23, KMOD_Main.KetherCloud);
         world.setBlock(i + 8, j + 0, k + 24, KMOD_Main.KetherCloud);
         world.setBlock(i + 8, j + 0, k + 25, KMOD_Main.KetherCloud);
         world.setBlock(i + 8, j + 0, k + 26, KMOD_Main.KetherCloud);
         world.setBlock(i + 8, j + 0, k + 27, KMOD_Main.KetherCloud);
         world.setBlock(i + 8, j + 1, k + 3, KMOD_Main.KetherCloud);
         world.setBlock(i + 8, j + 1, k + 6, KMOD_Main.CarvedScrapyBrick);
         world.setBlock(i + 8, j + 1, k + 7, KMOD_Main.ScrapyBrick);
         world.setBlock(i + 8, j + 1, k + 8, KMOD_Main.ScrapyBrick);
         world.setBlock(i + 8, j + 1, k + 9, KMOD_Main.KetherStone);
         world.setBlock(i + 8, j + 1, k + 10, KMOD_Main.KetherStone);
         world.setBlock(i + 8, j + 1, k + 11, KMOD_Main.KetherStone);
         world.setBlock(i + 8, j + 1, k + 12, KMOD_Main.KetherStone);
         world.setBlock(i + 8, j + 1, k + 13, KMOD_Main.KetherStone);
         world.setBlock(i + 8, j + 1, k + 14, KMOD_Main.KetherStone);
         world.setBlock(i + 8, j + 1, k + 15, KMOD_Main.KetherStone);
         world.setBlock(i + 8, j + 1, k + 16, KMOD_Main.ScrapyBrick);
         world.setBlock(i + 8, j + 1, k + 17, KMOD_Main.ScrapyBrick);
         world.setBlock(i + 8, j + 1, k + 18, KMOD_Main.CarvedScrapyBrick);
         world.setBlock(i + 8, j + 2, k + 6, KMOD_Main.CarvedScrapyBrick);
         world.setBlock(i + 8, j + 2, k + 18, KMOD_Main.CarvedScrapyBrick);
         world.setBlock(i + 8, j + 3, k + 6, KMOD_Main.CarvedScrapyBrick);
         world.setBlock(i + 8, j + 3, k + 18, KMOD_Main.CarvedScrapyBrick);
         world.setBlock(i + 8, j + 4, k + 6, KMOD_Main.CarvedScrapyBrick);
         world.setBlock(i + 8, j + 4, k + 18, KMOD_Main.CarvedScrapyBrick);
         world.setBlock(i + 8, j + 5, k + 7, KMOD_Main.CarvedScrapyBrick);
         world.setBlock(i + 8, j + 5, k + 17, KMOD_Main.CarvedScrapyBrick);
         world.setBlock(i + 8, j + 6, k + 8, KMOD_Main.CarvedScrapyBrick);
         world.setBlock(i + 8, j + 6, k + 16, KMOD_Main.CarvedScrapyBrick);
         world.setBlock(i + 8, j + 7, k + 9, KMOD_Main.CarvedScrapyBrick);
         world.setBlock(i + 8, j + 7, k + 15, KMOD_Main.CarvedScrapyBrick);
         world.setBlock(i + 8, j + 8, k + 10, KMOD_Main.CarvedScrapyBrick);
         world.setBlock(i + 8, j + 8, k + 14, KMOD_Main.CarvedScrapyBrick);
         world.setBlock(i + 8, j + 9, k + 11, KMOD_Main.CarvedScrapyBrick);
         world.setBlock(i + 8, j + 9, k + 13, KMOD_Main.CarvedScrapyBrick);
         world.setBlock(i + 8, j + 10, k + 12, KMOD_Main.CarvedScrapyBrick);
         world.setBlock(i + 9, j + 0, k + 3, KMOD_Main.KetherCloud);
         world.setBlock(i + 9, j + 0, k + 4, KMOD_Main.KetherCloud);
         world.setBlock(i + 9, j + 0, k + 5, KMOD_Main.KetherCloud);
         world.setBlock(i + 9, j + 0, k + 6, KMOD_Main.KetherCloud);
         world.setBlock(i + 9, j + 0, k + 7, KMOD_Main.KetherCloud);
         world.setBlock(i + 9, j + 0, k + 8, KMOD_Main.KetherCloud);
         world.setBlock(i + 9, j + 0, k + 9, KMOD_Main.KetherCloud);
         world.setBlock(i + 9, j + 0, k + 10, KMOD_Main.KetherCloud);
         world.setBlock(i + 9, j + 0, k + 11, KMOD_Main.KetherCloud);
         world.setBlock(i + 9, j + 0, k + 12, KMOD_Main.KetherCloud);
         world.setBlock(i + 9, j + 0, k + 13, KMOD_Main.KetherCloud);
         world.setBlock(i + 9, j + 0, k + 14, KMOD_Main.KetherCloud);
         world.setBlock(i + 9, j + 0, k + 15, KMOD_Main.KetherCloud);
         world.setBlock(i + 9, j + 0, k + 16, KMOD_Main.KetherCloud);
         world.setBlock(i + 9, j + 0, k + 17, KMOD_Main.KetherCloud);
         world.setBlock(i + 9, j + 0, k + 18, KMOD_Main.KetherCloud);
         world.setBlock(i + 9, j + 0, k + 19, KMOD_Main.KetherCloud);
         world.setBlock(i + 9, j + 0, k + 20, KMOD_Main.KetherCloud);
         world.setBlock(i + 9, j + 0, k + 21, KMOD_Main.KetherCloud);
         world.setBlock(i + 9, j + 0, k + 22, KMOD_Main.KetherCloud);
         world.setBlock(i + 9, j + 0, k + 23, KMOD_Main.KetherCloud);
         world.setBlock(i + 9, j + 0, k + 24, KMOD_Main.KetherCloud);
         world.setBlock(i + 9, j + 0, k + 25, KMOD_Main.KetherCloud);
         world.setBlock(i + 9, j + 0, k + 26, KMOD_Main.KetherCloud);
         world.setBlock(i + 9, j + 0, k + 27, KMOD_Main.KetherCloud);
         world.setBlock(i + 9, j + 1, k + 3, KMOD_Main.KetherCloud);
         world.setBlock(i + 9, j + 1, k + 5, KMOD_Main.CarvedScrapyBrick);
         world.setBlock(i + 9, j + 1, k + 6, KMOD_Main.ScrapyBrick);
         world.setBlock(i + 9, j + 1, k + 7, KMOD_Main.ScrapyBrick);
         world.setBlock(i + 9, j + 1, k + 8, KMOD_Main.KetherStone);
         world.setBlock(i + 9, j + 1, k + 9, KMOD_Main.KetherStone);
         world.setBlock(i + 9, j + 1, k + 10, KMOD_Main.KetherStone);
         world.setBlock(i + 9, j + 1, k + 11, KMOD_Main.KetherStone);
         world.setBlock(i + 9, j + 1, k + 12, KMOD_Main.KetherStone);
         world.setBlock(i + 9, j + 1, k + 13, KMOD_Main.KetherStone);
         world.setBlock(i + 9, j + 1, k + 14, KMOD_Main.KetherStone);
         world.setBlock(i + 9, j + 1, k + 15, KMOD_Main.KetherStone);
         world.setBlock(i + 9, j + 1, k + 16, KMOD_Main.KetherStone);
         world.setBlock(i + 9, j + 1, k + 17, KMOD_Main.ScrapyBrick);
         world.setBlock(i + 9, j + 1, k + 18, KMOD_Main.ScrapyBrick);
         world.setBlock(i + 9, j + 1, k + 19, KMOD_Main.CarvedScrapyBrick);
         world.setBlock(i + 9, j + 1, k + 20, KMOD_Main.CarvedScrapyBrick);
         world.setBlock(i + 9, j + 1, k + 21, KMOD_Main.CarvedScrapyBrick);
         world.setBlock(i + 9, j + 1, k + 22, KMOD_Main.CarvedScrapyBrick);
         world.setBlock(i + 9, j + 1, k + 23, KMOD_Main.CarvedScrapyBrick);
         world.setBlock(i + 9, j + 1, k + 24, KMOD_Main.CarvedScrapyBrick);
         world.setBlock(i + 9, j + 1, k + 25, KMOD_Main.CarvedScrapyBrick);
         world.setBlock(i + 9, j + 1, k + 26, KMOD_Main.CarvedScrapyBrick);
         world.setBlock(i + 9, j + 2, k + 5, KMOD_Main.CarvedScrapyBrick);
         world.setBlock(i + 9, j + 2, k + 19, KMOD_Main.CarvedScrapyBrick);
         world.setBlock(i + 9, j + 2, k + 20, KMOD_Main.CarvedScrapyBrick);
         world.setBlock(i + 9, j + 2, k + 21, KMOD_Main.CarvedScrapyBrick);
         world.setBlock(i + 9, j + 2, k + 22, KMOD_Main.CarvedScrapyBrick);
         world.setBlock(i + 9, j + 2, k + 23, KMOD_Main.CarvedScrapyBrick);
         world.setBlock(i + 9, j + 2, k + 24, KMOD_Main.CarvedScrapyBrick);
         world.setBlock(i + 9, j + 2, k + 25, KMOD_Main.CarvedScrapyBrick);
         world.setBlock(i + 9, j + 2, k + 26, KMOD_Main.CarvedScrapyBrick);
         world.setBlock(i + 9, j + 3, k + 5, KMOD_Main.CarvedScrapyBrick);
         world.setBlock(i + 9, j + 3, k + 19, KMOD_Main.CarvedScrapyBrick);
         world.setBlock(i + 9, j + 3, k + 20, KMOD_Main.CarvedScrapyBrick);
         world.setBlock(i + 9, j + 3, k + 21, KMOD_Main.CarvedScrapyBrick);
         world.setBlock(i + 9, j + 3, k + 22, KMOD_Main.CarvedScrapyBrick);
         world.setBlock(i + 9, j + 3, k + 23, KMOD_Main.CarvedScrapyBrick);
         world.setBlock(i + 9, j + 3, k + 24, KMOD_Main.CarvedScrapyBrick);
         world.setBlock(i + 9, j + 3, k + 25, KMOD_Main.CarvedScrapyBrick);
         world.setBlock(i + 9, j + 3, k + 26, KMOD_Main.CarvedScrapyBrick);
         world.setBlock(i + 9, j + 4, k + 5, KMOD_Main.CarvedScrapyBrick);
         world.setBlock(i + 9, j + 4, k + 19, KMOD_Main.CarvedScrapyBrick);
         world.setBlock(i + 9, j + 4, k + 20, KMOD_Main.CarvedScrapyBrick);
         world.setBlock(i + 9, j + 4, k + 21, KMOD_Main.CarvedScrapyBrick);
         world.setBlock(i + 9, j + 4, k + 22, KMOD_Main.CarvedScrapyBrick);
         world.setBlock(i + 9, j + 4, k + 23, KMOD_Main.CarvedScrapyBrick);
         world.setBlock(i + 9, j + 4, k + 24, KMOD_Main.CarvedScrapyBrick);
         world.setBlock(i + 9, j + 4, k + 25, KMOD_Main.CarvedScrapyBrick);
         world.setBlock(i + 9, j + 4, k + 26, KMOD_Main.CarvedScrapyBrick);
         world.setBlock(i + 9, j + 5, k + 6, KMOD_Main.CarvedScrapyBrick);
         world.setBlock(i + 9, j + 5, k + 18, KMOD_Main.CarvedScrapyBrick);
         world.setBlock(i + 9, j + 5, k + 25, KMOD_Main.CarvedScrapyBrick);
         world.setBlock(i + 9, j + 6, k + 7, KMOD_Main.CarvedScrapyBrick);
         world.setBlock(i + 9, j + 6, k + 17, KMOD_Main.CarvedScrapyBrick);
         world.setBlock(i + 9, j + 7, k + 8, KMOD_Main.CarvedScrapyBrick);
         world.setBlock(i + 9, j + 7, k + 16, KMOD_Main.CarvedScrapyBrick);
         world.setBlock(i + 9, j + 8, k + 9, KMOD_Main.CarvedScrapyBrick);
         world.setBlock(i + 9, j + 8, k + 15, KMOD_Main.CarvedScrapyBrick);
         world.setBlock(i + 9, j + 9, k + 10, KMOD_Main.CarvedScrapyBrick);
         world.setBlock(i + 9, j + 9, k + 11, Blocks.glowstone);
         world.setBlock(i + 9, j + 9, k + 13, Blocks.glowstone);
         world.setBlock(i + 9, j + 9, k + 14, KMOD_Main.CarvedScrapyBrick);
         world.setBlock(i + 9, j + 10, k + 11, KMOD_Main.CarvedScrapyBrick);
         world.setBlock(i + 9, j + 10, k + 13, KMOD_Main.CarvedScrapyBrick);
         world.setBlock(i + 9, j + 11, k + 12, KMOD_Main.CarvedScrapyBrick);
         world.setBlock(i + 10, j + 0, k + 2, KMOD_Main.KetherCloud);
         world.setBlock(i + 10, j + 0, k + 3, KMOD_Main.KetherCloud);
         world.setBlock(i + 10, j + 0, k + 4, KMOD_Main.KetherCloud);
         world.setBlock(i + 10, j + 0, k + 5, KMOD_Main.KetherCloud);
         world.setBlock(i + 10, j + 0, k + 6, KMOD_Main.KetherCloud);
         world.setBlock(i + 10, j + 0, k + 7, KMOD_Main.KetherCloud);
         world.setBlock(i + 10, j + 0, k + 8, KMOD_Main.KetherCloud);
         world.setBlock(i + 10, j + 0, k + 9, KMOD_Main.KetherCloud);
         world.setBlock(i + 10, j + 0, k + 10, KMOD_Main.KetherCloud);
         world.setBlock(i + 10, j + 0, k + 11, KMOD_Main.KetherCloud);
         world.setBlock(i + 10, j + 0, k + 12, KMOD_Main.KetherCloud);
         world.setBlock(i + 10, j + 0, k + 13, KMOD_Main.KetherCloud);
         world.setBlock(i + 10, j + 0, k + 14, KMOD_Main.KetherCloud);
         world.setBlock(i + 10, j + 0, k + 15, KMOD_Main.KetherCloud);
         world.setBlock(i + 10, j + 0, k + 16, KMOD_Main.KetherCloud);
         world.setBlock(i + 10, j + 0, k + 17, KMOD_Main.KetherCloud);
         world.setBlock(i + 10, j + 0, k + 18, KMOD_Main.KetherCloud);
         world.setBlock(i + 10, j + 0, k + 19, KMOD_Main.KetherCloud);
         world.setBlock(i + 10, j + 0, k + 20, KMOD_Main.KetherCloud);
         world.setBlock(i + 10, j + 0, k + 21, KMOD_Main.KetherCloud);
         world.setBlock(i + 10, j + 0, k + 22, KMOD_Main.KetherCloud);
         world.setBlock(i + 10, j + 0, k + 23, KMOD_Main.KetherCloud);
         world.setBlock(i + 10, j + 0, k + 24, KMOD_Main.KetherCloud);
         world.setBlock(i + 10, j + 0, k + 25, KMOD_Main.KetherCloud);
         world.setBlock(i + 10, j + 0, k + 26, KMOD_Main.KetherCloud);
         world.setBlock(i + 10, j + 0, k + 27, KMOD_Main.KetherCloud);
         world.setBlock(i + 10, j + 1, k + 2, KMOD_Main.KetherCloud);
         world.setBlock(i + 10, j + 1, k + 4, KMOD_Main.CarvedScrapyBrick);
         world.setBlock(i + 10, j + 1, k + 5, KMOD_Main.ScrapyBrick);
         world.setBlock(i + 10, j + 1, k + 6, KMOD_Main.ScrapyBrick);
         world.setBlock(i + 10, j + 1, k + 7, KMOD_Main.KetherStone);
         world.setBlock(i + 10, j + 1, k + 8, KMOD_Main.KetherStone);
         world.setBlock(i + 10, j + 1, k + 9, KMOD_Main.KetherStone);
         world.setBlock(i + 10, j + 1, k + 10, KMOD_Main.KetherStone);
         world.setBlock(i + 10, j + 1, k + 11, KMOD_Main.KetherStone);
         world.setBlock(i + 10, j + 1, k + 12, KMOD_Main.KetherStone);
         world.setBlock(i + 10, j + 1, k + 13, KMOD_Main.KetherStone);
         world.setBlock(i + 10, j + 1, k + 14, KMOD_Main.KetherStone);
         world.setBlock(i + 10, j + 1, k + 15, KMOD_Main.KetherStone);
         world.setBlock(i + 10, j + 1, k + 16, KMOD_Main.KetherStone);
         world.setBlock(i + 10, j + 1, k + 17, KMOD_Main.KetherStone);
         world.setBlock(i + 10, j + 1, k + 18, KMOD_Main.ScrapyBrick);
         world.setBlock(i + 10, j + 1, k + 19, KMOD_Main.ScrapyBrick);
         world.setBlock(i + 10, j + 1, k + 20, KMOD_Main.ScrapyBrick);
         world.setBlock(i + 10, j + 1, k + 21, KMOD_Main.ScrapyBrick);
         world.setBlock(i + 10, j + 1, k + 22, KMOD_Main.ScrapyBrick);
         world.setBlock(i + 10, j + 1, k + 23, KMOD_Main.ScrapyBrick);
         world.setBlock(i + 10, j + 1, k + 24, KMOD_Main.ScrapyBrick);
         world.setBlock(i + 10, j + 1, k + 25, KMOD_Main.ScrapyBrick);
         world.setBlock(i + 10, j + 1, k + 26, KMOD_Main.ScrapyBrick);
         world.setBlock(i + 10, j + 2, k + 4, KMOD_Main.CarvedScrapyBrick);
         world.setBlock(i + 10, j + 3, k + 4, KMOD_Main.CarvedScrapyBrick);
         world.setBlock(i + 10, j + 4, k + 4, KMOD_Main.CarvedScrapyBrick);
         world.setBlock(i + 10, j + 4, k + 26, Blocks.glowstone);
         world.setBlock(i + 10, j + 5, k + 5, KMOD_Main.CarvedScrapyBrick);
         world.setBlock(i + 10, j + 5, k + 19, KMOD_Main.CarvedScrapyBrick);
         world.setBlock(i + 10, j + 5, k + 20, KMOD_Main.CarvedScrapyBrick);
         world.setBlock(i + 10, j + 5, k + 21, KMOD_Main.CarvedScrapyBrick);
         world.setBlock(i + 10, j + 5, k + 22, KMOD_Main.CarvedScrapyBrick);
         world.setBlock(i + 10, j + 5, k + 23, KMOD_Main.CarvedScrapyBrick);
         world.setBlock(i + 10, j + 5, k + 24, KMOD_Main.CarvedScrapyBrick);
         world.setBlock(i + 10, j + 5, k + 25, KMOD_Main.CarvedScrapyBrick);
         world.setBlock(i + 10, j + 5, k + 26, KMOD_Main.CarvedScrapyBrick);
         world.setBlock(i + 10, j + 6, k + 6, KMOD_Main.CarvedScrapyBrick);
         world.setBlock(i + 10, j + 6, k + 18, KMOD_Main.CarvedScrapyBrick);
         world.setBlock(i + 10, j + 7, k + 7, KMOD_Main.CarvedScrapyBrick);
         world.setBlock(i + 10, j + 7, k + 17, KMOD_Main.CarvedScrapyBrick);
         world.setBlock(i + 10, j + 8, k + 8, KMOD_Main.CarvedScrapyBrick);
         world.setBlock(i + 10, j + 8, k + 16, KMOD_Main.CarvedScrapyBrick);
         world.setBlock(i + 10, j + 9, k + 9, KMOD_Main.CarvedScrapyBrick);
         world.setBlock(i + 10, j + 9, k + 10, Blocks.glowstone);
         world.setBlock(i + 10, j + 9, k + 14, Blocks.glowstone);
         world.setBlock(i + 10, j + 9, k + 15, KMOD_Main.CarvedScrapyBrick);
         world.setBlock(i + 10, j + 10, k + 10, KMOD_Main.CarvedScrapyBrick);
         world.setBlock(i + 10, j + 10, k + 11, Blocks.glowstone);
         world.setBlock(i + 10, j + 10, k + 13, Blocks.glowstone);
         world.setBlock(i + 10, j + 10, k + 14, KMOD_Main.CarvedScrapyBrick);
         world.setBlock(i + 10, j + 11, k + 11, KMOD_Main.CarvedScrapyBrick);
         world.setBlock(i + 10, j + 11, k + 13, KMOD_Main.CarvedScrapyBrick);
         world.setBlock(i + 10, j + 12, k + 12, KMOD_Main.CarvedScrapyBrick);
         world.setBlock(i + 11, j + 0, k + 1, KMOD_Main.KetherCloud);
         world.setBlock(i + 11, j + 0, k + 2, KMOD_Main.KetherCloud);
         world.setBlock(i + 11, j + 0, k + 3, KMOD_Main.KetherCloud);
         world.setBlock(i + 11, j + 0, k + 4, KMOD_Main.KetherCloud);
         world.setBlock(i + 11, j + 0, k + 5, KMOD_Main.KetherCloud);
         world.setBlock(i + 11, j + 0, k + 6, KMOD_Main.KetherCloud);
         world.setBlock(i + 11, j + 0, k + 7, KMOD_Main.KetherCloud);
         world.setBlock(i + 11, j + 0, k + 8, KMOD_Main.KetherCloud);
         world.setBlock(i + 11, j + 0, k + 9, KMOD_Main.KetherCloud);
         world.setBlock(i + 11, j + 0, k + 10, KMOD_Main.KetherCloud);
         world.setBlock(i + 11, j + 0, k + 11, KMOD_Main.KetherCloud);
         world.setBlock(i + 11, j + 0, k + 12, KMOD_Main.KetherCloud);
         world.setBlock(i + 11, j + 0, k + 13, KMOD_Main.KetherCloud);
         world.setBlock(i + 11, j + 0, k + 14, KMOD_Main.KetherCloud);
         world.setBlock(i + 11, j + 0, k + 15, KMOD_Main.KetherCloud);
         world.setBlock(i + 11, j + 0, k + 16, KMOD_Main.KetherCloud);
         world.setBlock(i + 11, j + 0, k + 17, KMOD_Main.KetherCloud);
         world.setBlock(i + 11, j + 0, k + 18, KMOD_Main.KetherCloud);
         world.setBlock(i + 11, j + 0, k + 19, KMOD_Main.KetherCloud);
         world.setBlock(i + 11, j + 0, k + 20, KMOD_Main.KetherCloud);
         world.setBlock(i + 11, j + 0, k + 21, KMOD_Main.KetherCloud);
         world.setBlock(i + 11, j + 0, k + 22, KMOD_Main.KetherCloud);
         world.setBlock(i + 11, j + 0, k + 23, KMOD_Main.KetherCloud);
         world.setBlock(i + 11, j + 0, k + 24, KMOD_Main.KetherCloud);
         world.setBlock(i + 11, j + 0, k + 25, KMOD_Main.KetherCloud);
         world.setBlock(i + 11, j + 0, k + 26, KMOD_Main.KetherCloud);
         world.setBlock(i + 11, j + 0, k + 27, KMOD_Main.KetherCloud);
         world.setBlock(i + 11, j + 1, k + 3, KMOD_Main.CarvedScrapyBrick);
         world.setBlock(i + 11, j + 1, k + 4, KMOD_Main.ScrapyBrick);
         world.setBlock(i + 11, j + 1, k + 5, KMOD_Main.ScrapyBrick);
         world.setBlock(i + 11, j + 1, k + 6, KMOD_Main.KetherStone);
         world.setBlock(i + 11, j + 1, k + 7, KMOD_Main.KetherStone);
         world.setBlock(i + 11, j + 1, k + 8, KMOD_Main.KetherStone);
         world.setBlock(i + 11, j + 1, k + 9, KMOD_Main.KetherStone);
         world.setBlock(i + 11, j + 1, k + 10, KMOD_Main.KetherStone);
         world.setBlock(i + 11, j + 1, k + 11, KMOD_Main.KetherStone);
         world.setBlock(i + 11, j + 1, k + 12, KMOD_Main.KetherStone);
         world.setBlock(i + 11, j + 1, k + 13, KMOD_Main.KetherStone);
         world.setBlock(i + 11, j + 1, k + 14, KMOD_Main.KetherStone);
         world.setBlock(i + 11, j + 1, k + 15, KMOD_Main.KetherStone);
         world.setBlock(i + 11, j + 1, k + 16, KMOD_Main.KetherStone);
         world.setBlock(i + 11, j + 1, k + 17, KMOD_Main.KetherStone);
         world.setBlock(i + 11, j + 1, k + 18, KMOD_Main.KetherStone);
         world.setBlock(i + 11, j + 1, k + 19, KMOD_Main.ScrapyBrick);
         world.setBlock(i + 11, j + 1, k + 20, KMOD_Main.ScrapyBrick);
         world.setBlock(i + 11, j + 1, k + 21, KMOD_Main.ScrapyBrick);
         world.setBlock(i + 11, j + 1, k + 22, KMOD_Main.ScrapyBrick);
         world.setBlock(i + 11, j + 1, k + 23, KMOD_Main.ScrapyBrick);
         world.setBlock(i + 11, j + 1, k + 24, KMOD_Main.ScrapyBrick);
         world.setBlock(i + 11, j + 1, k + 25, KMOD_Main.ScrapyBrick);
         world.setBlock(i + 11, j + 1, k + 26, KMOD_Main.ScrapyBrick);
         world.setBlock(i + 11, j + 2, k + 3, KMOD_Main.CarvedScrapyBrick);
         world.setBlock(i + 11, j + 2, k + 12, Blocks.chest);
         TileEntityChest tileentitychest = (TileEntityChest)world.getTileEntity(i + 11, j + 2, k + 12);
         int RandomChestSlot1 = rand.nextInt(32);
         int RandomChestSlot2 = rand.nextInt(32);
         int RandomChestSlot3 = rand.nextInt(32);
         int RandomChestSlot4 = rand.nextInt(32);
         int RandomChestSlot5 = rand.nextInt(32);
         int RandomChestSlot6 = rand.nextInt(32);
         int RandomChestSlot7 = rand.nextInt(32);
         int RandomChestSlot8 = rand.nextInt(32);
         int RandomChestSlot9 = rand.nextInt(32);
         int RandomChestSlot10 = rand.nextInt(32);
         int ic = rand.nextInt(25);
         int ic1 = rand.nextInt(15);
         int ic2 = rand.nextInt(10);
         int ic3 = rand.nextInt(10);
         int ic4 = rand.nextInt(15);
         if (tileentitychest != null && tileentitychest.getSizeInventory() > 0) {
            ItemStack itemstack = new ItemStack(KMOD_Main.YellowFlowerEssence, ic);
            tileentitychest.setInventorySlotContents(RandomChestSlot1, itemstack);
            ItemStack itemstack1 = new ItemStack(KMOD_Main.YellowFlowerEssence, ic);
            tileentitychest.setInventorySlotContents(RandomChestSlot2, itemstack1);
            ItemStack itemstack2 = new ItemStack(KMOD_Main.YellowFlowerEssence, ic);
            tileentitychest.setInventorySlotContents(RandomChestSlot3, itemstack2);
            ItemStack itemstack4;
            if (rand.nextInt(2) == 1) {
               itemstack4 = new ItemStack(KMOD_Main.JumpBoots, 1);
               tileentitychest.setInventorySlotContents(RandomChestSlot3, itemstack4);
            }

            itemstack4 = new ItemStack(KMOD_Main.KetherEnergy, ic1);
            tileentitychest.setInventorySlotContents(RandomChestSlot4, itemstack4);
            ItemStack itemstack5 = new ItemStack(KMOD_Main.RubyGem, ic2);
            tileentitychest.setInventorySlotContents(RandomChestSlot5, itemstack5);
            ItemStack itemstack6 = new ItemStack(KMOD_Main.TopazGem, ic2);
            tileentitychest.setInventorySlotContents(RandomChestSlot6, itemstack6);
            ItemStack itemstack7 = new ItemStack(KMOD_Main.SapphireGem, ic2);
            tileentitychest.setInventorySlotContents(RandomChestSlot7, itemstack7);
            ItemStack itemstack10;
            if (rand.nextInt(2) == 1) {
               itemstack10 = new ItemStack(KMOD_Main.DemonEyeSummoner, 1);
               tileentitychest.setInventorySlotContents(RandomChestSlot8, itemstack10);
            }

            if (rand.nextInt(5) == 1) {
               itemstack10 = new ItemStack(KMOD_Main.KetherWand, 1);
               tileentitychest.setInventorySlotContents(RandomChestSlot9, itemstack10);
            }

            itemstack10 = new ItemStack(KMOD_Main.Pytajnik, 1);
            tileentitychest.setInventorySlotContents(RandomChestSlot10, itemstack10);
         }

         world.setBlock(i + 11, j + 3, k + 3, KMOD_Main.CarvedScrapyBrick);
         world.setBlock(i + 11, j + 4, k + 3, KMOD_Main.CarvedScrapyBrick);
         world.setBlock(i + 11, j + 5, k + 4, KMOD_Main.CarvedScrapyBrick);
         world.setBlock(i + 11, j + 5, k + 26, Blocks.glowstone);
         world.setBlock(i + 11, j + 6, k + 5, KMOD_Main.CarvedScrapyBrick);
         world.setBlock(i + 11, j + 6, k + 19, KMOD_Main.CarvedScrapyBrick);
         world.setBlock(i + 11, j + 6, k + 20, KMOD_Main.CarvedScrapyBrick);
         world.setBlock(i + 11, j + 6, k + 21, KMOD_Main.CarvedScrapyBrick);
         world.setBlock(i + 11, j + 6, k + 22, KMOD_Main.CarvedScrapyBrick);
         world.setBlock(i + 11, j + 6, k + 23, KMOD_Main.CarvedScrapyBrick);
         world.setBlock(i + 11, j + 6, k + 24, KMOD_Main.CarvedScrapyBrick);
         world.setBlock(i + 11, j + 6, k + 25, KMOD_Main.CarvedScrapyBrick);
         world.setBlock(i + 11, j + 6, k + 26, KMOD_Main.CarvedScrapyBrick);
         world.setBlock(i + 11, j + 7, k + 6, KMOD_Main.CarvedScrapyBrick);
         world.setBlock(i + 11, j + 7, k + 18, KMOD_Main.CarvedScrapyBrick);
         world.setBlock(i + 11, j + 8, k + 7, KMOD_Main.CarvedScrapyBrick);
         world.setBlock(i + 11, j + 8, k + 17, KMOD_Main.CarvedScrapyBrick);
         world.setBlock(i + 11, j + 9, k + 8, KMOD_Main.CarvedScrapyBrick);
         world.setBlock(i + 11, j + 9, k + 16, KMOD_Main.CarvedScrapyBrick);
         world.setBlock(i + 11, j + 10, k + 9, KMOD_Main.CarvedScrapyBrick);
         world.setBlock(i + 11, j + 10, k + 15, KMOD_Main.CarvedScrapyBrick);
         world.setBlock(i + 11, j + 11, k + 10, KMOD_Main.CarvedScrapyBrick);
         world.setBlock(i + 11, j + 11, k + 14, KMOD_Main.CarvedScrapyBrick);
         world.setBlock(i + 11, j + 12, k + 11, KMOD_Main.CarvedScrapyBrick);
         world.setBlock(i + 11, j + 12, k + 12, Blocks.glowstone);
         world.setBlock(i + 11, j + 12, k + 13, KMOD_Main.CarvedScrapyBrick);
         world.setBlock(i + 11, j + 13, k + 12, KMOD_Main.CarvedScrapyBrick);
         world.setBlock(i + 12, j + 0, k + 2, KMOD_Main.KetherCloud);
         world.setBlock(i + 12, j + 0, k + 3, KMOD_Main.KetherCloud);
         world.setBlock(i + 12, j + 0, k + 4, KMOD_Main.KetherCloud);
         world.setBlock(i + 12, j + 0, k + 5, KMOD_Main.KetherCloud);
         world.setBlock(i + 12, j + 0, k + 6, KMOD_Main.KetherCloud);
         world.setBlock(i + 12, j + 0, k + 7, KMOD_Main.KetherCloud);
         world.setBlock(i + 12, j + 0, k + 8, KMOD_Main.KetherCloud);
         world.setBlock(i + 12, j + 0, k + 9, KMOD_Main.KetherCloud);
         world.setBlock(i + 12, j + 0, k + 10, KMOD_Main.KetherCloud);
         world.setBlock(i + 12, j + 0, k + 11, KMOD_Main.KetherCloud);
         world.setBlock(i + 12, j + 0, k + 12, KMOD_Main.KetherCloud);
         world.setBlock(i + 12, j + 0, k + 13, KMOD_Main.KetherCloud);
         world.setBlock(i + 12, j + 0, k + 14, KMOD_Main.KetherCloud);
         world.setBlock(i + 12, j + 0, k + 15, KMOD_Main.KetherCloud);
         world.setBlock(i + 12, j + 0, k + 16, KMOD_Main.KetherCloud);
         world.setBlock(i + 12, j + 0, k + 17, KMOD_Main.KetherCloud);
         world.setBlock(i + 12, j + 0, k + 18, KMOD_Main.KetherCloud);
         world.setBlock(i + 12, j + 0, k + 19, KMOD_Main.KetherCloud);
         world.setBlock(i + 12, j + 0, k + 20, KMOD_Main.KetherCloud);
         world.setBlock(i + 12, j + 0, k + 21, KMOD_Main.KetherCloud);
         world.setBlock(i + 12, j + 0, k + 22, KMOD_Main.KetherCloud);
         world.setBlock(i + 12, j + 0, k + 23, KMOD_Main.KetherCloud);
         world.setBlock(i + 12, j + 0, k + 24, KMOD_Main.KetherCloud);
         world.setBlock(i + 12, j + 0, k + 25, KMOD_Main.KetherCloud);
         world.setBlock(i + 12, j + 0, k + 26, KMOD_Main.KetherCloud);
         world.setBlock(i + 12, j + 0, k + 27, KMOD_Main.KetherCloud);
         world.setBlock(i + 12, j + 1, k + 0, KMOD_Main.KetherCloud);
         world.setBlock(i + 12, j + 1, k + 1, KMOD_Main.KetherCloud);
         world.setBlock(i + 12, j + 1, k + 2, KMOD_Main.KetherCloud);
         world.setBlock(i + 12, j + 1, k + 4, KMOD_Main.CarvedScrapyBrick);
         world.setBlock(i + 12, j + 1, k + 5, KMOD_Main.ScrapyBrick);
         world.setBlock(i + 12, j + 1, k + 6, KMOD_Main.ScrapyBrick);
         world.setBlock(i + 12, j + 1, k + 7, KMOD_Main.KetherStone);
         world.setBlock(i + 12, j + 1, k + 8, KMOD_Main.KetherStone);
         world.setBlock(i + 12, j + 1, k + 9, KMOD_Main.KetherStone);
         world.setBlock(i + 12, j + 1, k + 10, KMOD_Main.KetherStone);
         world.setBlock(i + 12, j + 1, k + 11, KMOD_Main.KetherStone);
         world.setBlock(i + 12, j + 1, k + 12, KMOD_Main.KetherStone);
         world.setBlock(i + 12, j + 1, k + 13, KMOD_Main.KetherStone);
         world.setBlock(i + 12, j + 1, k + 14, KMOD_Main.KetherStone);
         world.setBlock(i + 12, j + 1, k + 15, KMOD_Main.KetherStone);
         world.setBlock(i + 12, j + 1, k + 16, KMOD_Main.KetherStone);
         world.setBlock(i + 12, j + 1, k + 17, KMOD_Main.KetherStone);
         world.setBlock(i + 12, j + 1, k + 18, KMOD_Main.ScrapyBrick);
         world.setBlock(i + 12, j + 1, k + 19, KMOD_Main.ScrapyBrick);
         world.setBlock(i + 12, j + 1, k + 20, KMOD_Main.ScrapyBrick);
         world.setBlock(i + 12, j + 1, k + 21, KMOD_Main.ScrapyBrick);
         world.setBlock(i + 12, j + 1, k + 22, KMOD_Main.ScrapyBrick);
         world.setBlock(i + 12, j + 1, k + 23, KMOD_Main.ScrapyBrick);
         world.setBlock(i + 12, j + 1, k + 24, KMOD_Main.ScrapyBrick);
         world.setBlock(i + 12, j + 1, k + 25, KMOD_Main.ScrapyBrick);
         world.setBlock(i + 12, j + 1, k + 26, KMOD_Main.ScrapyBrick);
         world.setBlock(i + 12, j + 2, k + 4, KMOD_Main.CarvedScrapyBrick);
         world.setBlock(i + 12, j + 3, k + 4, KMOD_Main.CarvedScrapyBrick);
         world.setBlock(i + 12, j + 4, k + 4, KMOD_Main.CarvedScrapyBrick);
         world.setBlock(i + 12, j + 4, k + 26, Blocks.glowstone);
         world.setBlock(i + 12, j + 5, k + 5, KMOD_Main.CarvedScrapyBrick);
         world.setBlock(i + 12, j + 5, k + 19, KMOD_Main.CarvedScrapyBrick);
         world.setBlock(i + 12, j + 5, k + 20, KMOD_Main.CarvedScrapyBrick);
         world.setBlock(i + 12, j + 5, k + 21, KMOD_Main.CarvedScrapyBrick);
         world.setBlock(i + 12, j + 5, k + 22, KMOD_Main.CarvedScrapyBrick);
         world.setBlock(i + 12, j + 5, k + 23, KMOD_Main.CarvedScrapyBrick);
         world.setBlock(i + 12, j + 5, k + 24, KMOD_Main.CarvedScrapyBrick);
         world.setBlock(i + 12, j + 5, k + 25, KMOD_Main.CarvedScrapyBrick);
         world.setBlock(i + 12, j + 5, k + 26, KMOD_Main.CarvedScrapyBrick);
         world.setBlock(i + 12, j + 6, k + 6, KMOD_Main.CarvedScrapyBrick);
         world.setBlock(i + 12, j + 6, k + 18, KMOD_Main.CarvedScrapyBrick);
         world.setBlock(i + 12, j + 7, k + 7, KMOD_Main.CarvedScrapyBrick);
         world.setBlock(i + 12, j + 7, k + 17, KMOD_Main.CarvedScrapyBrick);
         world.setBlock(i + 12, j + 8, k + 8, KMOD_Main.CarvedScrapyBrick);
         world.setBlock(i + 12, j + 8, k + 16, KMOD_Main.CarvedScrapyBrick);
         world.setBlock(i + 12, j + 9, k + 9, KMOD_Main.CarvedScrapyBrick);
         world.setBlock(i + 12, j + 9, k + 10, Blocks.glowstone);
         world.setBlock(i + 12, j + 9, k + 14, Blocks.glowstone);
         world.setBlock(i + 12, j + 9, k + 15, KMOD_Main.CarvedScrapyBrick);
         world.setBlock(i + 12, j + 10, k + 10, KMOD_Main.CarvedScrapyBrick);
         world.setBlock(i + 12, j + 10, k + 11, Blocks.glowstone);
         world.setBlock(i + 12, j + 10, k + 13, Blocks.glowstone);
         world.setBlock(i + 12, j + 10, k + 14, KMOD_Main.CarvedScrapyBrick);
         world.setBlock(i + 12, j + 11, k + 11, KMOD_Main.CarvedScrapyBrick);
         world.setBlock(i + 12, j + 11, k + 13, KMOD_Main.CarvedScrapyBrick);
         world.setBlock(i + 12, j + 12, k + 12, KMOD_Main.CarvedScrapyBrick);
         world.setBlock(i + 13, j + 0, k + 2, KMOD_Main.KetherCloud);
         world.setBlock(i + 13, j + 0, k + 4, KMOD_Main.KetherCloud);
         world.setBlock(i + 13, j + 0, k + 5, KMOD_Main.KetherCloud);
         world.setBlock(i + 13, j + 0, k + 6, KMOD_Main.KetherCloud);
         world.setBlock(i + 13, j + 0, k + 7, KMOD_Main.KetherCloud);
         world.setBlock(i + 13, j + 0, k + 8, KMOD_Main.KetherCloud);
         world.setBlock(i + 13, j + 0, k + 9, KMOD_Main.KetherCloud);
         world.setBlock(i + 13, j + 0, k + 10, KMOD_Main.KetherCloud);
         world.setBlock(i + 13, j + 0, k + 11, KMOD_Main.KetherCloud);
         world.setBlock(i + 13, j + 0, k + 12, KMOD_Main.KetherCloud);
         world.setBlock(i + 13, j + 0, k + 13, KMOD_Main.KetherCloud);
         world.setBlock(i + 13, j + 0, k + 14, KMOD_Main.KetherCloud);
         world.setBlock(i + 13, j + 0, k + 15, KMOD_Main.KetherCloud);
         world.setBlock(i + 13, j + 0, k + 16, KMOD_Main.KetherCloud);
         world.setBlock(i + 13, j + 0, k + 17, KMOD_Main.KetherCloud);
         world.setBlock(i + 13, j + 0, k + 18, KMOD_Main.KetherCloud);
         world.setBlock(i + 13, j + 0, k + 19, KMOD_Main.KetherCloud);
         world.setBlock(i + 13, j + 0, k + 20, KMOD_Main.KetherCloud);
         world.setBlock(i + 13, j + 0, k + 21, KMOD_Main.KetherCloud);
         world.setBlock(i + 13, j + 0, k + 22, KMOD_Main.KetherCloud);
         world.setBlock(i + 13, j + 0, k + 23, KMOD_Main.KetherCloud);
         world.setBlock(i + 13, j + 0, k + 24, KMOD_Main.KetherCloud);
         world.setBlock(i + 13, j + 0, k + 25, KMOD_Main.KetherCloud);
         world.setBlock(i + 13, j + 0, k + 26, KMOD_Main.KetherCloud);
         world.setBlock(i + 13, j + 0, k + 27, KMOD_Main.KetherCloud);
         world.setBlock(i + 13, j + 1, k + 1, KMOD_Main.KetherCloud);
         world.setBlock(i + 13, j + 1, k + 5, KMOD_Main.CarvedScrapyBrick);
         world.setBlock(i + 13, j + 1, k + 6, KMOD_Main.ScrapyBrick);
         world.setBlock(i + 13, j + 1, k + 7, KMOD_Main.ScrapyBrick);
         world.setBlock(i + 13, j + 1, k + 8, KMOD_Main.KetherStone);
         world.setBlock(i + 13, j + 1, k + 9, KMOD_Main.KetherStone);
         world.setBlock(i + 13, j + 1, k + 10, KMOD_Main.KetherStone);
         world.setBlock(i + 13, j + 1, k + 11, KMOD_Main.KetherStone);
         world.setBlock(i + 13, j + 1, k + 12, KMOD_Main.KetherStone);
         world.setBlock(i + 13, j + 1, k + 13, KMOD_Main.KetherStone);
         world.setBlock(i + 13, j + 1, k + 14, KMOD_Main.KetherStone);
         world.setBlock(i + 13, j + 1, k + 15, KMOD_Main.KetherStone);
         world.setBlock(i + 13, j + 1, k + 16, KMOD_Main.KetherStone);
         world.setBlock(i + 13, j + 1, k + 17, KMOD_Main.ScrapyBrick);
         world.setBlock(i + 13, j + 1, k + 18, KMOD_Main.ScrapyBrick);
         world.setBlock(i + 13, j + 1, k + 19, KMOD_Main.CarvedScrapyBrick);
         world.setBlock(i + 13, j + 1, k + 20, KMOD_Main.CarvedScrapyBrick);
         world.setBlock(i + 13, j + 1, k + 21, KMOD_Main.CarvedScrapyBrick);
         world.setBlock(i + 13, j + 1, k + 22, KMOD_Main.CarvedScrapyBrick);
         world.setBlock(i + 13, j + 1, k + 23, KMOD_Main.CarvedScrapyBrick);
         world.setBlock(i + 13, j + 1, k + 24, KMOD_Main.CarvedScrapyBrick);
         world.setBlock(i + 13, j + 1, k + 25, KMOD_Main.CarvedScrapyBrick);
         world.setBlock(i + 13, j + 1, k + 26, KMOD_Main.CarvedScrapyBrick);
         world.setBlock(i + 13, j + 2, k + 5, KMOD_Main.CarvedScrapyBrick);
         world.setBlock(i + 13, j + 2, k + 19, KMOD_Main.CarvedScrapyBrick);
         world.setBlock(i + 13, j + 2, k + 20, KMOD_Main.CarvedScrapyBrick);
         world.setBlock(i + 13, j + 2, k + 21, KMOD_Main.CarvedScrapyBrick);
         world.setBlock(i + 13, j + 2, k + 22, KMOD_Main.CarvedScrapyBrick);
         world.setBlock(i + 13, j + 2, k + 23, KMOD_Main.CarvedScrapyBrick);
         world.setBlock(i + 13, j + 2, k + 24, KMOD_Main.CarvedScrapyBrick);
         world.setBlock(i + 13, j + 2, k + 25, KMOD_Main.CarvedScrapyBrick);
         world.setBlock(i + 13, j + 2, k + 26, KMOD_Main.CarvedScrapyBrick);
         world.setBlock(i + 13, j + 3, k + 5, KMOD_Main.CarvedScrapyBrick);
         world.setBlock(i + 13, j + 3, k + 19, KMOD_Main.CarvedScrapyBrick);
         world.setBlock(i + 13, j + 3, k + 20, KMOD_Main.CarvedScrapyBrick);
         world.setBlock(i + 13, j + 3, k + 21, KMOD_Main.CarvedScrapyBrick);
         world.setBlock(i + 13, j + 3, k + 22, KMOD_Main.CarvedScrapyBrick);
         world.setBlock(i + 13, j + 3, k + 23, KMOD_Main.CarvedScrapyBrick);
         world.setBlock(i + 13, j + 3, k + 24, KMOD_Main.CarvedScrapyBrick);
         world.setBlock(i + 13, j + 3, k + 25, KMOD_Main.CarvedScrapyBrick);
         world.setBlock(i + 13, j + 3, k + 26, KMOD_Main.CarvedScrapyBrick);
         world.setBlock(i + 13, j + 4, k + 5, KMOD_Main.CarvedScrapyBrick);
         world.setBlock(i + 13, j + 4, k + 19, KMOD_Main.CarvedScrapyBrick);
         world.setBlock(i + 13, j + 4, k + 20, KMOD_Main.CarvedScrapyBrick);
         world.setBlock(i + 13, j + 4, k + 21, KMOD_Main.CarvedScrapyBrick);
         world.setBlock(i + 13, j + 4, k + 22, KMOD_Main.CarvedScrapyBrick);
         world.setBlock(i + 13, j + 4, k + 23, KMOD_Main.CarvedScrapyBrick);
         world.setBlock(i + 13, j + 4, k + 24, KMOD_Main.CarvedScrapyBrick);
         world.setBlock(i + 13, j + 4, k + 25, KMOD_Main.CarvedScrapyBrick);
         world.setBlock(i + 13, j + 4, k + 26, KMOD_Main.CarvedScrapyBrick);
         world.setBlock(i + 13, j + 5, k + 6, KMOD_Main.CarvedScrapyBrick);
         world.setBlock(i + 13, j + 5, k + 18, KMOD_Main.CarvedScrapyBrick);
         world.setBlock(i + 13, j + 5, k + 25, KMOD_Main.CarvedScrapyBrick);
         world.setBlock(i + 13, j + 6, k + 7, KMOD_Main.CarvedScrapyBrick);
         world.setBlock(i + 13, j + 6, k + 17, KMOD_Main.CarvedScrapyBrick);
         world.setBlock(i + 13, j + 7, k + 8, KMOD_Main.CarvedScrapyBrick);
         world.setBlock(i + 13, j + 7, k + 16, KMOD_Main.CarvedScrapyBrick);
         world.setBlock(i + 13, j + 8, k + 9, KMOD_Main.CarvedScrapyBrick);
         world.setBlock(i + 13, j + 8, k + 15, KMOD_Main.CarvedScrapyBrick);
         world.setBlock(i + 13, j + 9, k + 10, KMOD_Main.CarvedScrapyBrick);
         world.setBlock(i + 13, j + 9, k + 11, Blocks.glowstone);
         world.setBlock(i + 13, j + 9, k + 13, Blocks.glowstone);
         world.setBlock(i + 13, j + 9, k + 14, KMOD_Main.CarvedScrapyBrick);
         world.setBlock(i + 13, j + 10, k + 11, KMOD_Main.CarvedScrapyBrick);
         world.setBlock(i + 13, j + 10, k + 13, KMOD_Main.CarvedScrapyBrick);
         world.setBlock(i + 13, j + 11, k + 12, KMOD_Main.CarvedScrapyBrick);
         world.setBlock(i + 14, j + 0, k + 3, KMOD_Main.KetherCloud);
         world.setBlock(i + 14, j + 0, k + 4, KMOD_Main.KetherCloud);
         world.setBlock(i + 14, j + 0, k + 5, KMOD_Main.KetherCloud);
         world.setBlock(i + 14, j + 0, k + 6, KMOD_Main.KetherCloud);
         world.setBlock(i + 14, j + 0, k + 7, KMOD_Main.KetherCloud);
         world.setBlock(i + 14, j + 0, k + 8, KMOD_Main.KetherCloud);
         world.setBlock(i + 14, j + 0, k + 9, KMOD_Main.KetherCloud);
         world.setBlock(i + 14, j + 0, k + 10, KMOD_Main.KetherCloud);
         world.setBlock(i + 14, j + 0, k + 11, KMOD_Main.KetherCloud);
         world.setBlock(i + 14, j + 0, k + 12, KMOD_Main.KetherCloud);
         world.setBlock(i + 14, j + 0, k + 13, KMOD_Main.KetherCloud);
         world.setBlock(i + 14, j + 0, k + 14, KMOD_Main.KetherCloud);
         world.setBlock(i + 14, j + 0, k + 15, KMOD_Main.KetherCloud);
         world.setBlock(i + 14, j + 0, k + 16, KMOD_Main.KetherCloud);
         world.setBlock(i + 14, j + 0, k + 17, KMOD_Main.KetherCloud);
         world.setBlock(i + 14, j + 0, k + 18, KMOD_Main.KetherCloud);
         world.setBlock(i + 14, j + 0, k + 19, KMOD_Main.KetherCloud);
         world.setBlock(i + 14, j + 0, k + 20, KMOD_Main.KetherCloud);
         world.setBlock(i + 14, j + 0, k + 21, KMOD_Main.KetherCloud);
         world.setBlock(i + 14, j + 0, k + 22, KMOD_Main.KetherCloud);
         world.setBlock(i + 14, j + 0, k + 23, KMOD_Main.KetherCloud);
         world.setBlock(i + 14, j + 0, k + 24, KMOD_Main.KetherCloud);
         world.setBlock(i + 14, j + 0, k + 25, KMOD_Main.KetherCloud);
         world.setBlock(i + 14, j + 0, k + 26, KMOD_Main.KetherCloud);
         world.setBlock(i + 14, j + 0, k + 27, KMOD_Main.KetherCloud);
         world.setBlock(i + 14, j + 1, k + 4, KMOD_Main.KetherCloud);
         world.setBlock(i + 14, j + 1, k + 6, KMOD_Main.CarvedScrapyBrick);
         world.setBlock(i + 14, j + 1, k + 7, KMOD_Main.ScrapyBrick);
         world.setBlock(i + 14, j + 1, k + 8, KMOD_Main.ScrapyBrick);
         world.setBlock(i + 14, j + 1, k + 9, KMOD_Main.KetherStone);
         world.setBlock(i + 14, j + 1, k + 10, KMOD_Main.KetherStone);
         world.setBlock(i + 14, j + 1, k + 11, KMOD_Main.KetherStone);
         world.setBlock(i + 14, j + 1, k + 12, KMOD_Main.KetherStone);
         world.setBlock(i + 14, j + 1, k + 13, KMOD_Main.KetherStone);
         world.setBlock(i + 14, j + 1, k + 14, KMOD_Main.KetherStone);
         world.setBlock(i + 14, j + 1, k + 15, KMOD_Main.KetherStone);
         world.setBlock(i + 14, j + 1, k + 16, KMOD_Main.ScrapyBrick);
         world.setBlock(i + 14, j + 1, k + 17, KMOD_Main.ScrapyBrick);
         world.setBlock(i + 14, j + 1, k + 18, KMOD_Main.CarvedScrapyBrick);
         world.setBlock(i + 14, j + 1, k + 22, KMOD_Main.KetherCloud);
         world.setBlock(i + 14, j + 1, k + 23, KMOD_Main.KetherCloud);
         world.setBlock(i + 14, j + 1, k + 24, KMOD_Main.KetherCloud);
         world.setBlock(i + 14, j + 1, k + 25, KMOD_Main.KetherCloud);
         world.setBlock(i + 14, j + 2, k + 6, KMOD_Main.CarvedScrapyBrick);
         world.setBlock(i + 14, j + 2, k + 18, KMOD_Main.CarvedScrapyBrick);
         world.setBlock(i + 14, j + 3, k + 6, KMOD_Main.CarvedScrapyBrick);
         world.setBlock(i + 14, j + 3, k + 18, KMOD_Main.CarvedScrapyBrick);
         world.setBlock(i + 14, j + 4, k + 6, KMOD_Main.CarvedScrapyBrick);
         world.setBlock(i + 14, j + 4, k + 18, KMOD_Main.CarvedScrapyBrick);
         world.setBlock(i + 14, j + 5, k + 7, KMOD_Main.CarvedScrapyBrick);
         world.setBlock(i + 14, j + 5, k + 17, KMOD_Main.CarvedScrapyBrick);
         world.setBlock(i + 14, j + 6, k + 8, KMOD_Main.CarvedScrapyBrick);
         world.setBlock(i + 14, j + 6, k + 16, KMOD_Main.CarvedScrapyBrick);
         world.setBlock(i + 14, j + 7, k + 9, KMOD_Main.CarvedScrapyBrick);
         world.setBlock(i + 14, j + 7, k + 15, KMOD_Main.CarvedScrapyBrick);
         world.setBlock(i + 14, j + 8, k + 10, KMOD_Main.CarvedScrapyBrick);
         world.setBlock(i + 14, j + 8, k + 14, KMOD_Main.CarvedScrapyBrick);
         world.setBlock(i + 14, j + 9, k + 11, KMOD_Main.CarvedScrapyBrick);
         world.setBlock(i + 14, j + 9, k + 13, KMOD_Main.CarvedScrapyBrick);
         world.setBlock(i + 14, j + 10, k + 12, KMOD_Main.CarvedScrapyBrick);
         world.setBlock(i + 15, j + 0, k + 5, KMOD_Main.KetherCloud);
         world.setBlock(i + 15, j + 0, k + 6, KMOD_Main.KetherCloud);
         world.setBlock(i + 15, j + 0, k + 7, KMOD_Main.KetherCloud);
         world.setBlock(i + 15, j + 0, k + 8, KMOD_Main.KetherCloud);
         world.setBlock(i + 15, j + 0, k + 9, KMOD_Main.KetherCloud);
         world.setBlock(i + 15, j + 0, k + 10, KMOD_Main.KetherCloud);
         world.setBlock(i + 15, j + 0, k + 11, KMOD_Main.KetherCloud);
         world.setBlock(i + 15, j + 0, k + 12, KMOD_Main.KetherCloud);
         world.setBlock(i + 15, j + 0, k + 13, KMOD_Main.KetherCloud);
         world.setBlock(i + 15, j + 0, k + 14, KMOD_Main.KetherCloud);
         world.setBlock(i + 15, j + 0, k + 15, KMOD_Main.KetherCloud);
         world.setBlock(i + 15, j + 0, k + 16, KMOD_Main.KetherCloud);
         world.setBlock(i + 15, j + 0, k + 17, KMOD_Main.KetherCloud);
         world.setBlock(i + 15, j + 0, k + 18, KMOD_Main.KetherCloud);
         world.setBlock(i + 15, j + 0, k + 19, KMOD_Main.KetherCloud);
         world.setBlock(i + 15, j + 0, k + 20, KMOD_Main.KetherCloud);
         world.setBlock(i + 15, j + 0, k + 21, KMOD_Main.KetherCloud);
         world.setBlock(i + 15, j + 0, k + 22, KMOD_Main.KetherCloud);
         world.setBlock(i + 15, j + 0, k + 23, KMOD_Main.KetherCloud);
         world.setBlock(i + 15, j + 0, k + 24, KMOD_Main.KetherCloud);
         world.setBlock(i + 15, j + 0, k + 25, KMOD_Main.KetherCloud);
         world.setBlock(i + 15, j + 0, k + 26, KMOD_Main.KetherCloud);
         world.setBlock(i + 15, j + 1, k + 5, KMOD_Main.KetherCloud);
         world.setBlock(i + 15, j + 1, k + 7, KMOD_Main.CarvedScrapyBrick);
         world.setBlock(i + 15, j + 1, k + 8, KMOD_Main.ScrapyBrick);
         world.setBlock(i + 15, j + 1, k + 9, KMOD_Main.ScrapyBrick);
         world.setBlock(i + 15, j + 1, k + 10, KMOD_Main.KetherStone);
         world.setBlock(i + 15, j + 1, k + 11, KMOD_Main.KetherStone);
         world.setBlock(i + 15, j + 1, k + 12, KMOD_Main.KetherStone);
         world.setBlock(i + 15, j + 1, k + 13, KMOD_Main.KetherStone);
         world.setBlock(i + 15, j + 1, k + 14, KMOD_Main.KetherStone);
         world.setBlock(i + 15, j + 1, k + 15, KMOD_Main.ScrapyBrick);
         world.setBlock(i + 15, j + 1, k + 16, KMOD_Main.ScrapyBrick);
         world.setBlock(i + 15, j + 1, k + 17, KMOD_Main.CarvedScrapyBrick);
         world.setBlock(i + 15, j + 1, k + 20, KMOD_Main.KetherCloud);
         world.setBlock(i + 15, j + 1, k + 21, KMOD_Main.KetherCloud);
         world.setBlock(i + 15, j + 1, k + 23, KMOD_Main.KetherCloud);
         world.setBlock(i + 15, j + 1, k + 24, KMOD_Main.KetherCloud);
         world.setBlock(i + 15, j + 1, k + 26, KMOD_Main.KetherCloud);
         world.setBlock(i + 15, j + 2, k + 7, KMOD_Main.CarvedScrapyBrick);
         world.setBlock(i + 15, j + 2, k + 17, KMOD_Main.CarvedScrapyBrick);
         world.setBlock(i + 15, j + 3, k + 7, KMOD_Main.CarvedScrapyBrick);
         world.setBlock(i + 15, j + 3, k + 17, KMOD_Main.CarvedScrapyBrick);
         world.setBlock(i + 15, j + 4, k + 7, KMOD_Main.CarvedScrapyBrick);
         world.setBlock(i + 15, j + 4, k + 17, KMOD_Main.CarvedScrapyBrick);
         world.setBlock(i + 15, j + 5, k + 8, KMOD_Main.CarvedScrapyBrick);
         world.setBlock(i + 15, j + 5, k + 16, KMOD_Main.CarvedScrapyBrick);
         world.setBlock(i + 15, j + 6, k + 9, KMOD_Main.CarvedScrapyBrick);
         world.setBlock(i + 15, j + 6, k + 15, KMOD_Main.CarvedScrapyBrick);
         world.setBlock(i + 15, j + 7, k + 10, KMOD_Main.CarvedScrapyBrick);
         world.setBlock(i + 15, j + 7, k + 14, KMOD_Main.CarvedScrapyBrick);
         world.setBlock(i + 15, j + 8, k + 11, KMOD_Main.CarvedScrapyBrick);
         world.setBlock(i + 15, j + 8, k + 13, KMOD_Main.CarvedScrapyBrick);
         world.setBlock(i + 15, j + 9, k + 12, KMOD_Main.CarvedScrapyBrick);
         world.setBlock(i + 16, j + 0, k + 6, KMOD_Main.KetherCloud);
         world.setBlock(i + 16, j + 0, k + 7, KMOD_Main.KetherCloud);
         world.setBlock(i + 16, j + 0, k + 8, KMOD_Main.KetherCloud);
         world.setBlock(i + 16, j + 0, k + 9, KMOD_Main.KetherCloud);
         world.setBlock(i + 16, j + 0, k + 10, KMOD_Main.KetherCloud);
         world.setBlock(i + 16, j + 0, k + 11, KMOD_Main.KetherCloud);
         world.setBlock(i + 16, j + 0, k + 12, KMOD_Main.KetherCloud);
         world.setBlock(i + 16, j + 0, k + 13, KMOD_Main.KetherCloud);
         world.setBlock(i + 16, j + 0, k + 14, KMOD_Main.KetherCloud);
         world.setBlock(i + 16, j + 0, k + 15, KMOD_Main.KetherCloud);
         world.setBlock(i + 16, j + 0, k + 16, KMOD_Main.KetherCloud);
         world.setBlock(i + 16, j + 0, k + 17, KMOD_Main.KetherCloud);
         world.setBlock(i + 16, j + 0, k + 18, KMOD_Main.KetherCloud);
         world.setBlock(i + 16, j + 0, k + 26, KMOD_Main.KetherCloud);
         world.setBlock(i + 16, j + 1, k + 6, KMOD_Main.KetherCloud);
         world.setBlock(i + 16, j + 1, k + 8, KMOD_Main.CarvedScrapyBrick);
         world.setBlock(i + 16, j + 1, k + 9, KMOD_Main.ScrapyBrick);
         world.setBlock(i + 16, j + 1, k + 10, KMOD_Main.ScrapyBrick);
         world.setBlock(i + 16, j + 1, k + 11, KMOD_Main.KetherStone);
         world.setBlock(i + 16, j + 1, k + 12, KMOD_Main.KetherStone);
         world.setBlock(i + 16, j + 1, k + 13, KMOD_Main.KetherStone);
         world.setBlock(i + 16, j + 1, k + 14, KMOD_Main.ScrapyBrick);
         world.setBlock(i + 16, j + 1, k + 15, KMOD_Main.ScrapyBrick);
         world.setBlock(i + 16, j + 1, k + 16, KMOD_Main.CarvedScrapyBrick);
         world.setBlock(i + 16, j + 1, k + 18, KMOD_Main.KetherCloud);
         world.setBlock(i + 16, j + 1, k + 20, KMOD_Main.KetherCloud);
         world.setBlock(i + 16, j + 1, k + 24, KMOD_Main.KetherCloud);
         world.setBlock(i + 16, j + 2, k + 8, KMOD_Main.CarvedScrapyBrick);
         world.setBlock(i + 16, j + 2, k + 16, KMOD_Main.CarvedScrapyBrick);
         world.setBlock(i + 16, j + 3, k + 8, KMOD_Main.CarvedScrapyBrick);
         world.setBlock(i + 16, j + 3, k + 16, KMOD_Main.CarvedScrapyBrick);
         world.setBlock(i + 16, j + 4, k + 8, KMOD_Main.CarvedScrapyBrick);
         world.setBlock(i + 16, j + 4, k + 16, KMOD_Main.CarvedScrapyBrick);
         world.setBlock(i + 16, j + 5, k + 9, KMOD_Main.CarvedScrapyBrick);
         world.setBlock(i + 16, j + 5, k + 15, KMOD_Main.CarvedScrapyBrick);
         world.setBlock(i + 16, j + 6, k + 10, KMOD_Main.CarvedScrapyBrick);
         world.setBlock(i + 16, j + 6, k + 14, KMOD_Main.CarvedScrapyBrick);
         world.setBlock(i + 16, j + 7, k + 11, KMOD_Main.CarvedScrapyBrick);
         world.setBlock(i + 16, j + 7, k + 13, KMOD_Main.CarvedScrapyBrick);
         world.setBlock(i + 16, j + 8, k + 12, KMOD_Main.CarvedScrapyBrick);
         world.setBlock(i + 17, j + 0, k + 8, KMOD_Main.KetherCloud);
         world.setBlock(i + 17, j + 0, k + 9, KMOD_Main.KetherCloud);
         world.setBlock(i + 17, j + 0, k + 10, KMOD_Main.KetherCloud);
         world.setBlock(i + 17, j + 0, k + 11, KMOD_Main.KetherCloud);
         world.setBlock(i + 17, j + 0, k + 12, KMOD_Main.KetherCloud);
         world.setBlock(i + 17, j + 0, k + 13, KMOD_Main.KetherCloud);
         world.setBlock(i + 17, j + 0, k + 14, KMOD_Main.KetherCloud);
         world.setBlock(i + 17, j + 0, k + 15, KMOD_Main.KetherCloud);
         world.setBlock(i + 17, j + 0, k + 16, KMOD_Main.KetherCloud);
         world.setBlock(i + 17, j + 1, k + 9, KMOD_Main.CarvedScrapyBrick);
         world.setBlock(i + 17, j + 1, k + 10, KMOD_Main.ScrapyBrick);
         world.setBlock(i + 17, j + 1, k + 11, KMOD_Main.ScrapyBrick);
         world.setBlock(i + 17, j + 1, k + 12, KMOD_Main.KetherStone);
         world.setBlock(i + 17, j + 1, k + 13, KMOD_Main.ScrapyBrick);
         world.setBlock(i + 17, j + 1, k + 14, KMOD_Main.ScrapyBrick);
         world.setBlock(i + 17, j + 1, k + 15, KMOD_Main.CarvedScrapyBrick);
         world.setBlock(i + 17, j + 1, k + 16, KMOD_Main.KetherCloud);
         world.setBlock(i + 17, j + 1, k + 17, KMOD_Main.KetherCloud);
         world.setBlock(i + 17, j + 1, k + 18, KMOD_Main.KetherCloud);
         world.setBlock(i + 17, j + 2, k + 9, KMOD_Main.CarvedScrapyBrick);
         world.setBlock(i + 17, j + 2, k + 15, KMOD_Main.CarvedScrapyBrick);
         world.setBlock(i + 17, j + 3, k + 9, KMOD_Main.CarvedScrapyBrick);
         world.setBlock(i + 17, j + 3, k + 15, KMOD_Main.CarvedScrapyBrick);
         world.setBlock(i + 17, j + 4, k + 9, KMOD_Main.CarvedScrapyBrick);
         world.setBlock(i + 17, j + 4, k + 15, KMOD_Main.CarvedScrapyBrick);
         world.setBlock(i + 17, j + 5, k + 10, KMOD_Main.CarvedScrapyBrick);
         world.setBlock(i + 17, j + 5, k + 14, KMOD_Main.CarvedScrapyBrick);
         world.setBlock(i + 17, j + 6, k + 11, KMOD_Main.CarvedScrapyBrick);
         world.setBlock(i + 17, j + 6, k + 13, KMOD_Main.CarvedScrapyBrick);
         world.setBlock(i + 17, j + 7, k + 12, KMOD_Main.CarvedScrapyBrick);
         world.setBlock(i + 18, j + 0, k + 7, KMOD_Main.KetherCloud);
         world.setBlock(i + 18, j + 0, k + 8, KMOD_Main.KetherCloud);
         world.setBlock(i + 18, j + 0, k + 9, KMOD_Main.KetherCloud);
         world.setBlock(i + 18, j + 0, k + 10, KMOD_Main.KetherCloud);
         world.setBlock(i + 18, j + 0, k + 11, KMOD_Main.KetherCloud);
         world.setBlock(i + 18, j + 0, k + 12, KMOD_Main.KetherCloud);
         world.setBlock(i + 18, j + 0, k + 13, KMOD_Main.KetherCloud);
         world.setBlock(i + 18, j + 0, k + 14, KMOD_Main.KetherCloud);
         world.setBlock(i + 18, j + 0, k + 15, KMOD_Main.KetherCloud);
         world.setBlock(i + 18, j + 1, k + 6, KMOD_Main.KetherCloud);
         world.setBlock(i + 18, j + 1, k + 7, KMOD_Main.KetherCloud);
         world.setBlock(i + 18, j + 1, k + 10, KMOD_Main.CarvedScrapyBrick);
         world.setBlock(i + 18, j + 1, k + 11, KMOD_Main.ScrapyBrick);
         world.setBlock(i + 18, j + 1, k + 12, KMOD_Main.ScrapyBrick);
         world.setBlock(i + 18, j + 1, k + 13, KMOD_Main.ScrapyBrick);
         world.setBlock(i + 18, j + 1, k + 14, KMOD_Main.CarvedScrapyBrick);
         world.setBlock(i + 18, j + 1, k + 16, KMOD_Main.KetherCloud);
         world.setBlock(i + 18, j + 2, k + 10, KMOD_Main.CarvedScrapyBrick);
         world.setBlock(i + 18, j + 2, k + 14, KMOD_Main.CarvedScrapyBrick);
         world.setBlock(i + 18, j + 3, k + 10, KMOD_Main.CarvedScrapyBrick);
         world.setBlock(i + 18, j + 3, k + 14, KMOD_Main.CarvedScrapyBrick);
         world.setBlock(i + 18, j + 4, k + 10, KMOD_Main.CarvedScrapyBrick);
         world.setBlock(i + 18, j + 4, k + 14, KMOD_Main.CarvedScrapyBrick);
         world.setBlock(i + 18, j + 5, k + 11, KMOD_Main.CarvedScrapyBrick);
         world.setBlock(i + 18, j + 5, k + 13, KMOD_Main.CarvedScrapyBrick);
         world.setBlock(i + 18, j + 6, k + 12, KMOD_Main.CarvedScrapyBrick);
         world.setBlock(i + 19, j + 0, k + 8, KMOD_Main.KetherCloud);
         world.setBlock(i + 19, j + 0, k + 9, KMOD_Main.KetherCloud);
         world.setBlock(i + 19, j + 0, k + 10, KMOD_Main.KetherCloud);
         world.setBlock(i + 19, j + 0, k + 11, KMOD_Main.KetherCloud);
         world.setBlock(i + 19, j + 0, k + 12, KMOD_Main.KetherCloud);
         world.setBlock(i + 19, j + 0, k + 13, KMOD_Main.KetherCloud);
         world.setBlock(i + 19, j + 0, k + 14, KMOD_Main.KetherCloud);
         world.setBlock(i + 19, j + 1, k + 8, KMOD_Main.KetherCloud);
         world.setBlock(i + 19, j + 1, k + 11, KMOD_Main.CarvedScrapyBrick);
         world.setBlock(i + 19, j + 1, k + 12, KMOD_Main.ScrapyBrick);
         world.setBlock(i + 19, j + 1, k + 13, KMOD_Main.CarvedScrapyBrick);
         world.setBlock(i + 19, j + 1, k + 16, KMOD_Main.KetherCloud);
         world.setBlock(i + 19, j + 1, k + 17, KMOD_Main.KetherCloud);
         world.setBlock(i + 19, j + 2, k + 11, KMOD_Main.CarvedScrapyBrick);
         world.setBlock(i + 19, j + 2, k + 13, KMOD_Main.CarvedScrapyBrick);
         world.setBlock(i + 19, j + 3, k + 11, KMOD_Main.CarvedScrapyBrick);
         world.setBlock(i + 19, j + 3, k + 13, KMOD_Main.CarvedScrapyBrick);
         world.setBlock(i + 19, j + 4, k + 11, KMOD_Main.CarvedScrapyBrick);
         world.setBlock(i + 19, j + 4, k + 13, KMOD_Main.CarvedScrapyBrick);
         world.setBlock(i + 19, j + 5, k + 12, KMOD_Main.CarvedScrapyBrick);
         world.setBlock(i + 20, j + 0, k + 10, KMOD_Main.KetherCloud);
         world.setBlock(i + 20, j + 0, k + 11, KMOD_Main.KetherCloud);
         world.setBlock(i + 20, j + 0, k + 12, KMOD_Main.KetherCloud);
         world.setBlock(i + 20, j + 0, k + 13, KMOD_Main.KetherCloud);
         world.setBlock(i + 20, j + 0, k + 14, KMOD_Main.KetherCloud);
         world.setBlock(i + 20, j + 1, k + 12, KMOD_Main.CarvedScrapyBrick);
         world.setBlock(i + 20, j + 1, k + 14, KMOD_Main.KetherCloud);
         world.setBlock(i + 20, j + 1, k + 16, KMOD_Main.KetherCloud);
         world.setBlock(i + 20, j + 2, k + 12, KMOD_Main.CarvedScrapyBrick);
         world.setBlock(i + 20, j + 2, k + 16, KMOD_Main.KetherCloud);
         world.setBlock(i + 20, j + 3, k + 12, KMOD_Main.CarvedScrapyBrick);
         world.setBlock(i + 20, j + 4, k + 12, KMOD_Main.CarvedScrapyBrick);
         world.setBlock(i + 21, j + 0, k + 10, KMOD_Main.KetherCloud);
         world.setBlock(i + 21, j + 0, k + 11, KMOD_Main.KetherCloud);
         world.setBlock(i + 21, j + 0, k + 12, KMOD_Main.KetherCloud);
         world.setBlock(i + 21, j + 0, k + 13, KMOD_Main.KetherCloud);
         world.setBlock(i + 21, j + 0, k + 14, KMOD_Main.KetherCloud);
         world.setBlock(i + 21, j + 1, k + 10, KMOD_Main.KetherCloud);
         world.setBlock(i + 21, j + 2, k + 16, KMOD_Main.KetherCloud);
         world.setBlock(i + 22, j + 0, k + 12, KMOD_Main.KetherCloud);
         world.setBlock(i + 22, j + 0, k + 13, KMOD_Main.KetherCloud);
         world.setBlock(i + 22, j + 1, k + 13, KMOD_Main.KetherCloud);
         return true;
      } else {
         return false;
      }
   }
}
