package fr.keter.KMOD.WorldGens.NewTestTrees;

import fr.keter.KMOD.Main.KMOD_Main;
import cpw.mods.fml.common.IWorldGenerator;
import java.util.Random;
import net.minecraft.block.Block;
import net.minecraft.world.World;
import net.minecraft.world.chunk.IChunkProvider;
import net.minecraft.world.gen.feature.WorldGenerator;

public class KetherGenTree2 extends WorldGenerator implements IWorldGenerator {
   public void generate(Random random, int chunkX, int chunkZ, World world, IChunkProvider chunkGenerator, IChunkProvider chunkProvider) {
   }

   public void setBlock(World world, int x, int y, int z, Block block) {
      Block b1 = world.getBlock(x, y, z);
      if (b1.isAir(world, x, y, z) || b1.isLeaves(world, x, y, z)) {
         world.setBlock(x, y, z, block);
      }

   }

   public boolean generate(World world, Random random, int x, int y, int z) {
      this.spawn(world, x, y, z);
      return true;
   }

   public void spawn(World world, int x, int y, int z) {
      if ((world.getBlock(x, y, z) == KMOD_Main.KetherGrass || world.getBlock(x, y - 1, z) == KMOD_Main.KetherGrass) && (world.getBlock(x + 9, y, z + 9) == KMOD_Main.KetherGrass || world.getBlock(x + 9, y - 1, z + 9) == KMOD_Main.KetherGrass || world.getBlock(x + 9, y, z + 9) == KMOD_Main.KetherDirt || world.getBlock(x + 9, y - 1, z + 9) == KMOD_Main.KetherDirt)) {
         this.setBlock(world, x + 9, y + 0, z + 9, KMOD_Main.KetherLog);
         world.setBlockMetadataWithNotify(x + 9, y + 0, z + 9, 12, 12);
         this.setBlock(world, x + 10, y + 0, z + 10, KMOD_Main.KetherLog);
         world.setBlockMetadataWithNotify(x + 10, y + 0, z + 10, 12, 12);
         this.setBlock(world, x + 11, y + 0, z + 10, KMOD_Main.KetherLog);
         world.setBlockMetadataWithNotify(x + 11, y + 0, z + 10, 12, 12);
         this.setBlock(world, x + 12, y + 0, z + 11, KMOD_Main.KetherLog);
         world.setBlockMetadataWithNotify(x + 12, y + 0, z + 11, 12, 12);
         this.setBlock(world, x + 14, y + 0, z + 11, KMOD_Main.KetherLog);
         world.setBlockMetadataWithNotify(x + 14, y + 0, z + 11, 12, 12);
         this.setBlock(world, x + 15, y + 0, z + 11, KMOD_Main.KetherLog);
         world.setBlockMetadataWithNotify(x + 15, y + 0, z + 11, 12, 12);
         this.setBlock(world, x + 10, y + 0, z + 12, KMOD_Main.KetherLog);
         world.setBlockMetadataWithNotify(x + 10, y + 0, z + 12, 12, 12);
         this.setBlock(world, x + 11, y + 0, z + 12, KMOD_Main.KetherLog);
         world.setBlockMetadataWithNotify(x + 11, y + 0, z + 12, 12, 12);
         this.setBlock(world, x + 12, y + 0, z + 12, KMOD_Main.KetherLog);
         world.setBlockMetadataWithNotify(x + 12, y + 0, z + 12, 12, 12);
         this.setBlock(world, x + 13, y + 0, z + 12, KMOD_Main.KetherLog);
         world.setBlockMetadataWithNotify(x + 13, y + 0, z + 12, 12, 12);
         this.setBlock(world, x + 16, y + 0, z + 12, KMOD_Main.KetherLog);
         world.setBlockMetadataWithNotify(x + 16, y + 0, z + 12, 12, 12);
         this.setBlock(world, x + 11, y + 0, z + 13, KMOD_Main.KetherLog);
         world.setBlockMetadataWithNotify(x + 11, y + 0, z + 13, 12, 12);
         this.setBlock(world, x + 12, y + 0, z + 13, KMOD_Main.KetherLog);
         world.setBlockMetadataWithNotify(x + 12, y + 0, z + 13, 12, 12);
         this.setBlock(world, x + 13, y + 0, z + 13, KMOD_Main.KetherLog);
         world.setBlockMetadataWithNotify(x + 13, y + 0, z + 13, 12, 12);
         this.setBlock(world, x + 11, y + 0, z + 14, KMOD_Main.KetherLog);
         world.setBlockMetadataWithNotify(x + 11, y + 0, z + 14, 12, 12);
         this.setBlock(world, x + 12, y + 0, z + 14, KMOD_Main.KetherLog);
         world.setBlockMetadataWithNotify(x + 12, y + 0, z + 14, 12, 12);
         this.setBlock(world, x + 11, y + 0, z + 15, KMOD_Main.KetherLog);
         world.setBlockMetadataWithNotify(x + 11, y + 0, z + 15, 12, 12);
         this.setBlock(world, x + 12, y + 0, z + 15, KMOD_Main.KetherLog);
         world.setBlockMetadataWithNotify(x + 12, y + 0, z + 15, 12, 12);
         this.setBlock(world, x + 12, y + 0, z + 16, KMOD_Main.KetherLog);
         world.setBlockMetadataWithNotify(x + 12, y + 0, z + 16, 12, 12);
         this.setBlock(world, x + 13, y + 0, z + 16, KMOD_Main.KetherLog);
         world.setBlockMetadataWithNotify(x + 13, y + 0, z + 16, 12, 12);
         this.setBlock(world, x + 14, y + 0, z + 17, KMOD_Main.KetherLog);
         world.setBlockMetadataWithNotify(x + 14, y + 0, z + 17, 12, 12);
         this.setBlock(world, x + 11, y + 1, z + 12, KMOD_Main.KetherLog);
         world.setBlockMetadataWithNotify(x + 11, y + 1, z + 12, 12, 12);
         this.setBlock(world, x + 12, y + 1, z + 12, KMOD_Main.KetherLog);
         world.setBlockMetadataWithNotify(x + 12, y + 1, z + 12, 12, 12);
         this.setBlock(world, x + 13, y + 1, z + 12, KMOD_Main.KetherLog);
         world.setBlockMetadataWithNotify(x + 13, y + 1, z + 12, 12, 12);
         this.setBlock(world, x + 11, y + 1, z + 13, KMOD_Main.KetherLog);
         world.setBlockMetadataWithNotify(x + 11, y + 1, z + 13, 12, 12);
         this.setBlock(world, x + 12, y + 1, z + 13, KMOD_Main.KetherLog);
         world.setBlockMetadataWithNotify(x + 12, y + 1, z + 13, 12, 12);
         this.setBlock(world, x + 13, y + 1, z + 13, KMOD_Main.KetherLog);
         world.setBlockMetadataWithNotify(x + 13, y + 1, z + 13, 12, 12);
         this.setBlock(world, x + 12, y + 1, z + 14, KMOD_Main.KetherLog);
         world.setBlockMetadataWithNotify(x + 12, y + 1, z + 14, 12, 12);
         this.setBlock(world, x + 12, y + 1, z + 15, KMOD_Main.KetherLog);
         world.setBlockMetadataWithNotify(x + 12, y + 1, z + 15, 12, 12);
         this.setBlock(world, x + 13, y + 2, z + 1, KMOD_Main.KetherBlueLeaves);
         world.setBlockMetadataWithNotify(x + 13, y + 2, z + 1, 14, 14);
         this.setBlock(world, x + 12, y + 2, z + 2, KMOD_Main.KetherBlueLeaves);
         world.setBlockMetadataWithNotify(x + 12, y + 2, z + 2, 14, 14);
         this.setBlock(world, x + 18, y + 2, z + 2, KMOD_Main.KetherBlueLeaves);
         world.setBlockMetadataWithNotify(x + 18, y + 2, z + 2, 14, 14);
         this.setBlock(world, x + 11, y + 2, z + 4, KMOD_Main.KetherBlueLeaves);
         world.setBlockMetadataWithNotify(x + 11, y + 2, z + 4, 14, 14);
         this.setBlock(world, x + 9, y + 2, z + 5, KMOD_Main.KetherBlueLeaves);
         world.setBlockMetadataWithNotify(x + 9, y + 2, z + 5, 14, 14);
         this.setBlock(world, x + 10, y + 2, z + 5, KMOD_Main.KetherBlueLeaves);
         world.setBlockMetadataWithNotify(x + 10, y + 2, z + 5, 14, 14);
         this.setBlock(world, x + 6, y + 2, z + 8, KMOD_Main.KetherBlueLeaves);
         world.setBlockMetadataWithNotify(x + 6, y + 2, z + 8, 14, 14);
         this.setBlock(world, x + 19, y + 2, z + 8, KMOD_Main.KetherBlueLeaves);
         world.setBlockMetadataWithNotify(x + 19, y + 2, z + 8, 14, 14);
         this.setBlock(world, x + 20, y + 2, z + 8, KMOD_Main.KetherBlueLeaves);
         world.setBlockMetadataWithNotify(x + 20, y + 2, z + 8, 14, 14);
         this.setBlock(world, x + 5, y + 2, z + 10, KMOD_Main.KetherBlueLeaves);
         world.setBlockMetadataWithNotify(x + 5, y + 2, z + 10, 14, 14);
         this.setBlock(world, x + 11, y + 2, z + 12, KMOD_Main.KetherLog);
         world.setBlockMetadataWithNotify(x + 11, y + 2, z + 12, 12, 12);
         this.setBlock(world, x + 12, y + 2, z + 12, KMOD_Main.KetherLog);
         world.setBlockMetadataWithNotify(x + 12, y + 2, z + 12, 12, 12);
         this.setBlock(world, x + 12, y + 2, z + 13, KMOD_Main.KetherLog);
         world.setBlockMetadataWithNotify(x + 12, y + 2, z + 13, 12, 12);
         this.setBlock(world, x + 13, y + 2, z + 13, KMOD_Main.KetherLog);
         world.setBlockMetadataWithNotify(x + 13, y + 2, z + 13, 12, 12);
         this.setBlock(world, x + 12, y + 2, z + 14, KMOD_Main.KetherLog);
         world.setBlockMetadataWithNotify(x + 12, y + 2, z + 14, 12, 12);
         this.setBlock(world, x + 13, y + 2, z + 14, KMOD_Main.KetherLog);
         world.setBlockMetadataWithNotify(x + 13, y + 2, z + 14, 12, 12);
         this.setBlock(world, x + 24, y + 2, z + 15, KMOD_Main.KetherBlueLeaves);
         world.setBlockMetadataWithNotify(x + 24, y + 2, z + 15, 14, 14);
         this.setBlock(world, x + 4, y + 2, z + 19, KMOD_Main.KetherBlueLeaves);
         world.setBlockMetadataWithNotify(x + 4, y + 2, z + 19, 14, 14);
         this.setBlock(world, x + 21, y + 2, z + 20, KMOD_Main.KetherBlueLeaves);
         world.setBlockMetadataWithNotify(x + 21, y + 2, z + 20, 14, 14);
         this.setBlock(world, x + 15, y + 2, z + 24, KMOD_Main.KetherBlueLeaves);
         world.setBlockMetadataWithNotify(x + 15, y + 2, z + 24, 14, 14);
         this.setBlock(world, x + 7, y + 2, z + 25, KMOD_Main.KetherBlueLeaves);
         world.setBlockMetadataWithNotify(x + 7, y + 2, z + 25, 14, 14);
         this.setBlock(world, x + 9, y + 3, z + 1, KMOD_Main.KetherBlueLeaves);
         world.setBlockMetadataWithNotify(x + 9, y + 3, z + 1, 14, 14);
         this.setBlock(world, x + 18, y + 3, z + 1, KMOD_Main.KetherBlueLeaves);
         world.setBlockMetadataWithNotify(x + 18, y + 3, z + 1, 14, 14);
         this.setBlock(world, x + 13, y + 3, z + 2, KMOD_Main.KetherBlueLeaves);
         world.setBlockMetadataWithNotify(x + 13, y + 3, z + 2, 14, 14);
         this.setBlock(world, x + 14, y + 3, z + 2, KMOD_Main.KetherBlueLeaves);
         world.setBlockMetadataWithNotify(x + 14, y + 3, z + 2, 14, 14);
         this.setBlock(world, x + 16, y + 3, z + 2, KMOD_Main.KetherBlueLeaves);
         world.setBlockMetadataWithNotify(x + 16, y + 3, z + 2, 14, 14);
         this.setBlock(world, x + 17, y + 3, z + 2, KMOD_Main.KetherBlueLeaves);
         world.setBlockMetadataWithNotify(x + 17, y + 3, z + 2, 14, 14);
         this.setBlock(world, x + 8, y + 3, z + 3, KMOD_Main.KetherBlueLeaves);
         world.setBlockMetadataWithNotify(x + 8, y + 3, z + 3, 14, 14);
         this.setBlock(world, x + 10, y + 3, z + 3, KMOD_Main.KetherBlueLeaves);
         world.setBlockMetadataWithNotify(x + 10, y + 3, z + 3, 14, 14);
         this.setBlock(world, x + 15, y + 3, z + 3, KMOD_Main.KetherBlueLeaves);
         world.setBlockMetadataWithNotify(x + 15, y + 3, z + 3, 14, 14);
         this.setBlock(world, x + 16, y + 3, z + 3, KMOD_Main.KetherBlueLeaves);
         world.setBlockMetadataWithNotify(x + 16, y + 3, z + 3, 14, 14);
         this.setBlock(world, x + 20, y + 3, z + 3, KMOD_Main.KetherBlueLeaves);
         world.setBlockMetadataWithNotify(x + 20, y + 3, z + 3, 14, 14);
         this.setBlock(world, x + 8, y + 3, z + 4, KMOD_Main.KetherBlueLeaves);
         world.setBlockMetadataWithNotify(x + 8, y + 3, z + 4, 14, 14);
         this.setBlock(world, x + 9, y + 3, z + 4, KMOD_Main.KetherBlueLeaves);
         world.setBlockMetadataWithNotify(x + 9, y + 3, z + 4, 14, 14);
         this.setBlock(world, x + 12, y + 3, z + 4, KMOD_Main.KetherBlueLeaves);
         world.setBlockMetadataWithNotify(x + 12, y + 3, z + 4, 14, 14);
         this.setBlock(world, x + 15, y + 3, z + 4, KMOD_Main.KetherBlueLeaves);
         world.setBlockMetadataWithNotify(x + 15, y + 3, z + 4, 14, 14);
         this.setBlock(world, x + 17, y + 3, z + 4, KMOD_Main.KetherBlueLeaves);
         world.setBlockMetadataWithNotify(x + 17, y + 3, z + 4, 14, 14);
         this.setBlock(world, x + 18, y + 3, z + 4, KMOD_Main.KetherBlueLeaves);
         world.setBlockMetadataWithNotify(x + 18, y + 3, z + 4, 14, 14);
         this.setBlock(world, x + 20, y + 3, z + 4, KMOD_Main.KetherBlueLeaves);
         world.setBlockMetadataWithNotify(x + 20, y + 3, z + 4, 14, 14);
         this.setBlock(world, x + 7, y + 3, z + 5, KMOD_Main.KetherBlueLeaves);
         world.setBlockMetadataWithNotify(x + 7, y + 3, z + 5, 14, 14);
         this.setBlock(world, x + 8, y + 3, z + 5, KMOD_Main.KetherBlueLeaves);
         world.setBlockMetadataWithNotify(x + 8, y + 3, z + 5, 14, 14);
         this.setBlock(world, x + 11, y + 3, z + 5, KMOD_Main.KetherBlueLeaves);
         world.setBlockMetadataWithNotify(x + 11, y + 3, z + 5, 14, 14);
         this.setBlock(world, x + 12, y + 3, z + 5, KMOD_Main.KetherBlueLeaves);
         world.setBlockMetadataWithNotify(x + 12, y + 3, z + 5, 14, 14);
         this.setBlock(world, x + 13, y + 3, z + 5, KMOD_Main.KetherBlueLeaves);
         world.setBlockMetadataWithNotify(x + 13, y + 3, z + 5, 14, 14);
         this.setBlock(world, x + 15, y + 3, z + 5, KMOD_Main.KetherBlueLeaves);
         world.setBlockMetadataWithNotify(x + 15, y + 3, z + 5, 14, 14);
         this.setBlock(world, x + 17, y + 3, z + 5, KMOD_Main.KetherBlueLeaves);
         world.setBlockMetadataWithNotify(x + 17, y + 3, z + 5, 14, 14);
         this.setBlock(world, x + 18, y + 3, z + 5, KMOD_Main.KetherBlueLeaves);
         world.setBlockMetadataWithNotify(x + 18, y + 3, z + 5, 14, 14);
         this.setBlock(world, x + 20, y + 3, z + 5, KMOD_Main.KetherBlueLeaves);
         world.setBlockMetadataWithNotify(x + 20, y + 3, z + 5, 14, 14);
         this.setBlock(world, x + 6, y + 3, z + 6, KMOD_Main.KetherBlueLeaves);
         world.setBlockMetadataWithNotify(x + 6, y + 3, z + 6, 14, 14);
         this.setBlock(world, x + 7, y + 3, z + 6, KMOD_Main.KetherBlueLeaves);
         world.setBlockMetadataWithNotify(x + 7, y + 3, z + 6, 14, 14);
         this.setBlock(world, x + 10, y + 3, z + 6, KMOD_Main.KetherBlueLeaves);
         world.setBlockMetadataWithNotify(x + 10, y + 3, z + 6, 14, 14);
         this.setBlock(world, x + 19, y + 3, z + 6, KMOD_Main.KetherBlueLeaves);
         world.setBlockMetadataWithNotify(x + 19, y + 3, z + 6, 14, 14);
         this.setBlock(world, x + 21, y + 3, z + 6, KMOD_Main.KetherBlueLeaves);
         world.setBlockMetadataWithNotify(x + 21, y + 3, z + 6, 14, 14);
         this.setBlock(world, x + 11, y + 3, z + 7, KMOD_Main.KetherBlueLeaves);
         world.setBlockMetadataWithNotify(x + 11, y + 3, z + 7, 14, 14);
         this.setBlock(world, x + 17, y + 3, z + 7, KMOD_Main.KetherBlueLeaves);
         world.setBlockMetadataWithNotify(x + 17, y + 3, z + 7, 14, 14);
         this.setBlock(world, x + 20, y + 3, z + 7, KMOD_Main.KetherBlueLeaves);
         world.setBlockMetadataWithNotify(x + 20, y + 3, z + 7, 14, 14);
         this.setBlock(world, x + 5, y + 3, z + 8, KMOD_Main.KetherBlueLeaves);
         world.setBlockMetadataWithNotify(x + 5, y + 3, z + 8, 14, 14);
         this.setBlock(world, x + 6, y + 3, z + 8, KMOD_Main.KetherBlueLeaves);
         world.setBlockMetadataWithNotify(x + 6, y + 3, z + 8, 14, 14);
         this.setBlock(world, x + 18, y + 3, z + 8, KMOD_Main.KetherBlueLeaves);
         world.setBlockMetadataWithNotify(x + 18, y + 3, z + 8, 14, 14);
         this.setBlock(world, x + 21, y + 3, z + 8, KMOD_Main.KetherBlueLeaves);
         world.setBlockMetadataWithNotify(x + 21, y + 3, z + 8, 14, 14);
         this.setBlock(world, x + 22, y + 3, z + 8, KMOD_Main.KetherBlueLeaves);
         world.setBlockMetadataWithNotify(x + 22, y + 3, z + 8, 14, 14);
         this.setBlock(world, x + 5, y + 3, z + 9, KMOD_Main.KetherBlueLeaves);
         world.setBlockMetadataWithNotify(x + 5, y + 3, z + 9, 14, 14);
         this.setBlock(world, x + 6, y + 3, z + 9, KMOD_Main.KetherBlueLeaves);
         world.setBlockMetadataWithNotify(x + 6, y + 3, z + 9, 14, 14);
         this.setBlock(world, x + 19, y + 3, z + 9, KMOD_Main.KetherBlueLeaves);
         world.setBlockMetadataWithNotify(x + 19, y + 3, z + 9, 14, 14);
         this.setBlock(world, x + 21, y + 3, z + 9, KMOD_Main.KetherBlueLeaves);
         world.setBlockMetadataWithNotify(x + 21, y + 3, z + 9, 14, 14);
         this.setBlock(world, x + 22, y + 3, z + 9, KMOD_Main.KetherBlueLeaves);
         world.setBlockMetadataWithNotify(x + 22, y + 3, z + 9, 14, 14);
         this.setBlock(world, x + 24, y + 3, z + 9, KMOD_Main.KetherBlueLeaves);
         world.setBlockMetadataWithNotify(x + 24, y + 3, z + 9, 14, 14);
         this.setBlock(world, x + 4, y + 3, z + 10, KMOD_Main.KetherBlueLeaves);
         world.setBlockMetadataWithNotify(x + 4, y + 3, z + 10, 14, 14);
         this.setBlock(world, x + 5, y + 3, z + 10, KMOD_Main.KetherBlueLeaves);
         world.setBlockMetadataWithNotify(x + 5, y + 3, z + 10, 14, 14);
         this.setBlock(world, x + 6, y + 3, z + 10, KMOD_Main.KetherBlueLeaves);
         world.setBlockMetadataWithNotify(x + 6, y + 3, z + 10, 14, 14);
         this.setBlock(world, x + 22, y + 3, z + 10, KMOD_Main.KetherBlueLeaves);
         world.setBlockMetadataWithNotify(x + 22, y + 3, z + 10, 14, 14);
         this.setBlock(world, x + 23, y + 3, z + 10, KMOD_Main.KetherBlueLeaves);
         world.setBlockMetadataWithNotify(x + 23, y + 3, z + 10, 14, 14);
         this.setBlock(world, x + 24, y + 3, z + 11, KMOD_Main.KetherBlueLeaves);
         world.setBlockMetadataWithNotify(x + 24, y + 3, z + 11, 14, 14);
         this.setBlock(world, x + 2, y + 3, z + 12, KMOD_Main.KetherBlueLeaves);
         world.setBlockMetadataWithNotify(x + 2, y + 3, z + 12, 14, 14);
         this.setBlock(world, x + 3, y + 3, z + 12, KMOD_Main.KetherBlueLeaves);
         world.setBlockMetadataWithNotify(x + 3, y + 3, z + 12, 14, 14);
         this.setBlock(world, x + 22, y + 3, z + 12, KMOD_Main.KetherBlueLeaves);
         world.setBlockMetadataWithNotify(x + 22, y + 3, z + 12, 14, 14);
         this.setBlock(world, x + 12, y + 3, z + 13, KMOD_Main.KetherLog);
         world.setBlockMetadataWithNotify(x + 12, y + 3, z + 13, 12, 12);
         this.setBlock(world, x + 13, y + 3, z + 13, KMOD_Main.KetherLog);
         world.setBlockMetadataWithNotify(x + 13, y + 3, z + 13, 12, 12);
         this.setBlock(world, x + 4, y + 3, z + 14, KMOD_Main.KetherBlueLeaves);
         world.setBlockMetadataWithNotify(x + 4, y + 3, z + 14, 14, 14);
         this.setBlock(world, x + 13, y + 3, z + 14, KMOD_Main.KetherLog);
         world.setBlockMetadataWithNotify(x + 13, y + 3, z + 14, 12, 12);
         this.setBlock(world, x + 24, y + 3, z + 14, KMOD_Main.KetherBlueLeaves);
         world.setBlockMetadataWithNotify(x + 24, y + 3, z + 14, 14, 14);
         this.setBlock(world, x + 2, y + 3, z + 15, KMOD_Main.KetherBlueLeaves);
         world.setBlockMetadataWithNotify(x + 2, y + 3, z + 15, 14, 14);
         this.setBlock(world, x + 3, y + 3, z + 15, KMOD_Main.KetherBlueLeaves);
         world.setBlockMetadataWithNotify(x + 3, y + 3, z + 15, 14, 14);
         this.setBlock(world, x + 4, y + 3, z + 15, KMOD_Main.KetherBlueLeaves);
         world.setBlockMetadataWithNotify(x + 4, y + 3, z + 15, 14, 14);
         this.setBlock(world, x + 24, y + 3, z + 15, KMOD_Main.KetherBlueLeaves);
         world.setBlockMetadataWithNotify(x + 24, y + 3, z + 15, 14, 14);
         this.setBlock(world, x + 3, y + 3, z + 16, KMOD_Main.KetherBlueLeaves);
         world.setBlockMetadataWithNotify(x + 3, y + 3, z + 16, 14, 14);
         this.setBlock(world, x + 4, y + 3, z + 16, KMOD_Main.KetherBlueLeaves);
         world.setBlockMetadataWithNotify(x + 4, y + 3, z + 16, 14, 14);
         this.setBlock(world, x + 22, y + 3, z + 16, KMOD_Main.KetherBlueLeaves);
         world.setBlockMetadataWithNotify(x + 22, y + 3, z + 16, 14, 14);
         this.setBlock(world, x + 24, y + 3, z + 16, KMOD_Main.KetherBlueLeaves);
         world.setBlockMetadataWithNotify(x + 24, y + 3, z + 16, 14, 14);
         this.setBlock(world, x + 2, y + 3, z + 17, KMOD_Main.KetherBlueLeaves);
         world.setBlockMetadataWithNotify(x + 2, y + 3, z + 17, 14, 14);
         this.setBlock(world, x + 4, y + 3, z + 17, KMOD_Main.KetherBlueLeaves);
         world.setBlockMetadataWithNotify(x + 4, y + 3, z + 17, 14, 14);
         this.setBlock(world, x + 22, y + 3, z + 17, KMOD_Main.KetherBlueLeaves);
         world.setBlockMetadataWithNotify(x + 22, y + 3, z + 17, 14, 14);
         this.setBlock(world, x + 23, y + 3, z + 17, KMOD_Main.KetherBlueLeaves);
         world.setBlockMetadataWithNotify(x + 23, y + 3, z + 17, 14, 14);
         this.setBlock(world, x + 24, y + 3, z + 17, KMOD_Main.KetherBlueLeaves);
         world.setBlockMetadataWithNotify(x + 24, y + 3, z + 17, 14, 14);
         this.setBlock(world, x + 2, y + 3, z + 18, KMOD_Main.KetherBlueLeaves);
         world.setBlockMetadataWithNotify(x + 2, y + 3, z + 18, 14, 14);
         this.setBlock(world, x + 3, y + 3, z + 18, KMOD_Main.KetherBlueLeaves);
         world.setBlockMetadataWithNotify(x + 3, y + 3, z + 18, 14, 14);
         this.setBlock(world, x + 4, y + 3, z + 19, KMOD_Main.KetherBlueLeaves);
         world.setBlockMetadataWithNotify(x + 4, y + 3, z + 19, 14, 14);
         this.setBlock(world, x + 21, y + 3, z + 20, KMOD_Main.KetherBlueLeaves);
         world.setBlockMetadataWithNotify(x + 21, y + 3, z + 20, 14, 14);
         this.setBlock(world, x + 22, y + 3, z + 20, KMOD_Main.KetherBlueLeaves);
         world.setBlockMetadataWithNotify(x + 22, y + 3, z + 20, 14, 14);
         this.setBlock(world, x + 24, y + 3, z + 20, KMOD_Main.KetherBlueLeaves);
         world.setBlockMetadataWithNotify(x + 24, y + 3, z + 20, 14, 14);
         this.setBlock(world, x + 3, y + 3, z + 21, KMOD_Main.KetherBlueLeaves);
         world.setBlockMetadataWithNotify(x + 3, y + 3, z + 21, 14, 14);
         this.setBlock(world, x + 4, y + 3, z + 22, KMOD_Main.KetherBlueLeaves);
         world.setBlockMetadataWithNotify(x + 4, y + 3, z + 22, 14, 14);
         this.setBlock(world, x + 6, y + 3, z + 22, KMOD_Main.KetherBlueLeaves);
         world.setBlockMetadataWithNotify(x + 6, y + 3, z + 22, 14, 14);
         this.setBlock(world, x + 5, y + 3, z + 23, KMOD_Main.KetherBlueLeaves);
         world.setBlockMetadataWithNotify(x + 5, y + 3, z + 23, 14, 14);
         this.setBlock(world, x + 7, y + 3, z + 23, KMOD_Main.KetherBlueLeaves);
         world.setBlockMetadataWithNotify(x + 7, y + 3, z + 23, 14, 14);
         this.setBlock(world, x + 11, y + 3, z + 23, KMOD_Main.KetherBlueLeaves);
         world.setBlockMetadataWithNotify(x + 11, y + 3, z + 23, 14, 14);
         this.setBlock(world, x + 15, y + 3, z + 23, KMOD_Main.KetherBlueLeaves);
         world.setBlockMetadataWithNotify(x + 15, y + 3, z + 23, 14, 14);
         this.setBlock(world, x + 23, y + 3, z + 23, KMOD_Main.KetherBlueLeaves);
         world.setBlockMetadataWithNotify(x + 23, y + 3, z + 23, 14, 14);
         this.setBlock(world, x + 3, y + 3, z + 24, KMOD_Main.KetherBlueLeaves);
         world.setBlockMetadataWithNotify(x + 3, y + 3, z + 24, 14, 14);
         this.setBlock(world, x + 14, y + 3, z + 24, KMOD_Main.KetherBlueLeaves);
         world.setBlockMetadataWithNotify(x + 14, y + 3, z + 24, 14, 14);
         this.setBlock(world, x + 15, y + 3, z + 24, KMOD_Main.KetherBlueLeaves);
         world.setBlockMetadataWithNotify(x + 15, y + 3, z + 24, 14, 14);
         this.setBlock(world, x + 17, y + 3, z + 24, KMOD_Main.KetherBlueLeaves);
         world.setBlockMetadataWithNotify(x + 17, y + 3, z + 24, 14, 14);
         this.setBlock(world, x + 19, y + 3, z + 24, KMOD_Main.KetherBlueLeaves);
         world.setBlockMetadataWithNotify(x + 19, y + 3, z + 24, 14, 14);
         this.setBlock(world, x + 4, y + 3, z + 25, KMOD_Main.KetherBlueLeaves);
         world.setBlockMetadataWithNotify(x + 4, y + 3, z + 25, 14, 14);
         this.setBlock(world, x + 5, y + 3, z + 25, KMOD_Main.KetherBlueLeaves);
         world.setBlockMetadataWithNotify(x + 5, y + 3, z + 25, 14, 14);
         this.setBlock(world, x + 6, y + 3, z + 25, KMOD_Main.KetherBlueLeaves);
         world.setBlockMetadataWithNotify(x + 6, y + 3, z + 25, 14, 14);
         this.setBlock(world, x + 7, y + 3, z + 25, KMOD_Main.KetherBlueLeaves);
         world.setBlockMetadataWithNotify(x + 7, y + 3, z + 25, 14, 14);
         this.setBlock(world, x + 14, y + 3, z + 25, KMOD_Main.KetherBlueLeaves);
         world.setBlockMetadataWithNotify(x + 14, y + 3, z + 25, 14, 14);
         this.setBlock(world, x + 20, y + 3, z + 25, KMOD_Main.KetherBlueLeaves);
         world.setBlockMetadataWithNotify(x + 20, y + 3, z + 25, 14, 14);
         this.setBlock(world, x + 11, y + 3, z + 26, KMOD_Main.KetherBlueLeaves);
         world.setBlockMetadataWithNotify(x + 11, y + 3, z + 26, 14, 14);
         this.setBlock(world, x + 12, y + 3, z + 26, KMOD_Main.KetherBlueLeaves);
         world.setBlockMetadataWithNotify(x + 12, y + 3, z + 26, 14, 14);
         this.setBlock(world, x + 14, y + 3, z + 26, KMOD_Main.KetherBlueLeaves);
         world.setBlockMetadataWithNotify(x + 14, y + 3, z + 26, 14, 14);
         this.setBlock(world, x + 18, y + 3, z + 26, KMOD_Main.KetherBlueLeaves);
         world.setBlockMetadataWithNotify(x + 18, y + 3, z + 26, 14, 14);
         this.setBlock(world, x + 20, y + 3, z + 26, KMOD_Main.KetherBlueLeaves);
         world.setBlockMetadataWithNotify(x + 20, y + 3, z + 26, 14, 14);
         this.setBlock(world, x + 11, y + 3, z + 27, KMOD_Main.KetherBlueLeaves);
         world.setBlockMetadataWithNotify(x + 11, y + 3, z + 27, 14, 14);
         this.setBlock(world, x + 15, y + 3, z + 27, KMOD_Main.KetherBlueLeaves);
         world.setBlockMetadataWithNotify(x + 15, y + 3, z + 27, 14, 14);
         this.setBlock(world, x + 16, y + 3, z + 27, KMOD_Main.KetherBlueLeaves);
         world.setBlockMetadataWithNotify(x + 16, y + 3, z + 27, 14, 14);
         this.setBlock(world, x + 20, y + 3, z + 27, KMOD_Main.KetherBlueLeaves);
         world.setBlockMetadataWithNotify(x + 20, y + 3, z + 27, 14, 14);
         this.setBlock(world, x + 9, y + 3, z + 28, KMOD_Main.KetherBlueLeaves);
         world.setBlockMetadataWithNotify(x + 9, y + 3, z + 28, 14, 14);
         this.setBlock(world, x + 10, y + 3, z + 28, KMOD_Main.KetherBlueLeaves);
         world.setBlockMetadataWithNotify(x + 10, y + 3, z + 28, 14, 14);
         this.setBlock(world, x + 11, y + 3, z + 28, KMOD_Main.KetherBlueLeaves);
         world.setBlockMetadataWithNotify(x + 11, y + 3, z + 28, 14, 14);
         this.setBlock(world, x + 13, y + 4, z + 1, KMOD_Main.KetherBlueLeaves);
         world.setBlockMetadataWithNotify(x + 13, y + 4, z + 1, 14, 14);
         this.setBlock(world, x + 16, y + 4, z + 1, KMOD_Main.KetherBlueLeaves);
         world.setBlockMetadataWithNotify(x + 16, y + 4, z + 1, 14, 14);
         this.setBlock(world, x + 18, y + 4, z + 1, KMOD_Main.KetherBlueLeaves);
         world.setBlockMetadataWithNotify(x + 18, y + 4, z + 1, 14, 14);
         this.setBlock(world, x + 8, y + 4, z + 2, KMOD_Main.KetherBlueLeaves);
         world.setBlockMetadataWithNotify(x + 8, y + 4, z + 2, 14, 14);
         this.setBlock(world, x + 10, y + 4, z + 2, KMOD_Main.KetherBlueLeaves);
         world.setBlockMetadataWithNotify(x + 10, y + 4, z + 2, 14, 14);
         this.setBlock(world, x + 13, y + 4, z + 2, KMOD_Main.KetherBlueLeaves);
         world.setBlockMetadataWithNotify(x + 13, y + 4, z + 2, 14, 14);
         this.setBlock(world, x + 16, y + 4, z + 2, KMOD_Main.KetherBlueLeaves);
         world.setBlockMetadataWithNotify(x + 16, y + 4, z + 2, 14, 14);
         this.setBlock(world, x + 17, y + 4, z + 2, KMOD_Main.KetherBlueLeaves);
         world.setBlockMetadataWithNotify(x + 17, y + 4, z + 2, 14, 14);
         this.setBlock(world, x + 11, y + 4, z + 3, KMOD_Main.KetherBlueLeaves);
         world.setBlockMetadataWithNotify(x + 11, y + 4, z + 3, 14, 14);
         this.setBlock(world, x + 13, y + 4, z + 3, KMOD_Main.KetherBlueLeaves);
         world.setBlockMetadataWithNotify(x + 13, y + 4, z + 3, 14, 14);
         this.setBlock(world, x + 17, y + 4, z + 3, KMOD_Main.KetherBlueLeaves);
         world.setBlockMetadataWithNotify(x + 17, y + 4, z + 3, 14, 14);
         this.setBlock(world, x + 19, y + 4, z + 3, KMOD_Main.KetherBlueLeaves);
         world.setBlockMetadataWithNotify(x + 19, y + 4, z + 3, 14, 14);
         this.setBlock(world, x + 20, y + 4, z + 3, KMOD_Main.KetherBlueLeaves);
         world.setBlockMetadataWithNotify(x + 20, y + 4, z + 3, 14, 14);
         this.setBlock(world, x + 6, y + 4, z + 4, KMOD_Main.KetherBlueLeaves);
         world.setBlockMetadataWithNotify(x + 6, y + 4, z + 4, 14, 14);
         this.setBlock(world, x + 7, y + 4, z + 4, KMOD_Main.KetherBlueLeaves);
         world.setBlockMetadataWithNotify(x + 7, y + 4, z + 4, 14, 14);
         this.setBlock(world, x + 8, y + 4, z + 4, KMOD_Main.KetherBlueLeaves);
         world.setBlockMetadataWithNotify(x + 8, y + 4, z + 4, 14, 14);
         this.setBlock(world, x + 10, y + 4, z + 4, KMOD_Main.KetherBlueLeaves);
         world.setBlockMetadataWithNotify(x + 10, y + 4, z + 4, 14, 14);
         this.setBlock(world, x + 11, y + 4, z + 4, KMOD_Main.KetherBlueLeaves);
         world.setBlockMetadataWithNotify(x + 11, y + 4, z + 4, 14, 14);
         this.setBlock(world, x + 14, y + 4, z + 4, KMOD_Main.KetherBlueLeaves);
         world.setBlockMetadataWithNotify(x + 14, y + 4, z + 4, 14, 14);
         this.setBlock(world, x + 18, y + 4, z + 4, KMOD_Main.KetherBlueLeaves);
         world.setBlockMetadataWithNotify(x + 18, y + 4, z + 4, 14, 14);
         this.setBlock(world, x + 8, y + 4, z + 5, KMOD_Main.KetherBlueLeaves);
         world.setBlockMetadataWithNotify(x + 8, y + 4, z + 5, 14, 14);
         this.setBlock(world, x + 13, y + 4, z + 5, KMOD_Main.KetherBlueLeaves);
         world.setBlockMetadataWithNotify(x + 13, y + 4, z + 5, 14, 14);
         this.setBlock(world, x + 16, y + 4, z + 5, KMOD_Main.KetherBlueLeaves);
         world.setBlockMetadataWithNotify(x + 16, y + 4, z + 5, 14, 14);
         this.setBlock(world, x + 19, y + 4, z + 5, KMOD_Main.KetherBlueLeaves);
         world.setBlockMetadataWithNotify(x + 19, y + 4, z + 5, 14, 14);
         this.setBlock(world, x + 20, y + 4, z + 5, KMOD_Main.KetherBlueLeaves);
         world.setBlockMetadataWithNotify(x + 20, y + 4, z + 5, 14, 14);
         this.setBlock(world, x + 6, y + 4, z + 6, KMOD_Main.KetherBlueLeaves);
         world.setBlockMetadataWithNotify(x + 6, y + 4, z + 6, 14, 14);
         this.setBlock(world, x + 7, y + 4, z + 6, KMOD_Main.KetherBlueLeaves);
         world.setBlockMetadataWithNotify(x + 7, y + 4, z + 6, 14, 14);
         this.setBlock(world, x + 12, y + 4, z + 6, KMOD_Main.KetherBlueLeaves);
         world.setBlockMetadataWithNotify(x + 12, y + 4, z + 6, 14, 14);
         this.setBlock(world, x + 15, y + 4, z + 6, KMOD_Main.KetherBlueLeaves);
         world.setBlockMetadataWithNotify(x + 15, y + 4, z + 6, 14, 14);
         this.setBlock(world, x + 18, y + 4, z + 6, KMOD_Main.KetherBlueLeaves);
         world.setBlockMetadataWithNotify(x + 18, y + 4, z + 6, 14, 14);
         this.setBlock(world, x + 4, y + 4, z + 7, KMOD_Main.KetherBlueLeaves);
         world.setBlockMetadataWithNotify(x + 4, y + 4, z + 7, 14, 14);
         this.setBlock(world, x + 6, y + 4, z + 7, KMOD_Main.KetherBlueLeaves);
         world.setBlockMetadataWithNotify(x + 6, y + 4, z + 7, 14, 14);
         this.setBlock(world, x + 8, y + 4, z + 7, KMOD_Main.KetherBlueLeaves);
         world.setBlockMetadataWithNotify(x + 8, y + 4, z + 7, 14, 14);
         this.setBlock(world, x + 15, y + 4, z + 7, KMOD_Main.KetherBlueLeaves);
         world.setBlockMetadataWithNotify(x + 15, y + 4, z + 7, 14, 14);
         this.setBlock(world, x + 17, y + 4, z + 7, KMOD_Main.KetherBlueLeaves);
         world.setBlockMetadataWithNotify(x + 17, y + 4, z + 7, 14, 14);
         this.setBlock(world, x + 19, y + 4, z + 7, KMOD_Main.KetherBlueLeaves);
         world.setBlockMetadataWithNotify(x + 19, y + 4, z + 7, 14, 14);
         this.setBlock(world, x + 20, y + 4, z + 7, KMOD_Main.KetherBlueLeaves);
         world.setBlockMetadataWithNotify(x + 20, y + 4, z + 7, 14, 14);
         this.setBlock(world, x + 21, y + 4, z + 7, KMOD_Main.KetherBlueLeaves);
         world.setBlockMetadataWithNotify(x + 21, y + 4, z + 7, 14, 14);
         this.setBlock(world, x + 6, y + 4, z + 8, KMOD_Main.KetherBlueLeaves);
         world.setBlockMetadataWithNotify(x + 6, y + 4, z + 8, 14, 14);
         this.setBlock(world, x + 7, y + 4, z + 8, KMOD_Main.KetherBlueLeaves);
         world.setBlockMetadataWithNotify(x + 7, y + 4, z + 8, 14, 14);
         this.setBlock(world, x + 10, y + 4, z + 8, KMOD_Main.KetherBlueLeaves);
         world.setBlockMetadataWithNotify(x + 10, y + 4, z + 8, 14, 14);
         this.setBlock(world, x + 11, y + 4, z + 8, KMOD_Main.KetherBlueLeaves);
         world.setBlockMetadataWithNotify(x + 11, y + 4, z + 8, 14, 14);
         this.setBlock(world, x + 12, y + 4, z + 8, KMOD_Main.KetherBlueLeaves);
         world.setBlockMetadataWithNotify(x + 12, y + 4, z + 8, 14, 14);
         this.setBlock(world, x + 17, y + 4, z + 8, KMOD_Main.KetherBlueLeaves);
         world.setBlockMetadataWithNotify(x + 17, y + 4, z + 8, 14, 14);
         this.setBlock(world, x + 22, y + 4, z + 8, KMOD_Main.KetherBlueLeaves);
         world.setBlockMetadataWithNotify(x + 22, y + 4, z + 8, 14, 14);
         this.setBlock(world, x + 3, y + 4, z + 9, KMOD_Main.KetherBlueLeaves);
         world.setBlockMetadataWithNotify(x + 3, y + 4, z + 9, 14, 14);
         this.setBlock(world, x + 6, y + 4, z + 9, KMOD_Main.KetherBlueLeaves);
         world.setBlockMetadataWithNotify(x + 6, y + 4, z + 9, 14, 14);
         this.setBlock(world, x + 7, y + 4, z + 9, KMOD_Main.KetherBlueLeaves);
         world.setBlockMetadataWithNotify(x + 7, y + 4, z + 9, 14, 14);
         this.setBlock(world, x + 22, y + 4, z + 9, KMOD_Main.KetherBlueLeaves);
         world.setBlockMetadataWithNotify(x + 22, y + 4, z + 9, 14, 14);
         this.setBlock(world, x + 4, y + 4, z + 10, KMOD_Main.KetherBlueLeaves);
         world.setBlockMetadataWithNotify(x + 4, y + 4, z + 10, 14, 14);
         this.setBlock(world, x + 6, y + 4, z + 10, KMOD_Main.KetherBlueLeaves);
         world.setBlockMetadataWithNotify(x + 6, y + 4, z + 10, 14, 14);
         this.setBlock(world, x + 7, y + 4, z + 10, KMOD_Main.KetherBlueLeaves);
         world.setBlockMetadataWithNotify(x + 7, y + 4, z + 10, 14, 14);
         this.setBlock(world, x + 18, y + 4, z + 10, KMOD_Main.KetherBlueLeaves);
         world.setBlockMetadataWithNotify(x + 18, y + 4, z + 10, 14, 14);
         this.setBlock(world, x + 22, y + 4, z + 10, KMOD_Main.KetherBlueLeaves);
         world.setBlockMetadataWithNotify(x + 22, y + 4, z + 10, 14, 14);
         this.setBlock(world, x + 3, y + 4, z + 11, KMOD_Main.KetherBlueLeaves);
         world.setBlockMetadataWithNotify(x + 3, y + 4, z + 11, 14, 14);
         this.setBlock(world, x + 20, y + 4, z + 11, KMOD_Main.KetherBlueLeaves);
         world.setBlockMetadataWithNotify(x + 20, y + 4, z + 11, 14, 14);
         this.setBlock(world, x + 21, y + 4, z + 11, KMOD_Main.KetherBlueLeaves);
         world.setBlockMetadataWithNotify(x + 21, y + 4, z + 11, 14, 14);
         this.setBlock(world, x + 0, y + 4, z + 12, KMOD_Main.KetherBlueLeaves);
         world.setBlockMetadataWithNotify(x + 0, y + 4, z + 12, 14, 14);
         this.setBlock(world, x + 4, y + 4, z + 12, KMOD_Main.KetherBlueLeaves);
         world.setBlockMetadataWithNotify(x + 4, y + 4, z + 12, 14, 14);
         this.setBlock(world, x + 21, y + 4, z + 12, KMOD_Main.KetherBlueLeaves);
         world.setBlockMetadataWithNotify(x + 21, y + 4, z + 12, 14, 14);
         this.setBlock(world, x + 24, y + 4, z + 12, KMOD_Main.KetherBlueLeaves);
         world.setBlockMetadataWithNotify(x + 24, y + 4, z + 12, 14, 14);
         this.setBlock(world, x + 1, y + 4, z + 13, KMOD_Main.KetherBlueLeaves);
         world.setBlockMetadataWithNotify(x + 1, y + 4, z + 13, 14, 14);
         this.setBlock(world, x + 13, y + 4, z + 13, KMOD_Main.KetherLog);
         world.setBlockMetadataWithNotify(x + 13, y + 4, z + 13, 12, 12);
         this.setBlock(world, x + 23, y + 4, z + 13, KMOD_Main.KetherBlueLeaves);
         world.setBlockMetadataWithNotify(x + 23, y + 4, z + 13, 14, 14);
         this.setBlock(world, x + 0, y + 4, z + 14, KMOD_Main.KetherBlueLeaves);
         world.setBlockMetadataWithNotify(x + 0, y + 4, z + 14, 14, 14);
         this.setBlock(world, x + 1, y + 4, z + 14, KMOD_Main.KetherBlueLeaves);
         world.setBlockMetadataWithNotify(x + 1, y + 4, z + 14, 14, 14);
         this.setBlock(world, x + 3, y + 4, z + 14, KMOD_Main.KetherBlueLeaves);
         world.setBlockMetadataWithNotify(x + 3, y + 4, z + 14, 14, 14);
         this.setBlock(world, x + 4, y + 4, z + 14, KMOD_Main.KetherBlueLeaves);
         world.setBlockMetadataWithNotify(x + 4, y + 4, z + 14, 14, 14);
         this.setBlock(world, x + 13, y + 4, z + 14, KMOD_Main.KetherLog);
         world.setBlockMetadataWithNotify(x + 13, y + 4, z + 14, 12, 12);
         this.setBlock(world, x + 14, y + 4, z + 14, KMOD_Main.KetherLog);
         world.setBlockMetadataWithNotify(x + 14, y + 4, z + 14, 12, 12);
         this.setBlock(world, x + 22, y + 4, z + 14, KMOD_Main.KetherBlueLeaves);
         world.setBlockMetadataWithNotify(x + 22, y + 4, z + 14, 14, 14);
         this.setBlock(world, x + 24, y + 4, z + 14, KMOD_Main.KetherBlueLeaves);
         world.setBlockMetadataWithNotify(x + 24, y + 4, z + 14, 14, 14);
         this.setBlock(world, x + 1, y + 4, z + 15, KMOD_Main.KetherBlueLeaves);
         world.setBlockMetadataWithNotify(x + 1, y + 4, z + 15, 14, 14);
         this.setBlock(world, x + 2, y + 4, z + 15, KMOD_Main.KetherBlueLeaves);
         world.setBlockMetadataWithNotify(x + 2, y + 4, z + 15, 14, 14);
         this.setBlock(world, x + 5, y + 4, z + 15, KMOD_Main.KetherBlueLeaves);
         world.setBlockMetadataWithNotify(x + 5, y + 4, z + 15, 14, 14);
         this.setBlock(world, x + 23, y + 4, z + 15, KMOD_Main.KetherBlueLeaves);
         world.setBlockMetadataWithNotify(x + 23, y + 4, z + 15, 14, 14);
         this.setBlock(world, x + 24, y + 4, z + 15, KMOD_Main.KetherBlueLeaves);
         world.setBlockMetadataWithNotify(x + 24, y + 4, z + 15, 14, 14);
         this.setBlock(world, x + 25, y + 4, z + 15, KMOD_Main.KetherBlueLeaves);
         world.setBlockMetadataWithNotify(x + 25, y + 4, z + 15, 14, 14);
         this.setBlock(world, x + 2, y + 4, z + 16, KMOD_Main.KetherBlueLeaves);
         world.setBlockMetadataWithNotify(x + 2, y + 4, z + 16, 14, 14);
         this.setBlock(world, x + 3, y + 4, z + 16, KMOD_Main.KetherBlueLeaves);
         world.setBlockMetadataWithNotify(x + 3, y + 4, z + 16, 14, 14);
         this.setBlock(world, x + 4, y + 4, z + 16, KMOD_Main.KetherBlueLeaves);
         world.setBlockMetadataWithNotify(x + 4, y + 4, z + 16, 14, 14);
         this.setBlock(world, x + 21, y + 4, z + 16, KMOD_Main.KetherBlueLeaves);
         world.setBlockMetadataWithNotify(x + 21, y + 4, z + 16, 14, 14);
         this.setBlock(world, x + 23, y + 4, z + 16, KMOD_Main.KetherBlueLeaves);
         world.setBlockMetadataWithNotify(x + 23, y + 4, z + 16, 14, 14);
         this.setBlock(world, x + 24, y + 4, z + 16, KMOD_Main.KetherBlueLeaves);
         world.setBlockMetadataWithNotify(x + 24, y + 4, z + 16, 14, 14);
         this.setBlock(world, x + 25, y + 4, z + 16, KMOD_Main.KetherBlueLeaves);
         world.setBlockMetadataWithNotify(x + 25, y + 4, z + 16, 14, 14);
         this.setBlock(world, x + 1, y + 4, z + 17, KMOD_Main.KetherBlueLeaves);
         world.setBlockMetadataWithNotify(x + 1, y + 4, z + 17, 14, 14);
         this.setBlock(world, x + 2, y + 4, z + 17, KMOD_Main.KetherBlueLeaves);
         world.setBlockMetadataWithNotify(x + 2, y + 4, z + 17, 14, 14);
         this.setBlock(world, x + 4, y + 4, z + 17, KMOD_Main.KetherBlueLeaves);
         world.setBlockMetadataWithNotify(x + 4, y + 4, z + 17, 14, 14);
         this.setBlock(world, x + 25, y + 4, z + 17, KMOD_Main.KetherBlueLeaves);
         world.setBlockMetadataWithNotify(x + 25, y + 4, z + 17, 14, 14);
         this.setBlock(world, x + 21, y + 4, z + 18, KMOD_Main.KetherBlueLeaves);
         world.setBlockMetadataWithNotify(x + 21, y + 4, z + 18, 14, 14);
         this.setBlock(world, x + 22, y + 4, z + 18, KMOD_Main.KetherBlueLeaves);
         world.setBlockMetadataWithNotify(x + 22, y + 4, z + 18, 14, 14);
         this.setBlock(world, x + 24, y + 4, z + 18, KMOD_Main.KetherBlueLeaves);
         world.setBlockMetadataWithNotify(x + 24, y + 4, z + 18, 14, 14);
         this.setBlock(world, x + 1, y + 4, z + 19, KMOD_Main.KetherBlueLeaves);
         world.setBlockMetadataWithNotify(x + 1, y + 4, z + 19, 14, 14);
         this.setBlock(world, x + 3, y + 4, z + 19, KMOD_Main.KetherBlueLeaves);
         world.setBlockMetadataWithNotify(x + 3, y + 4, z + 19, 14, 14);
         this.setBlock(world, x + 3, y + 4, z + 20, KMOD_Main.KetherBlueLeaves);
         world.setBlockMetadataWithNotify(x + 3, y + 4, z + 20, 14, 14);
         this.setBlock(world, x + 4, y + 4, z + 20, KMOD_Main.KetherBlueLeaves);
         world.setBlockMetadataWithNotify(x + 4, y + 4, z + 20, 14, 14);
         this.setBlock(world, x + 18, y + 4, z + 20, KMOD_Main.KetherBlueLeaves);
         world.setBlockMetadataWithNotify(x + 18, y + 4, z + 20, 14, 14);
         this.setBlock(world, x + 21, y + 4, z + 20, KMOD_Main.KetherBlueLeaves);
         world.setBlockMetadataWithNotify(x + 21, y + 4, z + 20, 14, 14);
         this.setBlock(world, x + 2, y + 4, z + 21, KMOD_Main.KetherBlueLeaves);
         world.setBlockMetadataWithNotify(x + 2, y + 4, z + 21, 14, 14);
         this.setBlock(world, x + 3, y + 4, z + 21, KMOD_Main.KetherBlueLeaves);
         world.setBlockMetadataWithNotify(x + 3, y + 4, z + 21, 14, 14);
         this.setBlock(world, x + 19, y + 4, z + 21, KMOD_Main.KetherBlueLeaves);
         world.setBlockMetadataWithNotify(x + 19, y + 4, z + 21, 14, 14);
         this.setBlock(world, x + 20, y + 4, z + 21, KMOD_Main.KetherBlueLeaves);
         world.setBlockMetadataWithNotify(x + 20, y + 4, z + 21, 14, 14);
         this.setBlock(world, x + 2, y + 4, z + 22, KMOD_Main.KetherBlueLeaves);
         world.setBlockMetadataWithNotify(x + 2, y + 4, z + 22, 14, 14);
         this.setBlock(world, x + 3, y + 4, z + 22, KMOD_Main.KetherBlueLeaves);
         world.setBlockMetadataWithNotify(x + 3, y + 4, z + 22, 14, 14);
         this.setBlock(world, x + 7, y + 4, z + 22, KMOD_Main.KetherBlueLeaves);
         world.setBlockMetadataWithNotify(x + 7, y + 4, z + 22, 14, 14);
         this.setBlock(world, x + 12, y + 4, z + 22, KMOD_Main.KetherBlueLeaves);
         world.setBlockMetadataWithNotify(x + 12, y + 4, z + 22, 14, 14);
         this.setBlock(world, x + 23, y + 4, z + 22, KMOD_Main.KetherBlueLeaves);
         world.setBlockMetadataWithNotify(x + 23, y + 4, z + 22, 14, 14);
         this.setBlock(world, x + 3, y + 4, z + 23, KMOD_Main.KetherBlueLeaves);
         world.setBlockMetadataWithNotify(x + 3, y + 4, z + 23, 14, 14);
         this.setBlock(world, x + 4, y + 4, z + 23, KMOD_Main.KetherBlueLeaves);
         world.setBlockMetadataWithNotify(x + 4, y + 4, z + 23, 14, 14);
         this.setBlock(world, x + 5, y + 4, z + 23, KMOD_Main.KetherBlueLeaves);
         world.setBlockMetadataWithNotify(x + 5, y + 4, z + 23, 14, 14);
         this.setBlock(world, x + 6, y + 4, z + 23, KMOD_Main.KetherBlueLeaves);
         world.setBlockMetadataWithNotify(x + 6, y + 4, z + 23, 14, 14);
         this.setBlock(world, x + 9, y + 4, z + 23, KMOD_Main.KetherBlueLeaves);
         world.setBlockMetadataWithNotify(x + 9, y + 4, z + 23, 14, 14);
         this.setBlock(world, x + 13, y + 4, z + 23, KMOD_Main.KetherBlueLeaves);
         world.setBlockMetadataWithNotify(x + 13, y + 4, z + 23, 14, 14);
         this.setBlock(world, x + 15, y + 4, z + 23, KMOD_Main.KetherBlueLeaves);
         world.setBlockMetadataWithNotify(x + 15, y + 4, z + 23, 14, 14);
         this.setBlock(world, x + 20, y + 4, z + 23, KMOD_Main.KetherBlueLeaves);
         world.setBlockMetadataWithNotify(x + 20, y + 4, z + 23, 14, 14);
         this.setBlock(world, x + 21, y + 4, z + 23, KMOD_Main.KetherBlueLeaves);
         world.setBlockMetadataWithNotify(x + 21, y + 4, z + 23, 14, 14);
         this.setBlock(world, x + 22, y + 4, z + 23, KMOD_Main.KetherBlueLeaves);
         world.setBlockMetadataWithNotify(x + 22, y + 4, z + 23, 14, 14);
         this.setBlock(world, x + 6, y + 4, z + 24, KMOD_Main.KetherBlueLeaves);
         world.setBlockMetadataWithNotify(x + 6, y + 4, z + 24, 14, 14);
         this.setBlock(world, x + 15, y + 4, z + 24, KMOD_Main.KetherBlueLeaves);
         world.setBlockMetadataWithNotify(x + 15, y + 4, z + 24, 14, 14);
         this.setBlock(world, x + 16, y + 4, z + 24, KMOD_Main.KetherBlueLeaves);
         world.setBlockMetadataWithNotify(x + 16, y + 4, z + 24, 14, 14);
         this.setBlock(world, x + 3, y + 4, z + 25, KMOD_Main.KetherBlueLeaves);
         world.setBlockMetadataWithNotify(x + 3, y + 4, z + 25, 14, 14);
         this.setBlock(world, x + 6, y + 4, z + 25, KMOD_Main.KetherBlueLeaves);
         world.setBlockMetadataWithNotify(x + 6, y + 4, z + 25, 14, 14);
         this.setBlock(world, x + 9, y + 4, z + 25, KMOD_Main.KetherBlueLeaves);
         world.setBlockMetadataWithNotify(x + 9, y + 4, z + 25, 14, 14);
         this.setBlock(world, x + 11, y + 4, z + 25, KMOD_Main.KetherBlueLeaves);
         world.setBlockMetadataWithNotify(x + 11, y + 4, z + 25, 14, 14);
         this.setBlock(world, x + 12, y + 4, z + 25, KMOD_Main.KetherBlueLeaves);
         world.setBlockMetadataWithNotify(x + 12, y + 4, z + 25, 14, 14);
         this.setBlock(world, x + 13, y + 4, z + 25, KMOD_Main.KetherBlueLeaves);
         world.setBlockMetadataWithNotify(x + 13, y + 4, z + 25, 14, 14);
         this.setBlock(world, x + 18, y + 4, z + 25, KMOD_Main.KetherBlueLeaves);
         world.setBlockMetadataWithNotify(x + 18, y + 4, z + 25, 14, 14);
         this.setBlock(world, x + 20, y + 4, z + 25, KMOD_Main.KetherBlueLeaves);
         world.setBlockMetadataWithNotify(x + 20, y + 4, z + 25, 14, 14);
         this.setBlock(world, x + 5, y + 4, z + 26, KMOD_Main.KetherBlueLeaves);
         world.setBlockMetadataWithNotify(x + 5, y + 4, z + 26, 14, 14);
         this.setBlock(world, x + 7, y + 4, z + 26, KMOD_Main.KetherBlueLeaves);
         world.setBlockMetadataWithNotify(x + 7, y + 4, z + 26, 14, 14);
         this.setBlock(world, x + 9, y + 4, z + 26, KMOD_Main.KetherBlueLeaves);
         world.setBlockMetadataWithNotify(x + 9, y + 4, z + 26, 14, 14);
         this.setBlock(world, x + 14, y + 4, z + 26, KMOD_Main.KetherBlueLeaves);
         world.setBlockMetadataWithNotify(x + 14, y + 4, z + 26, 14, 14);
         this.setBlock(world, x + 16, y + 4, z + 26, KMOD_Main.KetherBlueLeaves);
         world.setBlockMetadataWithNotify(x + 16, y + 4, z + 26, 14, 14);
         this.setBlock(world, x + 17, y + 4, z + 26, KMOD_Main.KetherBlueLeaves);
         world.setBlockMetadataWithNotify(x + 17, y + 4, z + 26, 14, 14);
         this.setBlock(world, x + 8, y + 4, z + 27, KMOD_Main.KetherBlueLeaves);
         world.setBlockMetadataWithNotify(x + 8, y + 4, z + 27, 14, 14);
         this.setBlock(world, x + 10, y + 4, z + 27, KMOD_Main.KetherBlueLeaves);
         world.setBlockMetadataWithNotify(x + 10, y + 4, z + 27, 14, 14);
         this.setBlock(world, x + 13, y + 4, z + 27, KMOD_Main.KetherBlueLeaves);
         world.setBlockMetadataWithNotify(x + 13, y + 4, z + 27, 14, 14);
         this.setBlock(world, x + 17, y + 4, z + 27, KMOD_Main.KetherBlueLeaves);
         world.setBlockMetadataWithNotify(x + 17, y + 4, z + 27, 14, 14);
         this.setBlock(world, x + 18, y + 4, z + 27, KMOD_Main.KetherBlueLeaves);
         world.setBlockMetadataWithNotify(x + 18, y + 4, z + 27, 14, 14);
         this.setBlock(world, x + 9, y + 4, z + 28, KMOD_Main.KetherBlueLeaves);
         world.setBlockMetadataWithNotify(x + 9, y + 4, z + 28, 14, 14);
         this.setBlock(world, x + 18, y + 4, z + 28, KMOD_Main.KetherBlueLeaves);
         world.setBlockMetadataWithNotify(x + 18, y + 4, z + 28, 14, 14);
         this.setBlock(world, x + 17, y + 5, z + 0, KMOD_Main.KetherBlueLeaves);
         world.setBlockMetadataWithNotify(x + 17, y + 5, z + 0, 14, 14);
         this.setBlock(world, x + 8, y + 5, z + 1, KMOD_Main.KetherBlueLeaves);
         world.setBlockMetadataWithNotify(x + 8, y + 5, z + 1, 14, 14);
         this.setBlock(world, x + 10, y + 5, z + 1, KMOD_Main.KetherBlueLeaves);
         world.setBlockMetadataWithNotify(x + 10, y + 5, z + 1, 14, 14);
         this.setBlock(world, x + 16, y + 5, z + 1, KMOD_Main.KetherBlueLeaves);
         world.setBlockMetadataWithNotify(x + 16, y + 5, z + 1, 14, 14);
         this.setBlock(world, x + 7, y + 5, z + 2, KMOD_Main.KetherBlueLeaves);
         world.setBlockMetadataWithNotify(x + 7, y + 5, z + 2, 14, 14);
         this.setBlock(world, x + 8, y + 5, z + 2, KMOD_Main.KetherBlueLeaves);
         world.setBlockMetadataWithNotify(x + 8, y + 5, z + 2, 14, 14);
         this.setBlock(world, x + 12, y + 5, z + 2, KMOD_Main.KetherBlueLeaves);
         world.setBlockMetadataWithNotify(x + 12, y + 5, z + 2, 14, 14);
         this.setBlock(world, x + 13, y + 5, z + 2, KMOD_Main.KetherBlueLeaves);
         world.setBlockMetadataWithNotify(x + 13, y + 5, z + 2, 14, 14);
         this.setBlock(world, x + 15, y + 5, z + 2, KMOD_Main.KetherBlueLeaves);
         world.setBlockMetadataWithNotify(x + 15, y + 5, z + 2, 14, 14);
         this.setBlock(world, x + 16, y + 5, z + 2, KMOD_Main.KetherBlueLeaves);
         world.setBlockMetadataWithNotify(x + 16, y + 5, z + 2, 14, 14);
         this.setBlock(world, x + 18, y + 5, z + 2, KMOD_Main.KetherBlueLeaves);
         world.setBlockMetadataWithNotify(x + 18, y + 5, z + 2, 14, 14);
         this.setBlock(world, x + 19, y + 5, z + 2, KMOD_Main.KetherBlueLeaves);
         world.setBlockMetadataWithNotify(x + 19, y + 5, z + 2, 14, 14);
         this.setBlock(world, x + 6, y + 5, z + 3, KMOD_Main.KetherBlueLeaves);
         world.setBlockMetadataWithNotify(x + 6, y + 5, z + 3, 14, 14);
         this.setBlock(world, x + 7, y + 5, z + 3, KMOD_Main.KetherBlueLeaves);
         world.setBlockMetadataWithNotify(x + 7, y + 5, z + 3, 14, 14);
         this.setBlock(world, x + 8, y + 5, z + 3, KMOD_Main.KetherBlueLeaves);
         world.setBlockMetadataWithNotify(x + 8, y + 5, z + 3, 14, 14);
         this.setBlock(world, x + 9, y + 5, z + 3, KMOD_Main.KetherBlueLeaves);
         world.setBlockMetadataWithNotify(x + 9, y + 5, z + 3, 14, 14);
         this.setBlock(world, x + 10, y + 5, z + 3, KMOD_Main.KetherBlueLeaves);
         world.setBlockMetadataWithNotify(x + 10, y + 5, z + 3, 14, 14);
         this.setBlock(world, x + 14, y + 5, z + 3, KMOD_Main.KetherBlueLeaves);
         world.setBlockMetadataWithNotify(x + 14, y + 5, z + 3, 14, 14);
         this.setBlock(world, x + 16, y + 5, z + 3, KMOD_Main.KetherBlueLeaves);
         world.setBlockMetadataWithNotify(x + 16, y + 5, z + 3, 14, 14);
         this.setBlock(world, x + 19, y + 5, z + 3, KMOD_Main.KetherBlueLeaves);
         world.setBlockMetadataWithNotify(x + 19, y + 5, z + 3, 14, 14);
         this.setBlock(world, x + 20, y + 5, z + 3, KMOD_Main.KetherBlueLeaves);
         world.setBlockMetadataWithNotify(x + 20, y + 5, z + 3, 14, 14);
         this.setBlock(world, x + 9, y + 5, z + 4, KMOD_Main.KetherBlueLeaves);
         world.setBlockMetadataWithNotify(x + 9, y + 5, z + 4, 14, 14);
         this.setBlock(world, x + 10, y + 5, z + 4, KMOD_Main.KetherBlueLeaves);
         world.setBlockMetadataWithNotify(x + 10, y + 5, z + 4, 14, 14);
         this.setBlock(world, x + 12, y + 5, z + 4, KMOD_Main.KetherBlueLeaves);
         world.setBlockMetadataWithNotify(x + 12, y + 5, z + 4, 14, 14);
         this.setBlock(world, x + 15, y + 5, z + 4, KMOD_Main.KetherBlueLeaves);
         world.setBlockMetadataWithNotify(x + 15, y + 5, z + 4, 14, 14);
         this.setBlock(world, x + 16, y + 5, z + 4, KMOD_Main.KetherBlueLeaves);
         world.setBlockMetadataWithNotify(x + 16, y + 5, z + 4, 14, 14);
         this.setBlock(world, x + 17, y + 5, z + 4, KMOD_Main.KetherBlueLeaves);
         world.setBlockMetadataWithNotify(x + 17, y + 5, z + 4, 14, 14);
         this.setBlock(world, x + 19, y + 5, z + 4, KMOD_Main.KetherBlueLeaves);
         world.setBlockMetadataWithNotify(x + 19, y + 5, z + 4, 14, 14);
         this.setBlock(world, x + 6, y + 5, z + 5, KMOD_Main.KetherBlueLeaves);
         world.setBlockMetadataWithNotify(x + 6, y + 5, z + 5, 14, 14);
         this.setBlock(world, x + 11, y + 5, z + 5, KMOD_Main.KetherBlueLeaves);
         world.setBlockMetadataWithNotify(x + 11, y + 5, z + 5, 14, 14);
         this.setBlock(world, x + 12, y + 5, z + 5, KMOD_Main.KetherBlueLeaves);
         world.setBlockMetadataWithNotify(x + 12, y + 5, z + 5, 14, 14);
         this.setBlock(world, x + 13, y + 5, z + 5, KMOD_Main.KetherBlueLeaves);
         world.setBlockMetadataWithNotify(x + 13, y + 5, z + 5, 14, 14);
         this.setBlock(world, x + 14, y + 5, z + 5, KMOD_Main.KetherBlueLeaves);
         world.setBlockMetadataWithNotify(x + 14, y + 5, z + 5, 14, 14);
         this.setBlock(world, x + 19, y + 5, z + 5, KMOD_Main.KetherBlueLeaves);
         world.setBlockMetadataWithNotify(x + 19, y + 5, z + 5, 14, 14);
         this.setBlock(world, x + 5, y + 5, z + 6, KMOD_Main.KetherBlueLeaves);
         world.setBlockMetadataWithNotify(x + 5, y + 5, z + 6, 14, 14);
         this.setBlock(world, x + 7, y + 5, z + 6, KMOD_Main.KetherBlueLeaves);
         world.setBlockMetadataWithNotify(x + 7, y + 5, z + 6, 14, 14);
         this.setBlock(world, x + 15, y + 5, z + 6, KMOD_Main.KetherBlueLeaves);
         world.setBlockMetadataWithNotify(x + 15, y + 5, z + 6, 14, 14);
         this.setBlock(world, x + 18, y + 5, z + 6, KMOD_Main.KetherBlueLeaves);
         world.setBlockMetadataWithNotify(x + 18, y + 5, z + 6, 14, 14);
         this.setBlock(world, x + 19, y + 5, z + 6, KMOD_Main.KetherBlueLeaves);
         world.setBlockMetadataWithNotify(x + 19, y + 5, z + 6, 14, 14);
         this.setBlock(world, x + 20, y + 5, z + 6, KMOD_Main.KetherBlueLeaves);
         world.setBlockMetadataWithNotify(x + 20, y + 5, z + 6, 14, 14);
         this.setBlock(world, x + 21, y + 5, z + 6, KMOD_Main.KetherBlueLeaves);
         world.setBlockMetadataWithNotify(x + 21, y + 5, z + 6, 14, 14);
         this.setBlock(world, x + 4, y + 5, z + 7, KMOD_Main.KetherBlueLeaves);
         world.setBlockMetadataWithNotify(x + 4, y + 5, z + 7, 14, 14);
         this.setBlock(world, x + 6, y + 5, z + 7, KMOD_Main.KetherBlueLeaves);
         world.setBlockMetadataWithNotify(x + 6, y + 5, z + 7, 14, 14);
         this.setBlock(world, x + 8, y + 5, z + 7, KMOD_Main.KetherBlueLeaves);
         world.setBlockMetadataWithNotify(x + 8, y + 5, z + 7, 14, 14);
         this.setBlock(world, x + 10, y + 5, z + 7, KMOD_Main.KetherBlueLeaves);
         world.setBlockMetadataWithNotify(x + 10, y + 5, z + 7, 14, 14);
         this.setBlock(world, x + 11, y + 5, z + 7, KMOD_Main.KetherBlueLeaves);
         world.setBlockMetadataWithNotify(x + 11, y + 5, z + 7, 14, 14);
         this.setBlock(world, x + 13, y + 5, z + 7, KMOD_Main.KetherBlueLeaves);
         world.setBlockMetadataWithNotify(x + 13, y + 5, z + 7, 14, 14);
         this.setBlock(world, x + 14, y + 5, z + 7, KMOD_Main.KetherBlueLeaves);
         world.setBlockMetadataWithNotify(x + 14, y + 5, z + 7, 14, 14);
         this.setBlock(world, x + 21, y + 5, z + 7, KMOD_Main.KetherBlueLeaves);
         world.setBlockMetadataWithNotify(x + 21, y + 5, z + 7, 14, 14);
         this.setBlock(world, x + 4, y + 5, z + 8, KMOD_Main.KetherBlueLeaves);
         world.setBlockMetadataWithNotify(x + 4, y + 5, z + 8, 14, 14);
         this.setBlock(world, x + 6, y + 5, z + 8, KMOD_Main.KetherBlueLeaves);
         world.setBlockMetadataWithNotify(x + 6, y + 5, z + 8, 14, 14);
         this.setBlock(world, x + 7, y + 5, z + 8, KMOD_Main.KetherBlueLeaves);
         world.setBlockMetadataWithNotify(x + 7, y + 5, z + 8, 14, 14);
         this.setBlock(world, x + 9, y + 5, z + 8, KMOD_Main.KetherBlueLeaves);
         world.setBlockMetadataWithNotify(x + 9, y + 5, z + 8, 14, 14);
         this.setBlock(world, x + 10, y + 5, z + 8, KMOD_Main.KetherBlueLeaves);
         world.setBlockMetadataWithNotify(x + 10, y + 5, z + 8, 14, 14);
         this.setBlock(world, x + 15, y + 5, z + 8, KMOD_Main.KetherBlueLeaves);
         world.setBlockMetadataWithNotify(x + 15, y + 5, z + 8, 14, 14);
         this.setBlock(world, x + 18, y + 5, z + 8, KMOD_Main.KetherBlueLeaves);
         world.setBlockMetadataWithNotify(x + 18, y + 5, z + 8, 14, 14);
         this.setBlock(world, x + 19, y + 5, z + 8, KMOD_Main.KetherBlueLeaves);
         world.setBlockMetadataWithNotify(x + 19, y + 5, z + 8, 14, 14);
         this.setBlock(world, x + 20, y + 5, z + 8, KMOD_Main.KetherBlueLeaves);
         world.setBlockMetadataWithNotify(x + 20, y + 5, z + 8, 14, 14);
         this.setBlock(world, x + 23, y + 5, z + 8, KMOD_Main.KetherBlueLeaves);
         world.setBlockMetadataWithNotify(x + 23, y + 5, z + 8, 14, 14);
         this.setBlock(world, x + 3, y + 5, z + 9, KMOD_Main.KetherBlueLeaves);
         world.setBlockMetadataWithNotify(x + 3, y + 5, z + 9, 14, 14);
         this.setBlock(world, x + 18, y + 5, z + 9, KMOD_Main.KetherBlueLeaves);
         world.setBlockMetadataWithNotify(x + 18, y + 5, z + 9, 14, 14);
         this.setBlock(world, x + 19, y + 5, z + 9, KMOD_Main.KetherBlueLeaves);
         world.setBlockMetadataWithNotify(x + 19, y + 5, z + 9, 14, 14);
         this.setBlock(world, x + 4, y + 5, z + 10, KMOD_Main.KetherBlueLeaves);
         world.setBlockMetadataWithNotify(x + 4, y + 5, z + 10, 14, 14);
         this.setBlock(world, x + 6, y + 5, z + 10, KMOD_Main.KetherBlueLeaves);
         world.setBlockMetadataWithNotify(x + 6, y + 5, z + 10, 14, 14);
         this.setBlock(world, x + 7, y + 5, z + 10, KMOD_Main.KetherBlueLeaves);
         world.setBlockMetadataWithNotify(x + 7, y + 5, z + 10, 14, 14);
         this.setBlock(world, x + 19, y + 5, z + 10, KMOD_Main.KetherBlueLeaves);
         world.setBlockMetadataWithNotify(x + 19, y + 5, z + 10, 14, 14);
         this.setBlock(world, x + 21, y + 5, z + 10, KMOD_Main.KetherBlueLeaves);
         world.setBlockMetadataWithNotify(x + 21, y + 5, z + 10, 14, 14);
         this.setBlock(world, x + 24, y + 5, z + 10, KMOD_Main.KetherBlueLeaves);
         world.setBlockMetadataWithNotify(x + 24, y + 5, z + 10, 14, 14);
         this.setBlock(world, x + 1, y + 5, z + 11, KMOD_Main.KetherBlueLeaves);
         world.setBlockMetadataWithNotify(x + 1, y + 5, z + 11, 14, 14);
         this.setBlock(world, x + 2, y + 5, z + 11, KMOD_Main.KetherBlueLeaves);
         world.setBlockMetadataWithNotify(x + 2, y + 5, z + 11, 14, 14);
         this.setBlock(world, x + 7, y + 5, z + 11, KMOD_Main.KetherBlueLeaves);
         world.setBlockMetadataWithNotify(x + 7, y + 5, z + 11, 14, 14);
         this.setBlock(world, x + 19, y + 5, z + 11, KMOD_Main.KetherBlueLeaves);
         world.setBlockMetadataWithNotify(x + 19, y + 5, z + 11, 14, 14);
         this.setBlock(world, x + 23, y + 5, z + 11, KMOD_Main.KetherBlueLeaves);
         world.setBlockMetadataWithNotify(x + 23, y + 5, z + 11, 14, 14);
         this.setBlock(world, x + 3, y + 5, z + 12, KMOD_Main.KetherBlueLeaves);
         world.setBlockMetadataWithNotify(x + 3, y + 5, z + 12, 14, 14);
         this.setBlock(world, x + 4, y + 5, z + 12, KMOD_Main.KetherBlueLeaves);
         world.setBlockMetadataWithNotify(x + 4, y + 5, z + 12, 14, 14);
         this.setBlock(world, x + 6, y + 5, z + 12, KMOD_Main.KetherBlueLeaves);
         world.setBlockMetadataWithNotify(x + 6, y + 5, z + 12, 14, 14);
         this.setBlock(world, x + 7, y + 5, z + 12, KMOD_Main.KetherBlueLeaves);
         world.setBlockMetadataWithNotify(x + 7, y + 5, z + 12, 14, 14);
         this.setBlock(world, x + 20, y + 5, z + 12, KMOD_Main.KetherBlueLeaves);
         world.setBlockMetadataWithNotify(x + 20, y + 5, z + 12, 14, 14);
         this.setBlock(world, x + 22, y + 5, z + 12, KMOD_Main.KetherBlueLeaves);
         world.setBlockMetadataWithNotify(x + 22, y + 5, z + 12, 14, 14);
         this.setBlock(world, x + 7, y + 5, z + 13, KMOD_Main.KetherBlueLeaves);
         world.setBlockMetadataWithNotify(x + 7, y + 5, z + 13, 14, 14);
         this.setBlock(world, x + 0, y + 5, z + 14, KMOD_Main.KetherBlueLeaves);
         world.setBlockMetadataWithNotify(x + 0, y + 5, z + 14, 14, 14);
         this.setBlock(world, x + 2, y + 5, z + 14, KMOD_Main.KetherBlueLeaves);
         world.setBlockMetadataWithNotify(x + 2, y + 5, z + 14, 14, 14);
         this.setBlock(world, x + 4, y + 5, z + 14, KMOD_Main.KetherBlueLeaves);
         world.setBlockMetadataWithNotify(x + 4, y + 5, z + 14, 14, 14);
         this.setBlock(world, x + 5, y + 5, z + 14, KMOD_Main.KetherBlueLeaves);
         world.setBlockMetadataWithNotify(x + 5, y + 5, z + 14, 14, 14);
         this.setBlock(world, x + 13, y + 5, z + 14, KMOD_Main.KetherLog);
         world.setBlockMetadataWithNotify(x + 13, y + 5, z + 14, 12, 12);
         this.setBlock(world, x + 14, y + 5, z + 14, KMOD_Main.KetherLog);
         world.setBlockMetadataWithNotify(x + 14, y + 5, z + 14, 12, 12);
         this.setBlock(world, x + 21, y + 5, z + 14, KMOD_Main.KetherBlueLeaves);
         world.setBlockMetadataWithNotify(x + 21, y + 5, z + 14, 14, 14);
         this.setBlock(world, x + 3, y + 5, z + 15, KMOD_Main.KetherBlueLeaves);
         world.setBlockMetadataWithNotify(x + 3, y + 5, z + 15, 14, 14);
         this.setBlock(world, x + 6, y + 5, z + 15, KMOD_Main.KetherBlueLeaves);
         world.setBlockMetadataWithNotify(x + 6, y + 5, z + 15, 14, 14);
         this.setBlock(world, x + 13, y + 5, z + 15, KMOD_Main.KetherLog);
         world.setBlockMetadataWithNotify(x + 13, y + 5, z + 15, 12, 12);
         this.setBlock(world, x + 21, y + 5, z + 15, KMOD_Main.KetherBlueLeaves);
         world.setBlockMetadataWithNotify(x + 21, y + 5, z + 15, 14, 14);
         this.setBlock(world, x + 22, y + 5, z + 15, KMOD_Main.KetherBlueLeaves);
         world.setBlockMetadataWithNotify(x + 22, y + 5, z + 15, 14, 14);
         this.setBlock(world, x + 23, y + 5, z + 15, KMOD_Main.KetherBlueLeaves);
         world.setBlockMetadataWithNotify(x + 23, y + 5, z + 15, 14, 14);
         this.setBlock(world, x + 2, y + 5, z + 16, KMOD_Main.KetherBlueLeaves);
         world.setBlockMetadataWithNotify(x + 2, y + 5, z + 16, 14, 14);
         this.setBlock(world, x + 4, y + 5, z + 16, KMOD_Main.KetherBlueLeaves);
         world.setBlockMetadataWithNotify(x + 4, y + 5, z + 16, 14, 14);
         this.setBlock(world, x + 5, y + 5, z + 16, KMOD_Main.KetherBlueLeaves);
         world.setBlockMetadataWithNotify(x + 5, y + 5, z + 16, 14, 14);
         this.setBlock(world, x + 20, y + 5, z + 17, KMOD_Main.KetherBlueLeaves);
         world.setBlockMetadataWithNotify(x + 20, y + 5, z + 17, 14, 14);
         this.setBlock(world, x + 23, y + 5, z + 17, KMOD_Main.KetherBlueLeaves);
         world.setBlockMetadataWithNotify(x + 23, y + 5, z + 17, 14, 14);
         this.setBlock(world, x + 2, y + 5, z + 18, KMOD_Main.KetherBlueLeaves);
         world.setBlockMetadataWithNotify(x + 2, y + 5, z + 18, 14, 14);
         this.setBlock(world, x + 3, y + 5, z + 18, KMOD_Main.KetherBlueLeaves);
         world.setBlockMetadataWithNotify(x + 3, y + 5, z + 18, 14, 14);
         this.setBlock(world, x + 5, y + 5, z + 18, KMOD_Main.KetherBlueLeaves);
         world.setBlockMetadataWithNotify(x + 5, y + 5, z + 18, 14, 14);
         this.setBlock(world, x + 18, y + 5, z + 19, KMOD_Main.KetherBlueLeaves);
         world.setBlockMetadataWithNotify(x + 18, y + 5, z + 19, 14, 14);
         this.setBlock(world, x + 4, y + 5, z + 20, KMOD_Main.KetherBlueLeaves);
         world.setBlockMetadataWithNotify(x + 4, y + 5, z + 20, 14, 14);
         this.setBlock(world, x + 5, y + 5, z + 20, KMOD_Main.KetherBlueLeaves);
         world.setBlockMetadataWithNotify(x + 5, y + 5, z + 20, 14, 14);
         this.setBlock(world, x + 9, y + 5, z + 20, KMOD_Main.KetherBlueLeaves);
         world.setBlockMetadataWithNotify(x + 9, y + 5, z + 20, 14, 14);
         this.setBlock(world, x + 17, y + 5, z + 20, KMOD_Main.KetherBlueLeaves);
         world.setBlockMetadataWithNotify(x + 17, y + 5, z + 20, 14, 14);
         this.setBlock(world, x + 18, y + 5, z + 20, KMOD_Main.KetherBlueLeaves);
         world.setBlockMetadataWithNotify(x + 18, y + 5, z + 20, 14, 14);
         this.setBlock(world, x + 19, y + 5, z + 20, KMOD_Main.KetherBlueLeaves);
         world.setBlockMetadataWithNotify(x + 19, y + 5, z + 20, 14, 14);
         this.setBlock(world, x + 1, y + 5, z + 21, KMOD_Main.KetherBlueLeaves);
         world.setBlockMetadataWithNotify(x + 1, y + 5, z + 21, 14, 14);
         this.setBlock(world, x + 2, y + 5, z + 21, KMOD_Main.KetherBlueLeaves);
         world.setBlockMetadataWithNotify(x + 2, y + 5, z + 21, 14, 14);
         this.setBlock(world, x + 4, y + 5, z + 21, KMOD_Main.KetherBlueLeaves);
         world.setBlockMetadataWithNotify(x + 4, y + 5, z + 21, 14, 14);
         this.setBlock(world, x + 16, y + 5, z + 21, KMOD_Main.KetherBlueLeaves);
         world.setBlockMetadataWithNotify(x + 16, y + 5, z + 21, 14, 14);
         this.setBlock(world, x + 19, y + 5, z + 21, KMOD_Main.KetherBlueLeaves);
         world.setBlockMetadataWithNotify(x + 19, y + 5, z + 21, 14, 14);
         this.setBlock(world, x + 22, y + 5, z + 21, KMOD_Main.KetherBlueLeaves);
         world.setBlockMetadataWithNotify(x + 22, y + 5, z + 21, 14, 14);
         this.setBlock(world, x + 1, y + 5, z + 22, KMOD_Main.KetherBlueLeaves);
         world.setBlockMetadataWithNotify(x + 1, y + 5, z + 22, 14, 14);
         this.setBlock(world, x + 2, y + 5, z + 22, KMOD_Main.KetherBlueLeaves);
         world.setBlockMetadataWithNotify(x + 2, y + 5, z + 22, 14, 14);
         this.setBlock(world, x + 3, y + 5, z + 22, KMOD_Main.KetherBlueLeaves);
         world.setBlockMetadataWithNotify(x + 3, y + 5, z + 22, 14, 14);
         this.setBlock(world, x + 6, y + 5, z + 22, KMOD_Main.KetherBlueLeaves);
         world.setBlockMetadataWithNotify(x + 6, y + 5, z + 22, 14, 14);
         this.setBlock(world, x + 7, y + 5, z + 22, KMOD_Main.KetherBlueLeaves);
         world.setBlockMetadataWithNotify(x + 7, y + 5, z + 22, 14, 14);
         this.setBlock(world, x + 8, y + 5, z + 22, KMOD_Main.KetherBlueLeaves);
         world.setBlockMetadataWithNotify(x + 8, y + 5, z + 22, 14, 14);
         this.setBlock(world, x + 9, y + 5, z + 22, KMOD_Main.KetherBlueLeaves);
         world.setBlockMetadataWithNotify(x + 9, y + 5, z + 22, 14, 14);
         this.setBlock(world, x + 19, y + 5, z + 22, KMOD_Main.KetherBlueLeaves);
         world.setBlockMetadataWithNotify(x + 19, y + 5, z + 22, 14, 14);
         this.setBlock(world, x + 23, y + 5, z + 22, KMOD_Main.KetherBlueLeaves);
         world.setBlockMetadataWithNotify(x + 23, y + 5, z + 22, 14, 14);
         this.setBlock(world, x + 4, y + 5, z + 23, KMOD_Main.KetherBlueLeaves);
         world.setBlockMetadataWithNotify(x + 4, y + 5, z + 23, 14, 14);
         this.setBlock(world, x + 8, y + 5, z + 23, KMOD_Main.KetherBlueLeaves);
         world.setBlockMetadataWithNotify(x + 8, y + 5, z + 23, 14, 14);
         this.setBlock(world, x + 11, y + 5, z + 23, KMOD_Main.KetherBlueLeaves);
         world.setBlockMetadataWithNotify(x + 11, y + 5, z + 23, 14, 14);
         this.setBlock(world, x + 12, y + 5, z + 23, KMOD_Main.KetherBlueLeaves);
         world.setBlockMetadataWithNotify(x + 12, y + 5, z + 23, 14, 14);
         this.setBlock(world, x + 16, y + 5, z + 23, KMOD_Main.KetherBlueLeaves);
         world.setBlockMetadataWithNotify(x + 16, y + 5, z + 23, 14, 14);
         this.setBlock(world, x + 17, y + 5, z + 23, KMOD_Main.KetherBlueLeaves);
         world.setBlockMetadataWithNotify(x + 17, y + 5, z + 23, 14, 14);
         this.setBlock(world, x + 18, y + 5, z + 23, KMOD_Main.KetherBlueLeaves);
         world.setBlockMetadataWithNotify(x + 18, y + 5, z + 23, 14, 14);
         this.setBlock(world, x + 21, y + 5, z + 23, KMOD_Main.KetherBlueLeaves);
         world.setBlockMetadataWithNotify(x + 21, y + 5, z + 23, 14, 14);
         this.setBlock(world, x + 2, y + 5, z + 24, KMOD_Main.KetherBlueLeaves);
         world.setBlockMetadataWithNotify(x + 2, y + 5, z + 24, 14, 14);
         this.setBlock(world, x + 4, y + 5, z + 24, KMOD_Main.KetherBlueLeaves);
         world.setBlockMetadataWithNotify(x + 4, y + 5, z + 24, 14, 14);
         this.setBlock(world, x + 5, y + 5, z + 24, KMOD_Main.KetherBlueLeaves);
         world.setBlockMetadataWithNotify(x + 5, y + 5, z + 24, 14, 14);
         this.setBlock(world, x + 8, y + 5, z + 24, KMOD_Main.KetherBlueLeaves);
         world.setBlockMetadataWithNotify(x + 8, y + 5, z + 24, 14, 14);
         this.setBlock(world, x + 12, y + 5, z + 24, KMOD_Main.KetherBlueLeaves);
         world.setBlockMetadataWithNotify(x + 12, y + 5, z + 24, 14, 14);
         this.setBlock(world, x + 14, y + 5, z + 24, KMOD_Main.KetherBlueLeaves);
         world.setBlockMetadataWithNotify(x + 14, y + 5, z + 24, 14, 14);
         this.setBlock(world, x + 15, y + 5, z + 24, KMOD_Main.KetherBlueLeaves);
         world.setBlockMetadataWithNotify(x + 15, y + 5, z + 24, 14, 14);
         this.setBlock(world, x + 19, y + 5, z + 24, KMOD_Main.KetherBlueLeaves);
         world.setBlockMetadataWithNotify(x + 19, y + 5, z + 24, 14, 14);
         this.setBlock(world, x + 20, y + 5, z + 24, KMOD_Main.KetherBlueLeaves);
         world.setBlockMetadataWithNotify(x + 20, y + 5, z + 24, 14, 14);
         this.setBlock(world, x + 21, y + 5, z + 24, KMOD_Main.KetherBlueLeaves);
         world.setBlockMetadataWithNotify(x + 21, y + 5, z + 24, 14, 14);
         this.setBlock(world, x + 22, y + 5, z + 24, KMOD_Main.KetherBlueLeaves);
         world.setBlockMetadataWithNotify(x + 22, y + 5, z + 24, 14, 14);
         this.setBlock(world, x + 4, y + 5, z + 25, KMOD_Main.KetherBlueLeaves);
         world.setBlockMetadataWithNotify(x + 4, y + 5, z + 25, 14, 14);
         this.setBlock(world, x + 7, y + 5, z + 25, KMOD_Main.KetherBlueLeaves);
         world.setBlockMetadataWithNotify(x + 7, y + 5, z + 25, 14, 14);
         this.setBlock(world, x + 11, y + 5, z + 25, KMOD_Main.KetherBlueLeaves);
         world.setBlockMetadataWithNotify(x + 11, y + 5, z + 25, 14, 14);
         this.setBlock(world, x + 12, y + 5, z + 25, KMOD_Main.KetherBlueLeaves);
         world.setBlockMetadataWithNotify(x + 12, y + 5, z + 25, 14, 14);
         this.setBlock(world, x + 16, y + 5, z + 25, KMOD_Main.KetherBlueLeaves);
         world.setBlockMetadataWithNotify(x + 16, y + 5, z + 25, 14, 14);
         this.setBlock(world, x + 18, y + 5, z + 25, KMOD_Main.KetherBlueLeaves);
         world.setBlockMetadataWithNotify(x + 18, y + 5, z + 25, 14, 14);
         this.setBlock(world, x + 5, y + 5, z + 26, KMOD_Main.KetherBlueLeaves);
         world.setBlockMetadataWithNotify(x + 5, y + 5, z + 26, 14, 14);
         this.setBlock(world, x + 14, y + 5, z + 26, KMOD_Main.KetherBlueLeaves);
         world.setBlockMetadataWithNotify(x + 14, y + 5, z + 26, 14, 14);
         this.setBlock(world, x + 15, y + 5, z + 26, KMOD_Main.KetherBlueLeaves);
         world.setBlockMetadataWithNotify(x + 15, y + 5, z + 26, 14, 14);
         this.setBlock(world, x + 11, y + 5, z + 27, KMOD_Main.KetherBlueLeaves);
         world.setBlockMetadataWithNotify(x + 11, y + 5, z + 27, 14, 14);
         this.setBlock(world, x + 13, y + 5, z + 27, KMOD_Main.KetherBlueLeaves);
         world.setBlockMetadataWithNotify(x + 13, y + 5, z + 27, 14, 14);
         this.setBlock(world, x + 14, y + 5, z + 27, KMOD_Main.KetherBlueLeaves);
         world.setBlockMetadataWithNotify(x + 14, y + 5, z + 27, 14, 14);
         this.setBlock(world, x + 18, y + 5, z + 27, KMOD_Main.KetherBlueLeaves);
         world.setBlockMetadataWithNotify(x + 18, y + 5, z + 27, 14, 14);
         this.setBlock(world, x + 19, y + 5, z + 27, KMOD_Main.KetherBlueLeaves);
         world.setBlockMetadataWithNotify(x + 19, y + 5, z + 27, 14, 14);
         this.setBlock(world, x + 11, y + 5, z + 28, KMOD_Main.KetherBlueLeaves);
         world.setBlockMetadataWithNotify(x + 11, y + 5, z + 28, 14, 14);
         this.setBlock(world, x + 13, y + 5, z + 28, KMOD_Main.KetherBlueLeaves);
         world.setBlockMetadataWithNotify(x + 13, y + 5, z + 28, 14, 14);
         this.setBlock(world, x + 16, y + 6, z + 0, KMOD_Main.KetherBlueLeaves);
         world.setBlockMetadataWithNotify(x + 16, y + 6, z + 0, 14, 14);
         this.setBlock(world, x + 11, y + 6, z + 2, KMOD_Main.KetherBlueLeaves);
         world.setBlockMetadataWithNotify(x + 11, y + 6, z + 2, 14, 14);
         this.setBlock(world, x + 12, y + 6, z + 2, KMOD_Main.KetherBlueLeaves);
         world.setBlockMetadataWithNotify(x + 12, y + 6, z + 2, 14, 14);
         this.setBlock(world, x + 16, y + 6, z + 2, KMOD_Main.KetherBlueLeaves);
         world.setBlockMetadataWithNotify(x + 16, y + 6, z + 2, 14, 14);
         this.setBlock(world, x + 17, y + 6, z + 2, KMOD_Main.KetherBlueLeaves);
         world.setBlockMetadataWithNotify(x + 17, y + 6, z + 2, 14, 14);
         this.setBlock(world, x + 18, y + 6, z + 2, KMOD_Main.KetherBlueLeaves);
         world.setBlockMetadataWithNotify(x + 18, y + 6, z + 2, 14, 14);
         this.setBlock(world, x + 6, y + 6, z + 3, KMOD_Main.KetherBlueLeaves);
         world.setBlockMetadataWithNotify(x + 6, y + 6, z + 3, 14, 14);
         this.setBlock(world, x + 8, y + 6, z + 3, KMOD_Main.KetherBlueLeaves);
         world.setBlockMetadataWithNotify(x + 8, y + 6, z + 3, 14, 14);
         this.setBlock(world, x + 15, y + 6, z + 3, KMOD_Main.KetherBlueLeaves);
         world.setBlockMetadataWithNotify(x + 15, y + 6, z + 3, 14, 14);
         this.setBlock(world, x + 5, y + 6, z + 4, KMOD_Main.KetherBlueLeaves);
         world.setBlockMetadataWithNotify(x + 5, y + 6, z + 4, 14, 14);
         this.setBlock(world, x + 7, y + 6, z + 4, KMOD_Main.KetherBlueLeaves);
         world.setBlockMetadataWithNotify(x + 7, y + 6, z + 4, 14, 14);
         this.setBlock(world, x + 10, y + 6, z + 4, KMOD_Main.KetherBlueLeaves);
         world.setBlockMetadataWithNotify(x + 10, y + 6, z + 4, 14, 14);
         this.setBlock(world, x + 11, y + 6, z + 4, KMOD_Main.KetherBlueLeaves);
         world.setBlockMetadataWithNotify(x + 11, y + 6, z + 4, 14, 14);
         this.setBlock(world, x + 17, y + 6, z + 4, KMOD_Main.KetherBlueLeaves);
         world.setBlockMetadataWithNotify(x + 17, y + 6, z + 4, 14, 14);
         this.setBlock(world, x + 6, y + 6, z + 5, KMOD_Main.KetherBlueLeaves);
         world.setBlockMetadataWithNotify(x + 6, y + 6, z + 5, 14, 14);
         this.setBlock(world, x + 7, y + 6, z + 5, KMOD_Main.KetherBlueLeaves);
         world.setBlockMetadataWithNotify(x + 7, y + 6, z + 5, 14, 14);
         this.setBlock(world, x + 9, y + 6, z + 5, KMOD_Main.KetherBlueLeaves);
         world.setBlockMetadataWithNotify(x + 9, y + 6, z + 5, 14, 14);
         this.setBlock(world, x + 11, y + 6, z + 5, KMOD_Main.KetherBlueLeaves);
         world.setBlockMetadataWithNotify(x + 11, y + 6, z + 5, 14, 14);
         this.setBlock(world, x + 12, y + 6, z + 5, KMOD_Main.KetherBlueLeaves);
         world.setBlockMetadataWithNotify(x + 12, y + 6, z + 5, 14, 14);
         this.setBlock(world, x + 14, y + 6, z + 5, KMOD_Main.KetherBlueLeaves);
         world.setBlockMetadataWithNotify(x + 14, y + 6, z + 5, 14, 14);
         this.setBlock(world, x + 16, y + 6, z + 5, KMOD_Main.KetherBlueLeaves);
         world.setBlockMetadataWithNotify(x + 16, y + 6, z + 5, 14, 14);
         this.setBlock(world, x + 19, y + 6, z + 5, KMOD_Main.KetherBlueLeaves);
         world.setBlockMetadataWithNotify(x + 19, y + 6, z + 5, 14, 14);
         this.setBlock(world, x + 6, y + 6, z + 6, KMOD_Main.KetherBlueLeaves);
         world.setBlockMetadataWithNotify(x + 6, y + 6, z + 6, 14, 14);
         this.setBlock(world, x + 8, y + 6, z + 6, KMOD_Main.KetherBlueLeaves);
         world.setBlockMetadataWithNotify(x + 8, y + 6, z + 6, 14, 14);
         this.setBlock(world, x + 16, y + 6, z + 6, KMOD_Main.KetherBlueLeaves);
         world.setBlockMetadataWithNotify(x + 16, y + 6, z + 6, 14, 14);
         this.setBlock(world, x + 17, y + 6, z + 6, KMOD_Main.KetherBlueLeaves);
         world.setBlockMetadataWithNotify(x + 17, y + 6, z + 6, 14, 14);
         this.setBlock(world, x + 9, y + 6, z + 7, KMOD_Main.KetherBlueLeaves);
         world.setBlockMetadataWithNotify(x + 9, y + 6, z + 7, 14, 14);
         this.setBlock(world, x + 10, y + 6, z + 7, KMOD_Main.KetherBlueLeaves);
         world.setBlockMetadataWithNotify(x + 10, y + 6, z + 7, 14, 14);
         this.setBlock(world, x + 11, y + 6, z + 7, KMOD_Main.KetherBlueLeaves);
         world.setBlockMetadataWithNotify(x + 11, y + 6, z + 7, 14, 14);
         this.setBlock(world, x + 12, y + 6, z + 7, KMOD_Main.KetherBlueLeaves);
         world.setBlockMetadataWithNotify(x + 12, y + 6, z + 7, 14, 14);
         this.setBlock(world, x + 13, y + 6, z + 7, KMOD_Main.KetherBlueLeaves);
         world.setBlockMetadataWithNotify(x + 13, y + 6, z + 7, 14, 14);
         this.setBlock(world, x + 15, y + 6, z + 7, KMOD_Main.KetherBlueLeaves);
         world.setBlockMetadataWithNotify(x + 15, y + 6, z + 7, 14, 14);
         this.setBlock(world, x + 20, y + 6, z + 7, KMOD_Main.KetherBlueLeaves);
         world.setBlockMetadataWithNotify(x + 20, y + 6, z + 7, 14, 14);
         this.setBlock(world, x + 6, y + 6, z + 8, KMOD_Main.KetherBlueLeaves);
         world.setBlockMetadataWithNotify(x + 6, y + 6, z + 8, 14, 14);
         this.setBlock(world, x + 7, y + 6, z + 8, KMOD_Main.KetherBlueLeaves);
         world.setBlockMetadataWithNotify(x + 7, y + 6, z + 8, 14, 14);
         this.setBlock(world, x + 8, y + 6, z + 8, KMOD_Main.KetherBlueLeaves);
         world.setBlockMetadataWithNotify(x + 8, y + 6, z + 8, 14, 14);
         this.setBlock(world, x + 12, y + 6, z + 8, KMOD_Main.KetherBlueLeaves);
         world.setBlockMetadataWithNotify(x + 12, y + 6, z + 8, 14, 14);
         this.setBlock(world, x + 15, y + 6, z + 8, KMOD_Main.KetherBlueLeaves);
         world.setBlockMetadataWithNotify(x + 15, y + 6, z + 8, 14, 14);
         this.setBlock(world, x + 17, y + 6, z + 8, KMOD_Main.KetherBlueLeaves);
         world.setBlockMetadataWithNotify(x + 17, y + 6, z + 8, 14, 14);
         this.setBlock(world, x + 18, y + 6, z + 8, KMOD_Main.KetherBlueLeaves);
         world.setBlockMetadataWithNotify(x + 18, y + 6, z + 8, 14, 14);
         this.setBlock(world, x + 20, y + 6, z + 8, KMOD_Main.KetherBlueLeaves);
         world.setBlockMetadataWithNotify(x + 20, y + 6, z + 8, 14, 14);
         this.setBlock(world, x + 21, y + 6, z + 8, KMOD_Main.KetherBlueLeaves);
         world.setBlockMetadataWithNotify(x + 21, y + 6, z + 8, 14, 14);
         this.setBlock(world, x + 4, y + 6, z + 9, KMOD_Main.KetherBlueLeaves);
         world.setBlockMetadataWithNotify(x + 4, y + 6, z + 9, 14, 14);
         this.setBlock(world, x + 7, y + 6, z + 9, KMOD_Main.KetherBlueLeaves);
         world.setBlockMetadataWithNotify(x + 7, y + 6, z + 9, 14, 14);
         this.setBlock(world, x + 8, y + 6, z + 9, KMOD_Main.KetherBlueLeaves);
         world.setBlockMetadataWithNotify(x + 8, y + 6, z + 9, 14, 14);
         this.setBlock(world, x + 19, y + 6, z + 9, KMOD_Main.KetherBlueLeaves);
         world.setBlockMetadataWithNotify(x + 19, y + 6, z + 9, 14, 14);
         this.setBlock(world, x + 23, y + 6, z + 9, KMOD_Main.KetherBlueLeaves);
         world.setBlockMetadataWithNotify(x + 23, y + 6, z + 9, 14, 14);
         this.setBlock(world, x + 2, y + 6, z + 10, KMOD_Main.KetherBlueLeaves);
         world.setBlockMetadataWithNotify(x + 2, y + 6, z + 10, 14, 14);
         this.setBlock(world, x + 4, y + 6, z + 10, KMOD_Main.KetherBlueLeaves);
         world.setBlockMetadataWithNotify(x + 4, y + 6, z + 10, 14, 14);
         this.setBlock(world, x + 6, y + 6, z + 10, KMOD_Main.KetherBlueLeaves);
         world.setBlockMetadataWithNotify(x + 6, y + 6, z + 10, 14, 14);
         this.setBlock(world, x + 7, y + 6, z + 10, KMOD_Main.KetherBlueLeaves);
         world.setBlockMetadataWithNotify(x + 7, y + 6, z + 10, 14, 14);
         this.setBlock(world, x + 8, y + 6, z + 10, KMOD_Main.KetherBlueLeaves);
         world.setBlockMetadataWithNotify(x + 8, y + 6, z + 10, 14, 14);
         this.setBlock(world, x + 9, y + 6, z + 10, KMOD_Main.KetherBlueLeaves);
         world.setBlockMetadataWithNotify(x + 9, y + 6, z + 10, 14, 14);
         this.setBlock(world, x + 11, y + 6, z + 10, KMOD_Main.KetherBlueLeaves);
         world.setBlockMetadataWithNotify(x + 11, y + 6, z + 10, 14, 14);
         this.setBlock(world, x + 21, y + 6, z + 10, KMOD_Main.KetherBlueLeaves);
         world.setBlockMetadataWithNotify(x + 21, y + 6, z + 10, 14, 14);
         this.setBlock(world, x + 23, y + 6, z + 10, KMOD_Main.KetherBlueLeaves);
         world.setBlockMetadataWithNotify(x + 23, y + 6, z + 10, 14, 14);
         this.setBlock(world, x + 2, y + 6, z + 11, KMOD_Main.KetherBlueLeaves);
         world.setBlockMetadataWithNotify(x + 2, y + 6, z + 11, 14, 14);
         this.setBlock(world, x + 7, y + 6, z + 11, KMOD_Main.KetherBlueLeaves);
         world.setBlockMetadataWithNotify(x + 7, y + 6, z + 11, 14, 14);
         this.setBlock(world, x + 19, y + 6, z + 11, KMOD_Main.KetherBlueLeaves);
         world.setBlockMetadataWithNotify(x + 19, y + 6, z + 11, 14, 14);
         this.setBlock(world, x + 22, y + 6, z + 11, KMOD_Main.KetherBlueLeaves);
         world.setBlockMetadataWithNotify(x + 22, y + 6, z + 11, 14, 14);
         this.setBlock(world, x + 0, y + 6, z + 12, KMOD_Main.KetherBlueLeaves);
         world.setBlockMetadataWithNotify(x + 0, y + 6, z + 12, 14, 14);
         this.setBlock(world, x + 2, y + 6, z + 12, KMOD_Main.KetherBlueLeaves);
         world.setBlockMetadataWithNotify(x + 2, y + 6, z + 12, 14, 14);
         this.setBlock(world, x + 23, y + 6, z + 12, KMOD_Main.KetherBlueLeaves);
         world.setBlockMetadataWithNotify(x + 23, y + 6, z + 12, 14, 14);
         this.setBlock(world, x + 2, y + 6, z + 13, KMOD_Main.KetherBlueLeaves);
         world.setBlockMetadataWithNotify(x + 2, y + 6, z + 13, 14, 14);
         this.setBlock(world, x + 3, y + 6, z + 13, KMOD_Main.KetherBlueLeaves);
         world.setBlockMetadataWithNotify(x + 3, y + 6, z + 13, 14, 14);
         this.setBlock(world, x + 6, y + 6, z + 13, KMOD_Main.KetherBlueLeaves);
         world.setBlockMetadataWithNotify(x + 6, y + 6, z + 13, 14, 14);
         this.setBlock(world, x + 11, y + 6, z + 13, KMOD_Main.KetherBlueLeaves);
         world.setBlockMetadataWithNotify(x + 11, y + 6, z + 13, 14, 14);
         this.setBlock(world, x + 19, y + 6, z + 13, KMOD_Main.KetherBlueLeaves);
         world.setBlockMetadataWithNotify(x + 19, y + 6, z + 13, 14, 14);
         this.setBlock(world, x + 23, y + 6, z + 13, KMOD_Main.KetherBlueLeaves);
         world.setBlockMetadataWithNotify(x + 23, y + 6, z + 13, 14, 14);
         this.setBlock(world, x + 0, y + 6, z + 14, KMOD_Main.KetherBlueLeaves);
         world.setBlockMetadataWithNotify(x + 0, y + 6, z + 14, 14, 14);
         this.setBlock(world, x + 5, y + 6, z + 14, KMOD_Main.KetherBlueLeaves);
         world.setBlockMetadataWithNotify(x + 5, y + 6, z + 14, 14, 14);
         this.setBlock(world, x + 6, y + 6, z + 14, KMOD_Main.KetherBlueLeaves);
         world.setBlockMetadataWithNotify(x + 6, y + 6, z + 14, 14, 14);
         this.setBlock(world, x + 7, y + 6, z + 14, KMOD_Main.KetherBlueLeaves);
         world.setBlockMetadataWithNotify(x + 7, y + 6, z + 14, 14, 14);
         this.setBlock(world, x + 13, y + 6, z + 14, KMOD_Main.KetherLog);
         world.setBlockMetadataWithNotify(x + 13, y + 6, z + 14, 12, 12);
         this.setBlock(world, x + 14, y + 6, z + 14, KMOD_Main.KetherLog);
         world.setBlockMetadataWithNotify(x + 14, y + 6, z + 14, 12, 12);
         this.setBlock(world, x + 19, y + 6, z + 14, KMOD_Main.KetherBlueLeaves);
         world.setBlockMetadataWithNotify(x + 19, y + 6, z + 14, 14, 14);
         this.setBlock(world, x + 20, y + 6, z + 14, KMOD_Main.KetherBlueLeaves);
         world.setBlockMetadataWithNotify(x + 20, y + 6, z + 14, 14, 14);
         this.setBlock(world, x + 21, y + 6, z + 14, KMOD_Main.KetherBlueLeaves);
         world.setBlockMetadataWithNotify(x + 21, y + 6, z + 14, 14, 14);
         this.setBlock(world, x + 23, y + 6, z + 14, KMOD_Main.KetherBlueLeaves);
         world.setBlockMetadataWithNotify(x + 23, y + 6, z + 14, 14, 14);
         this.setBlock(world, x + 1, y + 6, z + 15, KMOD_Main.KetherBlueLeaves);
         world.setBlockMetadataWithNotify(x + 1, y + 6, z + 15, 14, 14);
         this.setBlock(world, x + 4, y + 6, z + 15, KMOD_Main.KetherBlueLeaves);
         world.setBlockMetadataWithNotify(x + 4, y + 6, z + 15, 14, 14);
         this.setBlock(world, x + 13, y + 6, z + 15, KMOD_Main.KetherLog);
         world.setBlockMetadataWithNotify(x + 13, y + 6, z + 15, 12, 12);
         this.setBlock(world, x + 14, y + 6, z + 15, KMOD_Main.KetherLog);
         world.setBlockMetadataWithNotify(x + 14, y + 6, z + 15, 12, 12);
         this.setBlock(world, x + 18, y + 6, z + 15, KMOD_Main.KetherBlueLeaves);
         world.setBlockMetadataWithNotify(x + 18, y + 6, z + 15, 14, 14);
         this.setBlock(world, x + 20, y + 6, z + 15, KMOD_Main.KetherBlueLeaves);
         world.setBlockMetadataWithNotify(x + 20, y + 6, z + 15, 14, 14);
         this.setBlock(world, x + 21, y + 6, z + 15, KMOD_Main.KetherBlueLeaves);
         world.setBlockMetadataWithNotify(x + 21, y + 6, z + 15, 14, 14);
         this.setBlock(world, x + 23, y + 6, z + 15, KMOD_Main.KetherBlueLeaves);
         world.setBlockMetadataWithNotify(x + 23, y + 6, z + 15, 14, 14);
         this.setBlock(world, x + 2, y + 6, z + 16, KMOD_Main.KetherBlueLeaves);
         world.setBlockMetadataWithNotify(x + 2, y + 6, z + 16, 14, 14);
         this.setBlock(world, x + 3, y + 6, z + 16, KMOD_Main.KetherBlueLeaves);
         world.setBlockMetadataWithNotify(x + 3, y + 6, z + 16, 14, 14);
         this.setBlock(world, x + 6, y + 6, z + 16, KMOD_Main.KetherBlueLeaves);
         world.setBlockMetadataWithNotify(x + 6, y + 6, z + 16, 14, 14);
         this.setBlock(world, x + 9, y + 6, z + 16, KMOD_Main.KetherBlueLeaves);
         world.setBlockMetadataWithNotify(x + 9, y + 6, z + 16, 14, 14);
         this.setBlock(world, x + 19, y + 6, z + 16, KMOD_Main.KetherBlueLeaves);
         world.setBlockMetadataWithNotify(x + 19, y + 6, z + 16, 14, 14);
         this.setBlock(world, x + 2, y + 6, z + 17, KMOD_Main.KetherBlueLeaves);
         world.setBlockMetadataWithNotify(x + 2, y + 6, z + 17, 14, 14);
         this.setBlock(world, x + 4, y + 6, z + 17, KMOD_Main.KetherBlueLeaves);
         world.setBlockMetadataWithNotify(x + 4, y + 6, z + 17, 14, 14);
         this.setBlock(world, x + 6, y + 6, z + 17, KMOD_Main.KetherBlueLeaves);
         world.setBlockMetadataWithNotify(x + 6, y + 6, z + 17, 14, 14);
         this.setBlock(world, x + 8, y + 6, z + 17, KMOD_Main.KetherBlueLeaves);
         world.setBlockMetadataWithNotify(x + 8, y + 6, z + 17, 14, 14);
         this.setBlock(world, x + 2, y + 6, z + 18, KMOD_Main.KetherBlueLeaves);
         world.setBlockMetadataWithNotify(x + 2, y + 6, z + 18, 14, 14);
         this.setBlock(world, x + 6, y + 6, z + 18, KMOD_Main.KetherBlueLeaves);
         world.setBlockMetadataWithNotify(x + 6, y + 6, z + 18, 14, 14);
         this.setBlock(world, x + 7, y + 6, z + 18, KMOD_Main.KetherBlueLeaves);
         world.setBlockMetadataWithNotify(x + 7, y + 6, z + 18, 14, 14);
         this.setBlock(world, x + 20, y + 6, z + 18, KMOD_Main.KetherBlueLeaves);
         world.setBlockMetadataWithNotify(x + 20, y + 6, z + 18, 14, 14);
         this.setBlock(world, x + 1, y + 6, z + 19, KMOD_Main.KetherBlueLeaves);
         world.setBlockMetadataWithNotify(x + 1, y + 6, z + 19, 14, 14);
         this.setBlock(world, x + 2, y + 6, z + 19, KMOD_Main.KetherBlueLeaves);
         world.setBlockMetadataWithNotify(x + 2, y + 6, z + 19, 14, 14);
         this.setBlock(world, x + 3, y + 6, z + 19, KMOD_Main.KetherBlueLeaves);
         world.setBlockMetadataWithNotify(x + 3, y + 6, z + 19, 14, 14);
         this.setBlock(world, x + 6, y + 6, z + 19, KMOD_Main.KetherBlueLeaves);
         world.setBlockMetadataWithNotify(x + 6, y + 6, z + 19, 14, 14);
         this.setBlock(world, x + 9, y + 6, z + 19, KMOD_Main.KetherBlueLeaves);
         world.setBlockMetadataWithNotify(x + 9, y + 6, z + 19, 14, 14);
         this.setBlock(world, x + 17, y + 6, z + 19, KMOD_Main.KetherBlueLeaves);
         world.setBlockMetadataWithNotify(x + 17, y + 6, z + 19, 14, 14);
         this.setBlock(world, x + 19, y + 6, z + 19, KMOD_Main.KetherBlueLeaves);
         world.setBlockMetadataWithNotify(x + 19, y + 6, z + 19, 14, 14);
         this.setBlock(world, x + 20, y + 6, z + 19, KMOD_Main.KetherBlueLeaves);
         world.setBlockMetadataWithNotify(x + 20, y + 6, z + 19, 14, 14);
         this.setBlock(world, x + 21, y + 6, z + 19, KMOD_Main.KetherBlueLeaves);
         world.setBlockMetadataWithNotify(x + 21, y + 6, z + 19, 14, 14);
         this.setBlock(world, x + 23, y + 6, z + 19, KMOD_Main.KetherBlueLeaves);
         world.setBlockMetadataWithNotify(x + 23, y + 6, z + 19, 14, 14);
         this.setBlock(world, x + 3, y + 6, z + 20, KMOD_Main.KetherBlueLeaves);
         world.setBlockMetadataWithNotify(x + 3, y + 6, z + 20, 14, 14);
         this.setBlock(world, x + 8, y + 6, z + 20, KMOD_Main.KetherBlueLeaves);
         world.setBlockMetadataWithNotify(x + 8, y + 6, z + 20, 14, 14);
         this.setBlock(world, x + 10, y + 6, z + 20, KMOD_Main.KetherBlueLeaves);
         world.setBlockMetadataWithNotify(x + 10, y + 6, z + 20, 14, 14);
         this.setBlock(world, x + 22, y + 6, z + 20, KMOD_Main.KetherBlueLeaves);
         world.setBlockMetadataWithNotify(x + 22, y + 6, z + 20, 14, 14);
         this.setBlock(world, x + 2, y + 6, z + 21, KMOD_Main.KetherBlueLeaves);
         world.setBlockMetadataWithNotify(x + 2, y + 6, z + 21, 14, 14);
         this.setBlock(world, x + 11, y + 6, z + 21, KMOD_Main.KetherBlueLeaves);
         world.setBlockMetadataWithNotify(x + 11, y + 6, z + 21, 14, 14);
         this.setBlock(world, x + 14, y + 6, z + 21, KMOD_Main.KetherBlueLeaves);
         world.setBlockMetadataWithNotify(x + 14, y + 6, z + 21, 14, 14);
         this.setBlock(world, x + 20, y + 6, z + 21, KMOD_Main.KetherBlueLeaves);
         world.setBlockMetadataWithNotify(x + 20, y + 6, z + 21, 14, 14);
         this.setBlock(world, x + 21, y + 6, z + 21, KMOD_Main.KetherBlueLeaves);
         world.setBlockMetadataWithNotify(x + 21, y + 6, z + 21, 14, 14);
         this.setBlock(world, x + 23, y + 6, z + 21, KMOD_Main.KetherBlueLeaves);
         world.setBlockMetadataWithNotify(x + 23, y + 6, z + 21, 14, 14);
         this.setBlock(world, x + 3, y + 6, z + 22, KMOD_Main.KetherBlueLeaves);
         world.setBlockMetadataWithNotify(x + 3, y + 6, z + 22, 14, 14);
         this.setBlock(world, x + 5, y + 6, z + 22, KMOD_Main.KetherBlueLeaves);
         world.setBlockMetadataWithNotify(x + 5, y + 6, z + 22, 14, 14);
         this.setBlock(world, x + 13, y + 6, z + 22, KMOD_Main.KetherBlueLeaves);
         world.setBlockMetadataWithNotify(x + 13, y + 6, z + 22, 14, 14);
         this.setBlock(world, x + 18, y + 6, z + 22, KMOD_Main.KetherBlueLeaves);
         world.setBlockMetadataWithNotify(x + 18, y + 6, z + 22, 14, 14);
         this.setBlock(world, x + 21, y + 6, z + 22, KMOD_Main.KetherBlueLeaves);
         world.setBlockMetadataWithNotify(x + 21, y + 6, z + 22, 14, 14);
         this.setBlock(world, x + 4, y + 6, z + 23, KMOD_Main.KetherBlueLeaves);
         world.setBlockMetadataWithNotify(x + 4, y + 6, z + 23, 14, 14);
         this.setBlock(world, x + 14, y + 6, z + 23, KMOD_Main.KetherBlueLeaves);
         world.setBlockMetadataWithNotify(x + 14, y + 6, z + 23, 14, 14);
         this.setBlock(world, x + 17, y + 6, z + 23, KMOD_Main.KetherBlueLeaves);
         world.setBlockMetadataWithNotify(x + 17, y + 6, z + 23, 14, 14);
         this.setBlock(world, x + 21, y + 6, z + 23, KMOD_Main.KetherBlueLeaves);
         world.setBlockMetadataWithNotify(x + 21, y + 6, z + 23, 14, 14);
         this.setBlock(world, x + 22, y + 6, z + 23, KMOD_Main.KetherBlueLeaves);
         world.setBlockMetadataWithNotify(x + 22, y + 6, z + 23, 14, 14);
         this.setBlock(world, x + 6, y + 6, z + 24, KMOD_Main.KetherBlueLeaves);
         world.setBlockMetadataWithNotify(x + 6, y + 6, z + 24, 14, 14);
         this.setBlock(world, x + 7, y + 6, z + 24, KMOD_Main.KetherBlueLeaves);
         world.setBlockMetadataWithNotify(x + 7, y + 6, z + 24, 14, 14);
         this.setBlock(world, x + 9, y + 6, z + 24, KMOD_Main.KetherBlueLeaves);
         world.setBlockMetadataWithNotify(x + 9, y + 6, z + 24, 14, 14);
         this.setBlock(world, x + 11, y + 6, z + 24, KMOD_Main.KetherBlueLeaves);
         world.setBlockMetadataWithNotify(x + 11, y + 6, z + 24, 14, 14);
         this.setBlock(world, x + 13, y + 6, z + 24, KMOD_Main.KetherBlueLeaves);
         world.setBlockMetadataWithNotify(x + 13, y + 6, z + 24, 14, 14);
         this.setBlock(world, x + 14, y + 6, z + 24, KMOD_Main.KetherBlueLeaves);
         world.setBlockMetadataWithNotify(x + 14, y + 6, z + 24, 14, 14);
         this.setBlock(world, x + 16, y + 6, z + 24, KMOD_Main.KetherBlueLeaves);
         world.setBlockMetadataWithNotify(x + 16, y + 6, z + 24, 14, 14);
         this.setBlock(world, x + 20, y + 6, z + 24, KMOD_Main.KetherBlueLeaves);
         world.setBlockMetadataWithNotify(x + 20, y + 6, z + 24, 14, 14);
         this.setBlock(world, x + 6, y + 6, z + 25, KMOD_Main.KetherBlueLeaves);
         world.setBlockMetadataWithNotify(x + 6, y + 6, z + 25, 14, 14);
         this.setBlock(world, x + 7, y + 6, z + 25, KMOD_Main.KetherBlueLeaves);
         world.setBlockMetadataWithNotify(x + 7, y + 6, z + 25, 14, 14);
         this.setBlock(world, x + 8, y + 6, z + 25, KMOD_Main.KetherBlueLeaves);
         world.setBlockMetadataWithNotify(x + 8, y + 6, z + 25, 14, 14);
         this.setBlock(world, x + 9, y + 6, z + 25, KMOD_Main.KetherBlueLeaves);
         world.setBlockMetadataWithNotify(x + 9, y + 6, z + 25, 14, 14);
         this.setBlock(world, x + 14, y + 6, z + 25, KMOD_Main.KetherBlueLeaves);
         world.setBlockMetadataWithNotify(x + 14, y + 6, z + 25, 14, 14);
         this.setBlock(world, x + 17, y + 6, z + 25, KMOD_Main.KetherBlueLeaves);
         world.setBlockMetadataWithNotify(x + 17, y + 6, z + 25, 14, 14);
         this.setBlock(world, x + 18, y + 6, z + 25, KMOD_Main.KetherBlueLeaves);
         world.setBlockMetadataWithNotify(x + 18, y + 6, z + 25, 14, 14);
         this.setBlock(world, x + 20, y + 6, z + 25, KMOD_Main.KetherBlueLeaves);
         world.setBlockMetadataWithNotify(x + 20, y + 6, z + 25, 14, 14);
         this.setBlock(world, x + 11, y + 6, z + 26, KMOD_Main.KetherBlueLeaves);
         world.setBlockMetadataWithNotify(x + 11, y + 6, z + 26, 14, 14);
         this.setBlock(world, x + 14, y + 6, z + 26, KMOD_Main.KetherBlueLeaves);
         world.setBlockMetadataWithNotify(x + 14, y + 6, z + 26, 14, 14);
         this.setBlock(world, x + 15, y + 6, z + 26, KMOD_Main.KetherBlueLeaves);
         world.setBlockMetadataWithNotify(x + 15, y + 6, z + 26, 14, 14);
         this.setBlock(world, x + 16, y + 6, z + 26, KMOD_Main.KetherBlueLeaves);
         world.setBlockMetadataWithNotify(x + 16, y + 6, z + 26, 14, 14);
         this.setBlock(world, x + 18, y + 6, z + 26, KMOD_Main.KetherBlueLeaves);
         world.setBlockMetadataWithNotify(x + 18, y + 6, z + 26, 14, 14);
         this.setBlock(world, x + 10, y + 6, z + 27, KMOD_Main.KetherBlueLeaves);
         world.setBlockMetadataWithNotify(x + 10, y + 6, z + 27, 14, 14);
         this.setBlock(world, x + 15, y + 6, z + 27, KMOD_Main.KetherBlueLeaves);
         world.setBlockMetadataWithNotify(x + 15, y + 6, z + 27, 14, 14);
         this.setBlock(world, x + 17, y + 6, z + 27, KMOD_Main.KetherBlueLeaves);
         world.setBlockMetadataWithNotify(x + 17, y + 6, z + 27, 14, 14);
         this.setBlock(world, x + 8, y + 6, z + 28, KMOD_Main.KetherBlueLeaves);
         world.setBlockMetadataWithNotify(x + 8, y + 6, z + 28, 14, 14);
         this.setBlock(world, x + 10, y + 6, z + 28, KMOD_Main.KetherBlueLeaves);
         world.setBlockMetadataWithNotify(x + 10, y + 6, z + 28, 14, 14);
         this.setBlock(world, x + 11, y + 6, z + 28, KMOD_Main.KetherBlueLeaves);
         world.setBlockMetadataWithNotify(x + 11, y + 6, z + 28, 14, 14);
         this.setBlock(world, x + 12, y + 6, z + 28, KMOD_Main.KetherBlueLeaves);
         world.setBlockMetadataWithNotify(x + 12, y + 6, z + 28, 14, 14);
         this.setBlock(world, x + 15, y + 7, z + 0, KMOD_Main.KetherBlueLeaves);
         world.setBlockMetadataWithNotify(x + 15, y + 7, z + 0, 14, 14);
         this.setBlock(world, x + 16, y + 7, z + 0, KMOD_Main.KetherBlueLeaves);
         world.setBlockMetadataWithNotify(x + 16, y + 7, z + 0, 14, 14);
         this.setBlock(world, x + 17, y + 7, z + 0, KMOD_Main.KetherBlueLeaves);
         world.setBlockMetadataWithNotify(x + 17, y + 7, z + 0, 14, 14);
         this.setBlock(world, x + 14, y + 7, z + 1, KMOD_Main.KetherBlueLeaves);
         world.setBlockMetadataWithNotify(x + 14, y + 7, z + 1, 14, 14);
         this.setBlock(world, x + 15, y + 7, z + 1, KMOD_Main.KetherBlueLeaves);
         world.setBlockMetadataWithNotify(x + 15, y + 7, z + 1, 14, 14);
         this.setBlock(world, x + 9, y + 7, z + 2, KMOD_Main.KetherBlueLeaves);
         world.setBlockMetadataWithNotify(x + 9, y + 7, z + 2, 14, 14);
         this.setBlock(world, x + 10, y + 7, z + 2, KMOD_Main.KetherBlueLeaves);
         world.setBlockMetadataWithNotify(x + 10, y + 7, z + 2, 14, 14);
         this.setBlock(world, x + 8, y + 7, z + 3, KMOD_Main.KetherBlueLeaves);
         world.setBlockMetadataWithNotify(x + 8, y + 7, z + 3, 14, 14);
         this.setBlock(world, x + 10, y + 7, z + 3, KMOD_Main.KetherBlueLeaves);
         world.setBlockMetadataWithNotify(x + 10, y + 7, z + 3, 14, 14);
         this.setBlock(world, x + 11, y + 7, z + 3, KMOD_Main.KetherBlueLeaves);
         world.setBlockMetadataWithNotify(x + 11, y + 7, z + 3, 14, 14);
         this.setBlock(world, x + 14, y + 7, z + 3, KMOD_Main.KetherBlueLeaves);
         world.setBlockMetadataWithNotify(x + 14, y + 7, z + 3, 14, 14);
         this.setBlock(world, x + 17, y + 7, z + 3, KMOD_Main.KetherBlueLeaves);
         world.setBlockMetadataWithNotify(x + 17, y + 7, z + 3, 14, 14);
         this.setBlock(world, x + 7, y + 7, z + 4, KMOD_Main.KetherBlueLeaves);
         world.setBlockMetadataWithNotify(x + 7, y + 7, z + 4, 14, 14);
         this.setBlock(world, x + 11, y + 7, z + 4, KMOD_Main.KetherBlueLeaves);
         world.setBlockMetadataWithNotify(x + 11, y + 7, z + 4, 14, 14);
         this.setBlock(world, x + 12, y + 7, z + 4, KMOD_Main.KetherBlueLeaves);
         world.setBlockMetadataWithNotify(x + 12, y + 7, z + 4, 14, 14);
         this.setBlock(world, x + 13, y + 7, z + 4, KMOD_Main.KetherBlueLeaves);
         world.setBlockMetadataWithNotify(x + 13, y + 7, z + 4, 14, 14);
         this.setBlock(world, x + 6, y + 7, z + 5, KMOD_Main.KetherBlueLeaves);
         world.setBlockMetadataWithNotify(x + 6, y + 7, z + 5, 14, 14);
         this.setBlock(world, x + 7, y + 7, z + 5, KMOD_Main.KetherBlueLeaves);
         world.setBlockMetadataWithNotify(x + 7, y + 7, z + 5, 14, 14);
         this.setBlock(world, x + 8, y + 7, z + 5, KMOD_Main.KetherBlueLeaves);
         world.setBlockMetadataWithNotify(x + 8, y + 7, z + 5, 14, 14);
         this.setBlock(world, x + 9, y + 7, z + 5, KMOD_Main.KetherBlueLeaves);
         world.setBlockMetadataWithNotify(x + 9, y + 7, z + 5, 14, 14);
         this.setBlock(world, x + 14, y + 7, z + 5, KMOD_Main.KetherBlueLeaves);
         world.setBlockMetadataWithNotify(x + 14, y + 7, z + 5, 14, 14);
         this.setBlock(world, x + 15, y + 7, z + 5, KMOD_Main.KetherBlueLeaves);
         world.setBlockMetadataWithNotify(x + 15, y + 7, z + 5, 14, 14);
         this.setBlock(world, x + 17, y + 7, z + 5, KMOD_Main.KetherBlueLeaves);
         world.setBlockMetadataWithNotify(x + 17, y + 7, z + 5, 14, 14);
         this.setBlock(world, x + 19, y + 7, z + 5, KMOD_Main.KetherBlueLeaves);
