package fr.keter.KMOD.WorldGens;

import fr.keter.KMOD.Main.KMOD_Main;
import java.util.Random;
import net.minecraft.block.Block;
import net.minecraft.world.World;
import net.minecraft.world.gen.feature.WorldGenerator;

public class KetherGenMovingSands extends WorldGenerator {
   Random random = new Random();
   private Block block;

   public KetherGenMovingSands(Block block) {
      this.block = block;
   }

   public boolean generate(World world, Random random, int i, int j, int k) {
      if (world.getBlock(i, j, k) == KMOD_Main.KetherGrass && world.getBlock(i, j - 2, k) == KMOD_Main.KetherDirt) {
         world.setBlock(i + 0, j + 1, k + 3, this.block);
         world.setBlock(i + 0, j + 1, k + 4, this.block);
         world.setBlock(i + 0, j + 1, k + 5, this.block);
         world.setBlock(i + 0, j + 1, k + 6, this.block);
         world.setBlock(i + 1, j + 0, k + 4, this.block);
         world.setBlock(i + 1, j + 0, k + 5, this.block);
         world.setBlock(i + 1, j + 1, k + 1, this.block);
         world.setBlock(i + 1, j + 1, k + 2, this.block);
         world.setBlock(i + 1, j + 1, k + 3, this.block);
         world.setBlock(i + 1, j + 1, k + 4, this.block);
         world.setBlock(i + 1, j + 1, k + 5, this.block);
         world.setBlock(i + 1, j + 1, k + 6, this.block);
         world.setBlock(i + 1, j + 1, k + 7, this.block);
         world.setBlock(i + 1, j + 1, k + 8, this.block);
         world.setBlock(i + 1, j + 2, k + 4, this.block);
         world.setBlock(i + 1, j + 2, k + 5, this.block);
         world.setBlock(i + 2, j + 0, k + 2, this.block);
         world.setBlock(i + 2, j + 0, k + 3, this.block);
         world.setBlock(i + 2, j + 0, k + 4, this.block);
         world.setBlock(i + 2, j + 0, k + 5, this.block);
         world.setBlock(i + 2, j + 0, k + 6, this.block);
         world.setBlock(i + 2, j + 0, k + 7, this.block);
         world.setBlock(i + 2, j + 1, k + 1, this.block);
         world.setBlock(i + 2, j + 1, k + 2, this.block);
         world.setBlock(i + 2, j + 1, k + 3, this.block);
         world.setBlock(i + 2, j + 1, k + 4, this.block);
         world.setBlock(i + 2, j + 1, k + 5, this.block);
         world.setBlock(i + 2, j + 1, k + 6, this.block);
         world.setBlock(i + 2, j + 1, k + 7, this.block);
         world.setBlock(i + 2, j + 1, k + 8, this.block);
         world.setBlock(i + 2, j + 2, k + 2, this.block);
         world.setBlock(i + 2, j + 2, k + 3, this.block);
         world.setBlock(i + 2, j + 2, k + 4, this.block);
         world.setBlock(i + 2, j + 2, k + 5, this.block);
         world.setBlock(i + 2, j + 2, k + 6, this.block);
         world.setBlock(i + 2, j + 2, k + 7, this.block);
         world.setBlock(i + 3, j + 0, k + 2, this.block);
         world.setBlock(i + 3, j + 0, k + 3, this.block);
         world.setBlock(i + 3, j + 0, k + 4, this.block);
         world.setBlock(i + 3, j + 0, k + 5, this.block);
         world.setBlock(i + 3, j + 0, k + 6, this.block);
         world.setBlock(i + 3, j + 0, k + 7, this.block);
         world.setBlock(i + 3, j + 1, k + 0, this.block);
         world.setBlock(i + 3, j + 1, k + 1, this.block);
         world.setBlock(i + 3, j + 1, k + 2, this.block);
         world.setBlock(i + 3, j + 1, k + 3, this.block);
         world.setBlock(i + 3, j + 1, k + 4, this.block);
         world.setBlock(i + 3, j + 1, k + 5, this.block);
         world.setBlock(i + 3, j + 1, k + 6, this.block);
         world.setBlock(i + 3, j + 1, k + 7, this.block);
         world.setBlock(i + 3, j + 1, k + 8, this.block);
         world.setBlock(i + 3, j + 1, k + 9, this.block);
         world.setBlock(i + 3, j + 2, k + 2, this.block);
         world.setBlock(i + 3, j + 2, k + 3, this.block);
         world.setBlock(i + 3, j + 2, k + 4, this.block);
         world.setBlock(i + 3, j + 2, k + 5, this.block);
         world.setBlock(i + 3, j + 2, k + 6, this.block);
         world.setBlock(i + 3, j + 2, k + 7, this.block);
         world.setBlock(i + 4, j + 0, k + 1, this.block);
         world.setBlock(i + 4, j + 0, k + 2, this.block);
         world.setBlock(i + 4, j + 0, k + 3, this.block);
         world.setBlock(i + 4, j + 0, k + 4, this.block);
         world.setBlock(i + 4, j + 0, k + 5, this.block);
         world.setBlock(i + 4, j + 0, k + 6, this.block);
         world.setBlock(i + 4, j + 0, k + 7, this.block);
         world.setBlock(i + 4, j + 0, k + 8, this.block);
         world.setBlock(i + 4, j + 1, k + 0, this.block);
         world.setBlock(i + 4, j + 1, k + 1, this.block);
         world.setBlock(i + 4, j + 1, k + 2, this.block);
         world.setBlock(i + 4, j + 1, k + 3, this.block);
         world.setBlock(i + 4, j + 1, k + 4, this.block);
         world.setBlock(i + 4, j + 1, k + 5, this.block);
         world.setBlock(i + 4, j + 1, k + 6, this.block);
         world.setBlock(i + 4, j + 1, k + 7, this.block);
         world.setBlock(i + 4, j + 1, k + 8, this.block);
         world.setBlock(i + 4, j + 1, k + 9, this.block);
         world.setBlock(i + 4, j + 2, k + 1, this.block);
         world.setBlock(i + 4, j + 2, k + 2, this.block);
         world.setBlock(i + 4, j + 2, k + 3, this.block);
         world.setBlock(i + 4, j + 2, k + 4, this.block);
         world.setBlock(i + 4, j + 2, k + 5, this.block);
         world.setBlock(i + 4, j + 2, k + 6, this.block);
         world.setBlock(i + 4, j + 2, k + 7, this.block);
         world.setBlock(i + 4, j + 2, k + 8, this.block);
         world.setBlock(i + 5, j + 0, k + 1, this.block);
         world.setBlock(i + 5, j + 0, k + 2, this.block);
         world.setBlock(i + 5, j + 0, k + 3, this.block);
         world.setBlock(i + 5, j + 0, k + 4, this.block);
         world.setBlock(i + 5, j + 0, k + 5, this.block);
         world.setBlock(i + 5, j + 0, k + 6, this.block);
         world.setBlock(i + 5, j + 0, k + 7, this.block);
         world.setBlock(i + 5, j + 0, k + 8, this.block);
         world.setBlock(i + 5, j + 1, k + 0, this.block);
         world.setBlock(i + 5, j + 1, k + 1, this.block);
         world.setBlock(i + 5, j + 1, k + 2, this.block);
         world.setBlock(i + 5, j + 1, k + 3, this.block);
         world.setBlock(i + 5, j + 1, k + 4, this.block);
         world.setBlock(i + 5, j + 1, k + 5, this.block);
         world.setBlock(i + 5, j + 1, k + 6, this.block);
         world.setBlock(i + 5, j + 1, k + 7, this.block);
         world.setBlock(i + 5, j + 1, k + 8, this.block);
         world.setBlock(i + 5, j + 1, k + 9, this.block);
         world.setBlock(i + 5, j + 2, k + 1, this.block);
         world.setBlock(i + 5, j + 2, k + 2, this.block);
         world.setBlock(i + 5, j + 2, k + 3, this.block);
         world.setBlock(i + 5, j + 2, k + 4, this.block);
         world.setBlock(i + 5, j + 2, k + 5, this.block);
         world.setBlock(i + 5, j + 2, k + 6, this.block);
         world.setBlock(i + 5, j + 2, k + 7, this.block);
         world.setBlock(i + 5, j + 2, k + 8, this.block);
         world.setBlock(i + 6, j + 0, k + 2, this.block);
         world.setBlock(i + 6, j + 0, k + 3, this.block);
         world.setBlock(i + 6, j + 0, k + 4, this.block);
         world.setBlock(i + 6, j + 0, k + 5, this.block);
         world.setBlock(i + 6, j + 0, k + 6, this.block);
         world.setBlock(i + 6, j + 0, k + 7, this.block);
         world.setBlock(i + 6, j + 1, k + 0, this.block);
         world.setBlock(i + 6, j + 1, k + 1, this.block);
         world.setBlock(i + 6, j + 1, k + 2, this.block);
         world.setBlock(i + 6, j + 1, k + 3, this.block);
         world.setBlock(i + 6, j + 1, k + 4, this.block);
         world.setBlock(i + 6, j + 1, k + 5, this.block);
         world.setBlock(i + 6, j + 1, k + 6, this.block);
         world.setBlock(i + 6, j + 1, k + 7, this.block);
         world.setBlock(i + 6, j + 1, k + 8, this.block);
         world.setBlock(i + 6, j + 1, k + 9, this.block);
         world.setBlock(i + 6, j + 2, k + 2, this.block);
         world.setBlock(i + 6, j + 2, k + 3, this.block);
         world.setBlock(i + 6, j + 2, k + 4, this.block);
         world.setBlock(i + 6, j + 2, k + 5, this.block);
         world.setBlock(i + 6, j + 2, k + 6, this.block);
         world.setBlock(i + 6, j + 2, k + 7, this.block);
         world.setBlock(i + 7, j + 0, k + 2, this.block);
         world.setBlock(i + 7, j + 0, k + 3, this.block);
         world.setBlock(i + 7, j + 0, k + 4, this.block);
         world.setBlock(i + 7, j + 0, k + 5, this.block);
         world.setBlock(i + 7, j + 0, k + 6, this.block);
         world.setBlock(i + 7, j + 0, k + 7, this.block);
         world.setBlock(i + 7, j + 1, k + 1, this.block);
         world.setBlock(i + 7, j + 1, k + 2, this.block);
         world.setBlock(i + 7, j + 1, k + 3, this.block);
         world.setBlock(i + 7, j + 1, k + 4, this.block);
         world.setBlock(i + 7, j + 1, k + 5, this.block);
         world.setBlock(i + 7, j + 1, k + 6, this.block);
         world.setBlock(i + 7, j + 1, k + 7, this.block);
         world.setBlock(i + 7, j + 1, k + 8, this.block);
         world.setBlock(i + 7, j + 2, k + 2, this.block);
         world.setBlock(i + 7, j + 2, k + 3, this.block);
         world.setBlock(i + 7, j + 2, k + 4, this.block);
         world.setBlock(i + 7, j + 2, k + 5, this.block);
         world.setBlock(i + 7, j + 2, k + 6, this.block);
         world.setBlock(i + 7, j + 2, k + 7, this.block);
         world.setBlock(i + 8, j + 0, k + 4, this.block);
         world.setBlock(i + 8, j + 0, k + 5, this.block);
         world.setBlock(i + 8, j + 1, k + 1, this.block);
         world.setBlock(i + 8, j + 1, k + 2, this.block);
         world.setBlock(i + 8, j + 1, k + 3, this.block);
         world.setBlock(i + 8, j + 1, k + 4, this.block);
         world.setBlock(i + 8, j + 1, k + 5, this.block);
         world.setBlock(i + 8, j + 1, k + 6, this.block);
         world.setBlock(i + 8, j + 1, k + 7, this.block);
         world.setBlock(i + 8, j + 1, k + 8, this.block);
         world.setBlock(i + 8, j + 2, k + 4, this.block);
         world.setBlock(i + 8, j + 2, k + 5, this.block);
         world.setBlock(i + 9, j + 1, k + 3, this.block);
         world.setBlock(i + 9, j + 1, k + 4, this.block);
         world.setBlock(i + 9, j + 1, k + 5, this.block);
         world.setBlock(i + 9, j + 1, k + 6, this.block);
         return true;
      } else {
         return false;
      }
   }
}
