package fr.keter.KMOD.WorldGens;

import fr.keter.KMOD.Main.KMOD_Main;
import java.util.Random;
import net.minecraft.world.World;
import net.minecraft.world.gen.feature.WorldGenerator;

public class KetherGenClouds extends WorldGenerator {
   public boolean locationIsValidSpawn(World world, int i, int j, int k) {
      return world.isAirBlock(i, j, k);
   }

   public boolean generate(World world, Random rand, int i, int j, int k) {
      if (this.locationIsValidSpawn(world, i, j, k) && this.locationIsValidSpawn(world, i + 9, j, k) && this.locationIsValidSpawn(world, i + 9, j, k + 9) && this.locationIsValidSpawn(world, i, j, k + 9)) {
         world.setBlock(i + 0, j + 1, k + 3, KMOD_Main.KetherCloud);
         world.setBlock(i + 0, j + 1, k + 4, KMOD_Main.KetherCloud);
         world.setBlock(i + 0, j + 1, k + 5, KMOD_Main.KetherCloud);
         world.setBlock(i + 0, j + 1, k + 6, KMOD_Main.KetherCloud);
         world.setBlock(i + 1, j + 0, k + 4, KMOD_Main.KetherCloud);
         world.setBlock(i + 1, j + 0, k + 5, KMOD_Main.KetherCloud);
         world.setBlock(i + 1, j + 1, k + 1, KMOD_Main.KetherCloud);
         world.setBlock(i + 1, j + 1, k + 2, KMOD_Main.KetherCloud);
         world.setBlock(i + 1, j + 1, k + 3, KMOD_Main.KetherCloud);
         world.setBlock(i + 1, j + 1, k + 4, KMOD_Main.KetherCloud);
         world.setBlock(i + 1, j + 1, k + 5, KMOD_Main.KetherCloud);
         world.setBlock(i + 1, j + 1, k + 6, KMOD_Main.KetherCloud);
         world.setBlock(i + 1, j + 1, k + 7, KMOD_Main.KetherCloud);
         world.setBlock(i + 1, j + 1, k + 8, KMOD_Main.KetherCloud);
         world.setBlock(i + 1, j + 2, k + 4, KMOD_Main.KetherCloud);
         world.setBlock(i + 1, j + 2, k + 5, KMOD_Main.KetherCloud);
         world.setBlock(i + 2, j + 0, k + 2, KMOD_Main.KetherCloud);
         world.setBlock(i + 2, j + 0, k + 3, KMOD_Main.KetherCloud);
         world.setBlock(i + 2, j + 0, k + 4, KMOD_Main.KetherCloud);
         world.setBlock(i + 2, j + 0, k + 5, KMOD_Main.KetherCloud);
         world.setBlock(i + 2, j + 0, k + 6, KMOD_Main.KetherCloud);
         world.setBlock(i + 2, j + 0, k + 7, KMOD_Main.KetherCloud);
         world.setBlock(i + 2, j + 1, k + 1, KMOD_Main.KetherCloud);
         world.setBlock(i + 2, j + 1, k + 2, KMOD_Main.KetherCloud);
         world.setBlock(i + 2, j + 1, k + 3, KMOD_Main.KetherCloud);
         world.setBlock(i + 2, j + 1, k + 4, KMOD_Main.KetherCloud);
         world.setBlock(i + 2, j + 1, k + 5, KMOD_Main.KetherCloud);
         world.setBlock(i + 2, j + 1, k + 6, KMOD_Main.KetherCloud);
         world.setBlock(i + 2, j + 1, k + 7, KMOD_Main.KetherCloud);
         world.setBlock(i + 2, j + 1, k + 8, KMOD_Main.KetherCloud);
         world.setBlock(i + 2, j + 2, k + 2, KMOD_Main.KetherCloud);
         world.setBlock(i + 2, j + 2, k + 3, KMOD_Main.KetherCloud);
         world.setBlock(i + 2, j + 2, k + 4, KMOD_Main.KetherCloud);
         world.setBlock(i + 2, j + 2, k + 5, KMOD_Main.KetherCloud);
         world.setBlock(i + 2, j + 2, k + 6, KMOD_Main.KetherCloud);
         world.setBlock(i + 2, j + 2, k + 7, KMOD_Main.KetherCloud);
         world.setBlock(i + 3, j + 0, k + 2, KMOD_Main.KetherCloud);
         world.setBlock(i + 3, j + 0, k + 3, KMOD_Main.KetherCloud);
         world.setBlock(i + 3, j + 0, k + 4, KMOD_Main.KetherCloud);
         world.setBlock(i + 3, j + 0, k + 5, KMOD_Main.KetherCloud);
         world.setBlock(i + 3, j + 0, k + 6, KMOD_Main.KetherCloud);
         world.setBlock(i + 3, j + 0, k + 7, KMOD_Main.KetherCloud);
         world.setBlock(i + 3, j + 1, k + 0, KMOD_Main.KetherCloud);
         world.setBlock(i + 3, j + 1, k + 1, KMOD_Main.KetherCloud);
         world.setBlock(i + 3, j + 1, k + 2, KMOD_Main.KetherCloud);
         world.setBlock(i + 3, j + 1, k + 3, KMOD_Main.KetherCloud);
         world.setBlock(i + 3, j + 1, k + 4, KMOD_Main.KetherCloud);
         world.setBlock(i + 3, j + 1, k + 5, KMOD_Main.KetherCloud);
         world.setBlock(i + 3, j + 1, k + 6, KMOD_Main.KetherCloud);
         world.setBlock(i + 3, j + 1, k + 7, KMOD_Main.KetherCloud);
         world.setBlock(i + 3, j + 1, k + 8, KMOD_Main.KetherCloud);
         world.setBlock(i + 3, j + 1, k + 9, KMOD_Main.KetherCloud);
         world.setBlock(i + 3, j + 2, k + 2, KMOD_Main.KetherCloud);
         world.setBlock(i + 3, j + 2, k + 3, KMOD_Main.KetherCloud);
         world.setBlock(i + 3, j + 2, k + 4, KMOD_Main.KetherCloud);
         world.setBlock(i + 3, j + 2, k + 5, KMOD_Main.KetherCloud);
         world.setBlock(i + 3, j + 2, k + 6, KMOD_Main.KetherCloud);
         world.setBlock(i + 3, j + 2, k + 7, KMOD_Main.KetherCloud);
         world.setBlock(i + 4, j + 0, k + 1, KMOD_Main.KetherCloud);
         world.setBlock(i + 4, j + 0, k + 2, KMOD_Main.KetherCloud);
         world.setBlock(i + 4, j + 0, k + 3, KMOD_Main.KetherCloud);
         world.setBlock(i + 4, j + 0, k + 4, KMOD_Main.KetherCloud);
         world.setBlock(i + 4, j + 0, k + 5, KMOD_Main.KetherCloud);
         world.setBlock(i + 4, j + 0, k + 6, KMOD_Main.KetherCloud);
         world.setBlock(i + 4, j + 0, k + 7, KMOD_Main.KetherCloud);
         world.setBlock(i + 4, j + 0, k + 8, KMOD_Main.KetherCloud);
         world.setBlock(i + 4, j + 1, k + 0, KMOD_Main.KetherCloud);
         world.setBlock(i + 4, j + 1, k + 1, KMOD_Main.KetherCloud);
         world.setBlock(i + 4, j + 1, k + 2, KMOD_Main.KetherCloud);
         world.setBlock(i + 4, j + 1, k + 3, KMOD_Main.KetherCloud);
         world.setBlock(i + 4, j + 1, k + 4, KMOD_Main.KetherCloud);
         world.setBlock(i + 4, j + 1, k + 5, KMOD_Main.KetherCloud);
         world.setBlock(i + 4, j + 1, k + 6, KMOD_Main.KetherCloud);
         world.setBlock(i + 4, j + 1, k + 7, KMOD_Main.KetherCloud);
         world.setBlock(i + 4, j + 1, k + 8, KMOD_Main.KetherCloud);
         world.setBlock(i + 4, j + 1, k + 9, KMOD_Main.KetherCloud);
         world.setBlock(i + 4, j + 2, k + 1, KMOD_Main.KetherCloud);
         world.setBlock(i + 4, j + 2, k + 2, KMOD_Main.KetherCloud);
         world.setBlock(i + 4, j + 2, k + 3, KMOD_Main.KetherCloud);
         world.setBlock(i + 4, j + 2, k + 4, KMOD_Main.KetherCloud);
         world.setBlock(i + 4, j + 2, k + 5, KMOD_Main.KetherCloud);
         world.setBlock(i + 4, j + 2, k + 6, KMOD_Main.KetherCloud);
         world.setBlock(i + 4, j + 2, k + 7, KMOD_Main.KetherCloud);
         world.setBlock(i + 4, j + 2, k + 8, KMOD_Main.KetherCloud);
         world.setBlock(i + 5, j + 0, k + 1, KMOD_Main.KetherCloud);
         world.setBlock(i + 5, j + 0, k + 2, KMOD_Main.KetherCloud);
         world.setBlock(i + 5, j + 0, k + 3, KMOD_Main.KetherCloud);
         world.setBlock(i + 5, j + 0, k + 4, KMOD_Main.KetherCloud);
         world.setBlock(i + 5, j + 0, k + 5, KMOD_Main.KetherCloud);
         world.setBlock(i + 5, j + 0, k + 6, KMOD_Main.KetherCloud);
         world.setBlock(i + 5, j + 0, k + 7, KMOD_Main.KetherCloud);
         world.setBlock(i + 5, j + 0, k + 8, KMOD_Main.KetherCloud);
         world.setBlock(i + 5, j + 1, k + 0, KMOD_Main.KetherCloud);
         world.setBlock(i + 5, j + 1, k + 1, KMOD_Main.KetherCloud);
         world.setBlock(i + 5, j + 1, k + 2, KMOD_Main.KetherCloud);
         world.setBlock(i + 5, j + 1, k + 3, KMOD_Main.KetherCloud);
         world.setBlock(i + 5, j + 1, k + 4, KMOD_Main.KetherCloud);
         world.setBlock(i + 5, j + 1, k + 5, KMOD_Main.KetherCloud);
         world.setBlock(i + 5, j + 1, k + 6, KMOD_Main.KetherCloud);
         world.setBlock(i + 5, j + 1, k + 7, KMOD_Main.KetherCloud);
         world.setBlock(i + 5, j + 1, k + 8, KMOD_Main.KetherCloud);
         world.setBlock(i + 5, j + 1, k + 9, KMOD_Main.KetherCloud);
         world.setBlock(i + 5, j + 2, k + 1, KMOD_Main.KetherCloud);
         world.setBlock(i + 5, j + 2, k + 2, KMOD_Main.KetherCloud);
         world.setBlock(i + 5, j + 2, k + 3, KMOD_Main.KetherCloud);
         world.setBlock(i + 5, j + 2, k + 4, KMOD_Main.KetherCloud);
         world.setBlock(i + 5, j + 2, k + 5, KMOD_Main.KetherCloud);
         world.setBlock(i + 5, j + 2, k + 6, KMOD_Main.KetherCloud);
         world.setBlock(i + 5, j + 2, k + 7, KMOD_Main.KetherCloud);
         world.setBlock(i + 5, j + 2, k + 8, KMOD_Main.KetherCloud);
         world.setBlock(i + 6, j + 0, k + 2, KMOD_Main.KetherCloud);
         world.setBlock(i + 6, j + 0, k + 3, KMOD_Main.KetherCloud);
         world.setBlock(i + 6, j + 0, k + 4, KMOD_Main.KetherCloud);
         world.setBlock(i + 6, j + 0, k + 5, KMOD_Main.KetherCloud);
         world.setBlock(i + 6, j + 0, k + 6, KMOD_Main.KetherCloud);
         world.setBlock(i + 6, j + 0, k + 7, KMOD_Main.KetherCloud);
         world.setBlock(i + 6, j + 1, k + 0, KMOD_Main.KetherCloud);
         world.setBlock(i + 6, j + 1, k + 1, KMOD_Main.KetherCloud);
         world.setBlock(i + 6, j + 1, k + 2, KMOD_Main.KetherCloud);
         world.setBlock(i + 6, j + 1, k + 3, KMOD_Main.KetherCloud);
         world.setBlock(i + 6, j + 1, k + 4, KMOD_Main.KetherCloud);
         world.setBlock(i + 6, j + 1, k + 5, KMOD_Main.KetherCloud);
         world.setBlock(i + 6, j + 1, k + 6, KMOD_Main.KetherCloud);
         world.setBlock(i + 6, j + 1, k + 7, KMOD_Main.KetherCloud);
         world.setBlock(i + 6, j + 1, k + 8, KMOD_Main.KetherCloud);
         world.setBlock(i + 6, j + 1, k + 9, KMOD_Main.KetherCloud);
         world.setBlock(i + 6, j + 2, k + 2, KMOD_Main.KetherCloud);
         world.setBlock(i + 6, j + 2, k + 3, KMOD_Main.KetherCloud);
         world.setBlock(i + 6, j + 2, k + 4, KMOD_Main.KetherCloud);
         world.setBlock(i + 6, j + 2, k + 5, KMOD_Main.KetherCloud);
         world.setBlock(i + 6, j + 2, k + 6, KMOD_Main.KetherCloud);
         world.setBlock(i + 6, j + 2, k + 7, KMOD_Main.KetherCloud);
         world.setBlock(i + 7, j + 0, k + 2, KMOD_Main.KetherCloud);
         world.setBlock(i + 7, j + 0, k + 3, KMOD_Main.KetherCloud);
         world.setBlock(i + 7, j + 0, k + 4, KMOD_Main.KetherCloud);
         world.setBlock(i + 7, j + 0, k + 5, KMOD_Main.KetherCloud);
         world.setBlock(i + 7, j + 0, k + 6, KMOD_Main.KetherCloud);
         world.setBlock(i + 7, j + 0, k + 7, KMOD_Main.KetherCloud);
         world.setBlock(i + 7, j + 1, k + 1, KMOD_Main.KetherCloud);
         world.setBlock(i + 7, j + 1, k + 2, KMOD_Main.KetherCloud);
         world.setBlock(i + 7, j + 1, k + 3, KMOD_Main.KetherCloud);
         world.setBlock(i + 7, j + 1, k + 4, KMOD_Main.KetherCloud);
         world.setBlock(i + 7, j + 1, k + 5, KMOD_Main.KetherCloud);
         world.setBlock(i + 7, j + 1, k + 6, KMOD_Main.KetherCloud);
         world.setBlock(i + 7, j + 1, k + 7, KMOD_Main.KetherCloud);
         world.setBlock(i + 7, j + 1, k + 8, KMOD_Main.KetherCloud);
         world.setBlock(i + 7, j + 2, k + 2, KMOD_Main.KetherCloud);
         world.setBlock(i + 7, j + 2, k + 3, KMOD_Main.KetherCloud);
         world.setBlock(i + 7, j + 2, k + 4, KMOD_Main.KetherCloud);
         world.setBlock(i + 7, j + 2, k + 5, KMOD_Main.KetherCloud);
         world.setBlock(i + 7, j + 2, k + 6, KMOD_Main.KetherCloud);
         world.setBlock(i + 7, j + 2, k + 7, KMOD_Main.KetherCloud);
         world.setBlock(i + 8, j + 0, k + 4, KMOD_Main.KetherCloud);
         world.setBlock(i + 8, j + 0, k + 5, KMOD_Main.KetherCloud);
         world.setBlock(i + 8, j + 1, k + 1, KMOD_Main.KetherCloud);
         world.setBlock(i + 8, j + 1, k + 2, KMOD_Main.KetherCloud);
         world.setBlock(i + 8, j + 1, k + 3, KMOD_Main.KetherCloud);
         world.setBlock(i + 8, j + 1, k + 4, KMOD_Main.KetherCloud);
         world.setBlock(i + 8, j + 1, k + 5, KMOD_Main.KetherCloud);
         world.setBlock(i + 8, j + 1, k + 6, KMOD_Main.KetherCloud);
         world.setBlock(i + 8, j + 1, k + 7, KMOD_Main.KetherCloud);
         world.setBlock(i + 8, j + 1, k + 8, KMOD_Main.KetherCloud);
         world.setBlock(i + 8, j + 2, k + 4, KMOD_Main.KetherCloud);
         world.setBlock(i + 8, j + 2, k + 5, KMOD_Main.KetherCloud);
         world.setBlock(i + 9, j + 1, k + 3, KMOD_Main.KetherCloud);
         world.setBlock(i + 9, j + 1, k + 4, KMOD_Main.KetherCloud);
         world.setBlock(i + 9, j + 1, k + 5, KMOD_Main.KetherCloud);
         world.setBlock(i + 9, j + 1, k + 6, KMOD_Main.KetherCloud);
         return true;
      } else {
         return false;
      }
   }
}
