package fr.keter.KMOD.WorldGens;

import fr.keter.KMOD.Main.KMOD_Main;
import java.util.Random;
import net.minecraft.block.Block;
import net.minecraft.init.Blocks;
import net.minecraft.item.ItemStack;
import net.minecraft.tileentity.TileEntityChest;
import net.minecraft.world.World;
import net.minecraft.world.gen.feature.WorldGenerator;

public class KetherGenGoldenGrove extends WorldGenerator {
   public boolean LocationIsValidSpawn(World world, int i, int j, int k) {
      Block block = world.getBlock(i, j, k);
      return block == Blocks.air;
   }

   public boolean generate(World world, Random rand, int i, int j, int k) {
      if (this.LocationIsValidSpawn(world, i, j, k) && this.LocationIsValidSpawn(world, i + 24, j, k) && this.LocationIsValidSpawn(world, i + 24, j, k + 24) && this.LocationIsValidSpawn(world, i, j, k + 24)) {
         world.setBlock(i + 2, j + 15, k + 4, KMOD_Main.KetherGoldenLeaves);
         world.setBlock(i + 2, j + 15, k + 5, KMOD_Main.KetherGoldenLeaves);
         world.setBlock(i + 2, j + 15, k + 6, KMOD_Main.KetherGoldenLeaves);
         world.setBlock(i + 2, j + 15, k + 7, KMOD_Main.KetherGoldenLeaves);
         world.setBlock(i + 2, j + 15, k + 8, KMOD_Main.KetherGoldenLeaves);
         world.setBlock(i + 2, j + 15, k + 17, KMOD_Main.KetherGoldenLeaves);
         world.setBlock(i + 2, j + 15, k + 18, KMOD_Main.KetherGoldenLeaves);
         world.setBlock(i + 2, j + 15, k + 19, KMOD_Main.KetherGoldenLeaves);
         world.setBlock(i + 2, j + 16, k + 15, KMOD_Main.KetherGoldenLeaves);
         world.setBlock(i + 2, j + 16, k + 16, KMOD_Main.KetherGoldenLeaves);
         world.setBlock(i + 2, j + 16, k + 17, KMOD_Main.KetherGoldenLeaves);
         world.setBlock(i + 2, j + 16, k + 18, KMOD_Main.KetherGoldenLeaves);
         world.setBlock(i + 2, j + 16, k + 19, KMOD_Main.KetherGoldenLeaves);
         world.setBlock(i + 3, j + 14, k + 4, KMOD_Main.KetherGoldenLeaves);
         world.setBlock(i + 3, j + 14, k + 5, KMOD_Main.KetherGoldenLeaves);
         world.setBlock(i + 3, j + 14, k + 6, KMOD_Main.KetherGoldenLeaves);
         world.setBlock(i + 3, j + 14, k + 7, KMOD_Main.KetherGoldenLeaves);
         world.setBlock(i + 3, j + 14, k + 8, KMOD_Main.KetherGoldenLeaves);
         world.setBlock(i + 3, j + 14, k + 9, KMOD_Main.KetherGoldenLeaves);
         world.setBlock(i + 3, j + 15, k + 3, KMOD_Main.KetherGoldenLeaves);
         world.setBlock(i + 3, j + 15, k + 4, KMOD_Main.KetherGoldenLeaves);
         world.setBlock(i + 3, j + 15, k + 5, KMOD_Main.KetherGoldenLeaves);
         world.setBlock(i + 3, j + 15, k + 6, KMOD_Main.KetherGoldenLeaves);
         world.setBlock(i + 3, j + 15, k + 7, KMOD_Main.KetherGoldenLeaves);
         world.setBlock(i + 3, j + 15, k + 8, KMOD_Main.KetherGoldenLeaves);
         world.setBlock(i + 3, j + 15, k + 9, KMOD_Main.KetherGoldenLeaves);
         world.setBlock(i + 3, j + 15, k + 10, KMOD_Main.KetherGoldenLeaves);
         world.setBlock(i + 3, j + 15, k + 15, KMOD_Main.KetherGoldenLeaves);
         world.setBlock(i + 3, j + 15, k + 16, KMOD_Main.KetherGoldenLeaves);
         world.setBlock(i + 3, j + 15, k + 17, KMOD_Main.KetherGoldenLeaves);
         world.setBlock(i + 3, j + 15, k + 18, KMOD_Main.KetherGoldenLeaves);
         world.setBlock(i + 3, j + 15, k + 19, KMOD_Main.KetherGoldenLeaves);
         world.setBlock(i + 3, j + 15, k + 20, KMOD_Main.KetherGoldenLeaves);
         world.setBlock(i + 3, j + 16, k + 6, KMOD_Main.KetherGoldenLeaves);
         world.setBlock(i + 3, j + 16, k + 7, KMOD_Main.KetherGoldenLeaves);
         world.setBlock(i + 3, j + 16, k + 14, KMOD_Main.KetherGoldenLeaves);
         world.setBlock(i + 3, j + 16, k + 15, KMOD_Main.KetherGoldenLeaves);
         world.setBlock(i + 3, j + 16, k + 16, KMOD_Main.KetherGoldenLeaves);
         world.setBlock(i + 3, j + 16, k + 17, KMOD_Main.KetherGoldenLeaves);
         world.setBlock(i + 3, j + 16, k + 18, KMOD_Main.KetherGoldenLeaves);
         world.setBlock(i + 3, j + 16, k + 19, KMOD_Main.KetherGoldenLeaves);
         world.setBlock(i + 3, j + 16, k + 20, KMOD_Main.KetherGoldenLeaves);
         world.setBlock(i + 3, j + 16, k + 21, KMOD_Main.KetherGoldenLeaves);
         world.setBlock(i + 3, j + 17, k + 17, KMOD_Main.KetherGoldenLeaves);
         world.setBlock(i + 3, j + 17, k + 18, KMOD_Main.KetherGoldenLeaves);
         world.setBlock(i + 4, j + 10, k + 9, KMOD_Main.KetherGoldenLeaves);
         world.setBlock(i + 4, j + 10, k + 10, KMOD_Main.KetherGoldenLeaves);
         world.setBlock(i + 4, j + 10, k + 11, KMOD_Main.KetherGoldenLeaves);
         world.setBlock(i + 4, j + 10, k + 12, KMOD_Main.KetherGoldenLeaves);
         world.setBlock(i + 4, j + 10, k + 13, KMOD_Main.KetherGoldenLeaves);
         world.setBlock(i + 4, j + 11, k + 9, KMOD_Main.KetherGoldenLeaves);
         world.setBlock(i + 4, j + 11, k + 10, KMOD_Main.KetherGoldenLeaves);
         world.setBlock(i + 4, j + 11, k + 11, KMOD_Main.KetherGoldenLeaves);
         world.setBlock(i + 4, j + 11, k + 12, KMOD_Main.KetherGoldenLeaves);
         world.setBlock(i + 4, j + 11, k + 13, KMOD_Main.KetherGoldenLeaves);
         world.setBlock(i + 4, j + 14, k + 3, KMOD_Main.KetherGoldenLeaves);
         world.setBlock(i + 4, j + 14, k + 4, KMOD_Main.KetherGoldenLeaves);
         world.setBlock(i + 4, j + 14, k + 5, KMOD_Main.KetherGoldenLeaves);
         world.setBlock(i + 4, j + 14, k + 6, KMOD_Main.KetherGoldenLeaves);
         world.setBlock(i + 4, j + 14, k + 7, KMOD_Main.KetherGoldenLeaves);
         world.setBlock(i + 4, j + 14, k + 8, KMOD_Main.KetherGoldenLeaves);
         world.setBlock(i + 4, j + 14, k + 9, KMOD_Main.KetherGoldenLeaves);
         world.setBlock(i + 4, j + 15, k + 3, KMOD_Main.KetherGoldenLeaves);
         world.setBlock(i + 4, j + 15, k + 4, KMOD_Main.KetherGoldenLeaves);
         world.setBlock(i + 4, j + 15, k + 5, KMOD_Main.KetherGoldenLeaves);
         world.setBlock(i + 4, j + 15, k + 6, KMOD_Main.KetherGoldenLeaves);
         world.setBlock(i + 4, j + 15, k + 7, KMOD_Main.KetherGoldenLeaves);
         world.setBlock(i + 4, j + 15, k + 8, KMOD_Main.KetherGoldenLeaves);
         world.setBlock(i + 4, j + 15, k + 9, KMOD_Main.KetherGoldenLeaves);
         world.setBlock(i + 4, j + 15, k + 10, KMOD_Main.KetherGoldenLeaves);
         world.setBlock(i + 4, j + 15, k + 15, KMOD_Main.KetherGoldenLeaves);
         world.setBlock(i + 4, j + 15, k + 16, KMOD_Main.KetherGoldenLeaves);
         world.setBlock(i + 4, j + 15, k + 17, KMOD_Main.KetherGoldenLeaves);
         world.setBlock(i + 4, j + 15, k + 18, KMOD_Main.KetherGoldenLeaves);
         world.setBlock(i + 4, j + 15, k + 19, KMOD_Main.KetherGoldenLeaves);
         world.setBlock(i + 4, j + 15, k + 20, KMOD_Main.KetherGoldenLeaves);
         world.setBlock(i + 4, j + 15, k + 21, KMOD_Main.KetherGoldenLeaves);
         world.setBlock(i + 4, j + 16, k + 5, KMOD_Main.KetherGoldenLeaves);
         world.setBlock(i + 4, j + 16, k + 6, KMOD_Main.KetherGoldenLeaves);
         world.setBlock(i + 4, j + 16, k + 7, KMOD_Main.KetherGoldenLeaves);
         world.setBlock(i + 4, j + 16, k + 8, KMOD_Main.KetherGoldenLeaves);
         world.setBlock(i + 4, j + 16, k + 14, KMOD_Main.KetherGoldenLeaves);
         world.setBlock(i + 4, j + 16, k + 15, KMOD_Main.KetherGoldenLeaves);
         world.setBlock(i + 4, j + 16, k + 16, KMOD_Main.KetherGoldenLeaves);
         world.setBlock(i + 4, j + 16, k + 17, KMOD_Main.KetherGoldenLeaves);
         world.setBlock(i + 4, j + 16, k + 18, KMOD_Main.KetherGoldenLeaves);
         world.setBlock(i + 4, j + 16, k + 19, KMOD_Main.KetherGoldenLeaves);
         world.setBlock(i + 4, j + 16, k + 20, KMOD_Main.KetherGoldenLeaves);
         world.setBlock(i + 4, j + 16, k + 21, KMOD_Main.KetherGoldenLeaves);
         world.setBlock(i + 4, j + 17, k + 16, KMOD_Main.KetherGoldenLeaves);
         world.setBlock(i + 4, j + 17, k + 17, KMOD_Main.KetherGoldenLeaves);
         world.setBlock(i + 4, j + 17, k + 18, KMOD_Main.KetherGoldenLeaves);
         world.setBlock(i + 4, j + 17, k + 19, KMOD_Main.KetherGoldenLeaves);
         world.setBlock(i + 5, j + 8, k + 1, KMOD_Main.KetherGrass);
         world.setBlock(i + 5, j + 8, k + 2, KMOD_Main.KetherGrass);
         world.setBlock(i + 5, j + 8, k + 3, KMOD_Main.KetherGrass);
         world.setBlock(i + 5, j + 8, k + 4, KMOD_Main.KetherGrass);
         world.setBlock(i + 5, j + 8, k + 5, KMOD_Main.KetherGrass);
         world.setBlock(i + 5, j + 8, k + 6, KMOD_Main.KetherGrass);
         world.setBlock(i + 5, j + 8, k + 7, KMOD_Main.KetherGrass);
         world.setBlock(i + 5, j + 8, k + 8, KMOD_Main.KetherGrass);
         world.setBlock(i + 5, j + 8, k + 9, KMOD_Main.KetherGrass);
         world.setBlock(i + 5, j + 8, k + 10, KMOD_Main.KetherGrass);
         world.setBlock(i + 5, j + 8, k + 11, KMOD_Main.KetherGrass);
         world.setBlock(i + 5, j + 8, k + 12, KMOD_Main.KetherGrass);
         world.setBlock(i + 5, j + 8, k + 13, KMOD_Main.KetherGrass);
         world.setBlock(i + 5, j + 8, k + 14, KMOD_Main.KetherGrass);
         world.setBlock(i + 5, j + 8, k + 15, KMOD_Main.KetherGrass);
         world.setBlock(i + 5, j + 8, k + 16, KMOD_Main.KetherGrass);
         world.setBlock(i + 5, j + 8, k + 17, KMOD_Main.KetherGrass);
         world.setBlock(i + 5, j + 8, k + 18, KMOD_Main.KetherGrass);
         world.setBlock(i + 5, j + 8, k + 19, KMOD_Main.KetherGrass);
         world.setBlock(i + 5, j + 8, k + 20, KMOD_Main.KetherGrass);
         world.setBlock(i + 5, j + 10, k + 9, KMOD_Main.KetherGoldenLeaves);
         world.setBlock(i + 5, j + 10, k + 10, KMOD_Main.KetherGoldenLeaves);
         world.setBlock(i + 5, j + 10, k + 11, KMOD_Main.KetherGoldenLeaves);
         world.setBlock(i + 5, j + 10, k + 12, KMOD_Main.KetherGoldenLeaves);
         world.setBlock(i + 5, j + 10, k + 13, KMOD_Main.KetherGoldenLeaves);
         world.setBlock(i + 5, j + 11, k + 9, KMOD_Main.KetherGoldenLeaves);
         world.setBlock(i + 5, j + 11, k + 10, KMOD_Main.KetherGoldenLeaves);
         world.setBlock(i + 5, j + 11, k + 11, KMOD_Main.KetherGoldenLeaves);
         world.setBlock(i + 5, j + 11, k + 12, KMOD_Main.KetherGoldenLeaves);
         world.setBlock(i + 5, j + 11, k + 13, KMOD_Main.KetherGoldenLeaves);
         world.setBlock(i + 5, j + 12, k + 11, KMOD_Main.KetherGoldenLeaves);
         world.setBlock(i + 5, j + 12, k + 12, KMOD_Main.KetherGoldenLeaves);
         world.setBlock(i + 5, j + 13, k + 11, KMOD_Main.KetherGoldenLeaves);
         world.setBlock(i + 5, j + 14, k + 3, KMOD_Main.KetherGoldenLeaves);
         world.setBlock(i + 5, j + 14, k + 4, KMOD_Main.KetherGoldenLeaves);
         world.setBlock(i + 5, j + 14, k + 5, KMOD_Main.KetherGoldenLeaves);
         world.setBlock(i + 5, j + 14, k + 6, KMOD_Main.KetherLog);
         world.setBlock(i + 5, j + 14, k + 7, KMOD_Main.KetherLog);
         world.setBlock(i + 5, j + 14, k + 8, KMOD_Main.KetherGoldenLeaves);
         world.setBlock(i + 5, j + 14, k + 9, KMOD_Main.KetherGoldenLeaves);
         world.setBlock(i + 5, j + 14, k + 10, KMOD_Main.KetherGoldenLeaves);
         world.setBlock(i + 5, j + 15, k + 3, KMOD_Main.KetherGoldenLeaves);
         world.setBlock(i + 5, j + 15, k + 4, KMOD_Main.KetherGoldenLeaves);
         world.setBlock(i + 5, j + 15, k + 5, KMOD_Main.KetherGoldenLeaves);
         world.setBlock(i + 5, j + 15, k + 6, KMOD_Main.KetherLog);
         world.setBlock(i + 5, j + 15, k + 7, KMOD_Main.KetherLog);
         world.setBlock(i + 5, j + 15, k + 8, KMOD_Main.KetherGoldenLeaves);
         world.setBlock(i + 5, j + 15, k + 9, KMOD_Main.KetherGoldenLeaves);
         world.setBlock(i + 5, j + 15, k + 10, KMOD_Main.KetherGoldenLeaves);
         world.setBlock(i + 5, j + 15, k + 15, KMOD_Main.KetherGoldenLeaves);
         world.setBlock(i + 5, j + 15, k + 16, KMOD_Main.KetherGoldenLeaves);
         world.setBlock(i + 5, j + 15, k + 17, KMOD_Main.KetherLog);
         world.setBlock(i + 5, j + 15, k + 18, KMOD_Main.KetherLog);
         world.setBlock(i + 5, j + 15, k + 19, KMOD_Main.KetherGoldenLeaves);
         world.setBlock(i + 5, j + 15, k + 20, KMOD_Main.KetherGoldenLeaves);
         world.setBlock(i + 5, j + 15, k + 21, KMOD_Main.KetherGoldenLeaves);
         world.setBlock(i + 5, j + 16, k + 4, KMOD_Main.KetherGoldenLeaves);
         world.setBlock(i + 5, j + 16, k + 5, KMOD_Main.KetherGoldenLeaves);
         world.setBlock(i + 5, j + 16, k + 6, KMOD_Main.KetherGoldenLeaves);
         world.setBlock(i + 5, j + 16, k + 7, KMOD_Main.KetherGoldenLeaves);
         world.setBlock(i + 5, j + 16, k + 8, KMOD_Main.KetherGoldenLeaves);
         world.setBlock(i + 5, j + 16, k + 9, KMOD_Main.KetherGoldenLeaves);
         world.setBlock(i + 5, j + 16, k + 14, KMOD_Main.KetherGoldenLeaves);
         world.setBlock(i + 5, j + 16, k + 15, KMOD_Main.KetherGoldenLeaves);
         world.setBlock(i + 5, j + 16, k + 16, KMOD_Main.KetherGoldenLeaves);
         world.setBlock(i + 5, j + 16, k + 17, KMOD_Main.KetherLog);
         world.setBlock(i + 5, j + 16, k + 18, KMOD_Main.KetherLog);
         world.setBlock(i + 5, j + 16, k + 19, KMOD_Main.KetherGoldenLeaves);
         world.setBlock(i + 5, j + 16, k + 20, KMOD_Main.KetherGoldenLeaves);
         world.setBlock(i + 5, j + 16, k + 21, KMOD_Main.KetherGoldenLeaves);
         world.setBlock(i + 5, j + 17, k + 6, KMOD_Main.KetherGoldenLeaves);
         world.setBlock(i + 5, j + 17, k + 7, KMOD_Main.KetherGoldenLeaves);
         world.setBlock(i + 5, j + 17, k + 15, KMOD_Main.KetherGoldenLeaves);
         world.setBlock(i + 5, j + 17, k + 16, KMOD_Main.KetherGoldenLeaves);
         world.setBlock(i + 5, j + 17, k + 17, KMOD_Main.KetherGoldenLeaves);
         world.setBlock(i + 5, j + 17, k + 18, KMOD_Main.KetherGoldenLeaves);
         world.setBlock(i + 5, j + 17, k + 19, KMOD_Main.KetherGoldenLeaves);
         world.setBlock(i + 5, j + 17, k + 20, KMOD_Main.KetherGoldenLeaves);
         world.setBlock(i + 5, j + 18, k + 17, KMOD_Main.KetherGoldenLeaves);
         world.setBlock(i + 5, j + 18, k + 18, KMOD_Main.KetherGoldenLeaves);
         world.setBlock(i + 6, j + 6, k + 13, KMOD_Main.KetherStone);
         world.setBlock(i + 6, j + 6, k + 14, KMOD_Main.KetherStone);
         world.setBlock(i + 6, j + 6, k + 16, KMOD_Main.KetherStone);
         world.setBlock(i + 6, j + 7, k + 2, KMOD_Main.KetherStone);
         world.setBlock(i + 6, j + 7, k + 3, KMOD_Main.KetherStone);
         world.setBlock(i + 6, j + 7, k + 4, KMOD_Main.KetherStone);
         world.setBlock(i + 6, j + 7, k + 5, KMOD_Main.KetherStone);
         world.setBlock(i + 6, j + 7, k + 6, KMOD_Main.KetherStone);
         world.setBlock(i + 6, j + 7, k + 7, KMOD_Main.KetherStone);
         world.setBlock(i + 6, j + 7, k + 8, KMOD_Main.KetherStone);
         world.setBlock(i + 6, j + 7, k + 9, KMOD_Main.KetherStone);
         world.setBlock(i + 6, j + 7, k + 10, KMOD_Main.KetherStone);
         world.setBlock(i + 6, j + 7, k + 11, KMOD_Main.KetherStone);
         world.setBlock(i + 6, j + 7, k + 12, KMOD_Main.KetherStone);
         world.setBlock(i + 6, j + 7, k + 13, KMOD_Main.KetherStone);
         world.setBlock(i + 6, j + 7, k + 14, KMOD_Main.KetherStone);
         world.setBlock(i + 6, j + 7, k + 15, KMOD_Main.KetherStone);
         world.setBlock(i + 6, j + 7, k + 16, KMOD_Main.KetherStone);
         world.setBlock(i + 6, j + 7, k + 17, KMOD_Main.KetherStone);
         world.setBlock(i + 6, j + 7, k + 18, KMOD_Main.KetherStone);
         world.setBlock(i + 6, j + 7, k + 19, KMOD_Main.KetherStone);
         world.setBlock(i + 6, j + 8, k + 1, KMOD_Main.KetherGrass);
         world.setBlock(i + 6, j + 8, k + 2, KMOD_Main.KetherGrass);
         world.setBlock(i + 6, j + 8, k + 3, KMOD_Main.KetherGrass);
         world.setBlock(i + 6, j + 8, k + 4, KMOD_Main.KetherGrass);
         world.setBlock(i + 6, j + 8, k + 5, KMOD_Main.KetherGrass);
         world.setBlock(i + 6, j + 8, k + 6, KMOD_Main.KetherGrass);
         world.setBlock(i + 6, j + 8, k + 7, KMOD_Main.KetherGrass);
         world.setBlock(i + 6, j + 8, k + 8, KMOD_Main.KetherGrass);
         world.setBlock(i + 6, j + 8, k + 9, KMOD_Main.KetherGrass);
         world.setBlock(i + 6, j + 8, k + 10, KMOD_Main.KetherGrass);
         world.setBlock(i + 6, j + 8, k + 11, KMOD_Main.KetherStone);
         world.setBlock(i + 6, j + 8, k + 12, KMOD_Main.KetherGrass);
         world.setBlock(i + 6, j + 8, k + 13, KMOD_Main.KetherGrass);
         world.setBlock(i + 6, j + 8, k + 14, KMOD_Main.KetherGrass);
         world.setBlock(i + 6, j + 8, k + 15, KMOD_Main.KetherGrass);
         world.setBlock(i + 6, j + 8, k + 16, KMOD_Main.KetherGrass);
         world.setBlock(i + 6, j + 8, k + 17, KMOD_Main.KetherGrass);
         world.setBlock(i + 6, j + 8, k + 18, KMOD_Main.KetherGrass);
         world.setBlock(i + 6, j + 8, k + 19, KMOD_Main.KetherGrass);
         world.setBlock(i + 6, j + 8, k + 20, KMOD_Main.KetherGrass);
         world.setBlock(i + 6, j + 9, k + 11, KMOD_Main.KetherLog);
         world.setBlock(i + 6, j + 10, k + 9, KMOD_Main.KetherGoldenLeaves);
         world.setBlock(i + 6, j + 10, k + 10, KMOD_Main.KetherGoldenLeaves);
         world.setBlock(i + 6, j + 10, k + 11, KMOD_Main.KetherLog);
         world.setBlock(i + 6, j + 10, k + 12, KMOD_Main.KetherGoldenLeaves);
         world.setBlock(i + 6, j + 10, k + 13, KMOD_Main.KetherGoldenLeaves);
         world.setBlock(i + 6, j + 11, k + 9, KMOD_Main.KetherGoldenLeaves);
         world.setBlock(i + 6, j + 11, k + 10, KMOD_Main.KetherGoldenLeaves);
         world.setBlock(i + 6, j + 11, k + 11, KMOD_Main.KetherLog);
         world.setBlock(i + 6, j + 11, k + 12, KMOD_Main.KetherGoldenLeaves);
         world.setBlock(i + 6, j + 11, k + 13, KMOD_Main.KetherGoldenLeaves);
         world.setBlock(i + 6, j + 12, k + 10, KMOD_Main.KetherGoldenLeaves);
         world.setBlock(i + 6, j + 12, k + 11, KMOD_Main.KetherLog);
         world.setBlock(i + 6, j + 12, k + 12, KMOD_Main.KetherGoldenLeaves);
         world.setBlock(i + 6, j + 13, k + 6, KMOD_Main.KetherLog);
         world.setBlock(i + 6, j + 13, k + 7, KMOD_Main.KetherLog);
         world.setBlock(i + 6, j + 13, k + 10, KMOD_Main.KetherGoldenLeaves);
         world.setBlock(i + 6, j + 13, k + 11, KMOD_Main.KetherGoldenLeaves);
         world.setBlock(i + 6, j + 13, k + 12, KMOD_Main.KetherGoldenLeaves);
         world.setBlock(i + 6, j + 13, k + 18, KMOD_Main.KetherLog);
         world.setBlock(i + 6, j + 14, k + 3, KMOD_Main.KetherGoldenLeaves);
         world.setBlock(i + 6, j + 14, k + 4, KMOD_Main.KetherLog);
         world.setBlock(i + 6, j + 14, k + 5, KMOD_Main.KetherLog);
         world.setBlock(i + 6, j + 14, k + 6, KMOD_Main.KetherLog);
         world.setBlock(i + 6, j + 14, k + 7, KMOD_Main.KetherLog);
         world.setBlock(i + 6, j + 14, k + 8, KMOD_Main.KetherGoldenLeaves);
         world.setBlock(i + 6, j + 14, k + 9, KMOD_Main.KetherGoldenLeaves);
         world.setBlock(i + 6, j + 14, k + 10, KMOD_Main.KetherGoldenLeaves);
         world.setBlock(i + 6, j + 14, k + 17, KMOD_Main.KetherLog);
         world.setBlock(i + 6, j + 14, k + 18, KMOD_Main.KetherLog);
         world.setBlock(i + 6, j + 15, k + 3, KMOD_Main.KetherGoldenLeaves);
         world.setBlock(i + 6, j + 15, k + 4, KMOD_Main.KetherLog);
         world.setBlock(i + 6, j + 15, k + 5, KMOD_Main.KetherGoldenLeaves);
         world.setBlock(i + 6, j + 15, k + 6, KMOD_Main.KetherLog);
         world.setBlock(i + 6, j + 15, k + 7, KMOD_Main.KetherLog);
         world.setBlock(i + 6, j + 15, k + 8, KMOD_Main.KetherGoldenLeaves);
         world.setBlock(i + 6, j + 15, k + 9, KMOD_Main.KetherGoldenLeaves);
         world.setBlock(i + 6, j + 15, k + 10, KMOD_Main.KetherGoldenLeaves);
         world.setBlock(i + 6, j + 15, k + 15, KMOD_Main.KetherGoldenLeaves);
         world.setBlock(i + 6, j + 15, k + 16, KMOD_Main.KetherGoldenLeaves);
         world.setBlock(i + 6, j + 15, k + 17, KMOD_Main.KetherLog);
         world.setBlock(i + 6, j + 15, k + 18, KMOD_Main.KetherLog);
         world.setBlock(i + 6, j + 15, k + 19, KMOD_Main.KetherLog);
         world.setBlock(i + 6, j + 15, k + 20, KMOD_Main.KetherLog);
         world.setBlock(i + 6, j + 15, k + 21, KMOD_Main.KetherGoldenLeaves);
         world.setBlock(i + 6, j + 16, k + 4, KMOD_Main.KetherGoldenLeaves);
         world.setBlock(i + 6, j + 16, k + 5, KMOD_Main.KetherGoldenLeaves);
         world.setBlock(i + 6, j + 16, k + 6, KMOD_Main.KetherGoldenLeaves);
         world.setBlock(i + 6, j + 16, k + 7, KMOD_Main.KetherGoldenLeaves);
         world.setBlock(i + 6, j + 16, k + 8, KMOD_Main.KetherGoldenLeaves);
         world.setBlock(i + 6, j + 16, k + 9, KMOD_Main.KetherGoldenLeaves);
         world.setBlock(i + 6, j + 16, k + 14, KMOD_Main.KetherGoldenLeaves);
         world.setBlock(i + 6, j + 16, k + 15, KMOD_Main.KetherGoldenLeaves);
         world.setBlock(i + 6, j + 16, k + 16, KMOD_Main.KetherGoldenLeaves);
         world.setBlock(i + 6, j + 16, k + 17, KMOD_Main.KetherLog);
         world.setBlock(i + 6, j + 16, k + 18, KMOD_Main.KetherLog);
         world.setBlock(i + 6, j + 16, k + 19, KMOD_Main.KetherGoldenLeaves);
         world.setBlock(i + 6, j + 16, k + 20, KMOD_Main.KetherGoldenLeaves);
         world.setBlock(i + 6, j + 16, k + 21, KMOD_Main.KetherGoldenLeaves);
         world.setBlock(i + 6, j + 17, k + 6, KMOD_Main.KetherGoldenLeaves);
         world.setBlock(i + 6, j + 17, k + 7, KMOD_Main.KetherGoldenLeaves);
         world.setBlock(i + 6, j + 17, k + 15, KMOD_Main.KetherGoldenLeaves);
         world.setBlock(i + 6, j + 17, k + 16, KMOD_Main.KetherGoldenLeaves);
         world.setBlock(i + 6, j + 17, k + 17, KMOD_Main.KetherGoldenLeaves);
         world.setBlock(i + 6, j + 17, k + 18, KMOD_Main.KetherGoldenLeaves);
         world.setBlock(i + 6, j + 17, k + 19, KMOD_Main.KetherGoldenLeaves);
         world.setBlock(i + 6, j + 17, k + 20, KMOD_Main.KetherGoldenLeaves);
         world.setBlock(i + 6, j + 18, k + 17, KMOD_Main.KetherGoldenLeaves);
         world.setBlock(i + 6, j + 18, k + 18, KMOD_Main.KetherGoldenLeaves);
         world.setBlock(i + 7, j + 2, k + 11, KMOD_Main.KetherStone);
         world.setBlock(i + 7, j + 3, k + 11, KMOD_Main.KetherStone);
         world.setBlock(i + 7, j + 4, k + 11, KMOD_Main.KetherStone);
         world.setBlock(i + 7, j + 5, k + 11, KMOD_Main.KetherStone);
         world.setBlock(i + 7, j + 6, k + 4, KMOD_Main.KetherStone);
         world.setBlock(i + 7, j + 6, k + 7, KMOD_Main.KetherStone);
         world.setBlock(i + 7, j + 6, k + 11, KMOD_Main.KetherStone);
         world.setBlock(i + 7, j + 6, k + 18, KMOD_Main.KetherStone);
         world.setBlock(i + 7, j + 6, k + 19, KMOD_Main.KetherStone);
         world.setBlock(i + 7, j + 7, k + 2, KMOD_Main.KetherStone);
         world.setBlock(i + 7, j + 7, k + 3, KMOD_Main.KetherStone);
         world.setBlock(i + 7, j + 7, k + 4, KMOD_Main.KetherStone);
         world.setBlock(i + 7, j + 7, k + 5, KMOD_Main.KetherStone);
         world.setBlock(i + 7, j + 7, k + 6, KMOD_Main.KetherStone);
         world.setBlock(i + 7, j + 7, k + 7, KMOD_Main.KetherStone);
         world.setBlock(i + 7, j + 7, k + 8, KMOD_Main.KetherStone);
         world.setBlock(i + 7, j + 7, k + 9, KMOD_Main.KetherStone);
         world.setBlock(i + 7, j + 7, k + 10, KMOD_Main.KetherStone);
         world.setBlock(i + 7, j + 7, k + 11, KMOD_Main.KetherStone);
         world.setBlock(i + 7, j + 7, k + 12, KMOD_Main.KetherStone);
         world.setBlock(i + 7, j + 7, k + 13, KMOD_Main.KetherStone);
         world.setBlock(i + 7, j + 7, k + 14, KMOD_Main.KetherStone);
         world.setBlock(i + 7, j + 7, k + 15, KMOD_Main.KetherStone);
         world.setBlock(i + 7, j + 7, k + 16, KMOD_Main.KetherStone);
         world.setBlock(i + 7, j + 7, k + 17, KMOD_Main.KetherStone);
         world.setBlock(i + 7, j + 7, k + 18, KMOD_Main.KetherStone);
         world.setBlock(i + 7, j + 7, k + 19, KMOD_Main.KetherStone);
         world.setBlock(i + 7, j + 8, k + 1, KMOD_Main.KetherGrass);
         world.setBlock(i + 7, j + 8, k + 2, KMOD_Main.KetherGrass);
         world.setBlock(i + 7, j + 8, k + 3, KMOD_Main.KetherGrass);
         world.setBlock(i + 7, j + 8, k + 4, KMOD_Main.KetherGrass);
         world.setBlock(i + 7, j + 8, k + 5, KMOD_Main.KetherGrass);
         world.setBlock(i + 7, j + 8, k + 6, KMOD_Main.KetherStone);
         world.setBlock(i + 7, j + 8, k + 7, KMOD_Main.KetherStone);
         world.setBlock(i + 7, j + 8, k + 8, KMOD_Main.KetherGrass);
         world.setBlock(i + 7, j + 8, k + 9, KMOD_Main.KetherGrass);
         world.setBlock(i + 7, j + 8, k + 10, KMOD_Main.KetherGrass);
         world.setBlock(i + 7, j + 8, k + 11, KMOD_Main.KetherGrass);
         world.setBlock(i + 7, j + 8, k + 12, KMOD_Main.KetherGrass);
         world.setBlock(i + 7, j + 8, k + 13, KMOD_Main.KetherGrass);
         world.setBlock(i + 7, j + 8, k + 14, KMOD_Main.KetherGrass);
         world.setBlock(i + 7, j + 8, k + 15, Blocks.gold_block);
         world.setBlock(i + 7, j + 8, k + 16, KMOD_Main.KetherGrass);
         world.setBlock(i + 7, j + 8, k + 17, KMOD_Main.KetherStone);
         world.setBlock(i + 7, j + 8, k + 18, KMOD_Main.KetherStone);
         world.setBlock(i + 7, j + 8, k + 19, KMOD_Main.KetherGrass);
         world.setBlock(i + 7, j + 8, k + 20, KMOD_Main.KetherGrass);
         world.setBlock(i + 7, j + 9, k + 6, KMOD_Main.KetherLog);
         world.setBlock(i + 7, j + 9, k + 7, KMOD_Main.KetherLog);
         world.setBlock(i + 7, j + 9, k + 17, KMOD_Main.KetherLog);
         world.setBlock(i + 7, j + 9, k + 18, KMOD_Main.KetherLog);
         world.setBlock(i + 7, j + 10, k + 6, KMOD_Main.KetherLog);
         world.setBlock(i + 7, j + 10, k + 7, KMOD_Main.KetherLog);
         world.setBlock(i + 7, j + 10, k + 9, KMOD_Main.KetherGoldenLeaves);
         world.setBlock(i + 7, j + 10, k + 10, KMOD_Main.KetherGoldenLeaves);
         world.setBlock(i + 7, j + 10, k + 11, KMOD_Main.KetherGoldenLeaves);
         world.setBlock(i + 7, j + 10, k + 12, KMOD_Main.KetherGoldenLeaves);
         world.setBlock(i + 7, j + 10, k + 13, KMOD_Main.KetherGoldenLeaves);
         world.setBlock(i + 7, j + 10, k + 17, KMOD_Main.KetherLog);
         world.setBlock(i + 7, j + 10, k + 18, KMOD_Main.KetherLog);
         world.setBlock(i + 7, j + 11, k + 6, KMOD_Main.KetherLog);
         world.setBlock(i + 7, j + 11, k + 7, KMOD_Main.KetherLog);
         world.setBlock(i + 7, j + 11, k + 9, KMOD_Main.KetherGoldenLeaves);
         world.setBlock(i + 7, j + 11, k + 10, KMOD_Main.KetherGoldenLeaves);
         world.setBlock(i + 7, j + 11, k + 11, KMOD_Main.KetherGoldenLeaves);
         world.setBlock(i + 7, j + 11, k + 12, KMOD_Main.KetherGoldenLeaves);
         world.setBlock(i + 7, j + 11, k + 13, KMOD_Main.KetherGoldenLeaves);
         world.setBlock(i + 7, j + 11, k + 17, KMOD_Main.KetherLog);
         world.setBlock(i + 7, j + 11, k + 18, KMOD_Main.KetherLog);
         world.setBlock(i + 7, j + 12, k + 1, KMOD_Main.KetherGoldenLeaves);
         world.setBlock(i + 7, j + 12, k + 2, KMOD_Main.KetherGoldenLeaves);
         world.setBlock(i + 7, j + 12, k + 3, KMOD_Main.KetherGoldenLeaves);
         world.setBlock(i + 7, j + 12, k + 4, KMOD_Main.KetherGoldenLeaves);
         world.setBlock(i + 7, j + 12, k + 5, KMOD_Main.KetherLog);
         world.setBlock(i + 7, j + 12, k + 6, KMOD_Main.KetherLog);
         world.setBlock(i + 7, j + 12, k + 7, KMOD_Main.KetherLog);
         world.setBlock(i + 7, j + 12, k + 11, KMOD_Main.KetherGoldenLeaves);
         world.setBlock(i + 7, j + 12, k + 17, KMOD_Main.KetherLog);
         world.setBlock(i + 7, j + 12, k + 18, KMOD_Main.KetherLog);
         world.setBlock(i + 7, j + 13, k + 1, KMOD_Main.KetherGoldenLeaves);
         world.setBlock(i + 7, j + 13, k + 2, KMOD_Main.KetherGoldenLeaves);
         world.setBlock(i + 7, j + 13, k + 3, KMOD_Main.KetherGoldenLeaves);
         world.setBlock(i + 7, j + 13, k + 4, KMOD_Main.KetherGoldenLeaves);
         world.setBlock(i + 7, j + 13, k + 5, KMOD_Main.KetherLog);
         world.setBlock(i + 7, j + 13, k + 6, KMOD_Main.KetherLog);
         world.setBlock(i + 7, j + 13, k + 7, KMOD_Main.KetherLog);
         world.setBlock(i + 7, j + 13, k + 11, KMOD_Main.KetherGoldenLeaves);
         world.setBlock(i + 7, j + 13, k + 17, KMOD_Main.KetherLog);
         world.setBlock(i + 7, j + 13, k + 18, KMOD_Main.KetherLog);
         world.setBlock(i + 7, j + 13, k + 19, KMOD_Main.KetherLog);
         world.setBlock(i + 7, j + 14, k + 3, KMOD_Main.KetherGoldenLeaves);
         world.setBlock(i + 7, j + 14, k + 4, KMOD_Main.KetherGoldenLeaves);
         world.setBlock(i + 7, j + 14, k + 5, KMOD_Main.KetherLog);
         world.setBlock(i + 7, j + 14, k + 6, KMOD_Main.KetherLog);
         world.setBlock(i + 7, j + 14, k + 7, KMOD_Main.KetherGoldenLeaves);
         world.setBlock(i + 7, j + 14, k + 8, KMOD_Main.KetherGoldenLeaves);
         world.setBlock(i + 7, j + 14, k + 9, KMOD_Main.KetherGoldenLeaves);
         world.setBlock(i + 7, j + 14, k + 10, KMOD_Main.KetherGoldenLeaves);
         world.setBlock(i + 7, j + 14, k + 17, KMOD_Main.KetherLog);
         world.setBlock(i + 7, j + 14, k + 18, KMOD_Main.KetherLog);
         world.setBlock(i + 7, j + 14, k + 19, KMOD_Main.KetherLog);
         world.setBlock(i + 7, j + 15, k + 3, KMOD_Main.KetherGoldenLeaves);
         world.setBlock(i + 7, j + 15, k + 4, KMOD_Main.KetherGoldenLeaves);
         world.setBlock(i + 7, j + 15, k + 5, KMOD_Main.KetherLog);
         world.setBlock(i + 7, j + 15, k + 6, KMOD_Main.KetherLog);
         world.setBlock(i + 7, j + 15, k + 7, KMOD_Main.KetherLog);
         world.setBlock(i + 7, j + 15, k + 8, KMOD_Main.KetherGoldenLeaves);
         world.setBlock(i + 7, j + 15, k + 9, KMOD_Main.KetherLog);
         world.setBlock(i + 7, j + 15, k + 10, KMOD_Main.KetherGoldenLeaves);
         world.setBlock(i + 7, j + 15, k + 15, KMOD_Main.KetherGoldenLeaves);
         world.setBlock(i + 7, j + 15, k + 16, KMOD_Main.KetherGoldenLeaves);
         world.setBlock(i + 7, j + 15, k + 17, KMOD_Main.KetherGoldenLeaves);
         world.setBlock(i + 7, j + 15, k + 18, KMOD_Main.KetherGoldenLeaves);
         world.setBlock(i + 7, j + 15, k + 19, KMOD_Main.KetherLog);
         world.setBlock(i + 7, j + 15, k + 20, KMOD_Main.KetherLog);
         world.setBlock(i + 7, j + 16, k + 5, KMOD_Main.KetherGoldenLeaves);
         world.setBlock(i + 7, j + 16, k + 6, KMOD_Main.KetherGoldenLeaves);
         world.setBlock(i + 7, j + 16, k + 7, KMOD_Main.KetherGoldenLeaves);
         world.setBlock(i + 7, j + 16, k + 8, KMOD_Main.KetherGoldenLeaves);
         world.setBlock(i + 7, j + 16, k + 14, KMOD_Main.KetherGoldenLeaves);
         world.setBlock(i + 7, j + 16, k + 15, KMOD_Main.KetherGoldenLeaves);
         world.setBlock(i + 7, j + 16, k + 16, KMOD_Main.KetherGoldenLeaves);
         world.setBlock(i + 7, j + 16, k + 17, KMOD_Main.KetherGoldenLeaves);
         world.setBlock(i + 7, j + 16, k + 18, KMOD_Main.KetherGoldenLeaves);
         world.setBlock(i + 7, j + 16, k + 19, KMOD_Main.KetherLog);
         world.setBlock(i + 7, j + 16, k + 20, KMOD_Main.KetherGoldenLeaves);
         world.setBlock(i + 7, j + 16, k + 21, KMOD_Main.KetherGoldenLeaves);
         world.setBlock(i + 7, j + 17, k + 16, KMOD_Main.KetherGoldenLeaves);
         world.setBlock(i + 7, j + 17, k + 17, KMOD_Main.KetherGoldenLeaves);
         world.setBlock(i + 7, j + 17, k + 18, KMOD_Main.KetherGoldenLeaves);
         world.setBlock(i + 7, j + 17, k + 19, KMOD_Main.KetherGoldenLeaves);
         world.setBlock(i + 8, j + 5, k + 2, KMOD_Main.KetherStone);
         world.setBlock(i + 8, j + 6, k + 2, KMOD_Main.KetherStone);
         world.setBlock(i + 8, j + 6, k + 4, KMOD_Main.KetherStone);
         world.setBlock(i + 8, j + 6, k + 5, KMOD_Main.KetherStone);
         world.setBlock(i + 8, j + 6, k + 6, KMOD_Main.KetherStone);
         world.setBlock(i + 8, j + 6, k + 7, KMOD_Main.KetherStone);
         world.setBlock(i + 8, j + 6, k + 8, KMOD_Main.KetherStone);
         world.setBlock(i + 8, j + 6, k + 9, KMOD_Main.KetherStone);
         world.setBlock(i + 8, j + 6, k + 10, KMOD_Main.KetherStone);
         world.setBlock(i + 8, j + 6, k + 11, KMOD_Main.KetherStone);
         world.setBlock(i + 8, j + 6, k + 12, KMOD_Main.KetherStone);
         world.setBlock(i + 8, j + 6, k + 13, KMOD_Main.KetherStone);
         world.setBlock(i + 8, j + 6, k + 14, KMOD_Main.KetherStone);
         world.setBlock(i + 8, j + 6, k + 15, KMOD_Main.KetherStone);
         world.setBlock(i + 8, j + 6, k + 16, KMOD_Main.KetherStone);
         world.setBlock(i + 8, j + 6, k + 17, KMOD_Main.KetherStone);
         world.setBlock(i + 8, j + 7, k + 2, KMOD_Main.KetherStone);
         world.setBlock(i + 8, j + 7, k + 3, KMOD_Main.KetherStone);
         world.setBlock(i + 8, j + 7, k + 4, KMOD_Main.KetherStone);
         world.setBlock(i + 8, j + 7, k + 5, KMOD_Main.KetherStone);
         world.setBlock(i + 8, j + 7, k + 6, KMOD_Main.KetherStone);
         world.setBlock(i + 8, j + 7, k + 7, KMOD_Main.KetherStone);
         world.setBlock(i + 8, j + 7, k + 8, KMOD_Main.KetherStone);
         world.setBlock(i + 8, j + 7, k + 9, KMOD_Main.KetherStone);
         world.setBlock(i + 8, j + 7, k + 10, KMOD_Main.KetherStone);
         world.setBlock(i + 8, j + 7, k + 11, KMOD_Main.KetherStone);
         world.setBlock(i + 8, j + 7, k + 12, KMOD_Main.KetherStone);
         world.setBlock(i + 8, j + 7, k + 13, KMOD_Main.KetherStone);
         world.setBlock(i + 8, j + 7, k + 14, KMOD_Main.KetherStone);
         world.setBlock(i + 8, j + 7, k + 15, KMOD_Main.KetherStone);
         world.setBlock(i + 8, j + 7, k + 16, KMOD_Main.KetherStone);
         world.setBlock(i + 8, j + 7, k + 17, KMOD_Main.KetherStone);
         world.setBlock(i + 8, j + 7, k + 18, KMOD_Main.KetherStone);
         world.setBlock(i + 8, j + 7, k + 19, KMOD_Main.KetherStone);
         world.setBlock(i + 8, j + 8, k + 1, KMOD_Main.KetherGrass);
         world.setBlock(i + 8, j + 8, k + 2, KMOD_Main.KetherGrass);
         world.setBlock(i + 8, j + 8, k + 3, KMOD_Main.KetherGrass);
         world.setBlock(i + 8, j + 8, k + 4, KMOD_Main.KetherGrass);
         world.setBlock(i + 8, j + 8, k + 5, KMOD_Main.KetherGrass);
         world.setBlock(i + 8, j + 8, k + 6, KMOD_Main.KetherStone);
         world.setBlock(i + 8, j + 8, k + 7, KMOD_Main.KetherStone);
         world.setBlock(i + 8, j + 8, k + 8, KMOD_Main.KetherGrass);
         world.setBlock(i + 8, j + 8, k + 9, KMOD_Main.KetherGrass);
         world.setBlock(i + 8, j + 8, k + 10, KMOD_Main.KetherGrass);
         world.setBlock(i + 8, j + 8, k + 11, KMOD_Main.KetherGrass);
         world.setBlock(i + 8, j + 8, k + 12, KMOD_Main.KetherGrass);
         world.setBlock(i + 8, j + 8, k + 13, KMOD_Main.KetherGrass);
         world.setBlock(i + 8, j + 8, k + 14, Blocks.gold_block);
         world.setBlock(i + 8, j + 8, k + 15, Blocks.gold_block);
         world.setBlock(i + 8, j + 8, k + 16, KMOD_Main.KetherGrass);
         world.setBlock(i + 8, j + 8, k + 17, KMOD_Main.KetherStone);
         world.setBlock(i + 8, j + 8, k + 18, KMOD_Main.KetherStone);
         world.setBlock(i + 8, j + 8, k + 19, KMOD_Main.KetherGrass);
         world.setBlock(i + 8, j + 8, k + 20, KMOD_Main.KetherGrass);
         world.setBlock(i + 8, j + 9, k + 6, KMOD_Main.KetherLog);
         world.setBlock(i + 8, j + 9, k + 7, KMOD_Main.KetherLog);
         world.setBlock(i + 8, j + 9, k + 17, KMOD_Main.KetherLog);
         world.setBlock(i + 8, j + 9, k + 18, KMOD_Main.KetherLog);
         world.setBlock(i + 8, j + 10, k + 6, KMOD_Main.KetherLog);
         world.setBlock(i + 8, j + 10, k + 7, KMOD_Main.KetherLog);
         world.setBlock(i + 8, j + 10, k + 9, KMOD_Main.KetherGoldenLeaves);
         world.setBlock(i + 8, j + 10, k + 10, KMOD_Main.KetherGoldenLeaves);
         world.setBlock(i + 8, j + 10, k + 11, KMOD_Main.KetherGoldenLeaves);
         world.setBlock(i + 8, j + 10, k + 12, KMOD_Main.KetherGoldenLeaves);
         world.setBlock(i + 8, j + 10, k + 17, KMOD_Main.KetherLog);
         world.setBlock(i + 8, j + 10, k + 18, KMOD_Main.KetherLog);
         world.setBlock(i + 8, j + 11, k + 6, KMOD_Main.KetherLog);
         world.setBlock(i + 8, j + 11, k + 7, KMOD_Main.KetherLog);
         world.setBlock(i + 8, j + 11, k + 9, KMOD_Main.KetherGoldenLeaves);
         world.setBlock(i + 8, j + 11, k + 10, KMOD_Main.KetherGoldenLeaves);
         world.setBlock(i + 8, j + 11, k + 11, KMOD_Main.KetherGoldenLeaves);
         world.setBlock(i + 8, j + 11, k + 12, KMOD_Main.KetherGoldenLeaves);
         world.setBlock(i + 8, j + 11, k + 17, KMOD_Main.KetherLog);
         world.setBlock(i + 8, j + 11, k + 18, KMOD_Main.KetherLog);
         world.setBlock(i + 8, j + 12, k + 1, KMOD_Main.KetherGoldenLeaves);
         world.setBlock(i + 8, j + 12, k + 2, KMOD_Main.KetherGoldenLeaves);
         world.setBlock(i + 8, j + 12, k + 3, KMOD_Main.KetherGoldenLeaves);
         world.setBlock(i + 8, j + 12, k + 4, KMOD_Main.KetherGoldenLeaves);
         world.setBlock(i + 8, j + 12, k + 5, KMOD_Main.KetherLog);
         world.setBlock(i + 8, j + 12, k + 6, KMOD_Main.KetherLog);
         world.setBlock(i + 8, j + 12, k + 7, KMOD_Main.KetherLog);
         world.setBlock(i + 8, j + 12, k + 8, KMOD_Main.KetherLog);
         world.setBlock(i + 8, j + 12, k + 17, KMOD_Main.KetherLog);
         world.setBlock(i + 8, j + 12, k + 18, KMOD_Main.KetherLog);
         world.setBlock(i + 8, j + 13, k + 1, KMOD_Main.KetherGoldenLeaves);
         world.setBlock(i + 8, j + 13, k + 2, KMOD_Main.KetherGoldenLeaves);
         world.setBlock(i + 8, j + 13, k + 3, KMOD_Main.KetherGoldenLeaves);
         world.setBlock(i + 8, j + 13, k + 4, KMOD_Main.KetherGoldenLeaves);
         world.setBlock(i + 8, j + 13, k + 5, KMOD_Main.KetherLog);
         world.setBlock(i + 8, j + 13, k + 8, KMOD_Main.KetherLog);
         world.setBlock(i + 8, j + 13, k + 17, KMOD_Main.KetherLog);
         world.setBlock(i + 8, j + 13, k + 18, KMOD_Main.KetherLog);
         world.setBlock(i + 8, j + 14, k + 3, KMOD_Main.KetherGoldenLeaves);
         world.setBlock(i + 8, j + 14, k + 4, KMOD_Main.KetherLog);
         world.setBlock(i + 8, j + 14, k + 5, KMOD_Main.KetherLog);
         world.setBlock(i + 8, j + 14, k + 6, KMOD_Main.KetherGoldenLeaves);
         world.setBlock(i + 8, j + 14, k + 7, KMOD_Main.KetherGoldenLeaves);
         world.setBlock(i + 8, j + 14, k + 8, KMOD_Main.KetherLog);
         world.setBlock(i + 8, j + 14, k + 9, KMOD_Main.KetherGoldenLeaves);
         world.setBlock(i + 8, j + 14, k + 10, KMOD_Main.KetherGoldenLeaves);
         world.setBlock(i + 8, j + 15, k + 3, KMOD_Main.KetherGoldenLeaves);
         world.setBlock(i + 8, j + 15, k + 4, KMOD_Main.KetherGoldenLeaves);
         world.setBlock(i + 8, j + 15, k + 5, KMOD_Main.KetherGoldenLeaves);
         world.setBlock(i + 8, j + 15, k + 6, KMOD_Main.KetherGoldenLeaves);
         world.setBlock(i + 8, j + 15, k + 7, KMOD_Main.KetherGoldenLeaves);
         world.setBlock(i + 8, j + 15, k + 8, KMOD_Main.KetherGoldenLeaves);
         world.setBlock(i + 8, j + 15, k + 9, KMOD_Main.KetherGoldenLeaves);
         world.setBlock(i + 8, j + 15, k + 15, KMOD_Main.KetherGoldenLeaves);
         world.setBlock(i + 8, j + 15, k + 16, KMOD_Main.KetherGoldenLeaves);
         world.setBlock(i + 8, j + 15, k + 17, KMOD_Main.KetherLog);
         world.setBlock(i + 8, j + 15, k + 18, KMOD_Main.KetherLog);
         world.setBlock(i + 8, j + 15, k + 19, KMOD_Main.KetherGoldenLeaves);
         world.setBlock(i + 8, j + 15, k + 20, KMOD_Main.KetherGoldenLeaves);
         world.setBlock(i + 8, j + 16, k + 6, KMOD_Main.KetherGoldenLeaves);
         world.setBlock(i + 8, j + 16, k + 7, KMOD_Main.KetherGoldenLeaves);
         world.setBlock(i + 8, j + 16, k + 15, KMOD_Main.KetherGoldenLeaves);
         world.setBlock(i + 8, j + 16, k + 16, KMOD_Main.KetherGoldenLeaves);
         world.setBlock(i + 8, j + 16, k + 17, KMOD_Main.KetherGoldenLeaves);
         world.setBlock(i + 8, j + 16, k + 18, KMOD_Main.KetherLog);
         world.setBlock(i + 8, j + 16, k + 19, KMOD_Main.KetherGoldenLeaves);
         world.setBlock(i + 8, j + 17, k + 17, KMOD_Main.KetherGoldenLeaves);
         world.setBlock(i + 8, j + 17, k + 18, KMOD_Main.KetherGoldenLeaves);
         world.setBlock(i + 9, j + 5, k + 7, KMOD_Main.KetherStone);
         world.setBlock(i + 9, j + 5, k + 12, KMOD_Main.KetherStone);
         world.setBlock(i + 9, j + 6, k + 4, KMOD_Main.KetherStone);
         world.setBlock(i + 9, j + 6, k + 5, KMOD_Main.KetherStone);
         world.setBlock(i + 9, j + 6, k + 6, KMOD_Main.KetherStone);
         world.setBlock(i + 9, j + 6, k + 7, KMOD_Main.KetherStone);
         world.setBlock(i + 9, j + 6, k + 8, KMOD_Main.KetherStone);
         world.setBlock(i + 9, j + 6, k + 9, KMOD_Main.KetherStone);
         world.setBlock(i + 9, j + 6, k + 10, KMOD_Main.KetherStone);
         world.setBlock(i + 9, j + 6, k + 11, KMOD_Main.KetherStone);
         world.setBlock(i + 9, j + 6, k + 12, KMOD_Main.KetherStone);
         world.setBlock(i + 9, j + 6, k + 13, KMOD_Main.KetherStone);
         world.setBlock(i + 9, j + 6, k + 14, KMOD_Main.KetherStone);
         world.setBlock(i + 9, j + 6, k + 15, KMOD_Main.KetherStone);
         world.setBlock(i + 9, j + 6, k + 16, KMOD_Main.KetherStone);
         world.setBlock(i + 9, j + 6, k + 17, KMOD_Main.KetherStone);
         world.setBlock(i + 9, j + 7, k + 2, KMOD_Main.KetherStone);
         world.setBlock(i + 9, j + 7, k + 3, KMOD_Main.KetherStone);
         world.setBlock(i + 9, j + 7, k + 4, KMOD_Main.KetherStone);
         world.setBlock(i + 9, j + 7, k + 17, KMOD_Main.KetherStone);
         world.setBlock(i + 9, j + 7, k + 18, KMOD_Main.KetherStone);
         world.setBlock(i + 9, j + 7, k + 19, KMOD_Main.KetherStone);
         world.setBlock(i + 9, j + 8, k + 1, KMOD_Main.KetherGrass);
         world.setBlock(i + 9, j + 8, k + 2, KMOD_Main.KetherGrass);
         world.setBlock(i + 9, j + 8, k + 3, KMOD_Main.KetherStone);
         world.setBlock(i + 9, j + 8, k + 4, KMOD_Main.KetherGrass);
         world.setBlock(i + 9, j + 8, k + 5, KMOD_Main.KetherGrass);
         world.setBlock(i + 9, j + 8, k + 6, KMOD_Main.KetherGrass);
         world.setBlock(i + 9, j + 8, k + 7, KMOD_Main.KetherGrass);
         world.setBlock(i + 9, j + 8, k + 8, KMOD_Main.KetherGrass);
         world.setBlock(i + 9, j + 8, k + 9, KMOD_Main.KetherGrass);
         world.setBlock(i + 9, j + 8, k + 10, KMOD_Main.KetherGrass);
         world.setBlock(i + 9, j + 8, k + 11, Blocks.gold_block);
         world.setBlock(i + 9, j + 8, k + 12, KMOD_Main.KetherGrass);
         world.setBlock(i + 9, j + 8, k + 13, KMOD_Main.KetherGrass);
         world.setBlock(i + 9, j + 8, k + 14, Blocks.gold_block);
         world.setBlock(i + 9, j + 8, k + 15, Blocks.gold_block);
         world.setBlock(i + 9, j + 8, k + 16, Blocks.gold_block);
         world.setBlock(i + 9, j + 8, k + 17, KMOD_Main.KetherGrass);
         world.setBlock(i + 9, j + 8, k + 18, KMOD_Main.KetherGrass);
         world.setBlock(i + 9, j + 8, k + 19, KMOD_Main.KetherGrass);
         world.setBlock(i + 9, j + 8, k + 20, KMOD_Main.KetherGrass);
         world.setBlock(i + 9, j + 9, k + 3, KMOD_Main.KetherLog);
         world.setBlock(i + 9, j + 10, k + 3, KMOD_Main.KetherLog);
         world.setBlock(i + 9, j + 11, k + 3, KMOD_Main.KetherLog);
         world.setBlock(i + 9, j + 12, k + 1, KMOD_Main.KetherGoldenLeaves);
         world.setBlock(i + 9, j + 12, k + 2, KMOD_Main.KetherGoldenLeaves);
         world.setBlock(i + 9, j + 12, k + 3, KMOD_Main.KetherLog);
         world.setBlock(i + 9, j + 12, k + 4, KMOD_Main.KetherGoldenLeaves);
         world.setBlock(i + 9, j + 12, k + 5, KMOD_Main.KetherGoldenLeaves);
         world.setBlock(i + 9, j + 12, k + 6, KMOD_Main.KetherLog);
         world.setBlock(i + 9, j + 12, k + 7, KMOD_Main.KetherLog);
         world.setBlock(i + 9, j + 12, k + 8, KMOD_Main.KetherLog);
         world.setBlock(i + 9, j + 12, k + 17, KMOD_Main.KetherLog);
         world.setBlock(i + 9, j + 13, k + 1, KMOD_Main.KetherGoldenLeaves);
         world.setBlock(i + 9, j + 13, k + 2, KMOD_Main.KetherGoldenLeaves);
         world.setBlock(i + 9, j + 13, k + 3, KMOD_Main.KetherLog);
         world.setBlock(i + 9, j + 13, k + 4, KMOD_Main.KetherGoldenLeaves);
         world.setBlock(i + 9, j + 13, k + 5, KMOD_Main.KetherGoldenLeaves);
         world.setBlock(i + 9, j + 13, k + 6, KMOD_Main.KetherLog);
         world.setBlock(i + 9, j + 13, k + 7, KMOD_Main.KetherLog);
         world.setBlock(i + 9, j + 13, k + 8, KMOD_Main.KetherLog);
         world.setBlock(i + 9, j + 13, k + 17, KMOD_Main.KetherLog);
         world.setBlock(i + 9, j + 14, k + 2, KMOD_Main.KetherGoldenLeaves);
         world.setBlock(i + 9, j + 14, k + 3, KMOD_Main.KetherLog);
         world.setBlock(i + 9, j + 14, k + 4, KMOD_Main.KetherGoldenLeaves);
         world.setBlock(i + 9, j + 14, k + 5, KMOD_Main.KetherLog);
         world.setBlock(i + 9, j + 14, k + 6, KMOD_Main.KetherLog);
         world.setBlock(i + 9, j + 14, k + 7, KMOD_Main.KetherLog);
         world.setBlock(i + 9, j + 14, k + 8, KMOD_Main.KetherLog);
         world.setBlock(i + 9, j + 14, k + 9, KMOD_Main.KetherGoldenLeaves);
         world.setBlock(i + 9, j + 14, k + 17, KMOD_Main.KetherLog);
         world.setBlock(i + 9, j + 14, k + 18, KMOD_Main.KetherLog);
         world.setBlock(i + 9, j + 15, k + 2, KMOD_Main.KetherGoldenLeaves);
         world.setBlock(i + 9, j + 15, k + 3, KMOD_Main.KetherGoldenLeaves);
         world.setBlock(i + 9, j + 15, k + 4, KMOD_Main.KetherGoldenLeaves);
         world.setBlock(i + 9, j + 15, k + 5, KMOD_Main.KetherLog);
         world.setBlock(i + 9, j + 15, k + 6, KMOD_Main.KetherLog);
         world.setBlock(i + 9, j + 15, k + 7, KMOD_Main.KetherLog);
         world.setBlock(i + 9, j + 15, k + 8, KMOD_Main.KetherGoldenLeaves);
         world.setBlock(i + 9, j + 15, k + 16, KMOD_Main.KetherGoldenLeaves);
         world.setBlock(i + 9, j + 15, k + 17, KMOD_Main.KetherLog);
         world.setBlock(i + 9, j + 15, k + 18, KMOD_Main.KetherLog);
         world.setBlock(i + 9, j + 15, k + 19, KMOD_Main.KetherGoldenLeaves);
         world.setBlock(i + 9, j + 16, k + 15, KMOD_Main.KetherGoldenLeaves);
         world.setBlock(i + 9, j + 16, k + 16, KMOD_Main.KetherGoldenLeaves);
         world.setBlock(i + 9, j + 16, k + 17, KMOD_Main.KetherGoldenLeaves);
         world.setBlock(i + 9, j + 16, k + 18, KMOD_Main.KetherGoldenLeaves);
         world.setBlock(i + 9, j + 16, k + 19, KMOD_Main.KetherLog);
         world.setBlock(i + 10, j + 2, k + 19, KMOD_Main.KetherStone);
         world.setBlock(i + 10, j + 3, k + 9, KMOD_Main.KetherStone);
         world.setBlock(i + 10, j + 3, k + 19, KMOD_Main.KetherStone);
         world.setBlock(i + 10, j + 4, k + 8, KMOD_Main.KetherStone);
         world.setBlock(i + 10, j + 4, k + 9, KMOD_Main.KetherStone);
         world.setBlock(i + 10, j + 4, k + 19, KMOD_Main.KetherStone);
         world.setBlock(i + 10, j + 5, k + 6, KMOD_Main.KetherStone);
         world.setBlock(i + 10, j + 5, k + 7, KMOD_Main.KetherStone);
         world.setBlock(i + 10, j + 5, k + 8, KMOD_Main.KetherStone);
         world.setBlock(i + 10, j + 5, k + 9, KMOD_Main.KetherStone);
         world.setBlock(i + 10, j + 5, k + 10, KMOD_Main.KetherStone);
         world.setBlock(i + 10, j + 5, k + 11, KMOD_Main.KetherStone);
         world.setBlock(i + 10, j + 5, k + 12, KMOD_Main.KetherStone);
         world.setBlock(i + 10, j + 5, k + 13, KMOD_Main.KetherStone);
         world.setBlock(i + 10, j + 5, k + 14, KMOD_Main.KetherStone);
         world.setBlock(i + 10, j + 5, k + 15, KMOD_Main.KetherStone);
         world.setBlock(i + 10, j + 5, k + 19, KMOD_Main.KetherStone);
         world.setBlock(i + 10, j + 6, k + 2, KMOD_Main.KetherStone);
         world.setBlock(i + 10, j + 6, k + 4, KMOD_Main.KetherStone);
         world.setBlock(i + 10, j + 6, k + 5, KMOD_Main.KetherStone);
         world.setBlock(i + 10, j + 6, k + 6, KMOD_Main.KetherStone);
         world.setBlock(i + 10, j + 6, k + 7, KMOD_Main.KetherStone);
         world.setBlock(i + 10, j + 6, k + 8, KMOD_Main.KetherStone);
         world.setBlock(i + 10, j + 6, k + 9, KMOD_Main.KetherStone);
         world.setBlock(i + 10, j + 6, k + 10, KMOD_Main.KetherStone);
         world.setBlock(i + 10, j + 6, k + 11, KMOD_Main.KetherStone);
         world.setBlock(i + 10, j + 6, k + 12, KMOD_Main.KetherStone);
         world.setBlock(i + 10, j + 6, k + 13, KMOD_Main.KetherStone);
         world.setBlock(i + 10, j + 6, k + 14, KMOD_Main.KetherStone);
         world.setBlock(i + 10, j + 6, k + 15, KMOD_Main.KetherStone);
         world.setBlock(i + 10, j + 6, k + 16, KMOD_Main.KetherStone);
         world.setBlock(i + 10, j + 6, k + 17, KMOD_Main.KetherStone);
         world.setBlock(i + 10, j + 6, k + 19, KMOD_Main.KetherStone);
         world.setBlock(i + 10, j + 7, k + 2, KMOD_Main.KetherStone);
         world.setBlock(i + 10, j + 7, k + 3, KMOD_Main.KetherStone);
         world.setBlock(i + 10, j + 7, k + 4, KMOD_Main.KetherStone);
         world.setBlock(i + 10, j + 7, k + 17, KMOD_Main.KetherStone);
         world.setBlock(i + 10, j + 7, k + 18, KMOD_Main.KetherStone);
         world.setBlock(i + 10, j + 7, k + 19, KMOD_Main.KetherStone);
         world.setBlock(i + 10, j + 8, k + 1, KMOD_Main.KetherGrass);
         world.setBlock(i + 10, j + 8, k + 2, KMOD_Main.KetherGrass);
         world.setBlock(i + 10, j + 8, k + 3, KMOD_Main.KetherGrass);
         world.setBlock(i + 10, j + 8, k + 4, KMOD_Main.KetherGrass);
         world.setBlock(i + 10, j + 8, k + 5, KMOD_Main.KetherGrass);
         world.setBlock(i + 10, j + 8, k + 6, KMOD_Main.KetherGrass);
         world.setBlock(i + 10, j + 8, k + 7, KMOD_Main.KetherGrass);
         world.setBlock(i + 10, j + 8, k + 8, KMOD_Main.KetherGrass);
         world.setBlock(i + 10, j + 8, k + 9, KMOD_Main.KetherGrass);
         world.setBlock(i + 10, j + 8, k + 10, Blocks.gold_block);
         world.setBlock(i + 10, j + 8, k + 11, Blocks.gold_block);
         world.setBlock(i + 10, j + 8, k + 12, Blocks.gold_block);
         world.setBlock(i + 10, j + 8, k + 13, Blocks.gold_block);
         world.setBlock(i + 10, j + 8, k + 14, Blocks.gold_block);
         world.setBlock(i + 10, j + 8, k + 15, Blocks.gold_block);
         world.setBlock(i + 10, j + 8, k + 16, Blocks.gold_block);
         world.setBlock(i + 10, j + 8, k + 17, Blocks.gold_block);
         world.setBlock(i + 10, j + 8, k + 18, KMOD_Main.KetherGrass);
         world.setBlock(i + 10, j + 8, k + 19, KMOD_Main.KetherGrass);
         world.setBlock(i + 10, j + 8, k + 20, KMOD_Main.KetherGrass);
         world.setBlock(i + 10, j + 12, k + 1, KMOD_Main.KetherGoldenLeaves);
         world.setBlock(i + 10, j + 12, k + 2, KMOD_Main.KetherGoldenLeaves);
         world.setBlock(i + 10, j + 12, k + 3, KMOD_Main.KetherGoldenLeaves);
         world.setBlock(i + 10, j + 12, k + 4, KMOD_Main.KetherGoldenLeaves);
         world.setBlock(i + 10, j + 12, k + 5, KMOD_Main.KetherGoldenLeaves);
         world.setBlock(i + 10, j + 13, k + 1, KMOD_Main.KetherGoldenLeaves);
         world.setBlock(i + 10, j + 13, k + 2, KMOD_Main.KetherGoldenLeaves);
         world.setBlock(i + 10, j + 13, k + 3, KMOD_Main.KetherGoldenLeaves);
         world.setBlock(i + 10, j + 13, k + 4, KMOD_Main.KetherGoldenLeaves);
         world.setBlock(i + 10, j + 13, k + 5, KMOD_Main.KetherGoldenLeaves);
         world.setBlock(i + 10, j + 14, k + 2, KMOD_Main.KetherGoldenLeaves);
         world.setBlock(i + 10, j + 14, k + 3, KMOD_Main.KetherGoldenLeaves);
         world.setBlock(i + 10, j + 14, k + 4, KMOD_Main.KetherGoldenLeaves);
         world.setBlock(i + 10, j + 15, k + 3, KMOD_Main.KetherGoldenLeaves);
         world.setBlock(i + 11, j + 0, k + 7, KMOD_Main.KetherStone);
         world.setBlock(i + 11, j + 1, k + 7, KMOD_Main.KetherStone);
         world.setBlock(i + 11, j + 2, k + 7, KMOD_Main.KetherStone);
         world.setBlock(i + 11, j + 2, k + 10, KMOD_Main.KetherStone);
         world.setBlock(i + 11, j + 3, k + 7, KMOD_Main.KetherStone);
         world.setBlock(i + 11, j + 3, k + 10, KMOD_Main.KetherStone);
         world.setBlock(i + 11, j + 4, k + 7, KMOD_Main.KetherStone);
         world.setBlock(i + 11, j + 4, k + 8, KMOD_Main.KetherStone);
         world.setBlock(i + 11, j + 4, k + 10, KMOD_Main.KetherStone);
         world.setBlock(i + 11, j + 4, k + 12, KMOD_Main.KetherStone);
         world.setBlock(i + 11, j + 4, k + 13, KMOD_Main.KetherStone);
         world.setBlock(i + 11, j + 5, k + 5, KMOD_Main.KetherStone);
         world.setBlock(i + 11, j + 5, k + 6, KMOD_Main.KetherStone);
         world.setBlock(i + 11, j + 5, k + 7, KMOD_Main.KetherStone);
         world.setBlock(i + 11, j + 5, k + 8, KMOD_Main.KetherStone);
         world.setBlock(i + 11, j + 5, k + 9, KMOD_Main.KetherStone);
         world.setBlock(i + 11, j + 5, k + 10, KMOD_Main.KetherStone);
         world.setBlock(i + 11, j + 5, k + 11, KMOD_Main.KetherStone);
         world.setBlock(i + 11, j + 5, k + 12, KMOD_Main.KetherStone);
         world.setBlock(i + 11, j + 5, k + 13, KMOD_Main.KetherStone);
         world.setBlock(i + 11, j + 5, k + 14, KMOD_Main.KetherStone);
         world.setBlock(i + 11, j + 5, k + 15, KMOD_Main.KetherStone);
         world.setBlock(i + 11, j + 5, k + 16, KMOD_Main.KetherStone);
         world.setBlock(i + 11, j + 6, k + 3, KMOD_Main.KetherStone);
         world.setBlock(i + 11, j + 6, k + 4, KMOD_Main.KetherStone);
         world.setBlock(i + 11, j + 6, k + 5, KMOD_Main.KetherStone);
         world.setBlock(i + 11, j + 6, k + 6, KMOD_Main.KetherStone);
         world.setBlock(i + 11, j + 6, k + 15, KMOD_Main.KetherStone);
         world.setBlock(i + 11, j + 6, k + 16, KMOD_Main.KetherStone);
         world.setBlock(i + 11, j + 6, k + 17, KMOD_Main.KetherStone);
         world.setBlock(i + 11, j + 7, k + 2, KMOD_Main.KetherStone);
         world.setBlock(i + 11, j + 7, k + 3, KMOD_Main.KetherStone);
         world.setBlock(i + 11, j + 7, k + 4, KMOD_Main.KetherStone);
         world.setBlock(i + 11, j + 7, k + 17, KMOD_Main.KetherStone);
         world.setBlock(i + 11, j + 7, k + 18, KMOD_Main.KetherStone);
         world.setBlock(i + 11, j + 7, k + 19, KMOD_Main.KetherStone);
         world.setBlock(i + 11, j + 8, k + 1, KMOD_Main.KetherGrass);
         world.setBlock(i + 11, j + 8, k + 2, KMOD_Main.KetherGrass);
         world.setBlock(i + 11, j + 8, k + 3, KMOD_Main.KetherGrass);
         world.setBlock(i + 11, j + 8, k + 4, KMOD_Main.KetherGrass);
         world.setBlock(i + 11, j + 8, k + 5, KMOD_Main.KetherGrass);
         world.setBlock(i + 11, j + 8, k + 6, KMOD_Main.KetherGrass);
         world.setBlock(i + 11, j + 8, k + 7, KMOD_Main.KetherGrass);
         world.setBlock(i + 11, j + 8, k + 8, KMOD_Main.KetherGrass);
         world.setBlock(i + 11, j + 8, k + 9, KMOD_Main.KetherGrass);
         world.setBlock(i + 11, j + 8, k + 10, KMOD_Main.KetherGrass);
         world.setBlock(i + 11, j + 8, k + 11, Blocks.gold_block);
         world.setBlock(i + 11, j + 8, k + 12, Blocks.gold_block);
         world.setBlock(i + 11, j + 8, k + 13, Blocks.gold_block);
         world.setBlock(i + 11, j + 8, k + 14, Blocks.gold_block);
         world.setBlock(i + 11, j + 8, k + 15, Blocks.gold_block);
         world.setBlock(i + 11, j + 8, k + 16, Blocks.gold_block);
         world.setBlock(i + 11, j + 8, k + 17, Blocks.gold_block);
         world.setBlock(i + 11, j + 8, k + 18, KMOD_Main.KetherGrass);
         world.setBlock(i + 11, j + 8, k + 19, KMOD_Main.KetherGrass);
         world.setBlock(i + 11, j + 8, k + 20, KMOD_Main.KetherGrass);
         world.setBlock(i + 11, j + 12, k + 1, KMOD_Main.KetherGoldenLeaves);
         world.setBlock(i + 11, j + 12, k + 2, KMOD_Main.KetherGoldenLeaves);
         world.setBlock(i + 11, j + 12, k + 3, KMOD_Main.KetherGoldenLeaves);
         world.setBlock(i + 11, j + 12, k + 4, KMOD_Main.KetherGoldenLeaves);
         world.setBlock(i + 11, j + 12, k + 5, KMOD_Main.KetherGoldenLeaves);
         world.setBlock(i + 11, j + 13, k + 1, KMOD_Main.KetherGoldenLeaves);
         world.setBlock(i + 11, j + 13, k + 2, KMOD_Main.KetherGoldenLeaves);
         world.setBlock(i + 11, j + 13, k + 3, KMOD_Main.KetherGoldenLeaves);
         world.setBlock(i + 11, j + 13, k + 4, KMOD_Main.KetherGoldenLeaves);
         world.setBlock(i + 11, j + 13, k + 5, KMOD_Main.KetherGoldenLeaves);
         world.setBlock(i + 12, j + 1, k + 15, KMOD_Main.KetherStone);
         world.setBlock(i + 12, j + 2, k + 15, KMOD_Main.KetherStone);
         world.setBlock(i + 12, j + 3, k + 8, KMOD_Main.KetherStone);
         world.setBlock(i + 12, j + 3, k + 15, KMOD_Main.KetherStone);
         world.setBlock(i + 12, j + 4, k + 7, KMOD_Main.KetherStone);
         world.setBlock(i + 12, j + 4, k + 8, KMOD_Main.KetherStone);
         world.setBlock(i + 12, j + 4, k + 10, KMOD_Main.KetherStone);
         world.setBlock(i + 12, j + 4, k + 15, KMOD_Main.KetherStone);
         world.setBlock(i + 12, j + 5, k + 6, KMOD_Main.KetherStone);
         world.setBlock(i + 12, j + 5, k + 7, KMOD_Main.KetherStone);
         world.setBlock(i + 12, j + 5, k + 8, KMOD_Main.KetherStone);
         world.setBlock(i + 12, j + 5, k + 9, KMOD_Main.KetherStone);
         world.setBlock(i + 12, j + 5, k + 10, KMOD_Main.KetherStone);
         world.setBlock(i + 12, j + 5, k + 11, KMOD_Main.KetherStone);
         world.setBlock(i + 12, j + 5, k + 12, KMOD_Main.KetherStone);
         world.setBlock(i + 12, j + 5, k + 13, KMOD_Main.KetherStone);
         world.setBlock(i + 12, j + 5, k + 14, KMOD_Main.KetherStone);
         world.setBlock(i + 12, j + 5, k + 15, KMOD_Main.KetherStone);
         world.setBlock(i + 12, j + 6, k + 4, KMOD_Main.KetherStone);
         world.setBlock(i + 12, j + 6, k + 5, KMOD_Main.KetherStone);
         world.setBlock(i + 12, j + 6, k + 6, KMOD_Main.KetherStone);
         world.setBlock(i + 12, j + 6, k + 9, Blocks.chest);
         this.fillChest(rand, world, i + 12, j + 6, k + 9);
         world.setBlock(i + 12, j + 6, k + 15, KMOD_Main.KetherStone);
         world.setBlock(i + 12, j + 6, k + 16, KMOD_Main.KetherStone);
         world.setBlock(i + 12, j + 6, k + 17, KMOD_Main.KetherStone);
         world.setBlock(i + 12, j + 7, k + 2, KMOD_Main.KetherStone);
         world.setBlock(i + 12, j + 7, k + 3, KMOD_Main.KetherStone);
         world.setBlock(i + 12, j + 7, k + 4, KMOD_Main.KetherStone);
         world.setBlock(i + 12, j + 7, k + 17, KMOD_Main.KetherStone);
         world.setBlock(i + 12, j + 7, k + 18, KMOD_Main.KetherStone);
         world.setBlock(i + 12, j + 7, k + 19, KMOD_Main.KetherStone);
         world.setBlock(i + 12, j + 8, k + 1, KMOD_Main.KetherGrass);
         world.setBlock(i + 12, j + 8, k + 2, KMOD_Main.KetherGrass);
         world.setBlock(i + 12, j + 8, k + 3, KMOD_Main.KetherGrass);
         world.setBlock(i + 12, j + 8, k + 4, KMOD_Main.KetherGrass);
         world.setBlock(i + 12, j + 8, k + 5, KMOD_Main.KetherGrass);
         world.setBlock(i + 12, j + 8, k + 6, KMOD_Main.KetherGrass);
         world.setBlock(i + 12, j + 8, k + 7, KMOD_Main.KetherGrass);
         world.setBlock(i + 12, j + 8, k + 8, KMOD_Main.KetherGrass);
         world.setBlock(i + 12, j + 8, k + 9, KMOD_Main.KetherGrass);
         world.setBlock(i + 12, j + 8, k + 10, Blocks.gold_block);
         world.setBlock(i + 12, j + 8, k + 11, Blocks.gold_block);
         world.setBlock(i + 12, j + 8, k + 12, KMOD_Main.KetherGrass);
         world.setBlock(i + 12, j + 8, k + 13, Blocks.gold_block);
         world.setBlock(i + 12, j + 8, k + 14, Blocks.gold_block);
         world.setBlock(i + 12, j + 8, k + 15, Blocks.gold_block);
         world.setBlock(i + 12, j + 8, k + 16, Blocks.gold_block);
         world.setBlock(i + 12, j + 8, k + 17, Blocks.gold_block);
         world.setBlock(i + 12, j + 8, k + 18, Blocks.gold_block);
         world.setBlock(i + 12, j + 8, k + 19, KMOD_Main.KetherGrass);
         world.setBlock(i + 12, j + 8, k + 20, KMOD_Main.KetherGrass);
         world.setBlock(i + 12, j + 10, k + 0, KMOD_Main.KetherGoldenLeaves);
         world.setBlock(i + 12, j + 10, k + 1, KMOD_Main.KetherGoldenLeaves);
         world.setBlock(i + 12, j + 10, k + 2, KMOD_Main.KetherGoldenLeaves);
         world.setBlock(i + 12, j + 11, k + 0, KMOD_Main.KetherGoldenLeaves);
         world.setBlock(i + 12, j + 11, k + 1, KMOD_Main.KetherGoldenLeaves);
         world.setBlock(i + 12, j + 11, k + 2, KMOD_Main.KetherGoldenLeaves);
         world.setBlock(i + 12, j + 11, k + 3, KMOD_Main.KetherGoldenLeaves);
         world.setBlock(i + 13, j + 1, k + 11, KMOD_Main.KetherStone);
         world.setBlock(i + 13, j + 1, k + 14, KMOD_Main.KetherStone);
         world.setBlock(i + 13, j + 2, k + 9, KMOD_Main.KetherStone);
         world.setBlock(i + 13, j + 2, k + 11, KMOD_Main.KetherStone);
         world.setBlock(i + 13, j + 2, k + 14, KMOD_Main.KetherStone);
         world.setBlock(i + 13, j + 3, k + 9, KMOD_Main.KetherStone);
         world.setBlock(i + 13, j + 3, k + 10, KMOD_Main.KetherStone);
         world.setBlock(i + 13, j + 3, k + 11, KMOD_Main.KetherStone);
         world.setBlock(i + 13, j + 3, k + 14, KMOD_Main.KetherStone);
         world.setBlock(i + 13, j + 4, k + 7, KMOD_Main.KetherStone);
         world.setBlock(i + 13, j + 4, k + 9, KMOD_Main.KetherStone);
         world.setBlock(i + 13, j + 4, k + 10, KMOD_Main.KetherStone);
         world.setBlock(i + 13, j + 4, k + 11, KMOD_Main.KetherStone);
         world.setBlock(i + 13, j + 4, k + 12, KMOD_Main.KetherStone);
         world.setBlock(i + 13, j + 4, k + 13, KMOD_Main.KetherStone);
         world.setBlock(i + 13, j + 4, k + 14, KMOD_Main.KetherStone);
         world.setBlock(i + 13, j + 5, k + 2, KMOD_Main.KetherStone);
         world.setBlock(i + 13, j + 5, k + 6, KMOD_Main.KetherStone);
         world.setBlock(i + 13, j + 5, k + 7, KMOD_Main.KetherStone);
         world.setBlock(i + 13, j + 5, k + 8, KMOD_Main.KetherStone);
         world.setBlock(i + 13, j + 5, k + 9, KMOD_Main.KetherStone);
         world.setBlock(i + 13, j + 5, k + 10, KMOD_Main.KetherStone);
         world.setBlock(i + 13, j + 5, k + 11, KMOD_Main.KetherStone);
         world.setBlock(i + 13, j + 5, k + 12, KMOD_Main.KetherStone);
         world.setBlock(i + 13, j + 5, k + 13, KMOD_Main.KetherStone);
         world.setBlock(i + 13, j + 5, k + 14, KMOD_Main.KetherStone);
         world.setBlock(i + 13, j + 5, k + 15, KMOD_Main.KetherStone);
         world.setBlock(i + 13, j + 5, k + 16, KMOD_Main.KetherStone);
         world.setBlock(i + 13, j + 6, k + 2, KMOD_Main.KetherStone);
         world.setBlock(i + 13, j + 6, k + 4, KMOD_Main.KetherStone);
         world.setBlock(i + 13, j + 6, k + 5, KMOD_Main.KetherStone);
         world.setBlock(i + 13, j + 6, k + 6, KMOD_Main.KetherStone);
         world.setBlock(i + 13, j + 6, k + 15, KMOD_Main.KetherStone);
         world.setBlock(i + 13, j + 6, k + 16, KMOD_Main.KetherStone);
         world.setBlock(i + 13, j + 6, k + 17, KMOD_Main.KetherStone);
         world.setBlock(i + 13, j + 6, k + 18, KMOD_Main.KetherStone);
         world.setBlock(i + 13, j + 6, k + 19, KMOD_Main.KetherStone);
         world.setBlock(i + 13, j + 7, k + 2, KMOD_Main.KetherStone);
         world.setBlock(i + 13, j + 7, k + 3, KMOD_Main.KetherStone);
         world.setBlock(i + 13, j + 7, k + 4, KMOD_Main.KetherStone);
         world.setBlock(i + 13, j + 7, k + 17, KMOD_Main.KetherStone);
         world.setBlock(i + 13, j + 7, k + 18, KMOD_Main.KetherStone);
         world.setBlock(i + 13, j + 7, k + 19, KMOD_Main.KetherStone);
         world.setBlock(i + 13, j + 8, k + 1, KMOD_Main.KetherGrass);
         world.setBlock(i + 13, j + 8, k + 2, KMOD_Main.KetherGrass);
         world.setBlock(i + 13, j + 8, k + 3, KMOD_Main.KetherGrass);
         world.setBlock(i + 13, j + 8, k + 4, KMOD_Main.KetherGrass);
         world.setBlock(i + 13, j + 8, k + 5, KMOD_Main.KetherGrass);
         world.setBlock(i + 13, j + 8, k + 6, KMOD_Main.KetherGrass);
         world.setBlock(i + 13, j + 8, k + 7, KMOD_Main.KetherGrass);
         world.setBlock(i + 13, j + 8, k + 8, KMOD_Main.KetherGrass);
         world.setBlock(i + 13, j + 8, k + 9, KMOD_Main.KetherGrass);
         world.setBlock(i + 13, j + 8, k + 10, KMOD_Main.KetherGrass);
         world.setBlock(i + 13, j + 8, k + 11, KMOD_Main.KetherGrass);
         world.setBlock(i + 13, j + 8, k + 12, Blocks.gold_block);
         world.setBlock(i + 13, j + 8, k + 13, Blocks.gold_block);
         world.setBlock(i + 13, j + 8, k + 14, Blocks.gold_block);
         world.setBlock(i + 13, j + 8, k + 15, Blocks.gold_block);
         world.setBlock(i + 13, j + 8, k + 16, Blocks.gold_block);
         world.setBlock(i + 13, j + 8, k + 17, KMOD_Main.KetherGrass);
         world.setBlock(i + 13, j + 8, k + 18, KMOD_Main.KetherGrass);
         world.setBlock(i + 13, j + 8, k + 19, KMOD_Main.KetherGrass);
         world.setBlock(i + 13, j + 8, k + 20, KMOD_Main.KetherGrass);
         world.setBlock(i + 13, j + 10, k + 0, KMOD_Main.KetherGoldenLeaves);
         world.setBlock(i + 13, j + 10, k + 1, KMOD_Main.KetherGoldenLeaves);
         world.setBlock(i + 13, j + 10, k + 2, KMOD_Main.KetherGoldenLeaves);
         world.setBlock(i + 13, j + 10, k + 3, KMOD_Main.KetherGoldenLeaves);
         world.setBlock(i + 13, j + 10, k + 4, KMOD_Main.KetherGoldenLeaves);
         world.setBlock(i + 13, j + 11, k + 0, KMOD_Main.KetherGoldenLeaves);
         world.setBlock(i + 13, j + 11, k + 1, KMOD_Main.KetherGoldenLeaves);
         world.setBlock(i + 13, j + 11, k + 2, KMOD_Main.KetherGoldenLeaves);
         world.setBlock(i + 13, j + 11, k + 3, KMOD_Main.KetherGoldenLeaves);
         world.setBlock(i + 13, j + 11, k + 4, KMOD_Main.KetherGoldenLeaves);
         world.setBlock(i + 13, j + 12, k + 1, KMOD_Main.KetherGoldenLeaves);
         world.setBlock(i + 13, j + 12, k + 2, KMOD_Main.KetherGoldenLeaves);
         world.setBlock(i + 13, j + 12, k + 3, KMOD_Main.KetherGoldenLeaves);
         world.setBlock(i + 13, j + 13, k + 2, KMOD_Main.KetherGoldenLeaves);
         world.setBlock(i + 14, j + 4, k + 7, KMOD_Main.KetherStone);
         world.setBlock(i + 14, j + 5, k + 5, KMOD_Main.KetherStone);
         world.setBlock(i + 14, j + 5, k + 6, KMOD_Main.KetherStone);
         world.setBlock(i + 14, j + 5, k + 7, KMOD_Main.KetherStone);
         world.setBlock(i + 14, j + 5, k + 8, KMOD_Main.KetherStone);
         world.setBlock(i + 14, j + 5, k + 9, KMOD_Main.KetherStone);
         world.setBlock(i + 14, j + 5, k + 10, KMOD_Main.KetherStone);
         world.setBlock(i + 14, j + 5, k + 11, KMOD_Main.KetherStone);
         world.setBlock(i + 14, j + 5, k + 12, KMOD_Main.KetherStone);
         world.setBlock(i + 14, j + 5, k + 13, KMOD_Main.KetherStone);
         world.setBlock(i + 14, j + 5, k + 14, KMOD_Main.KetherStone);
         world.setBlock(i + 14, j + 5, k + 15, KMOD_Main.KetherStone);
         world.setBlock(i + 14, j + 6, k + 3, KMOD_Main.KetherStone);
         world.setBlock(i + 14, j + 6, k + 4, KMOD_Main.KetherStone);
         world.setBlock(i + 14, j + 6, k + 5, KMOD_Main.KetherStone);
         world.setBlock(i + 14, j + 6, k + 6, KMOD_Main.KetherStone);
         world.setBlock(i + 14, j + 6, k + 7, KMOD_Main.KetherStone);
         world.setBlock(i + 14, j + 6, k + 8, KMOD_Main.KetherStone);
         world.setBlock(i + 14, j + 6, k + 9, KMOD_Main.KetherStone);
         world.setBlock(i + 14, j + 6, k + 10, KMOD_Main.KetherStone);
         world.setBlock(i + 14, j + 6, k + 11, KMOD_Main.KetherStone);
         world.setBlock(i + 14, j + 6, k + 12, KMOD_Main.KetherStone);
         world.setBlock(i + 14, j + 6, k + 13, KMOD_Main.KetherStone);
         world.setBlock(i + 14, j + 6, k + 14, KMOD_Main.KetherStone);
         world.setBlock(i + 14, j + 6, k + 15, KMOD_Main.KetherStone);
         world.setBlock(i + 14, j + 6, k + 16, KMOD_Main.KetherStone);
         world.setBlock(i + 14, j + 6, k + 17, KMOD_Main.KetherStone);
         world.setBlock(i + 14, j + 7, k + 2, KMOD_Main.KetherStone);
         world.setBlock(i + 14, j + 7, k + 3, KMOD_Main.KetherStone);
         world.setBlock(i + 14, j + 7, k + 4, KMOD_Main.KetherStone);
         world.setBlock(i + 14, j + 7, k + 17, KMOD_Main.KetherStone);
         world.setBlock(i + 14, j + 7, k + 18, KMOD_Main.KetherStone);
         world.setBlock(i + 14, j + 7, k + 19, KMOD_Main.KetherStone);
         world.setBlock(i + 14, j + 8, k + 1, KMOD_Main.KetherGrass);
         world.setBlock(i + 14, j + 8, k + 2, KMOD_Main.KetherStone);
         world.setBlock(i + 14, j + 8, k + 3, KMOD_Main.KetherGrass);
         world.setBlock(i + 14, j + 8, k + 4, KMOD_Main.KetherGrass);
         world.setBlock(i + 14, j + 8, k + 5, KMOD_Main.KetherGrass);
         world.setBlock(i + 14, j + 8, k + 6, KMOD_Main.KetherGrass);
         world.setBlock(i + 14, j + 8, k + 7, KMOD_Main.KetherGrass);
         world.setBlock(i + 14, j + 8, k + 8, KMOD_Main.KetherGrass);
         world.setBlock(i + 14, j + 8, k + 9, KMOD_Main.KetherGrass);
         world.setBlock(i + 14, j + 8, k + 10, KMOD_Main.KetherGrass);
         world.setBlock(i + 14, j + 8, k + 11, KMOD_Main.KetherGrass);
         world.setBlock(i + 14, j + 8, k + 12, KMOD_Main.KetherGrass);
         world.setBlock(i + 14, j + 8, k + 13, Blocks.gold_block);
         world.setBlock(i + 14, j + 8, k + 14, KMOD_Main.KetherGrass);
         world.setBlock(i + 14, j + 8, k + 15, Blocks.gold_block);
         world.setBlock(i + 14, j + 8, k + 16, KMOD_Main.KetherGrass);
         world.setBlock(i + 14, j + 8, k + 17, KMOD_Main.KetherGrass);
         world.setBlock(i + 14, j + 8, k + 18, KMOD_Main.KetherGrass);
         world.setBlock(i + 14, j + 8, k + 19, KMOD_Main.KetherGrass);
         world.setBlock(i + 14, j + 8, k + 20, KMOD_Main.KetherGrass);
         world.setBlock(i + 14, j + 9, k + 2, KMOD_Main.KetherLog);
         world.setBlock(i + 14, j + 10, k + 0, KMOD_Main.KetherGoldenLeaves);
         world.setBlock(i + 14, j + 10, k + 1, KMOD_Main.KetherGoldenLeaves);
         world.setBlock(i + 14, j + 10, k + 2, KMOD_Main.KetherLog);
         world.setBlock(i + 14, j + 10, k + 3, KMOD_Main.KetherGoldenLeaves);
         world.setBlock(i + 14, j + 10, k + 4, KMOD_Main.KetherGoldenLeaves);
         world.setBlock(i + 14, j + 11, k + 0, KMOD_Main.KetherGoldenLeaves);
         world.setBlock(i + 14, j + 11, k + 1, KMOD_Main.KetherGoldenLeaves);
         world.setBlock(i + 14, j + 11, k + 2, KMOD_Main.KetherLog);
         world.setBlock(i + 14, j + 11, k + 3, KMOD_Main.KetherGoldenLeaves);
         world.setBlock(i + 14, j + 11, k + 4, KMOD_Main.KetherGoldenLeaves);
         world.setBlock(i + 14, j + 12, k + 1, KMOD_Main.KetherGoldenLeaves);
         world.setBlock(i + 14, j + 12, k + 2, KMOD_Main.KetherLog);
         world.setBlock(i + 14, j + 12, k + 3, KMOD_Main.KetherGoldenLeaves);
         world.setBlock(i + 14, j + 13, k + 1, KMOD_Main.KetherGoldenLeaves);
         world.setBlock(i + 14, j + 13, k + 2, KMOD_Main.KetherGoldenLeaves);
         world.setBlock(i + 14, j + 13, k + 3, KMOD_Main.KetherGoldenLeaves);
         world.setBlock(i + 14, j + 16, k + 4, KMOD_Main.KetherGoldenLeaves);
         world.setBlock(i + 14, j + 16, k + 5, KMOD_Main.KetherGoldenLeaves);
         world.setBlock(i + 14, j + 16, k + 6, KMOD_Main.KetherGoldenLeaves);
         world.setBlock(i + 14, j + 16, k + 7, KMOD_Main.KetherGoldenLeaves);
         world.setBlock(i + 14, j + 16, k + 8, KMOD_Main.KetherGoldenLeaves);
         world.setBlock(i + 14, j + 16, k + 18, KMOD_Main.KetherGoldenLeaves);
         world.setBlock(i + 14, j + 16, k + 19, KMOD_Main.KetherGoldenLeaves);
         world.setBlock(i + 14, j + 16, k + 20, KMOD_Main.KetherGoldenLeaves);
         world.setBlock(i + 14, j + 16, k + 21, KMOD_Main.KetherGoldenLeaves);
         world.setBlock(i + 14, j + 16, k + 22, KMOD_Main.KetherGoldenLeaves);
         world.setBlock(i + 15, j + 3, k + 14, KMOD_Main.KetherStone);
         world.setBlock(i + 15, j + 4, k + 12, KMOD_Main.KetherStone);
         world.setBlock(i + 15, j + 4, k + 14, KMOD_Main.KetherStone);
         world.setBlock(i + 15, j + 5, k + 8, KMOD_Main.KetherStone);
         world.setBlock(i + 15, j + 5, k + 9, KMOD_Main.KetherStone);
         world.setBlock(i + 15, j + 5, k + 11, KMOD_Main.KetherStone);
         world.setBlock(i + 15, j + 5, k + 12, KMOD_Main.KetherStone);
         world.setBlock(i + 15, j + 5, k + 14, KMOD_Main.KetherStone);
         world.setBlock(i + 15, j + 6, k + 4, KMOD_Main.KetherStone);
         world.setBlock(i + 15, j + 6, k + 5, KMOD_Main.KetherStone);
         world.setBlock(i + 15, j + 6, k + 6, KMOD_Main.KetherStone);
         world.setBlock(i + 15, j + 6, k + 7, KMOD_Main.KetherStone);
         world.setBlock(i + 15, j + 6, k + 8, KMOD_Main.KetherStone);
         world.setBlock(i + 15, j + 6, k + 9, KMOD_Main.KetherStone);
         world.setBlock(i + 15, j + 6, k + 10, KMOD_Main.KetherStone);
         world.setBlock(i + 15, j + 6, k + 11, KMOD_Main.KetherStone);
         world.setBlock(i + 15, j + 6, k + 12, KMOD_Main.KetherStone);
         world.setBlock(i + 15, j + 6, k + 13, KMOD_Main.KetherStone);
         world.setBlock(i + 15, j + 6, k + 14, KMOD_Main.KetherStone);
         world.setBlock(i + 15, j + 6, k + 15, KMOD_Main.KetherStone);
         world.setBlock(i + 15, j + 6, k + 16, KMOD_Main.KetherStone);
         world.setBlock(i + 15, j + 6, k + 17, KMOD_Main.KetherStone);
         world.setBlock(i + 15, j + 6, k + 18, KMOD_Main.KetherStone);
         world.setBlock(i + 15, j + 7, k + 2, KMOD_Main.KetherStone);
         world.setBlock(i + 15, j + 7, k + 3, KMOD_Main.KetherStone);
         world.setBlock(i + 15, j + 7, k + 4, KMOD_Main.KetherStone);
         world.setBlock(i + 15, j + 7, k + 17, KMOD_Main.KetherStone);
         world.setBlock(i + 15, j + 7, k + 18, KMOD_Main.KetherStone);
         world.setBlock(i + 15, j + 7, k + 19, KMOD_Main.KetherStone);
         world.setBlock(i + 15, j + 8, k + 1, KMOD_Main.KetherGrass);
         world.setBlock(i + 15, j + 8, k + 2, KMOD_Main.KetherGrass);
         world.setBlock(i + 15, j + 8, k + 3, KMOD_Main.KetherGrass);
         world.setBlock(i + 15, j + 8, k + 4, KMOD_Main.KetherGrass);
         world.setBlock(i + 15, j + 8, k + 5, KMOD_Main.KetherGrass);
         world.setBlock(i + 15, j + 8, k + 6, KMOD_Main.KetherGrass);
         world.setBlock(i + 15, j + 8, k + 7, KMOD_Main.KetherGrass);
         world.setBlock(i + 15, j + 8, k + 8, KMOD_Main.KetherGrass);
         world.setBlock(i + 15, j + 8, k + 9, KMOD_Main.KetherGrass);
         world.setBlock(i + 15, j + 8, k + 10, KMOD_Main.KetherGrass);
         world.setBlock(i + 15, j + 8, k + 11, KMOD_Main.KetherGrass);
         world.setBlock(i + 15, j + 8, k + 12, KMOD_Main.KetherGrass);
         world.setBlock(i + 15, j + 8, k + 13, KMOD_Main.KetherGrass);
         world.setBlock(i + 15, j + 8, k + 14, KMOD_Main.KetherGrass);
         world.setBlock(i + 15, j + 8, k + 15, KMOD_Main.KetherGrass);
         world.setBlock(i + 15, j + 8, k + 16, KMOD_Main.KetherGrass);
         world.setBlock(i + 15, j + 8, k + 17, KMOD_Main.KetherGrass);
         world.setBlock(i + 15, j + 8, k + 18, KMOD_Main.KetherGrass);
         world.setBlock(i + 15, j + 8, k + 19, KMOD_Main.KetherGrass);
         world.setBlock(i + 15, j + 8, k + 20, KMOD_Main.KetherGrass);
         world.setBlock(i + 15, j + 10, k + 0, KMOD_Main.KetherGoldenLeaves);
         world.setBlock(i + 15, j + 10, k + 1, KMOD_Main.KetherGoldenLeaves);
         world.setBlock(i + 15, j + 10, k + 2, KMOD_Main.KetherGoldenLeaves);
         world.setBlock(i + 15, j + 10, k + 3, KMOD_Main.KetherGoldenLeaves);
         world.setBlock(i + 15, j + 10, k + 4, KMOD_Main.KetherGoldenLeaves);
         world.setBlock(i + 15, j + 11, k + 0, KMOD_Main.KetherGoldenLeaves);
         world.setBlock(i + 15, j + 11, k + 1, KMOD_Main.KetherGoldenLeaves);
         world.setBlock(i + 15, j + 11, k + 2, KMOD_Main.KetherGoldenLeaves);
         world.setBlock(i + 15, j + 11, k + 3, KMOD_Main.KetherGoldenLeaves);
         world.setBlock(i + 15, j + 11, k + 4, KMOD_Main.KetherGoldenLeaves);
         world.setBlock(i + 15, j + 12, k + 2, KMOD_Main.KetherGoldenLeaves);
         world.setBlock(i + 15, j + 12, k + 3, KMOD_Main.KetherGoldenLeaves);
         world.setBlock(i + 15, j + 13, k + 2, KMOD_Main.KetherGoldenLeaves);
         world.setBlock(i + 15, j + 15, k + 4, KMOD_Main.KetherGoldenLeaves);
         world.setBlock(i + 15, j + 15, k + 5, KMOD_Main.KetherGoldenLeaves);
         world.setBlock(i + 15, j + 15, k + 6, KMOD_Main.KetherGoldenLeaves);
         world.setBlock(i + 15, j + 15, k + 7, KMOD_Main.KetherGoldenLeaves);
         world.setBlock(i + 15, j + 15, k + 8, KMOD_Main.KetherGoldenLeaves);
         world.setBlock(i + 15, j + 15, k + 9, KMOD_Main.KetherGoldenLeaves);
         world.setBlock(i + 15, j + 15, k + 18, KMOD_Main.KetherGoldenLeaves);
         world.setBlock(i + 15, j + 15, k + 19, KMOD_Main.KetherGoldenLeaves);
         world.setBlock(i + 15, j + 15, k + 20, KMOD_Main.KetherGoldenLeaves);
         world.setBlock(i + 15, j + 15, k + 21, KMOD_Main.KetherGoldenLeaves);
         world.setBlock(i + 15, j + 15, k + 22, KMOD_Main.KetherGoldenLeaves);
         world.setBlock(i + 15, j + 15, k + 23, KMOD_Main.KetherGoldenLeaves);
         world.setBlock(i + 15, j + 16, k + 3, KMOD_Main.KetherGoldenLeaves);
         world.setBlock(i + 15, j + 16, k + 4, KMOD_Main.KetherGoldenLeaves);
         world.setBlock(i + 15, j + 16, k + 5, KMOD_Main.KetherGoldenLeaves);
         world.setBlock(i + 15, j + 16, k + 6, KMOD_Main.KetherGoldenLeaves);
         world.setBlock(i + 15, j + 16, k + 7, KMOD_Main.KetherGoldenLeaves);
         world.setBlock(i + 15, j + 16, k + 8, KMOD_Main.KetherGoldenLeaves);
         world.setBlock(i + 15, j + 16, k + 9, KMOD_Main.KetherGoldenLeaves);
         world.setBlock(i + 15, j + 16, k + 10, KMOD_Main.KetherGoldenLeaves);
         world.setBlock(i + 15, j + 16, k + 17, KMOD_Main.KetherGoldenLeaves);
         world.setBlock(i + 15, j + 16, k + 18, KMOD_Main.KetherGoldenLeaves);
         world.setBlock(i + 15, j + 16, k + 19, KMOD_Main.KetherGoldenLeaves);
         world.setBlock(i + 15, j + 16, k + 20, KMOD_Main.KetherGoldenLeaves);
         world.setBlock(i + 15, j + 16, k + 21, KMOD_Main.KetherGoldenLeaves);
         world.setBlock(i + 15, j + 16, k + 22, KMOD_Main.KetherGoldenLeaves);
         world.setBlock(i + 15, j + 16, k + 23, KMOD_Main.KetherGoldenLeaves);
         world.setBlock(i + 15, j + 16, k + 24, KMOD_Main.KetherGoldenLeaves);
         world.setBlock(i + 15, j + 17, k + 6, KMOD_Main.KetherGoldenLeaves);
         world.setBlock(i + 15, j + 17, k + 7, KMOD_Main.KetherGoldenLeaves);
         world.setBlock(i + 15, j + 17, k + 20, KMOD_Main.KetherGoldenLeaves);
         world.setBlock(i + 15, j + 17, k + 21, KMOD_Main.KetherGoldenLeaves);
         world.setBlock(i + 16, j + 4, k + 6, KMOD_Main.KetherStone);
         world.setBlock(i + 16, j + 5, k + 6, KMOD_Main.KetherStone);
         world.setBlock(i + 16, j + 5, k + 7, KMOD_Main.KetherStone);
         world.setBlock(i + 16, j + 5, k + 13, KMOD_Main.KetherStone);
         world.setBlock(i + 16, j + 6, k + 4, KMOD_Main.KetherStone);
         world.setBlock(i + 16, j + 6, k + 5, KMOD_Main.KetherStone);
         world.setBlock(i + 16, j + 6, k + 6, KMOD_Main.KetherStone);
         world.setBlock(i + 16, j + 6, k + 7, KMOD_Main.KetherStone);
         world.setBlock(i + 16, j + 6, k + 8, KMOD_Main.KetherStone);
         world.setBlock(i + 16, j + 6, k + 9, KMOD_Main.KetherStone);
         world.setBlock(i + 16, j + 6, k + 10, KMOD_Main.KetherStone);
         world.setBlock(i + 16, j + 6, k + 11, KMOD_Main.KetherStone);
         world.setBlock(i + 16, j + 6, k + 12, KMOD_Main.KetherStone);
         world.setBlock(i + 16, j + 6, k + 13, KMOD_Main.KetherStone);
         world.setBlock(i + 16, j + 6, k + 14, KMOD_Main.KetherStone);
         world.setBlock(i + 16, j + 6, k + 15, KMOD_Main.KetherStone);
         world.setBlock(i + 16, j + 6, k + 16, KMOD_Main.KetherStone);
         world.setBlock(i + 16, j + 6, k + 17, KMOD_Main.KetherStone);
         world.setBlock(i + 16, j + 7, k + 2, KMOD_Main.KetherStone);
         world.setBlock(i + 16, j + 7, k + 3, KMOD_Main.KetherStone);
         world.setBlock(i + 16, j + 7, k + 4, KMOD_Main.KetherStone);
         world.setBlock(i + 16, j + 7, k + 5, KMOD_Main.KetherStone);
         world.setBlock(i + 16, j + 7, k + 6, KMOD_Main.KetherStone);
         world.setBlock(i + 16, j + 7, k + 7, KMOD_Main.KetherStone);
         world.setBlock(i + 16, j + 7, k + 8, KMOD_Main.KetherStone);
         world.setBlock(i + 16, j + 7, k + 9, KMOD_Main.KetherStone);
         world.setBlock(i + 16, j + 7, k + 10, KMOD_Main.KetherStone);
         world.setBlock(i + 16, j + 7, k + 11, KMOD_Main.KetherStone);
         world.setBlock(i + 16, j + 7, k + 12, KMOD_Main.KetherStone);
         world.setBlock(i + 16, j + 7, k + 13, KMOD_Main.KetherStone);
         world.setBlock(i + 16, j + 7, k + 14, KMOD_Main.KetherStone);
         world.setBlock(i + 16, j + 7, k + 15, KMOD_Main.KetherStone);
         world.setBlock(i + 16, j + 7, k + 16, KMOD_Main.KetherStone);
         world.setBlock(i + 16, j + 7, k + 17, KMOD_Main.KetherStone);
         world.setBlock(i + 16, j + 7, k + 18, KMOD_Main.KetherStone);
         world.setBlock(i + 16, j + 7, k + 19, KMOD_Main.KetherStone);
         world.setBlock(i + 16, j + 8, k + 1, KMOD_Main.KetherGrass);
         world.setBlock(i + 16, j + 8, k + 2, KMOD_Main.KetherGrass);
         world.setBlock(i + 16, j + 8, k + 3, KMOD_Main.KetherGrass);
         world.setBlock(i + 16, j + 8, k + 4, KMOD_Main.KetherGrass);
         world.setBlock(i + 16, j + 8, k + 5, KMOD_Main.KetherGrass);
         world.setBlock(i + 16, j + 8, k + 6, KMOD_Main.KetherGrass);
         world.setBlock(i + 16, j + 8, k + 7, KMOD_Main.KetherGrass);
         world.setBlock(i + 16, j + 8, k + 8, KMOD_Main.KetherGrass);
         world.setBlock(i + 16, j + 8, k + 9, KMOD_Main.KetherGrass);
         world.setBlock(i + 16, j + 8, k + 10, KMOD_Main.KetherGrass);
         world.setBlock(i + 16, j + 8, k + 11, KMOD_Main.KetherGrass);
         world.setBlock(i + 16, j + 8, k + 12, KMOD_Main.KetherGrass);
         world.setBlock(i + 16, j + 8, k + 13, KMOD_Main.KetherGrass);
         world.setBlock(i + 16, j + 8, k + 14, KMOD_Main.KetherGrass);
         world.setBlock(i + 16, j + 8, k + 15, KMOD_Main.KetherGrass);
         world.setBlock(i + 16, j + 8, k + 16, KMOD_Main.KetherGrass);
         world.setBlock(i + 16, j + 8, k + 17, KMOD_Main.KetherGrass);
         world.setBlock(i + 16, j + 8, k + 18, KMOD_Main.KetherGrass);
         world.setBlock(i + 16, j + 8, k + 19, KMOD_Main.KetherGrass);
         world.setBlock(i + 16, j + 8, k + 20, KMOD_Main.KetherGrass);
         world.setBlock(i + 16, j + 10, k + 1, KMOD_Main.KetherGoldenLeaves);
         world.setBlock(i + 16, j + 10, k + 2, KMOD_Main.KetherGoldenLeaves);
         world.setBlock(i + 16, j + 10, k + 3, KMOD_Main.KetherGoldenLeaves);
         world.setBlock(i + 16, j + 11, k + 1, KMOD_Main.KetherGoldenLeaves);
         world.setBlock(i + 16, j + 11, k + 2, KMOD_Main.KetherGoldenLeaves);
         world.setBlock(i + 16, j + 11, k + 3, KMOD_Main.KetherGoldenLeaves);
         world.setBlock(i + 16, j + 11, k + 4, KMOD_Main.KetherGoldenLeaves);
         world.setBlock(i + 16, j + 12, k + 10, KMOD_Main.KetherGoldenLeaves);
         world.setBlock(i + 16, j + 12, k + 11, KMOD_Main.KetherGoldenLeaves);
         world.setBlock(i + 16, j + 12, k + 12, KMOD_Main.KetherGoldenLeaves);
         world.setBlock(i + 16, j + 12, k + 13, KMOD_Main.KetherGoldenLeaves);
         world.setBlock(i + 16, j + 13, k + 11, KMOD_Main.KetherGoldenLeaves);
         world.setBlock(i + 16, j + 13, k + 12, KMOD_Main.KetherGoldenLeaves);
         world.setBlock(i + 16, j + 13, k + 13, KMOD_Main.KetherGoldenLeaves);
         world.setBlock(i + 16, j + 15, k + 4, KMOD_Main.KetherGoldenLeaves);
         world.setBlock(i + 16, j + 15, k + 5, KMOD_Main.KetherGoldenLeaves);
         world.setBlock(i + 16, j + 15, k + 6, KMOD_Main.KetherGoldenLeaves);
         world.setBlock(i + 16, j + 15, k + 7, KMOD_Main.KetherGoldenLeaves);
         world.setBlock(i + 16, j + 15, k + 8, KMOD_Main.KetherGoldenLeaves);
         world.setBlock(i + 16, j + 15, k + 9, KMOD_Main.KetherLog);
         world.setBlock(i + 16, j + 15, k + 10, KMOD_Main.KetherGoldenLeaves);
         world.setBlock(i + 16, j + 15, k + 18, KMOD_Main.KetherGoldenLeaves);
         world.setBlock(i + 16, j + 15, k + 19, KMOD_Main.KetherGoldenLeaves);
         world.setBlock(i + 16, j + 15, k + 20, KMOD_Main.KetherGoldenLeaves);
         world.setBlock(i + 16, j + 15, k + 21, KMOD_Main.KetherGoldenLeaves);
         world.setBlock(i + 16, j + 15, k + 22, KMOD_Main.KetherGoldenLeaves);
         world.setBlock(i + 16, j + 15, k + 23, KMOD_Main.KetherGoldenLeaves);
         world.setBlock(i + 16, j + 16, k + 3, KMOD_Main.KetherGoldenLeaves);
         world.setBlock(i + 16, j + 16, k + 4, KMOD_Main.KetherGoldenLeaves);
         world.setBlock(i + 16, j + 16, k + 5, KMOD_Main.KetherGoldenLeaves);
         world.setBlock(i + 16, j + 16, k + 6, KMOD_Main.KetherGoldenLeaves);
         world.setBlock(i + 16, j + 16, k + 7, KMOD_Main.KetherGoldenLeaves);
         world.setBlock(i + 16, j + 16, k + 8, KMOD_Main.KetherLog);
         world.setBlock(i + 16, j + 16, k + 9, KMOD_Main.KetherGoldenLeaves);
         world.setBlock(i + 16, j + 16, k + 10, KMOD_Main.KetherGoldenLeaves);
         world.setBlock(i + 16, j + 16, k + 17, KMOD_Main.KetherGoldenLeaves);
         world.setBlock(i + 16, j + 16, k + 18, KMOD_Main.KetherGoldenLeaves);
         world.setBlock(i + 16, j + 16, k + 19, KMOD_Main.KetherGoldenLeaves);
         world.setBlock(i + 16, j + 16, k + 20, KMOD_Main.KetherGoldenLeaves);
         world.setBlock(i + 16, j + 16, k + 21, KMOD_Main.KetherGoldenLeaves);
         world.setBlock(i + 16, j + 16, k + 22, KMOD_Main.KetherGoldenLeaves);
         world.setBlock(i + 16, j + 16, k + 23, KMOD_Main.KetherGoldenLeaves);
         world.setBlock(i + 16, j + 16, k + 24, KMOD_Main.KetherGoldenLeaves);
         world.setBlock(i + 16, j + 17, k + 5, KMOD_Main.KetherGoldenLeaves);
         world.setBlock(i + 16, j + 17, k + 6, KMOD_Main.KetherGoldenLeaves);
         world.setBlock(i + 16, j + 17, k + 7, KMOD_Main.KetherGoldenLeaves);
         world.setBlock(i + 16, j + 17, k + 8, KMOD_Main.KetherGoldenLeaves);
         world.setBlock(i + 16, j + 17, k + 19, KMOD_Main.KetherGoldenLeaves);
         world.setBlock(i + 16, j + 17, k + 20, KMOD_Main.KetherGoldenLeaves);
         world.setBlock(i + 16, j + 17, k + 21, KMOD_Main.KetherGoldenLeaves);
         world.setBlock(i + 16, j + 17, k + 22, KMOD_Main.KetherGoldenLeaves);
         world.setBlock(i + 17, j + 5, k + 6, KMOD_Main.KetherStone);
         world.setBlock(i + 17, j + 6, k + 3, KMOD_Main.KetherStone);
         world.setBlock(i + 17, j + 6, k + 5, KMOD_Main.KetherStone);
         world.setBlock(i + 17, j + 6, k + 8, KMOD_Main.KetherStone);
         world.setBlock(i + 17, j + 6, k + 15, KMOD_Main.KetherStone);
         world.setBlock(i + 17, j + 6, k + 18, KMOD_Main.KetherStone);
         world.setBlock(i + 17, j + 6, k + 19, KMOD_Main.KetherStone);
         world.setBlock(i + 17, j + 7, k + 2, KMOD_Main.KetherStone);
         world.setBlock(i + 17, j + 7, k + 3, KMOD_Main.KetherStone);
         world.setBlock(i + 17, j + 7, k + 4, KMOD_Main.KetherStone);
         world.setBlock(i + 17, j + 7, k + 5, KMOD_Main.KetherStone);
         world.setBlock(i + 17, j + 7, k + 6, KMOD_Main.KetherStone);
         world.setBlock(i + 17, j + 7, k + 7, KMOD_Main.KetherStone);
         world.setBlock(i + 17, j + 7, k + 8, KMOD_Main.KetherStone);
         world.setBlock(i + 17, j + 7, k + 9, KMOD_Main.KetherStone);
         world.setBlock(i + 17, j + 7, k + 10, KMOD_Main.KetherStone);
         world.setBlock(i + 17, j + 7, k + 11, KMOD_Main.KetherStone);
         world.setBlock(i + 17, j + 7, k + 12, KMOD_Main.KetherStone);
         world.setBlock(i + 17, j + 7, k + 13, KMOD_Main.KetherStone);
         world.setBlock(i + 17, j + 7, k + 14, KMOD_Main.KetherStone);
         world.setBlock(i + 17, j + 7, k + 15, KMOD_Main.KetherStone);
         world.setBlock(i + 17, j + 7, k + 16, KMOD_Main.KetherStone);
         world.setBlock(i + 17, j + 7, k + 17, KMOD_Main.KetherStone);
         world.setBlock(i + 17, j + 7, k + 18, KMOD_Main.KetherStone);
         world.setBlock(i + 17, j + 7, k + 19, KMOD_Main.KetherStone);
         world.setBlock(i + 17, j + 8, k + 1, KMOD_Main.KetherGrass);
         world.setBlock(i + 17, j + 8, k + 2, KMOD_Main.KetherGrass);
         world.setBlock(i + 17, j + 8, k + 3, KMOD_Main.KetherGrass);
         world.setBlock(i + 17, j + 8, k + 4, KMOD_Main.KetherGrass);
         world.setBlock(i + 17, j + 8, k + 5, KMOD_Main.KetherGrass);
         world.setBlock(i + 17, j + 8, k + 6, KMOD_Main.KetherStone);
         world.setBlock(i + 17, j + 8, k + 7, KMOD_Main.KetherStone);
         world.setBlock(i + 17, j + 8, k + 8, KMOD_Main.KetherGrass);
         world.setBlock(i + 17, j + 8, k + 9, KMOD_Main.KetherGrass);
         world.setBlock(i + 17, j + 8, k + 10, KMOD_Main.KetherGrass);
         world.setBlock(i + 17, j + 8, k + 11, KMOD_Main.KetherGrass);
         world.setBlock(i + 17, j + 8, k + 12, KMOD_Main.KetherGrass);
         world.setBlock(i + 17, j + 8, k + 13, KMOD_Main.KetherGrass);
         world.setBlock(i + 17, j + 8, k + 14, KMOD_Main.KetherGrass);
         world.setBlock(i + 17, j + 8, k + 15, KMOD_Main.KetherGrass);
         world.setBlock(i + 17, j + 8, k + 16, KMOD_Main.KetherGrass);
         world.setBlock(i + 17, j + 8, k + 17, KMOD_Main.KetherGrass);
         world.setBlock(i + 17, j + 8, k + 18, KMOD_Main.KetherStone);
         world.setBlock(i + 17, j + 8, k + 19, KMOD_Main.KetherStone);
         world.setBlock(i + 17, j + 8, k + 20, KMOD_Main.KetherGrass);
         world.setBlock(i + 17, j + 9, k + 6, KMOD_Main.KetherLog);
         world.setBlock(i + 17, j + 9, k + 7, KMOD_Main.KetherLog);
         world.setBlock(i + 17, j + 9, k + 18, KMOD_Main.KetherLog);
         world.setBlock(i + 17, j + 9, k + 19, KMOD_Main.KetherLog);
         world.setBlock(i + 17, j + 10, k + 6, KMOD_Main.KetherLog);
         world.setBlock(i + 17, j + 10, k + 7, KMOD_Main.KetherLog);
         world.setBlock(i + 17, j + 10, k + 18, KMOD_Main.KetherLog);
         world.setBlock(i + 17, j + 10, k + 19, KMOD_Main.KetherLog);
         world.setBlock(i + 17, j + 11, k + 6, KMOD_Main.KetherLog);
         world.setBlock(i + 17, j + 11, k + 7, KMOD_Main.KetherLog);
         world.setBlock(i + 17, j + 11, k + 18, KMOD_Main.KetherLog);
         world.setBlock(i + 17, j + 11, k + 19, KMOD_Main.KetherLog);
         world.setBlock(i + 17, j + 12, k + 6, KMOD_Main.KetherLog);
         world.setBlock(i + 17, j + 12, k + 7, KMOD_Main.KetherLog);
         world.setBlock(i + 17, j + 12, k + 10, KMOD_Main.KetherGoldenLeaves);
         world.setBlock(i + 17, j + 12, k + 11, KMOD_Main.KetherGoldenLeaves);
         world.setBlock(i + 17, j + 12, k + 12, KMOD_Main.KetherGoldenLeaves);
         world.setBlock(i + 17, j + 12, k + 13, KMOD_Main.KetherGoldenLeaves);
         world.setBlock(i + 17, j + 12, k + 14, KMOD_Main.KetherGoldenLeaves);
         world.setBlock(i + 17, j + 12, k + 18, KMOD_Main.KetherLog);
         world.setBlock(i + 17, j + 12, k + 19, KMOD_Main.KetherLog);
         world.setBlock(i + 17, j + 13, k + 6, KMOD_Main.KetherLog);
         world.setBlock(i + 17, j + 13, k + 7, KMOD_Main.KetherLog);
         world.setBlock(i + 17, j + 13, k + 8, KMOD_Main.KetherLog);
         world.setBlock(i + 17, j + 13, k + 10, KMOD_Main.KetherGoldenLeaves);
         world.setBlock(i + 17, j + 13, k + 11, KMOD_Main.KetherGoldenLeaves);
         world.setBlock(i + 17, j + 13, k + 12, KMOD_Main.KetherGoldenLeaves);
         world.setBlock(i + 17, j + 13, k + 13, KMOD_Main.KetherGoldenLeaves);
         world.setBlock(i + 17, j + 13, k + 14, KMOD_Main.KetherGoldenLeaves);
         world.setBlock(i + 17, j + 13, k + 18, KMOD_Main.KetherLog);
         world.setBlock(i + 17, j + 13, k + 19, KMOD_Main.KetherLog);
         world.setBlock(i + 17, j + 14, k + 6, KMOD_Main.KetherLog);
         world.setBlock(i + 17, j + 14, k + 7, KMOD_Main.KetherLog);
         world.setBlock(i + 17, j + 14, k + 8, KMOD_Main.KetherLog);
         world.setBlock(i + 17, j + 14, k + 12, KMOD_Main.KetherGoldenLeaves);
         world.setBlock(i + 17, j + 14, k + 13, KMOD_Main.KetherGoldenLeaves);
         world.setBlock(i + 17, j + 14, k + 18, KMOD_Main.KetherLog);
         world.setBlock(i + 17, j + 14, k + 19, KMOD_Main.KetherLog);
         world.setBlock(i + 17, j + 15, k + 3, KMOD_Main.KetherGoldenLeaves);
         world.setBlock(i + 17, j + 15, k + 4, KMOD_Main.KetherGoldenLeaves);
         world.setBlock(i + 17, j + 15, k + 5, KMOD_Main.KetherLog);
         world.setBlock(i + 17, j + 15, k + 6, KMOD_Main.KetherLog);
         world.setBlock(i + 17, j + 15, k + 7, KMOD_Main.KetherLog);
         world.setBlock(i + 17, j + 15, k + 8, KMOD_Main.KetherLog);
         world.setBlock(i + 17, j + 15, k + 9, KMOD_Main.KetherLog);
         world.setBlock(i + 17, j + 15, k + 10, KMOD_Main.KetherGoldenLeaves);
         world.setBlock(i + 17, j + 15, k + 12, KMOD_Main.KetherGoldenLeaves);
         world.setBlock(i + 17, j + 15, k + 18, KMOD_Main.KetherGoldenLeaves);
         world.setBlock(i + 17, j + 15, k + 19, KMOD_Main.KetherLog);
         world.setBlock(i + 17, j + 15, k + 20, KMOD_Main.KetherLog);
         world.setBlock(i + 17, j + 15, k + 21, KMOD_Main.KetherGoldenLeaves);
         world.setBlock(i + 17, j + 15, k + 22, KMOD_Main.KetherGoldenLeaves);
         world.setBlock(i + 17, j + 15, k + 23, KMOD_Main.KetherGoldenLeaves);
         world.setBlock(i + 17, j + 16, k + 3, KMOD_Main.KetherGoldenLeaves);
         world.setBlock(i + 17, j + 16, k + 4, KMOD_Main.KetherLog);
         world.setBlock(i + 17, j + 16, k + 5, KMOD_Main.KetherLog);
         world.setBlock(i + 17, j + 16, k + 6, KMOD_Main.KetherLog);
         world.setBlock(i + 17, j + 16, k + 7, KMOD_Main.KetherLog);
         world.setBlock(i + 17, j + 16, k + 8, KMOD_Main.KetherGoldenLeaves);
         world.setBlock(i + 17, j + 16, k + 9, KMOD_Main.KetherGoldenLeaves);
         world.setBlock(i + 17, j + 16, k + 10, KMOD_Main.KetherGoldenLeaves);
         world.setBlock(i + 17, j + 16, k + 17, KMOD_Main.KetherGoldenLeaves);
         world.setBlock(i + 17, j + 16, k + 18, KMOD_Main.KetherGoldenLeaves);
         world.setBlock(i + 17, j + 16, k + 19, KMOD_Main.KetherGoldenLeaves);
         world.setBlock(i + 17, j + 16, k + 20, KMOD_Main.KetherLog);
         world.setBlock(i + 17, j + 16, k + 21, KMOD_Main.KetherLog);
         world.setBlock(i + 17, j + 16, k + 22, KMOD_Main.KetherGoldenLeaves);
         world.setBlock(i + 17, j + 16, k + 23, KMOD_Main.KetherGoldenLeaves);
         world.setBlock(i + 17, j + 16, k + 24, KMOD_Main.KetherGoldenLeaves);
         world.setBlock(i + 17, j + 17, k + 4, KMOD_Main.KetherGoldenLeaves);
         world.setBlock(i + 17, j + 17, k + 5, KMOD_Main.KetherGoldenLeaves);
         world.setBlock(i + 17, j + 17, k + 6, KMOD_Main.KetherGoldenLeaves);
         world.setBlock(i + 17, j + 17, k + 7, KMOD_Main.KetherGoldenLeaves);
         world.setBlock(i + 17, j + 17, k + 8, KMOD_Main.KetherGoldenLeaves);
         world.setBlock(i + 17, j + 17, k + 9, KMOD_Main.KetherGoldenLeaves);
         world.setBlock(i + 17, j + 17, k + 18, KMOD_Main.KetherGoldenLeaves);
         world.setBlock(i + 17, j + 17, k + 19, KMOD_Main.KetherGoldenLeaves);
         world.setBlock(i + 17, j + 17, k + 20, KMOD_Main.KetherGoldenLeaves);
         world.setBlock(i + 17, j + 17, k + 21, KMOD_Main.KetherGoldenLeaves);
         world.setBlock(i + 17, j + 17, k + 22, KMOD_Main.KetherGoldenLeaves);
         world.setBlock(i + 17, j + 17, k + 23, KMOD_Main.KetherGoldenLeaves);
         world.setBlock(i + 17, j + 18, k + 6, KMOD_Main.KetherGoldenLeaves);
         world.setBlock(i + 17, j + 18, k + 7, KMOD_Main.KetherGoldenLeaves);
         world.setBlock(i + 17, j + 18, k + 20, KMOD_Main.KetherGoldenLeaves);
         world.setBlock(i + 17, j + 18, k + 21, KMOD_Main.KetherGoldenLeaves);
         world.setBlock(i + 18, j + 5, k + 17, KMOD_Main.KetherStone);
         world.setBlock(i + 18, j + 6, k + 4, KMOD_Main.KetherStone);
         world.setBlock(i + 18, j + 6, k + 6, KMOD_Main.KetherStone);
         world.setBlock(i + 18, j + 6, k + 12, KMOD_Main.KetherStone);
         world.setBlock(i + 18, j + 6, k + 13, KMOD_Main.KetherStone);
         world.setBlock(i + 18, j + 6, k + 17, KMOD_Main.KetherStone);
         world.setBlock(i + 18, j + 7, k + 2, KMOD_Main.KetherStone);
         world.setBlock(i + 18, j + 7, k + 3, KMOD_Main.KetherStone);
         world.setBlock(i + 18, j + 7, k + 4, KMOD_Main.KetherStone);
         world.setBlock(i + 18, j + 7, k + 5, KMOD_Main.KetherStone);
         world.setBlock(i + 18, j + 7, k + 6, KMOD_Main.KetherStone);
         world.setBlock(i + 18, j + 7, k + 7, KMOD_Main.KetherStone);
         world.setBlock(i + 18, j + 7, k + 8, KMOD_Main.KetherStone);
         world.setBlock(i + 18, j + 7, k + 9, KMOD_Main.KetherStone);
         world.setBlock(i + 18, j + 7, k + 10, KMOD_Main.KetherStone);
         world.setBlock(i + 18, j + 7, k + 11, KMOD_Main.KetherStone);
         world.setBlock(i + 18, j + 7, k + 12, KMOD_Main.KetherStone);
         world.setBlock(i + 18, j + 7, k + 13, KMOD_Main.KetherStone);
         world.setBlock(i + 18, j + 7, k + 14, KMOD_Main.KetherStone);
         world.setBlock(i + 18, j + 7, k + 15, KMOD_Main.KetherStone);
         world.setBlock(i + 18, j + 7, k + 16, KMOD_Main.KetherStone);
         world.setBlock(i + 18, j + 7, k + 17, KMOD_Main.KetherStone);
         world.setBlock(i + 18, j + 7, k + 18, KMOD_Main.KetherStone);
         world.setBlock(i + 18, j + 7, k + 19, KMOD_Main.KetherStone);
         world.setBlock(i + 18, j + 8, k + 1, KMOD_Main.KetherGrass);
         world.setBlock(i + 18, j + 8, k + 2, KMOD_Main.KetherGrass);
         world.setBlock(i + 18, j + 8, k + 3, KMOD_Main.KetherGrass);
         world.setBlock(i + 18, j + 8, k + 4, KMOD_Main.KetherGrass);
         world.setBlock(i + 18, j + 8, k + 5, KMOD_Main.KetherGrass);
         world.setBlock(i + 18, j + 8, k + 6, KMOD_Main.KetherStone);
         world.setBlock(i + 18, j + 8, k + 7, KMOD_Main.KetherStone);
         world.setBlock(i + 18, j + 8, k + 8, KMOD_Main.KetherGrass);
         world.setBlock(i + 18, j + 8, k + 9, KMOD_Main.KetherGrass);
         world.setBlock(i + 18, j + 8, k + 10, KMOD_Main.KetherGrass);
         world.setBlock(i + 18, j + 8, k + 11, KMOD_Main.KetherGrass);
         world.setBlock(i + 18, j + 8, k + 12, KMOD_Main.KetherStone);
         world.setBlock(i + 18, j + 8, k + 13, KMOD_Main.KetherGrass);
         world.setBlock(i + 18, j + 8, k + 14, KMOD_Main.KetherGrass);
         world.setBlock(i + 18, j + 8, k + 15, KMOD_Main.KetherGrass);
         world.setBlock(i + 18, j + 8, k + 16, KMOD_Main.KetherGrass);
         world.setBlock(i + 18, j + 8, k + 17, KMOD_Main.KetherGrass);
         world.setBlock(i + 18, j + 8, k + 18, KMOD_Main.KetherStone);
         world.setBlock(i + 18, j + 8, k + 19, KMOD_Main.KetherStone);
         world.setBlock(i + 18, j + 8, k + 20, KMOD_Main.KetherGrass);
         world.setBlock(i + 18, j + 9, k + 6, KMOD_Main.KetherLog);
         world.setBlock(i + 18, j + 9, k + 7, KMOD_Main.KetherLog);
         world.setBlock(i + 18, j + 9, k + 12, KMOD_Main.KetherLog);
         world.setBlock(i + 18, j + 9, k + 18, KMOD_Main.KetherLog);
         world.setBlock(i + 18, j + 9, k + 19, KMOD_Main.KetherLog);
         world.setBlock(i + 18, j + 10, k + 6, KMOD_Main.KetherLog);
         world.setBlock(i + 18, j + 10, k + 7, KMOD_Main.KetherLog);
