package fr.keter.KMOD.WorldGens;

import fr.keter.KMOD.Main.KMOD_Main;
import java.util.Random;
import net.minecraft.world.World;
import net.minecraft.world.gen.feature.WorldGenerator;

public class KetherGenLifeTree extends WorldGenerator {
   public boolean LocationIsValidSpawn(World world, int i, int j, int k) {
      return world.isAirBlock(i, j, k);
   }

   public boolean generate(World world, Random rand, int i, int j, int k) {
      if (this.LocationIsValidSpawn(world, i, j, k) && this.LocationIsValidSpawn(world, i + 22, j, k) && this.LocationIsValidSpawn(world, i + 22, j, k + 22) && this.LocationIsValidSpawn(world, i, j, k + 22)) {
         world.setBlock(i + 0, j + 2, k + 3, KMOD_Main.KetherCloud);
         world.setBlock(i + 0, j + 2, k + 16, KMOD_Main.KetherCloud);
         world.setBlock(i + 0, j + 2, k + 20, KMOD_Main.KetherCloud);
         world.setBlock(i + 0, j + 3, k + 3, KMOD_Main.KetherCloud);
         world.setBlock(i + 0, j + 3, k + 16, KMOD_Main.KetherCloud);
         world.setBlock(i + 0, j + 3, k + 20, KMOD_Main.KetherCloud);
         world.setBlock(i + 1, j + 2, k + 2, KMOD_Main.KetherCloud);
         world.setBlock(i + 1, j + 2, k + 3, KMOD_Main.KetherCloud);
         world.setBlock(i + 1, j + 2, k + 4, KMOD_Main.KetherCloud);
         world.setBlock(i + 1, j + 2, k + 15, KMOD_Main.KetherCloud);
         world.setBlock(i + 1, j + 2, k + 16, KMOD_Main.KetherCloud);
         world.setBlock(i + 1, j + 2, k + 17, KMOD_Main.KetherCloud);
         world.setBlock(i + 1, j + 2, k + 19, KMOD_Main.KetherCloud);
         world.setBlock(i + 1, j + 2, k + 20, KMOD_Main.KetherCloud);
         world.setBlock(i + 1, j + 2, k + 21, KMOD_Main.KetherCloud);
         world.setBlock(i + 1, j + 3, k + 2, KMOD_Main.KetherCloud);
         world.setBlock(i + 1, j + 3, k + 3, KMOD_Main.KetherCloud);
         world.setBlock(i + 1, j + 3, k + 4, KMOD_Main.KetherCloud);
         world.setBlock(i + 1, j + 3, k + 15, KMOD_Main.KetherCloud);
         world.setBlock(i + 1, j + 3, k + 16, KMOD_Main.KetherCloud);
         world.setBlock(i + 1, j + 3, k + 17, KMOD_Main.KetherCloud);
         world.setBlock(i + 1, j + 3, k + 19, KMOD_Main.KetherCloud);
         world.setBlock(i + 1, j + 3, k + 20, KMOD_Main.KetherCloud);
         world.setBlock(i + 1, j + 3, k + 21, KMOD_Main.KetherCloud);
         world.setBlock(i + 2, j + 2, k + 1, KMOD_Main.KetherCloud);
         world.setBlock(i + 2, j + 2, k + 2, KMOD_Main.KetherCloud);
         world.setBlock(i + 2, j + 2, k + 3, KMOD_Main.KetherCloud);
         world.setBlock(i + 2, j + 2, k + 4, KMOD_Main.KetherCloud);
         world.setBlock(i + 2, j + 2, k + 5, KMOD_Main.KetherCloud);
         world.setBlock(i + 2, j + 2, k + 13, KMOD_Main.KetherCloud);
         world.setBlock(i + 2, j + 2, k + 14, KMOD_Main.KetherCloud);
         world.setBlock(i + 2, j + 2, k + 15, KMOD_Main.KetherCloud);
         world.setBlock(i + 2, j + 2, k + 16, KMOD_Main.KetherCloud);
         world.setBlock(i + 2, j + 2, k + 17, KMOD_Main.KetherCloud);
         world.setBlock(i + 2, j + 2, k + 18, KMOD_Main.KetherCloud);
         world.setBlock(i + 2, j + 2, k + 19, KMOD_Main.KetherCloud);
         world.setBlock(i + 2, j + 2, k + 20, KMOD_Main.KetherCloud);
         world.setBlock(i + 2, j + 2, k + 21, KMOD_Main.KetherCloud);
         world.setBlock(i + 2, j + 2, k + 22, KMOD_Main.KetherCloud);
         world.setBlock(i + 2, j + 3, k + 1, KMOD_Main.KetherCloud);
         world.setBlock(i + 2, j + 3, k + 2, KMOD_Main.KetherCloud);
         world.setBlock(i + 2, j + 3, k + 3, KMOD_Main.KetherCloud);
         world.setBlock(i + 2, j + 3, k + 4, KMOD_Main.KetherCloud);
         world.setBlock(i + 2, j + 3, k + 5, KMOD_Main.KetherCloud);
         world.setBlock(i + 2, j + 3, k + 13, KMOD_Main.KetherCloud);
         world.setBlock(i + 2, j + 3, k + 14, KMOD_Main.KetherCloud);
         world.setBlock(i + 2, j + 3, k + 15, KMOD_Main.KetherCloud);
         world.setBlock(i + 2, j + 3, k + 16, KMOD_Main.KetherCloud);
         world.setBlock(i + 2, j + 3, k + 17, KMOD_Main.KetherCloud);
         world.setBlock(i + 2, j + 3, k + 18, KMOD_Main.KetherCloud);
         world.setBlock(i + 2, j + 3, k + 19, KMOD_Main.KetherCloud);
         world.setBlock(i + 2, j + 3, k + 20, KMOD_Main.KetherCloud);
         world.setBlock(i + 2, j + 3, k + 21, KMOD_Main.KetherCloud);
         world.setBlock(i + 2, j + 3, k + 22, KMOD_Main.KetherCloud);
         world.setBlock(i + 3, j + 1, k + 9, KMOD_Main.KetherCloud);
         world.setBlock(i + 3, j + 2, k + 1, KMOD_Main.KetherCloud);
         world.setBlock(i + 3, j + 2, k + 2, KMOD_Main.KetherCloud);
         world.setBlock(i + 3, j + 2, k + 3, KMOD_Main.KetherCloud);
         world.setBlock(i + 3, j + 2, k + 4, KMOD_Main.KetherCloud);
         world.setBlock(i + 3, j + 2, k + 5, KMOD_Main.KetherCloud);
         world.setBlock(i + 3, j + 2, k + 9, KMOD_Main.KetherCloud);
         world.setBlock(i + 3, j + 2, k + 12, KMOD_Main.KetherCloud);
         world.setBlock(i + 3, j + 2, k + 13, KMOD_Main.KetherCloud);
         world.setBlock(i + 3, j + 2, k + 14, KMOD_Main.KetherCloud);
         world.setBlock(i + 3, j + 2, k + 15, KMOD_Main.KetherCloud);
         world.setBlock(i + 3, j + 2, k + 16, KMOD_Main.KetherCloud);
         world.setBlock(i + 3, j + 2, k + 17, KMOD_Main.KetherCloud);
         world.setBlock(i + 3, j + 2, k + 18, KMOD_Main.KetherCloud);
         world.setBlock(i + 3, j + 2, k + 19, KMOD_Main.KetherCloud);
         world.setBlock(i + 3, j + 2, k + 20, KMOD_Main.KetherCloud);
         world.setBlock(i + 3, j + 2, k + 21, KMOD_Main.KetherCloud);
         world.setBlock(i + 3, j + 2, k + 22, KMOD_Main.KetherCloud);
         world.setBlock(i + 3, j + 3, k + 1, KMOD_Main.KetherCloud);
         world.setBlock(i + 3, j + 3, k + 2, KMOD_Main.KetherCloud);
         world.setBlock(i + 3, j + 3, k + 3, KMOD_Main.KetherCloud);
         world.setBlock(i + 3, j + 3, k + 4, KMOD_Main.KetherCloud);
         world.setBlock(i + 3, j + 3, k + 5, KMOD_Main.KetherCloud);
         world.setBlock(i + 3, j + 3, k + 12, KMOD_Main.KetherCloud);
         world.setBlock(i + 3, j + 3, k + 13, KMOD_Main.KetherCloud);
         world.setBlock(i + 3, j + 3, k + 14, KMOD_Main.KetherCloud);
         world.setBlock(i + 3, j + 3, k + 15, KMOD_Main.KetherCloud);
         world.setBlock(i + 3, j + 3, k + 16, KMOD_Main.KetherCloud);
         world.setBlock(i + 3, j + 3, k + 17, KMOD_Main.KetherCloud);
         world.setBlock(i + 3, j + 3, k + 18, KMOD_Main.KetherCloud);
         world.setBlock(i + 3, j + 3, k + 19, KMOD_Main.KetherCloud);
         world.setBlock(i + 3, j + 3, k + 20, KMOD_Main.KetherCloud);
         world.setBlock(i + 3, j + 3, k + 21, KMOD_Main.KetherCloud);
         world.setBlock(i + 3, j + 3, k + 22, KMOD_Main.KetherCloud);
         world.setBlock(i + 3, j + 4, k + 3, KMOD_Main.LifeLog);
         world.setBlock(i + 3, j + 4, k + 4, KMOD_Main.LifeLog);
         world.setBlock(i + 3, j + 4, k + 16, KMOD_Main.LifeLog);
         world.setBlock(i + 3, j + 4, k + 20, KMOD_Main.LifeLog);
         world.setBlock(i + 3, j + 28, k + 12, KMOD_Main.LifeLeaves);
         world.setBlock(i + 4, j + 1, k + 6, KMOD_Main.KetherCloud);
         world.setBlock(i + 4, j + 1, k + 8, KMOD_Main.KetherCloud);
         world.setBlock(i + 4, j + 1, k + 9, KMOD_Main.KetherCloud);
         world.setBlock(i + 4, j + 1, k + 10, KMOD_Main.KetherCloud);
         world.setBlock(i + 4, j + 2, k + 2, KMOD_Main.KetherCloud);
         world.setBlock(i + 4, j + 2, k + 3, KMOD_Main.KetherCloud);
         world.setBlock(i + 4, j + 2, k + 4, KMOD_Main.KetherCloud);
         world.setBlock(i + 4, j + 2, k + 5, KMOD_Main.KetherCloud);
         world.setBlock(i + 4, j + 2, k + 6, KMOD_Main.KetherCloud);
         world.setBlock(i + 4, j + 2, k + 8, KMOD_Main.KetherCloud);
         world.setBlock(i + 4, j + 2, k + 9, KMOD_Main.KetherCloud);
         world.setBlock(i + 4, j + 2, k + 10, KMOD_Main.KetherCloud);
         world.setBlock(i + 4, j + 2, k + 11, KMOD_Main.KetherCloud);
         world.setBlock(i + 4, j + 2, k + 12, KMOD_Main.KetherCloud);
         world.setBlock(i + 4, j + 2, k + 13, KMOD_Main.KetherCloud);
         world.setBlock(i + 4, j + 2, k + 14, KMOD_Main.KetherCloud);
         world.setBlock(i + 4, j + 2, k + 15, KMOD_Main.KetherCloud);
         world.setBlock(i + 4, j + 2, k + 16, KMOD_Main.KetherCloud);
         world.setBlock(i + 4, j + 2, k + 17, KMOD_Main.KetherCloud);
         world.setBlock(i + 4, j + 2, k + 18, KMOD_Main.KetherCloud);
         world.setBlock(i + 4, j + 2, k + 19, KMOD_Main.KetherCloud);
         world.setBlock(i + 4, j + 2, k + 20, KMOD_Main.KetherCloud);
         world.setBlock(i + 4, j + 2, k + 21, KMOD_Main.KetherCloud);
         world.setBlock(i + 4, j + 3, k + 2, KMOD_Main.KetherCloud);
         world.setBlock(i + 4, j + 3, k + 3, KMOD_Main.KetherCloud);
         world.setBlock(i + 4, j + 3, k + 4, KMOD_Main.KetherCloud);
         world.setBlock(i + 4, j + 3, k + 5, KMOD_Main.KetherCloud);
         world.setBlock(i + 4, j + 3, k + 11, KMOD_Main.KetherCloud);
         world.setBlock(i + 4, j + 3, k + 12, KMOD_Main.KetherCloud);
         world.setBlock(i + 4, j + 3, k + 13, KMOD_Main.KetherCloud);
         world.setBlock(i + 4, j + 3, k + 14, KMOD_Main.KetherCloud);
         world.setBlock(i + 4, j + 3, k + 15, KMOD_Main.KetherCloud);
         world.setBlock(i + 4, j + 3, k + 16, KMOD_Main.KetherCloud);
         world.setBlock(i + 4, j + 3, k + 17, KMOD_Main.KetherCloud);
         world.setBlock(i + 4, j + 3, k + 18, KMOD_Main.KetherCloud);
         world.setBlock(i + 4, j + 3, k + 19, KMOD_Main.KetherCloud);
         world.setBlock(i + 4, j + 3, k + 20, KMOD_Main.KetherCloud);
         world.setBlock(i + 4, j + 3, k + 21, KMOD_Main.KetherCloud);
         world.setBlock(i + 4, j + 4, k + 3, KMOD_Main.LifeLog);
         world.setBlock(i + 4, j + 4, k + 4, KMOD_Main.LifeLog);
         world.setBlock(i + 4, j + 4, k + 5, KMOD_Main.LifeLog);
         world.setBlock(i + 4, j + 4, k + 16, KMOD_Main.LifeLog);
         world.setBlock(i + 4, j + 4, k + 17, KMOD_Main.LifeLog);
         world.setBlock(i + 4, j + 4, k + 18, KMOD_Main.LifeLog);
         world.setBlock(i + 4, j + 4, k + 19, KMOD_Main.LifeLog);
         world.setBlock(i + 4, j + 28, k + 12, KMOD_Main.LifeLeaves);
         world.setBlock(i + 4, j + 29, k + 9, KMOD_Main.LifeLeaves);
         world.setBlock(i + 4, j + 29, k + 10, KMOD_Main.LifeLeaves);
         world.setBlock(i + 4, j + 29, k + 11, KMOD_Main.LifeLeaves);
         world.setBlock(i + 4, j + 30, k + 12, KMOD_Main.LifeLeaves);
         world.setBlock(i + 4, j + 31, k + 11, KMOD_Main.LifeLeaves);
         world.setBlock(i + 5, j + 1, k + 5, KMOD_Main.KetherCloud);
         world.setBlock(i + 5, j + 1, k + 6, KMOD_Main.KetherCloud);
         world.setBlock(i + 5, j + 1, k + 7, KMOD_Main.KetherCloud);
         world.setBlock(i + 5, j + 1, k + 8, KMOD_Main.KetherCloud);
         world.setBlock(i + 5, j + 1, k + 9, KMOD_Main.KetherCloud);
         world.setBlock(i + 5, j + 1, k + 10, KMOD_Main.KetherCloud);
         world.setBlock(i + 5, j + 1, k + 11, KMOD_Main.KetherCloud);
         world.setBlock(i + 5, j + 2, k + 2, KMOD_Main.KetherCloud);
         world.setBlock(i + 5, j + 2, k + 3, KMOD_Main.KetherCloud);
         world.setBlock(i + 5, j + 2, k + 4, KMOD_Main.KetherCloud);
         world.setBlock(i + 5, j + 2, k + 5, KMOD_Main.KetherCloud);
         world.setBlock(i + 5, j + 2, k + 6, KMOD_Main.KetherCloud);
         world.setBlock(i + 5, j + 2, k + 7, KMOD_Main.KetherCloud);
         world.setBlock(i + 5, j + 2, k + 8, KMOD_Main.KetherCloud);
         world.setBlock(i + 5, j + 2, k + 9, KMOD_Main.KetherCloud);
         world.setBlock(i + 5, j + 2, k + 10, KMOD_Main.KetherCloud);
         world.setBlock(i + 5, j + 2, k + 11, KMOD_Main.KetherCloud);
         world.setBlock(i + 5, j + 2, k + 12, KMOD_Main.KetherCloud);
         world.setBlock(i + 5, j + 2, k + 13, KMOD_Main.KetherCloud);
         world.setBlock(i + 5, j + 2, k + 14, KMOD_Main.KetherCloud);
         world.setBlock(i + 5, j + 2, k + 15, KMOD_Main.KetherCloud);
         world.setBlock(i + 5, j + 2, k + 16, KMOD_Main.KetherCloud);
         world.setBlock(i + 5, j + 2, k + 17, KMOD_Main.KetherCloud);
         world.setBlock(i + 5, j + 2, k + 18, KMOD_Main.KetherCloud);
         world.setBlock(i + 5, j + 2, k + 19, KMOD_Main.KetherCloud);
         world.setBlock(i + 5, j + 2, k + 20, KMOD_Main.KetherCloud);
         world.setBlock(i + 5, j + 2, k + 21, KMOD_Main.KetherCloud);
         world.setBlock(i + 5, j + 3, k + 2, KMOD_Main.KetherCloud);
         world.setBlock(i + 5, j + 3, k + 3, KMOD_Main.KetherCloud);
         world.setBlock(i + 5, j + 3, k + 4, KMOD_Main.KetherCloud);
         world.setBlock(i + 5, j + 3, k + 5, KMOD_Main.KetherCloud);
         world.setBlock(i + 5, j + 3, k + 6, KMOD_Main.KetherCloud);
         world.setBlock(i + 5, j + 3, k + 11, KMOD_Main.KetherCloud);
         world.setBlock(i + 5, j + 3, k + 12, KMOD_Main.KetherCloud);
         world.setBlock(i + 5, j + 3, k + 13, KMOD_Main.KetherCloud);
         world.setBlock(i + 5, j + 3, k + 14, KMOD_Main.KetherCloud);
         world.setBlock(i + 5, j + 3, k + 15, KMOD_Main.KetherCloud);
         world.setBlock(i + 5, j + 3, k + 16, KMOD_Main.KetherCloud);
         world.setBlock(i + 5, j + 3, k + 17, KMOD_Main.KetherCloud);
         world.setBlock(i + 5, j + 3, k + 18, KMOD_Main.KetherCloud);
         world.setBlock(i + 5, j + 3, k + 19, KMOD_Main.KetherCloud);
         world.setBlock(i + 5, j + 3, k + 20, KMOD_Main.KetherCloud);
         world.setBlock(i + 5, j + 3, k + 21, KMOD_Main.KetherCloud);
         world.setBlock(i + 5, j + 4, k + 5, KMOD_Main.LifeLog);
         world.setBlock(i + 5, j + 4, k + 6, KMOD_Main.LifeLog);
         world.setBlock(i + 5, j + 4, k + 16, KMOD_Main.LifeLog);
         world.setBlock(i + 5, j + 4, k + 17, KMOD_Main.LifeLog);
         world.setBlock(i + 5, j + 4, k + 18, KMOD_Main.LifeLog);
         world.setBlock(i + 5, j + 27, k + 10, KMOD_Main.LifeLeaves);
         world.setBlock(i + 5, j + 27, k + 12, KMOD_Main.LifeLeaves);
         world.setBlock(i + 5, j + 27, k + 13, KMOD_Main.LifeLeaves);
         world.setBlock(i + 5, j + 27, k + 15, KMOD_Main.LifeLeaves);
         world.setBlock(i + 5, j + 28, k + 7, KMOD_Main.LifeLeaves);
         world.setBlock(i + 5, j + 28, k + 8, KMOD_Main.LifeLeaves);
         world.setBlock(i + 5, j + 28, k + 12, KMOD_Main.LifeLeaves);
         world.setBlock(i + 5, j + 28, k + 13, KMOD_Main.LifeLeaves);
         world.setBlock(i + 5, j + 29, k + 8, KMOD_Main.LifeLeaves);
         world.setBlock(i + 5, j + 29, k + 10, KMOD_Main.LifeLeaves);
         world.setBlock(i + 5, j + 29, k + 11, KMOD_Main.LifeLeaves);
         world.setBlock(i + 5, j + 29, k + 12, KMOD_Main.LifeLeaves);
         world.setBlock(i + 5, j + 29, k + 13, KMOD_Main.LifeLeaves);
         world.setBlock(i + 5, j + 30, k + 10, KMOD_Main.LifeLeaves);
         world.setBlock(i + 5, j + 30, k + 11, KMOD_Main.LifeLeaves);
         world.setBlock(i + 5, j + 30, k + 12, KMOD_Main.LifeLeaves);
         world.setBlock(i + 5, j + 30, k + 13, KMOD_Main.LifeLeaves);
         world.setBlock(i + 5, j + 31, k + 9, KMOD_Main.LifeLeaves);
         world.setBlock(i + 5, j + 31, k + 10, KMOD_Main.LifeLeaves);
         world.setBlock(i + 5, j + 31, k + 11, KMOD_Main.LifeLeaves);
         world.setBlock(i + 5, j + 31, k + 12, KMOD_Main.LifeLeaves);
         world.setBlock(i + 5, j + 32, k + 9, KMOD_Main.LifeLeaves);
         world.setBlock(i + 5, j + 32, k + 12, KMOD_Main.LifeLeaves);
         world.setBlock(i + 6, j + 1, k + 4, KMOD_Main.KetherCloud);
         world.setBlock(i + 6, j + 1, k + 5, KMOD_Main.KetherCloud);
         world.setBlock(i + 6, j + 1, k + 6, KMOD_Main.KetherCloud);
         world.setBlock(i + 6, j + 1, k + 7, KMOD_Main.KetherCloud);
         world.setBlock(i + 6, j + 1, k + 8, KMOD_Main.KetherCloud);
         world.setBlock(i + 6, j + 1, k + 9, KMOD_Main.KetherCloud);
         world.setBlock(i + 6, j + 1, k + 10, KMOD_Main.KetherCloud);
         world.setBlock(i + 6, j + 1, k + 11, KMOD_Main.KetherCloud);
         world.setBlock(i + 6, j + 2, k + 2, KMOD_Main.KetherCloud);
         world.setBlock(i + 6, j + 2, k + 3, KMOD_Main.KetherCloud);
         world.setBlock(i + 6, j + 2, k + 4, KMOD_Main.KetherCloud);
         world.setBlock(i + 6, j + 2, k + 5, KMOD_Main.KetherCloud);
         world.setBlock(i + 6, j + 2, k + 6, KMOD_Main.KetherCloud);
         world.setBlock(i + 6, j + 2, k + 7, KMOD_Main.KetherCloud);
         world.setBlock(i + 6, j + 2, k + 8, KMOD_Main.KetherCloud);
         world.setBlock(i + 6, j + 2, k + 9, KMOD_Main.KetherCloud);
         world.setBlock(i + 6, j + 2, k + 10, KMOD_Main.KetherCloud);
         world.setBlock(i + 6, j + 2, k + 11, KMOD_Main.KetherCloud);
         world.setBlock(i + 6, j + 2, k + 12, KMOD_Main.KetherCloud);
         world.setBlock(i + 6, j + 2, k + 13, KMOD_Main.KetherCloud);
         world.setBlock(i + 6, j + 2, k + 14, KMOD_Main.KetherCloud);
         world.setBlock(i + 6, j + 2, k + 15, KMOD_Main.KetherCloud);
         world.setBlock(i + 6, j + 2, k + 16, KMOD_Main.KetherCloud);
         world.setBlock(i + 6, j + 2, k + 17, KMOD_Main.KetherCloud);
         world.setBlock(i + 6, j + 2, k + 18, KMOD_Main.KetherCloud);
         world.setBlock(i + 6, j + 2, k + 19, KMOD_Main.KetherCloud);
         world.setBlock(i + 6, j + 2, k + 20, KMOD_Main.KetherCloud);
         world.setBlock(i + 6, j + 2, k + 21, KMOD_Main.KetherCloud);
         world.setBlock(i + 6, j + 2, k + 22, KMOD_Main.KetherCloud);
         world.setBlock(i + 6, j + 3, k + 2, KMOD_Main.KetherCloud);
         world.setBlock(i + 6, j + 3, k + 3, KMOD_Main.KetherCloud);
         world.setBlock(i + 6, j + 3, k + 4, KMOD_Main.KetherCloud);
         world.setBlock(i + 6, j + 3, k + 5, KMOD_Main.KetherCloud);
         world.setBlock(i + 6, j + 3, k + 6, KMOD_Main.KetherCloud);
         world.setBlock(i + 6, j + 3, k + 8, KMOD_Main.KetherCloud);
         world.setBlock(i + 6, j + 3, k + 12, KMOD_Main.KetherCloud);
         world.setBlock(i + 6, j + 3, k + 13, KMOD_Main.KetherCloud);
         world.setBlock(i + 6, j + 3, k + 14, KMOD_Main.KetherCloud);
         world.setBlock(i + 6, j + 3, k + 15, KMOD_Main.KetherCloud);
         world.setBlock(i + 6, j + 3, k + 16, KMOD_Main.KetherCloud);
         world.setBlock(i + 6, j + 3, k + 17, KMOD_Main.KetherCloud);
         world.setBlock(i + 6, j + 3, k + 18, KMOD_Main.KetherCloud);
         world.setBlock(i + 6, j + 3, k + 19, KMOD_Main.KetherCloud);
         world.setBlock(i + 6, j + 3, k + 20, KMOD_Main.KetherCloud);
         world.setBlock(i + 6, j + 3, k + 21, KMOD_Main.KetherCloud);
         world.setBlock(i + 6, j + 3, k + 22, KMOD_Main.KetherCloud);
         world.setBlock(i + 6, j + 4, k + 4, KMOD_Main.LifeLog);
         world.setBlock(i + 6, j + 4, k + 5, KMOD_Main.LifeLog);
         world.setBlock(i + 6, j + 4, k + 6, KMOD_Main.LifeLog);
         world.setBlock(i + 6, j + 4, k + 7, KMOD_Main.LifeLog);
         world.setBlock(i + 6, j + 4, k + 14, KMOD_Main.LifeLog);
         world.setBlock(i + 6, j + 4, k + 15, KMOD_Main.LifeLog);
         world.setBlock(i + 6, j + 4, k + 16, KMOD_Main.LifeLog);
         world.setBlock(i + 6, j + 4, k + 17, KMOD_Main.LifeLog);
         world.setBlock(i + 6, j + 4, k + 18, KMOD_Main.LifeLog);
         world.setBlock(i + 6, j + 4, k + 19, KMOD_Main.LifeLog);
         world.setBlock(i + 6, j + 5, k + 6, KMOD_Main.LifeLog);
         world.setBlock(i + 6, j + 5, k + 7, KMOD_Main.LifeLog);
         world.setBlock(i + 6, j + 22, k + 18, KMOD_Main.LifeLeaves);
         world.setBlock(i + 6, j + 22, k + 19, KMOD_Main.LifeLeaves);
         world.setBlock(i + 6, j + 23, k + 18, KMOD_Main.LifeLeaves);
         world.setBlock(i + 6, j + 23, k + 19, KMOD_Main.LifeLeaves);
         world.setBlock(i + 6, j + 23, k + 20, KMOD_Main.LifeLeaves);
         world.setBlock(i + 6, j + 24, k + 17, KMOD_Main.LifeLeaves);
         world.setBlock(i + 6, j + 24, k + 18, KMOD_Main.LifeLeaves);
         world.setBlock(i + 6, j + 24, k + 19, KMOD_Main.LifeLeaves);
         world.setBlock(i + 6, j + 24, k + 20, KMOD_Main.LifeLeaves);
         world.setBlock(i + 6, j + 25, k + 21, KMOD_Main.LifeLeaves);
         world.setBlock(i + 6, j + 26, k + 10, KMOD_Main.LifeLeaves);
         world.setBlock(i + 6, j + 26, k + 11, KMOD_Main.LifeLeaves);
         world.setBlock(i + 6, j + 26, k + 12, KMOD_Main.LifeLeaves);
         world.setBlock(i + 6, j + 27, k + 7, KMOD_Main.LifeLeaves);
         world.setBlock(i + 6, j + 27, k + 9, KMOD_Main.LifeLeaves);
         world.setBlock(i + 6, j + 27, k + 10, KMOD_Main.LifeLeaves);
         world.setBlock(i + 6, j + 27, k + 11, KMOD_Main.LifeLeaves);
         world.setBlock(i + 6, j + 27, k + 12, KMOD_Main.LifeLeaves);
         world.setBlock(i + 6, j + 27, k + 13, KMOD_Main.LifeLeaves);
         world.setBlock(i + 6, j + 27, k + 14, KMOD_Main.LifeLeaves);
         world.setBlock(i + 6, j + 27, k + 15, KMOD_Main.LifeLeaves);
         world.setBlock(i + 6, j + 28, k + 7, KMOD_Main.LifeLeaves);
         world.setBlock(i + 6, j + 28, k + 8, KMOD_Main.LifeLeaves);
         world.setBlock(i + 6, j + 28, k + 9, KMOD_Main.LifeLeaves);
         world.setBlock(i + 6, j + 28, k + 10, KMOD_Main.LifeLeaves);
         world.setBlock(i + 6, j + 28, k + 11, KMOD_Main.LifeLeaves);
         world.setBlock(i + 6, j + 28, k + 12, KMOD_Main.LifeLeaves);
         world.setBlock(i + 6, j + 28, k + 13, KMOD_Main.LifeLeaves);
         world.setBlock(i + 6, j + 28, k + 15, KMOD_Main.LifeLeaves);
         world.setBlock(i + 6, j + 29, k + 8, KMOD_Main.LifeLeaves);
         world.setBlock(i + 6, j + 29, k + 9, KMOD_Main.LifeLeaves);
         world.setBlock(i + 6, j + 29, k + 10, KMOD_Main.LifeLog);
         world.setBlock(i + 6, j + 29, k + 11, KMOD_Main.LifeLog);
         world.setBlock(i + 6, j + 29, k + 12, KMOD_Main.LifeLog);
         world.setBlock(i + 6, j + 29, k + 13, KMOD_Main.LifeLeaves);
         world.setBlock(i + 6, j + 30, k + 9, KMOD_Main.LifeLeaves);
         world.setBlock(i + 6, j + 30, k + 10, KMOD_Main.LifeLeaves);
         world.setBlock(i + 6, j + 30, k + 11, KMOD_Main.LifeLeaves);
         world.setBlock(i + 6, j + 30, k + 12, KMOD_Main.LifeLeaves);
         world.setBlock(i + 6, j + 30, k + 13, KMOD_Main.LifeLeaves);
         world.setBlock(i + 6, j + 31, k + 9, KMOD_Main.LifeLeaves);
         world.setBlock(i + 6, j + 31, k + 10, KMOD_Main.LifeLeaves);
         world.setBlock(i + 6, j + 31, k + 11, KMOD_Main.LifeLeaves);
         world.setBlock(i + 6, j + 31, k + 12, KMOD_Main.LifeLeaves);
         world.setBlock(i + 6, j + 32, k + 11, KMOD_Main.LifeLeaves);
         world.setBlock(i + 6, j + 32, k + 12, KMOD_Main.LifeLeaves);
         world.setBlock(i + 6, j + 32, k + 13, KMOD_Main.LifeLeaves);
         world.setBlock(i + 6, j + 33, k + 11, KMOD_Main.LifeLeaves);
         world.setBlock(i + 6, j + 33, k + 13, KMOD_Main.LifeLeaves);
         world.setBlock(i + 7, j + 0, k + 18, KMOD_Main.KetherCloud);
         world.setBlock(i + 7, j + 1, k + 4, KMOD_Main.KetherCloud);
         world.setBlock(i + 7, j + 1, k + 5, KMOD_Main.KetherCloud);
         world.setBlock(i + 7, j + 1, k + 6, KMOD_Main.KetherCloud);
         world.setBlock(i + 7, j + 1, k + 7, KMOD_Main.KetherCloud);
         world.setBlock(i + 7, j + 1, k + 8, KMOD_Main.KetherCloud);
         world.setBlock(i + 7, j + 1, k + 9, KMOD_Main.KetherCloud);
         world.setBlock(i + 7, j + 1, k + 10, KMOD_Main.KetherCloud);
         world.setBlock(i + 7, j + 1, k + 18, KMOD_Main.KetherCloud);
         world.setBlock(i + 7, j + 2, k + 3, KMOD_Main.KetherCloud);
         world.setBlock(i + 7, j + 2, k + 4, KMOD_Main.KetherCloud);
         world.setBlock(i + 7, j + 2, k + 5, KMOD_Main.KetherCloud);
         world.setBlock(i + 7, j + 2, k + 6, KMOD_Main.KetherCloud);
         world.setBlock(i + 7, j + 2, k + 7, KMOD_Main.KetherCloud);
         world.setBlock(i + 7, j + 2, k + 8, KMOD_Main.KetherCloud);
         world.setBlock(i + 7, j + 2, k + 9, KMOD_Main.KetherCloud);
         world.setBlock(i + 7, j + 2, k + 10, KMOD_Main.KetherCloud);
         world.setBlock(i + 7, j + 2, k + 13, KMOD_Main.KetherCloud);
         world.setBlock(i + 7, j + 2, k + 14, KMOD_Main.KetherCloud);
         world.setBlock(i + 7, j + 2, k + 15, KMOD_Main.KetherCloud);
         world.setBlock(i + 7, j + 2, k + 16, KMOD_Main.KetherCloud);
         world.setBlock(i + 7, j + 2, k + 17, KMOD_Main.KetherCloud);
         world.setBlock(i + 7, j + 2, k + 18, KMOD_Main.KetherCloud);
         world.setBlock(i + 7, j + 2, k + 19, KMOD_Main.KetherCloud);
         world.setBlock(i + 7, j + 2, k + 20, KMOD_Main.KetherCloud);
         world.setBlock(i + 7, j + 2, k + 21, KMOD_Main.KetherCloud);
         world.setBlock(i + 7, j + 2, k + 22, KMOD_Main.KetherCloud);
         world.setBlock(i + 7, j + 3, k + 3, KMOD_Main.KetherCloud);
         world.setBlock(i + 7, j + 3, k + 4, KMOD_Main.KetherCloud);
         world.setBlock(i + 7, j + 3, k + 5, KMOD_Main.KetherCloud);
         world.setBlock(i + 7, j + 3, k + 7, KMOD_Main.KetherCloud);
         world.setBlock(i + 7, j + 3, k + 8, KMOD_Main.KetherCloud);
         world.setBlock(i + 7, j + 3, k + 9, KMOD_Main.KetherCloud);
         world.setBlock(i + 7, j + 3, k + 13, KMOD_Main.KetherCloud);
         world.setBlock(i + 7, j + 3, k + 14, KMOD_Main.KetherCloud);
         world.setBlock(i + 7, j + 3, k + 15, KMOD_Main.KetherCloud);
         world.setBlock(i + 7, j + 3, k + 16, KMOD_Main.KetherCloud);
         world.setBlock(i + 7, j + 3, k + 17, KMOD_Main.KetherCloud);
         world.setBlock(i + 7, j + 3, k + 18, KMOD_Main.KetherCloud);
         world.setBlock(i + 7, j + 3, k + 19, KMOD_Main.KetherCloud);
         world.setBlock(i + 7, j + 3, k + 20, KMOD_Main.KetherCloud);
         world.setBlock(i + 7, j + 3, k + 21, KMOD_Main.KetherCloud);
         world.setBlock(i + 7, j + 3, k + 22, KMOD_Main.KetherCloud);
         world.setBlock(i + 7, j + 4, k + 5, KMOD_Main.LifeLog);
         world.setBlock(i + 7, j + 4, k + 6, KMOD_Main.LifeLog);
         world.setBlock(i + 7, j + 4, k + 7, KMOD_Main.LifeLog);
         world.setBlock(i + 7, j + 4, k + 8, KMOD_Main.LifeLog);
         world.setBlock(i + 7, j + 4, k + 13, KMOD_Main.LifeLog);
         world.setBlock(i + 7, j + 4, k + 15, KMOD_Main.LifeLog);
         world.setBlock(i + 7, j + 4, k + 16, KMOD_Main.LifeLog);
         world.setBlock(i + 7, j + 4, k + 17, KMOD_Main.LifeLog);
         world.setBlock(i + 7, j + 4, k + 18, KMOD_Main.LifeLog);
         world.setBlock(i + 7, j + 4, k + 20, KMOD_Main.LifeLog);
         world.setBlock(i + 7, j + 5, k + 6, KMOD_Main.LifeLog);
         world.setBlock(i + 7, j + 5, k + 7, KMOD_Main.LifeLog);
         world.setBlock(i + 7, j + 5, k + 8, KMOD_Main.LifeLog);
         world.setBlock(i + 7, j + 5, k + 15, KMOD_Main.LifeLog);
         world.setBlock(i + 7, j + 5, k + 16, KMOD_Main.LifeLog);
         world.setBlock(i + 7, j + 6, k + 7, KMOD_Main.LifeLog);
         world.setBlock(i + 7, j + 6, k + 8, KMOD_Main.LifeLog);
         world.setBlock(i + 7, j + 21, k + 16, KMOD_Main.LifeLog);
         world.setBlock(i + 7, j + 22, k + 16, KMOD_Main.LifeLog);
         world.setBlock(i + 7, j + 22, k + 17, KMOD_Main.LifeLog);
         world.setBlock(i + 7, j + 22, k + 18, KMOD_Main.LifeLog);
         world.setBlock(i + 7, j + 22, k + 19, KMOD_Main.LifeLog);
         world.setBlock(i + 7, j + 22, k + 20, KMOD_Main.LifeLeaves);
         world.setBlock(i + 7, j + 23, k + 16, KMOD_Main.LifeLog);
         world.setBlock(i + 7, j + 23, k + 17, KMOD_Main.LifeLog);
         world.setBlock(i + 7, j + 23, k + 18, KMOD_Main.LifeLog);
         world.setBlock(i + 7, j + 23, k + 19, KMOD_Main.LifeLog);
         world.setBlock(i + 7, j + 23, k + 20, KMOD_Main.LifeLeaves);
         world.setBlock(i + 7, j + 23, k + 21, KMOD_Main.LifeLeaves);
         world.setBlock(i + 7, j + 24, k + 17, KMOD_Main.LifeLeaves);
         world.setBlock(i + 7, j + 24, k + 18, KMOD_Main.LifeLeaves);
         world.setBlock(i + 7, j + 24, k + 19, KMOD_Main.LifeLog);
         world.setBlock(i + 7, j + 24, k + 20, KMOD_Main.LifeLeaves);
         world.setBlock(i + 7, j + 24, k + 21, KMOD_Main.LifeLeaves);
         world.setBlock(i + 7, j + 25, k + 19, KMOD_Main.LifeLeaves);
         world.setBlock(i + 7, j + 25, k + 20, KMOD_Main.LifeLeaves);
         world.setBlock(i + 7, j + 25, k + 21, KMOD_Main.LifeLeaves);
         world.setBlock(i + 7, j + 26, k + 9, KMOD_Main.LifeLeaves);
         world.setBlock(i + 7, j + 26, k + 10, KMOD_Main.LifeLog);
         world.setBlock(i + 7, j + 26, k + 11, KMOD_Main.LifeLog);
         world.setBlock(i + 7, j + 26, k + 12, KMOD_Main.LifeLog);
         world.setBlock(i + 7, j + 26, k + 13, KMOD_Main.LifeLeaves);
         world.setBlock(i + 7, j + 27, k + 7, KMOD_Main.LifeLeaves);
         world.setBlock(i + 7, j + 27, k + 8, KMOD_Main.LifeLeaves);
         world.setBlock(i + 7, j + 27, k + 9, KMOD_Main.LifeLeaves);
         world.setBlock(i + 7, j + 27, k + 10, KMOD_Main.LifeLog);
         world.setBlock(i + 7, j + 27, k + 11, KMOD_Main.LifeLog);
         world.setBlock(i + 7, j + 27, k + 12, KMOD_Main.LifeLog);
         world.setBlock(i + 7, j + 27, k + 13, KMOD_Main.LifeLeaves);
         world.setBlock(i + 7, j + 27, k + 14, KMOD_Main.LifeLeaves);
         world.setBlock(i + 7, j + 27, k + 15, KMOD_Main.LifeLeaves);
         world.setBlock(i + 7, j + 27, k + 16, KMOD_Main.LifeLeaves);
         world.setBlock(i + 7, j + 28, k + 5, KMOD_Main.LifeLeaves);
         world.setBlock(i + 7, j + 28, k + 6, KMOD_Main.LifeLeaves);
         world.setBlock(i + 7, j + 28, k + 7, KMOD_Main.LifeLeaves);
         world.setBlock(i + 7, j + 28, k + 8, KMOD_Main.LifeLeaves);
         world.setBlock(i + 7, j + 28, k + 9, KMOD_Main.LifeLeaves);
         world.setBlock(i + 7, j + 28, k + 13, KMOD_Main.LifeLeaves);
         world.setBlock(i + 7, j + 28, k + 14, KMOD_Main.LifeLeaves);
         world.setBlock(i + 7, j + 28, k + 15, KMOD_Main.LifeLeaves);
         world.setBlock(i + 7, j + 29, k + 8, KMOD_Main.LifeLeaves);
         world.setBlock(i + 7, j + 29, k + 9, KMOD_Main.LifeLog);
         world.setBlock(i + 7, j + 29, k + 13, KMOD_Main.LifeLog);
         world.setBlock(i + 7, j + 29, k + 14, KMOD_Main.LifeLeaves);
         world.setBlock(i + 7, j + 30, k + 8, KMOD_Main.LifeLeaves);
         world.setBlock(i + 7, j + 30, k + 9, KMOD_Main.LifeLeaves);
         world.setBlock(i + 7, j + 30, k + 10, KMOD_Main.LifeLeaves);
         world.setBlock(i + 7, j + 30, k + 11, KMOD_Main.LifeLeaves);
         world.setBlock(i + 7, j + 30, k + 12, KMOD_Main.LifeLeaves);
         world.setBlock(i + 7, j + 30, k + 13, KMOD_Main.LifeLeaves);
         world.setBlock(i + 7, j + 30, k + 14, KMOD_Main.LifeLeaves);
         world.setBlock(i + 7, j + 31, k + 8, KMOD_Main.LifeLeaves);
         world.setBlock(i + 7, j + 31, k + 9, KMOD_Main.LifeLeaves);
         world.setBlock(i + 7, j + 31, k + 10, KMOD_Main.LifeLeaves);
         world.setBlock(i + 7, j + 31, k + 11, KMOD_Main.LifeLeaves);
         world.setBlock(i + 7, j + 31, k + 12, KMOD_Main.LifeLeaves);
         world.setBlock(i + 7, j + 31, k + 13, KMOD_Main.LifeLeaves);
         world.setBlock(i + 7, j + 31, k + 14, KMOD_Main.LifeLeaves);
         world.setBlock(i + 7, j + 32, k + 10, KMOD_Main.LifeLeaves);
         world.setBlock(i + 7, j + 32, k + 12, KMOD_Main.LifeLeaves);
         world.setBlock(i + 7, j + 32, k + 13, KMOD_Main.LifeLeaves);
         world.setBlock(i + 7, j + 32, k + 14, KMOD_Main.LifeLeaves);
         world.setBlock(i + 7, j + 32, k + 15, KMOD_Main.LifeLeaves);
         world.setBlock(i + 7, j + 33, k + 12, KMOD_Main.LifeLeaves);
         world.setBlock(i + 7, j + 33, k + 13, KMOD_Main.LifeLeaves);
         world.setBlock(i + 8, j + 0, k + 17, KMOD_Main.KetherCloud);
         world.setBlock(i + 8, j + 0, k + 18, KMOD_Main.KetherCloud);
         world.setBlock(i + 8, j + 0, k + 19, KMOD_Main.KetherCloud);
         world.setBlock(i + 8, j + 1, k + 5, KMOD_Main.KetherCloud);
         world.setBlock(i + 8, j + 1, k + 6, KMOD_Main.KetherCloud);
         world.setBlock(i + 8, j + 1, k + 7, KMOD_Main.KetherCloud);
         world.setBlock(i + 8, j + 1, k + 9, KMOD_Main.KetherCloud);
         world.setBlock(i + 8, j + 1, k + 11, KMOD_Main.KetherCloud);
         world.setBlock(i + 8, j + 1, k + 15, KMOD_Main.KetherCloud);
         world.setBlock(i + 8, j + 1, k + 17, KMOD_Main.KetherCloud);
         world.setBlock(i + 8, j + 1, k + 18, KMOD_Main.KetherCloud);
         world.setBlock(i + 8, j + 1, k + 19, KMOD_Main.KetherCloud);
         world.setBlock(i + 8, j + 2, k + 4, KMOD_Main.KetherCloud);
         world.setBlock(i + 8, j + 2, k + 5, KMOD_Main.KetherCloud);
         world.setBlock(i + 8, j + 2, k + 6, KMOD_Main.KetherCloud);
         world.setBlock(i + 8, j + 2, k + 7, KMOD_Main.KetherCloud);
         world.setBlock(i + 8, j + 2, k + 8, KMOD_Main.KetherCloud);
         world.setBlock(i + 8, j + 2, k + 9, KMOD_Main.KetherCloud);
         world.setBlock(i + 8, j + 2, k + 10, KMOD_Main.KetherCloud);
         world.setBlock(i + 8, j + 2, k + 11, KMOD_Main.KetherCloud);
         world.setBlock(i + 8, j + 2, k + 12, KMOD_Main.KetherCloud);
         world.setBlock(i + 8, j + 2, k + 13, KMOD_Main.KetherCloud);
         world.setBlock(i + 8, j + 2, k + 14, KMOD_Main.KetherCloud);
         world.setBlock(i + 8, j + 2, k + 15, KMOD_Main.KetherCloud);
         world.setBlock(i + 8, j + 2, k + 16, KMOD_Main.KetherCloud);
         world.setBlock(i + 8, j + 2, k + 17, KMOD_Main.KetherCloud);
         world.setBlock(i + 8, j + 2, k + 19, KMOD_Main.KetherCloud);
         world.setBlock(i + 8, j + 2, k + 20, KMOD_Main.KetherCloud);
         world.setBlock(i + 8, j + 2, k + 21, KMOD_Main.KetherCloud);
         world.setBlock(i + 8, j + 3, k + 4, KMOD_Main.KetherCloud);
         world.setBlock(i + 8, j + 3, k + 6, KMOD_Main.KetherCloud);
         world.setBlock(i + 8, j + 3, k + 7, KMOD_Main.KetherCloud);
         world.setBlock(i + 8, j + 3, k + 8, KMOD_Main.KetherCloud);
         world.setBlock(i + 8, j + 3, k + 9, KMOD_Main.KetherCloud);
         world.setBlock(i + 8, j + 3, k + 10, KMOD_Main.KetherCloud);
         world.setBlock(i + 8, j + 3, k + 12, KMOD_Main.KetherCloud);
         world.setBlock(i + 8, j + 3, k + 13, KMOD_Main.KetherCloud);
         world.setBlock(i + 8, j + 3, k + 14, KMOD_Main.KetherCloud);
         world.setBlock(i + 8, j + 3, k + 15, KMOD_Main.KetherCloud);
         world.setBlock(i + 8, j + 3, k + 16, KMOD_Main.KetherCloud);
         world.setBlock(i + 8, j + 3, k + 17, KMOD_Main.KetherCloud);
         world.setBlock(i + 8, j + 3, k + 19, KMOD_Main.KetherCloud);
         world.setBlock(i + 8, j + 3, k + 20, KMOD_Main.KetherCloud);
         world.setBlock(i + 8, j + 3, k + 21, KMOD_Main.KetherCloud);
         world.setBlock(i + 8, j + 4, k + 7, KMOD_Main.LifeLog);
         world.setBlock(i + 8, j + 4, k + 8, KMOD_Main.LifeLog);
         world.setBlock(i + 8, j + 4, k + 9, KMOD_Main.LifeLog);
         world.setBlock(i + 8, j + 4, k + 13, KMOD_Main.LifeLog);
         world.setBlock(i + 8, j + 4, k + 14, KMOD_Main.LifeLog);
         world.setBlock(i + 8, j + 4, k + 15, KMOD_Main.LifeLog);
         world.setBlock(i + 8, j + 4, k + 16, KMOD_Main.LifeLog);
         world.setBlock(i + 8, j + 4, k + 17, KMOD_Main.LifeLog);
         world.setBlock(i + 8, j + 5, k + 7, KMOD_Main.LifeLog);
         world.setBlock(i + 8, j + 5, k + 8, KMOD_Main.LifeLog);
         world.setBlock(i + 8, j + 5, k + 9, KMOD_Main.LifeLog);
         world.setBlock(i + 8, j + 5, k + 13, KMOD_Main.LifeLog);
         world.setBlock(i + 8, j + 5, k + 14, KMOD_Main.LifeLog);
         world.setBlock(i + 8, j + 5, k + 15, KMOD_Main.LifeLog);
         world.setBlock(i + 8, j + 5, k + 16, KMOD_Main.LifeLog);
         world.setBlock(i + 8, j + 6, k + 7, KMOD_Main.LifeLog);
         world.setBlock(i + 8, j + 6, k + 8, KMOD_Main.LifeLog);
         world.setBlock(i + 8, j + 6, k + 9, KMOD_Main.LifeLog);
         world.setBlock(i + 8, j + 6, k + 14, KMOD_Main.LifeLog);
         world.setBlock(i + 8, j + 6, k + 15, KMOD_Main.LifeLog);
         world.setBlock(i + 8, j + 7, k + 9, KMOD_Main.LifeLog);
         world.setBlock(i + 8, j + 7, k + 13, KMOD_Main.LifeLog);
         world.setBlock(i + 8, j + 8, k + 10, KMOD_Main.LifeLog);
         world.setBlock(i + 8, j + 8, k + 12, KMOD_Main.LifeLog);
         world.setBlock(i + 8, j + 9, k + 10, KMOD_Main.LifeLog);
         world.setBlock(i + 8, j + 9, k + 11, KMOD_Main.LifeLog);
         world.setBlock(i + 8, j + 21, k + 15, KMOD_Main.LifeLog);
         world.setBlock(i + 8, j + 21, k + 16, KMOD_Main.LifeLog);
         world.setBlock(i + 8, j + 21, k + 17, KMOD_Main.LifeLog);
         world.setBlock(i + 8, j + 22, k + 15, KMOD_Main.LifeLog);
         world.setBlock(i + 8, j + 22, k + 16, KMOD_Main.LifeLog);
         world.setBlock(i + 8, j + 22, k + 17, KMOD_Main.LifeLog);
         world.setBlock(i + 8, j + 22, k + 18, KMOD_Main.LifeLog);
         world.setBlock(i + 8, j + 22, k + 19, KMOD_Main.LifeLog);
         world.setBlock(i + 8, j + 22, k + 20, KMOD_Main.LifeLeaves);
         world.setBlock(i + 8, j + 23, k + 17, KMOD_Main.LifeLog);
         world.setBlock(i + 8, j + 23, k + 18, KMOD_Main.LifeLog);
         world.setBlock(i + 8, j + 23, k + 19, KMOD_Main.LifeLog);
         world.setBlock(i + 8, j + 23, k + 20, KMOD_Main.LifeLeaves);
         world.setBlock(i + 8, j + 24, k + 18, KMOD_Main.LifeLeaves);
         world.setBlock(i + 8, j + 24, k + 19, KMOD_Main.LifeLog);
         world.setBlock(i + 8, j + 24, k + 20, KMOD_Main.LifeLeaves);
         world.setBlock(i + 8, j + 24, k + 21, KMOD_Main.LifeLeaves);
         world.setBlock(i + 8, j + 25, k + 10, KMOD_Main.LifeLog);
         world.setBlock(i + 8, j + 25, k + 11, KMOD_Main.LifeLog);
         world.setBlock(i + 8, j + 25, k + 12, KMOD_Main.LifeLog);
         world.setBlock(i + 8, j + 25, k + 18, KMOD_Main.LifeLeaves);
         world.setBlock(i + 8, j + 25, k + 19, KMOD_Main.LifeLeaves);
         world.setBlock(i + 8, j + 25, k + 20, KMOD_Main.LifeLeaves);
         world.setBlock(i + 8, j + 25, k + 21, KMOD_Main.LifeLeaves);
         world.setBlock(i + 8, j + 26, k + 8, KMOD_Main.LifeLeaves);
         world.setBlock(i + 8, j + 26, k + 9, KMOD_Main.LifeLog);
         world.setBlock(i + 8, j + 26, k + 13, KMOD_Main.LifeLog);
         world.setBlock(i + 8, j + 26, k + 14, KMOD_Main.LifeLeaves);
         world.setBlock(i + 8, j + 27, k + 7, KMOD_Main.LifeLeaves);
         world.setBlock(i + 8, j + 27, k + 8, KMOD_Main.LifeLeaves);
         world.setBlock(i + 8, j + 27, k + 9, KMOD_Main.LifeLog);
         world.setBlock(i + 8, j + 27, k + 13, KMOD_Main.LifeLog);
         world.setBlock(i + 8, j + 27, k + 14, KMOD_Main.LifeLeaves);
         world.setBlock(i + 8, j + 28, k + 5, KMOD_Main.LifeLeaves);
         world.setBlock(i + 8, j + 28, k + 6, KMOD_Main.LifeLeaves);
         world.setBlock(i + 8, j + 28, k + 7, KMOD_Main.LifeLeaves);
         world.setBlock(i + 8, j + 28, k + 8, KMOD_Main.LifeLeaves);
         world.setBlock(i + 8, j + 28, k + 14, KMOD_Main.LifeLeaves);
         world.setBlock(i + 8, j + 28, k + 15, KMOD_Main.LifeLeaves);
         world.setBlock(i + 8, j + 28, k + 16, KMOD_Main.LifeLeaves);
         world.setBlock(i + 8, j + 29, k + 5, KMOD_Main.LifeLeaves);
         world.setBlock(i + 8, j + 29, k + 7, KMOD_Main.LifeLeaves);
         world.setBlock(i + 8, j + 29, k + 8, KMOD_Main.LifeLog);
         world.setBlock(i + 8, j + 29, k + 14, KMOD_Main.LifeLog);
         world.setBlock(i + 8, j + 29, k + 15, KMOD_Main.LifeLeaves);
         world.setBlock(i + 8, j + 29, k + 16, KMOD_Main.LifeLeaves);
         world.setBlock(i + 8, j + 30, k + 6, KMOD_Main.LifeLeaves);
         world.setBlock(i + 8, j + 30, k + 7, KMOD_Main.LifeLeaves);
         world.setBlock(i + 8, j + 30, k + 8, KMOD_Main.LifeLeaves);
         world.setBlock(i + 8, j + 30, k + 9, KMOD_Main.LifeLeaves);
         world.setBlock(i + 8, j + 30, k + 10, KMOD_Main.LifeLeaves);
         world.setBlock(i + 8, j + 30, k + 11, KMOD_Main.LifeLeaves);
         world.setBlock(i + 8, j + 30, k + 12, KMOD_Main.LifeLeaves);
         world.setBlock(i + 8, j + 30, k + 13, KMOD_Main.LifeLeaves);
         world.setBlock(i + 8, j + 30, k + 14, KMOD_Main.LifeLeaves);
         world.setBlock(i + 8, j + 30, k + 15, KMOD_Main.LifeLeaves);
         world.setBlock(i + 8, j + 31, k + 7, KMOD_Main.LifeLeaves);
         world.setBlock(i + 8, j + 31, k + 8, KMOD_Main.LifeLeaves);
         world.setBlock(i + 8, j + 31, k + 9, KMOD_Main.LifeLeaves);
         world.setBlock(i + 8, j + 31, k + 10, KMOD_Main.LifeLeaves);
         world.setBlock(i + 8, j + 31, k + 11, KMOD_Main.LifeLeaves);
         world.setBlock(i + 8, j + 31, k + 12, KMOD_Main.LifeLeaves);
         world.setBlock(i + 8, j + 31, k + 13, KMOD_Main.LifeLeaves);
         world.setBlock(i + 8, j + 31, k + 14, KMOD_Main.LifeLeaves);
         world.setBlock(i + 8, j + 32, k + 9, KMOD_Main.LifeLeaves);
         world.setBlock(i + 8, j + 32, k + 10, KMOD_Main.LifeLeaves);
         world.setBlock(i + 8, j + 32, k + 11, KMOD_Main.LifeLeaves);
         world.setBlock(i + 8, j + 32, k + 12, KMOD_Main.LifeLeaves);
         world.setBlock(i + 8, j + 32, k + 14, KMOD_Main.LifeLeaves);
         world.setBlock(i + 8, j + 32, k + 15, KMOD_Main.LifeLeaves);
         world.setBlock(i + 9, j + 0, k + 16, KMOD_Main.KetherCloud);
         world.setBlock(i + 9, j + 0, k + 17, KMOD_Main.KetherCloud);
         world.setBlock(i + 9, j + 0, k + 18, KMOD_Main.KetherCloud);
         world.setBlock(i + 9, j + 0, k + 19, KMOD_Main.KetherCloud);
         world.setBlock(i + 9, j + 0, k + 20, KMOD_Main.KetherCloud);
         world.setBlock(i + 9, j + 1, k + 4, KMOD_Main.KetherCloud);
         world.setBlock(i + 9, j + 1, k + 5, KMOD_Main.KetherCloud);
         world.setBlock(i + 9, j + 1, k + 6, KMOD_Main.KetherCloud);
         world.setBlock(i + 9, j + 1, k + 7, KMOD_Main.KetherCloud);
         world.setBlock(i + 9, j + 1, k + 8, KMOD_Main.KetherCloud);
         world.setBlock(i + 9, j + 1, k + 10, KMOD_Main.KetherCloud);
         world.setBlock(i + 9, j + 1, k + 11, KMOD_Main.KetherCloud);
         world.setBlock(i + 9, j + 1, k + 12, KMOD_Main.KetherCloud);
         world.setBlock(i + 9, j + 1, k + 14, KMOD_Main.KetherCloud);
         world.setBlock(i + 9, j + 1, k + 15, KMOD_Main.KetherCloud);
         world.setBlock(i + 9, j + 1, k + 16, KMOD_Main.KetherCloud);
         world.setBlock(i + 9, j + 1, k + 17, KMOD_Main.KetherCloud);
         world.setBlock(i + 9, j + 1, k + 18, KMOD_Main.KetherCloud);
         world.setBlock(i + 9, j + 1, k + 19, KMOD_Main.KetherCloud);
         world.setBlock(i + 9, j + 1, k + 20, KMOD_Main.KetherCloud);
         world.setBlock(i + 9, j + 2, k + 4, KMOD_Main.KetherCloud);
         world.setBlock(i + 9, j + 2, k + 5, KMOD_Main.KetherCloud);
         world.setBlock(i + 9, j + 2, k + 6, KMOD_Main.KetherCloud);
         world.setBlock(i + 9, j + 2, k + 7, KMOD_Main.KetherCloud);
         world.setBlock(i + 9, j + 2, k + 8, KMOD_Main.KetherCloud);
         world.setBlock(i + 9, j + 2, k + 9, KMOD_Main.KetherCloud);
         world.setBlock(i + 9, j + 2, k + 10, KMOD_Main.KetherCloud);
         world.setBlock(i + 9, j + 2, k + 11, KMOD_Main.KetherCloud);
         world.setBlock(i + 9, j + 2, k + 12, KMOD_Main.KetherCloud);
         world.setBlock(i + 9, j + 2, k + 13, KMOD_Main.KetherCloud);
         world.setBlock(i + 9, j + 2, k + 14, KMOD_Main.KetherCloud);
         world.setBlock(i + 9, j + 2, k + 15, KMOD_Main.KetherCloud);
         world.setBlock(i + 9, j + 2, k + 16, KMOD_Main.KetherCloud);
         world.setBlock(i + 9, j + 2, k + 20, KMOD_Main.KetherCloud);
         world.setBlock(i + 9, j + 3, k + 6, KMOD_Main.KetherCloud);
         world.setBlock(i + 9, j + 3, k + 7, KMOD_Main.KetherCloud);
         world.setBlock(i + 9, j + 3, k + 8, KMOD_Main.KetherCloud);
         world.setBlock(i + 9, j + 3, k + 9, KMOD_Main.KetherCloud);
         world.setBlock(i + 9, j + 3, k + 10, KMOD_Main.KetherCloud);
         world.setBlock(i + 9, j + 3, k + 11, KMOD_Main.KetherCloud);
         world.setBlock(i + 9, j + 3, k + 12, KMOD_Main.KetherCloud);
         world.setBlock(i + 9, j + 3, k + 13, KMOD_Main.KetherCloud);
         world.setBlock(i + 9, j + 3, k + 14, KMOD_Main.KetherCloud);
         world.setBlock(i + 9, j + 3, k + 15, KMOD_Main.KetherCloud);
         world.setBlock(i + 9, j + 3, k + 16, KMOD_Main.KetherCloud);
         world.setBlock(i + 9, j + 3, k + 20, KMOD_Main.KetherCloud);
         world.setBlock(i + 9, j + 4, k + 8, KMOD_Main.LifeLog);
         world.setBlock(i + 9, j + 4, k + 9, KMOD_Main.LifeLog);
         world.setBlock(i + 9, j + 4, k + 13, KMOD_Main.LifeLog);
         world.setBlock(i + 9, j + 4, k + 14, KMOD_Main.LifeLog);
         world.setBlock(i + 9, j + 4, k + 15, KMOD_Main.LifeLog);
         world.setBlock(i + 9, j + 5, k + 8, KMOD_Main.LifeLog);
         world.setBlock(i + 9, j + 5, k + 9, KMOD_Main.LifeLog);
         world.setBlock(i + 9, j + 5, k + 13, KMOD_Main.LifeLog);
         world.setBlock(i + 9, j + 5, k + 14, KMOD_Main.LifeLog);
         world.setBlock(i + 9, j + 5, k + 15, KMOD_Main.LifeLog);
         world.setBlock(i + 9, j + 6, k + 8, KMOD_Main.LifeLog);
         world.setBlock(i + 9, j + 6, k + 9, KMOD_Main.LifeLog);
         world.setBlock(i + 9, j + 6, k + 13, KMOD_Main.LifeLog);
         world.setBlock(i + 9, j + 6, k + 14, KMOD_Main.LifeLog);
         world.setBlock(i + 9, j + 6, k + 15, KMOD_Main.LifeLog);
         world.setBlock(i + 9, j + 7, k + 8, KMOD_Main.LifeLog);
         world.setBlock(i + 9, j + 7, k + 9, KMOD_Main.LifeLog);
         world.setBlock(i + 9, j + 7, k + 13, KMOD_Main.LifeLog);
         world.setBlock(i + 9, j + 8, k + 9, KMOD_Main.LifeLog);
         world.setBlock(i + 9, j + 8, k + 10, KMOD_Main.LifeLog);
         world.setBlock(i + 9, j + 8, k + 12, KMOD_Main.LifeLog);
         world.setBlock(i + 9, j + 8, k + 13, KMOD_Main.LifeLog);
         world.setBlock(i + 9, j + 9, k + 9, KMOD_Main.LifeLog);
         world.setBlock(i + 9, j + 9, k + 10, KMOD_Main.LifeLog);
         world.setBlock(i + 9, j + 9, k + 11, KMOD_Main.LifeLog);
         world.setBlock(i + 9, j + 9, k + 12, KMOD_Main.LifeLog);
         world.setBlock(i + 9, j + 9, k + 13, KMOD_Main.LifeLog);
         world.setBlock(i + 9, j + 10, k + 10, KMOD_Main.LifeLog);
         world.setBlock(i + 9, j + 10, k + 11, KMOD_Main.LifeLog);
         world.setBlock(i + 9, j + 10, k + 12, KMOD_Main.LifeLog);
         world.setBlock(i + 9, j + 11, k + 10, KMOD_Main.LifeLog);
         world.setBlock(i + 9, j + 11, k + 11, KMOD_Main.LifeLog);
         world.setBlock(i + 9, j + 11, k + 12, KMOD_Main.LifeLog);
         world.setBlock(i + 9, j + 12, k + 10, KMOD_Main.LifeLog);
         world.setBlock(i + 9, j + 12, k + 11, KMOD_Main.LifeLog);
         world.setBlock(i + 9, j + 12, k + 12, KMOD_Main.LifeLog);
         world.setBlock(i + 9, j + 13, k + 10, KMOD_Main.LifeLog);
         world.setBlock(i + 9, j + 13, k + 11, KMOD_Main.LifeLog);
         world.setBlock(i + 9, j + 13, k + 12, KMOD_Main.LifeLog);
         world.setBlock(i + 9, j + 14, k + 10, KMOD_Main.LifeLog);
         world.setBlock(i + 9, j + 14, k + 11, KMOD_Main.LifeLog);
         world.setBlock(i + 9, j + 14, k + 12, KMOD_Main.LifeLog);
         world.setBlock(i + 9, j + 15, k + 10, KMOD_Main.LifeLog);
         world.setBlock(i + 9, j + 15, k + 11, KMOD_Main.LifeLog);
         world.setBlock(i + 9, j + 15, k + 12, KMOD_Main.LifeLog);
         world.setBlock(i + 9, j + 16, k + 10, KMOD_Main.LifeLog);
         world.setBlock(i + 9, j + 16, k + 11, KMOD_Main.LifeLog);
         world.setBlock(i + 9, j + 16, k + 12, KMOD_Main.LifeLog);
         world.setBlock(i + 9, j + 17, k + 10, KMOD_Main.LifeLog);
         world.setBlock(i + 9, j + 17, k + 11, KMOD_Main.LifeLog);
         world.setBlock(i + 9, j + 17, k + 12, KMOD_Main.LifeLog);
         world.setBlock(i + 9, j + 18, k + 10, KMOD_Main.LifeLog);
         world.setBlock(i + 9, j + 18, k + 11, KMOD_Main.LifeLog);
         world.setBlock(i + 9, j + 18, k + 12, KMOD_Main.LifeLog);
         world.setBlock(i + 9, j + 19, k + 10, KMOD_Main.LifeLog);
         world.setBlock(i + 9, j + 19, k + 11, KMOD_Main.LifeLog);
         world.setBlock(i + 9, j + 19, k + 12, KMOD_Main.LifeLog);
         world.setBlock(i + 9, j + 20, k + 10, KMOD_Main.LifeLog);
         world.setBlock(i + 9, j + 20, k + 11, KMOD_Main.LifeLog);
         world.setBlock(i + 9, j + 20, k + 12, KMOD_Main.LifeLog);
         world.setBlock(i + 9, j + 20, k + 13, KMOD_Main.LifeLog);
         world.setBlock(i + 9, j + 20, k + 14, KMOD_Main.LifeLog);
         world.setBlock(i + 9, j + 21, k + 10, KMOD_Main.LifeLog);
         world.setBlock(i + 9, j + 21, k + 11, KMOD_Main.LifeLog);
         world.setBlock(i + 9, j + 21, k + 12, KMOD_Main.LifeLog);
         world.setBlock(i + 9, j + 21, k + 14, KMOD_Main.LifeLog);
         world.setBlock(i + 9, j + 21, k + 15, KMOD_Main.LifeLog);
         world.setBlock(i + 9, j + 21, k + 16, KMOD_Main.LifeLog);
         world.setBlock(i + 9, j + 22, k + 10, KMOD_Main.LifeLog);
         world.setBlock(i + 9, j + 22, k + 11, KMOD_Main.LifeLog);
         world.setBlock(i + 9, j + 22, k + 12, KMOD_Main.LifeLog);
         world.setBlock(i + 9, j + 22, k + 15, KMOD_Main.LifeLog);
         world.setBlock(i + 9, j + 22, k + 16, KMOD_Main.LifeLog);
         world.setBlock(i + 9, j + 22, k + 19, KMOD_Main.LifeLeaves);
         world.setBlock(i + 9, j + 23, k + 10, KMOD_Main.LifeLog);
         world.setBlock(i + 9, j + 23, k + 11, KMOD_Main.LifeLog);
         world.setBlock(i + 9, j + 23, k + 12, KMOD_Main.LifeLog);
         world.setBlock(i + 9, j + 23, k + 19, KMOD_Main.LifeLeaves);
         world.setBlock(i + 9, j + 23, k + 20, KMOD_Main.LifeLeaves);
         world.setBlock(i + 9, j + 24, k + 10, KMOD_Main.LifeLog);
         world.setBlock(i + 9, j + 24, k + 11, KMOD_Main.LifeLog);
         world.setBlock(i + 9, j + 24, k + 12, KMOD_Main.LifeLog);
         world.setBlock(i + 9, j + 24, k + 19, KMOD_Main.LifeLeaves);
         world.setBlock(i + 9, j + 24, k + 20, KMOD_Main.LifeLeaves);
         world.setBlock(i + 9, j + 24, k + 21, KMOD_Main.LifeLeaves);
         world.setBlock(i + 9, j + 25, k + 9, KMOD_Main.LifeLog);
         world.setBlock(i + 9, j + 25, k + 13, KMOD_Main.LifeLog);
         world.setBlock(i + 9, j + 25, k + 18, KMOD_Main.LifeLeaves);
         world.setBlock(i + 9, j + 25, k + 19, KMOD_Main.LifeLeaves);
         world.setBlock(i + 9, j + 25, k + 20, KMOD_Main.LifeLeaves);
         world.setBlock(i + 9, j + 25, k + 21, KMOD_Main.LifeLeaves);
         world.setBlock(i + 9, j + 26, k + 7, KMOD_Main.LifeLeaves);
         world.setBlock(i + 9, j + 26, k + 8, KMOD_Main.LifeLog);
         world.setBlock(i + 9, j + 26, k + 14, KMOD_Main.LifeLog);
         world.setBlock(i + 9, j + 26, k + 15, KMOD_Main.LifeLeaves);
         world.setBlock(i + 9, j + 26, k + 21, KMOD_Main.LifeLeaves);
         world.setBlock(i + 9, j + 27, k + 7, KMOD_Main.LifeLeaves);
         world.setBlock(i + 9, j + 27, k + 8, KMOD_Main.LifeLog);
         world.setBlock(i + 9, j + 27, k + 14, KMOD_Main.LifeLog);
         world.setBlock(i + 9, j + 27, k + 15, KMOD_Main.LifeLeaves);
         world.setBlock(i + 9, j + 28, k + 5, KMOD_Main.LifeLeaves);
         world.setBlock(i + 9, j + 28, k + 6, KMOD_Main.LifeLeaves);
         world.setBlock(i + 9, j + 28, k + 7, KMOD_Main.LifeLeaves);
         world.setBlock(i + 9, j + 28, k + 15, KMOD_Main.LifeLeaves);
         world.setBlock(i + 9, j + 29, k + 5, KMOD_Main.LifeLeaves);
         world.setBlock(i + 9, j + 29, k + 6, KMOD_Main.LifeLeaves);
         world.setBlock(i + 9, j + 29, k + 7, KMOD_Main.LifeLog);
         world.setBlock(i + 9, j + 29, k + 15, KMOD_Main.LifeLog);
         world.setBlock(i + 9, j + 29, k + 16, KMOD_Main.LifeLeaves);
         world.setBlock(i + 9, j + 29, k + 17, KMOD_Main.LifeLeaves);
         world.setBlock(i + 9, j + 29, k + 18, KMOD_Main.LifeLeaves);
         world.setBlock(i + 9, j + 30, k + 6, KMOD_Main.LifeLeaves);
         world.setBlock(i + 9, j + 30, k + 7, KMOD_Main.LifeLeaves);
         world.setBlock(i + 9, j + 30, k + 8, KMOD_Main.LifeLeaves);
         world.setBlock(i + 9, j + 30, k + 9, KMOD_Main.LifeLeaves);
         world.setBlock(i + 9, j + 30, k + 10, KMOD_Main.LifeLog);
         world.setBlock(i + 9, j + 30, k + 11, KMOD_Main.LifeLog);
         world.setBlock(i + 9, j + 30, k + 12, KMOD_Main.LifeLog);
         world.setBlock(i + 9, j + 30, k + 13, KMOD_Main.LifeLeaves);
         world.setBlock(i + 9, j + 30, k + 14, KMOD_Main.LifeLeaves);
         world.setBlock(i + 9, j + 30, k + 15, KMOD_Main.LifeLeaves);
         world.setBlock(i + 9, j + 30, k + 16, KMOD_Main.LifeLeaves);
         world.setBlock(i + 9, j + 31, k + 7, KMOD_Main.LifeLeaves);
         world.setBlock(i + 9, j + 31, k + 8, KMOD_Main.LifeLeaves);
         world.setBlock(i + 9, j + 31, k + 9, KMOD_Main.LifeLeaves);
         world.setBlock(i + 9, j + 31, k + 10, KMOD_Main.LifeLeaves);
         world.setBlock(i + 9, j + 31, k + 11, KMOD_Main.LifeLeaves);
         world.setBlock(i + 9, j + 31, k + 12, KMOD_Main.LifeLeaves);
         world.setBlock(i + 9, j + 31, k + 13, KMOD_Main.LifeLeaves);
         world.setBlock(i + 9, j + 31, k + 14, KMOD_Main.LifeLeaves);
         world.setBlock(i + 9, j + 31, k + 15, KMOD_Main.LifeLeaves);
         world.setBlock(i + 9, j + 32, k + 9, KMOD_Main.LifeLeaves);
         world.setBlock(i + 9, j + 32, k + 10, KMOD_Main.LifeLeaves);
         world.setBlock(i + 9, j + 32, k + 11, KMOD_Main.LifeLeaves);
         world.setBlock(i + 9, j + 32, k + 12, KMOD_Main.LifeLeaves);
         world.setBlock(i + 9, j + 32, k + 13, KMOD_Main.LifeLeaves);
         world.setBlock(i + 9, j + 32, k + 15, KMOD_Main.LifeLeaves);
         world.setBlock(i + 9, j + 32, k + 16, KMOD_Main.LifeLeaves);
         world.setBlock(i + 9, j + 32, k + 17, KMOD_Main.LifeLeaves);
         world.setBlock(i + 9, j + 33, k + 10, KMOD_Main.LifeLeaves);
         world.setBlock(i + 9, j + 34, k + 10, KMOD_Main.LifeLeaves);
         world.setBlock(i + 10, j + 0, k + 9, KMOD_Main.KetherCloud);
         world.setBlock(i + 10, j + 0, k + 12, KMOD_Main.KetherCloud);
         world.setBlock(i + 10, j + 0, k + 16, KMOD_Main.KetherCloud);
         world.setBlock(i + 10, j + 0, k + 17, KMOD_Main.KetherCloud);
         world.setBlock(i + 10, j + 0, k + 18, KMOD_Main.KetherCloud);
         world.setBlock(i + 10, j + 0, k + 19, KMOD_Main.KetherCloud);
         world.setBlock(i + 10, j + 0, k + 20, KMOD_Main.KetherCloud);
         world.setBlock(i + 10, j + 1, k + 3, KMOD_Main.KetherCloud);
         world.setBlock(i + 10, j + 1, k + 4, KMOD_Main.KetherCloud);
         world.setBlock(i + 10, j + 1, k + 5, KMOD_Main.KetherCloud);
         world.setBlock(i + 10, j + 1, k + 6, KMOD_Main.KetherCloud);
         world.setBlock(i + 10, j + 1, k + 7, KMOD_Main.KetherCloud);
         world.setBlock(i + 10, j + 1, k + 8, KMOD_Main.KetherCloud);
         world.setBlock(i + 10, j + 1, k + 9, KMOD_Main.KetherCloud);
         world.setBlock(i + 10, j + 1, k + 10, KMOD_Main.KetherCloud);
         world.setBlock(i + 10, j + 1, k + 11, KMOD_Main.KetherCloud);
         world.setBlock(i + 10, j + 1, k + 12, KMOD_Main.KetherCloud);
         world.setBlock(i + 10, j + 1, k + 13, KMOD_Main.KetherCloud);
         world.setBlock(i + 10, j + 1, k + 14, KMOD_Main.KetherCloud);
         world.setBlock(i + 10, j + 1, k + 15, KMOD_Main.KetherCloud);
         world.setBlock(i + 10, j + 1, k + 16, KMOD_Main.KetherCloud);
         world.setBlock(i + 10, j + 1, k + 17, KMOD_Main.KetherCloud);
         world.setBlock(i + 10, j + 1, k + 18, KMOD_Main.KetherCloud);
         world.setBlock(i + 10, j + 1, k + 19, KMOD_Main.KetherCloud);
         world.setBlock(i + 10, j + 1, k + 20, KMOD_Main.KetherCloud);
         world.setBlock(i + 10, j + 2, k + 3, KMOD_Main.KetherCloud);
         world.setBlock(i + 10, j + 2, k + 4, KMOD_Main.KetherCloud);
         world.setBlock(i + 10, j + 2, k + 5, KMOD_Main.KetherCloud);
         world.setBlock(i + 10, j + 2, k + 6, KMOD_Main.KetherCloud);
         world.setBlock(i + 10, j + 2, k + 7, KMOD_Main.KetherCloud);
         world.setBlock(i + 10, j + 2, k + 8, KMOD_Main.KetherCloud);
         world.setBlock(i + 10, j + 2, k + 9, KMOD_Main.KetherCloud);
         world.setBlock(i + 10, j + 2, k + 10, KMOD_Main.KetherCloud);
         world.setBlock(i + 10, j + 2, k + 11, KMOD_Main.KetherCloud);
         world.setBlock(i + 10, j + 2, k + 12, KMOD_Main.KetherCloud);
         world.setBlock(i + 10, j + 2, k + 13, KMOD_Main.KetherCloud);
         world.setBlock(i + 10, j + 2, k + 14, KMOD_Main.KetherCloud);
         world.setBlock(i + 10, j + 2, k + 15, KMOD_Main.KetherCloud);
         world.setBlock(i + 10, j + 2, k + 16, KMOD_Main.KetherCloud);
         world.setBlock(i + 10, j + 2, k + 17, KMOD_Main.KetherCloud);
         world.setBlock(i + 10, j + 3, k + 7, KMOD_Main.KetherCloud);
         world.setBlock(i + 10, j + 3, k + 8, KMOD_Main.KetherCloud);
         world.setBlock(i + 10, j + 3, k + 9, KMOD_Main.KetherCloud);
         world.setBlock(i + 10, j + 3, k + 10, KMOD_Main.KetherCloud);
         world.setBlock(i + 10, j + 3, k + 11, KMOD_Main.KetherCloud);
         world.setBlock(i + 10, j + 3, k + 12, KMOD_Main.KetherCloud);
         world.setBlock(i + 10, j + 3, k + 13, KMOD_Main.KetherCloud);
         world.setBlock(i + 10, j + 3, k + 14, KMOD_Main.KetherCloud);
         world.setBlock(i + 10, j + 3, k + 15, KMOD_Main.KetherCloud);
         world.setBlock(i + 10, j + 7, k + 14, KMOD_Main.LifeLog);
         world.setBlock(i + 10, j + 8, k + 8, KMOD_Main.LifeLog);
         world.setBlock(i + 10, j + 8, k + 9, KMOD_Main.LifeLog);
         world.setBlock(i + 10, j + 8, k + 13, KMOD_Main.LifeLog);
         world.setBlock(i + 10, j + 8, k + 14, KMOD_Main.LifeLog);
         world.setBlock(i + 10, j + 9, k + 9, KMOD_Main.LifeLog);
         world.setBlock(i + 10, j + 9, k + 13, KMOD_Main.LifeLog);
         world.setBlock(i + 10, j + 10, k + 9, KMOD_Main.LifeLog);
         world.setBlock(i + 10, j + 10, k + 13, KMOD_Main.LifeLog);
         world.setBlock(i + 10, j + 11, k + 9, KMOD_Main.LifeLog);
         world.setBlock(i + 10, j + 11, k + 13, KMOD_Main.LifeLog);
         world.setBlock(i + 10, j + 12, k + 9, KMOD_Main.LifeLog);
         world.setBlock(i + 10, j + 12, k + 13, KMOD_Main.LifeLog);
         world.setBlock(i + 10, j + 13, k + 9, KMOD_Main.LifeLog);
         world.setBlock(i + 10, j + 13, k + 13, KMOD_Main.LifeLog);
         world.setBlock(i + 10, j + 14, k + 9, KMOD_Main.LifeLog);
         world.setBlock(i + 10, j + 14, k + 13, KMOD_Main.LifeLog);
         world.setBlock(i + 10, j + 15, k + 9, KMOD_Main.LifeLog);
         world.setBlock(i + 10, j + 15, k + 13, KMOD_Main.LifeLog);
         world.setBlock(i + 10, j + 16, k + 9, KMOD_Main.LifeLog);
         world.setBlock(i + 10, j + 16, k + 13, KMOD_Main.LifeLog);
         world.setBlock(i + 10, j + 17, k + 9, KMOD_Main.LifeLog);
         world.setBlock(i + 10, j + 17, k + 13, KMOD_Main.LifeLog);
         world.setBlock(i + 10, j + 18, k + 9, KMOD_Main.LifeLog);
         world.setBlock(i + 10, j + 18, k + 13, KMOD_Main.LifeLog);
         world.setBlock(i + 10, j + 19, k + 9, KMOD_Main.LifeLog);
         world.setBlock(i + 10, j + 19, k + 13, KMOD_Main.LifeLog);
         world.setBlock(i + 10, j + 20, k + 9, KMOD_Main.LifeLog);
         world.setBlock(i + 10, j + 20, k + 13, KMOD_Main.LifeLog);
         world.setBlock(i + 10, j + 20, k + 14, KMOD_Main.LifeLog);
         world.setBlock(i + 10, j + 21, k + 9, KMOD_Main.LifeLog);
         world.setBlock(i + 10, j + 21, k + 13, KMOD_Main.LifeLog);
         world.setBlock(i + 10, j + 21, k + 14, KMOD_Main.LifeLog);
         world.setBlock(i + 10, j + 22, k + 9, KMOD_Main.LifeLog);
         world.setBlock(i + 10, j + 22, k + 13, KMOD_Main.LifeLog);
         world.setBlock(i + 10, j + 23, k + 9, KMOD_Main.LifeLog);
         world.setBlock(i + 10, j + 23, k + 13, KMOD_Main.LifeLog);
         world.setBlock(i + 10, j + 24, k + 9, KMOD_Main.LifeLog);
         world.setBlock(i + 10, j + 24, k + 13, KMOD_Main.LifeLog);
         world.setBlock(i + 10, j + 24, k + 20, KMOD_Main.LifeLeaves);
         world.setBlock(i + 10, j + 25, k + 8, KMOD_Main.LifeLog);
         world.setBlock(i + 10, j + 25, k + 14, KMOD_Main.LifeLog);
         world.setBlock(i + 10, j + 25, k + 20, KMOD_Main.LifeLeaves);
         world.setBlock(i + 10, j + 26, k + 6, KMOD_Main.LifeLeaves);
         world.setBlock(i + 10, j + 26, k + 7, KMOD_Main.LifeLog);
         world.setBlock(i + 10, j + 26, k + 15, KMOD_Main.LifeLog);
         world.setBlock(i + 10, j + 26, k + 16, KMOD_Main.LifeLeaves);
         world.setBlock(i + 10, j + 27, k + 6, KMOD_Main.LifeLeaves);
         world.setBlock(i + 10, j + 27, k + 7, KMOD_Main.LifeLog);
         world.setBlock(i + 10, j + 27, k + 15, KMOD_Main.LifeLog);
         world.setBlock(i + 10, j + 27, k + 16, KMOD_Main.LifeLeaves);
         world.setBlock(i + 10, j + 28, k + 3, KMOD_Main.LifeLeaves);
         world.setBlock(i + 10, j + 28, k + 4, KMOD_Main.LifeLeaves);
         world.setBlock(i + 10, j + 28, k + 5, KMOD_Main.LifeLeaves);
         world.setBlock(i + 10, j + 28, k + 6, KMOD_Main.LifeLeaves);
         world.setBlock(i + 10, j + 28, k + 16, KMOD_Main.LifeLeaves);
         world.setBlock(i + 10, j + 28, k + 17, KMOD_Main.LifeLeaves);
         world.setBlock(i + 10, j + 29, k + 2, KMOD_Main.LifeLeaves);
         world.setBlock(i + 10, j + 29, k + 3, KMOD_Main.LifeLeaves);
         world.setBlock(i + 10, j + 29, k + 4, KMOD_Main.LifeLeaves);
         world.setBlock(i + 10, j + 29, k + 5, KMOD_Main.LifeLeaves);
         world.setBlock(i + 10, j + 29, k + 6, KMOD_Main.LifeLog);
         world.setBlock(i + 10, j + 29, k + 16, KMOD_Main.LifeLog);
         world.setBlock(i + 10, j + 29, k + 17, KMOD_Main.LifeLeaves);
         world.setBlock(i + 10, j + 29, k + 18, KMOD_Main.LifeLeaves);
         world.setBlock(i + 10, j + 30, k + 5, KMOD_Main.LifeLeaves);
         world.setBlock(i + 10, j + 30, k + 6, KMOD_Main.LifeLeaves);
         world.setBlock(i + 10, j + 30, k + 7, KMOD_Main.LifeLeaves);
         world.setBlock(i + 10, j + 30, k + 8, KMOD_Main.LifeLeaves);
         world.setBlock(i + 10, j + 30, k + 9, KMOD_Main.LifeLeaves);
         world.setBlock(i + 10, j + 30, k + 10, KMOD_Main.LifeLog);
         world.setBlock(i + 10, j + 30, k + 11, KMOD_Main.LifeLog);
         world.setBlock(i + 10, j + 30, k + 12, KMOD_Main.LifeLog);
         world.setBlock(i + 10, j + 30, k + 13, KMOD_Main.LifeLeaves);
         world.setBlock(i + 10, j + 30, k + 14, KMOD_Main.LifeLeaves);
         world.setBlock(i + 10, j + 30, k + 15, KMOD_Main.LifeLeaves);
         world.setBlock(i + 10, j + 30, k + 16, KMOD_Main.LifeLeaves);
         world.setBlock(i + 10, j + 30, k + 17, KMOD_Main.LifeLeaves);
         world.setBlock(i + 10, j + 31, k + 4, KMOD_Main.LifeLeaves);
         world.setBlock(i + 10, j + 31, k + 5, KMOD_Main.LifeLeaves);
         world.setBlock(i + 10, j + 31, k + 6, KMOD_Main.LifeLeaves);
         world.setBlock(i + 10, j + 31, k + 7, KMOD_Main.LifeLeaves);
         world.setBlock(i + 10, j + 31, k + 8, KMOD_Main.LifeLeaves);
         world.setBlock(i + 10, j + 31, k + 9, KMOD_Main.LifeLeaves);
         world.setBlock(i + 10, j + 31, k + 10, KMOD_Main.LifeLeaves);
         world.setBlock(i + 10, j + 31, k + 11, KMOD_Main.LifeLeaves);
         world.setBlock(i + 10, j + 31, k + 13, KMOD_Main.LifeLeaves);
         world.setBlock(i + 10, j + 31, k + 14, KMOD_Main.LifeLeaves);
         world.setBlock(i + 10, j + 31, k + 15, KMOD_Main.LifeLeaves);
         world.setBlock(i + 10, j + 31, k + 16, KMOD_Main.LifeLeaves);
         world.setBlock(i + 10, j + 32, k + 8, KMOD_Main.LifeLeaves);
         world.setBlock(i + 10, j + 32, k + 9, KMOD_Main.LifeLeaves);
         world.setBlock(i + 10, j + 32, k + 10, KMOD_Main.LifeLeaves);
         world.setBlock(i + 10, j + 32, k + 11, KMOD_Main.LifeLeaves);
         world.setBlock(i + 10, j + 32, k + 12, KMOD_Main.LifeLeaves);
         world.setBlock(i + 10, j + 32, k + 13, KMOD_Main.LifeLeaves);
         world.setBlock(i + 10, j + 32, k + 14, KMOD_Main.LifeLeaves);
         world.setBlock(i + 10, j + 33, k + 8, KMOD_Main.LifeLeaves);
         world.setBlock(i + 10, j + 33, k + 10, KMOD_Main.LifeLeaves);
         world.setBlock(i + 10, j + 33, k + 11, KMOD_Main.LifeLeaves);
         world.setBlock(i + 10, j + 33, k + 13, KMOD_Main.LifeLeaves);
         world.setBlock(i + 10, j + 33, k + 14, KMOD_Main.LifeLeaves);
         world.setBlock(i + 10, j + 34, k + 13, KMOD_Main.LifeLeaves);
         world.setBlock(i + 11, j + 0, k + 8, KMOD_Main.KetherCloud);
         world.setBlock(i + 11, j + 0, k + 9, KMOD_Main.KetherCloud);
         world.setBlock(i + 11, j + 0, k + 10, KMOD_Main.KetherCloud);
         world.setBlock(i + 11, j + 0, k + 11, KMOD_Main.KetherCloud);
         world.setBlock(i + 11, j + 0, k + 12, KMOD_Main.KetherCloud);
         world.setBlock(i + 11, j + 0, k + 13, KMOD_Main.KetherCloud);
         world.setBlock(i + 11, j + 0, k + 17, KMOD_Main.KetherCloud);
         world.setBlock(i + 11, j + 0, k + 18, KMOD_Main.KetherCloud);
         world.setBlock(i + 11, j + 0, k + 19, KMOD_Main.KetherCloud);
         world.setBlock(i + 11, j + 1, k + 2, KMOD_Main.KetherCloud);
         world.setBlock(i + 11, j + 1, k + 3, KMOD_Main.KetherCloud);
         world.setBlock(i + 11, j + 1, k + 4, KMOD_Main.KetherCloud);
         world.setBlock(i + 11, j + 1, k + 5, KMOD_Main.KetherCloud);
         world.setBlock(i + 11, j + 1, k + 6, KMOD_Main.KetherCloud);
         world.setBlock(i + 11, j + 1, k + 7, KMOD_Main.KetherCloud);
         world.setBlock(i + 11, j + 1, k + 8, KMOD_Main.KetherCloud);
         world.setBlock(i + 11, j + 1, k + 9, KMOD_Main.KetherCloud);
         world.setBlock(i + 11, j + 1, k + 10, KMOD_Main.KetherCloud);
         world.setBlock(i + 11, j + 1, k + 11, KMOD_Main.KetherCloud);
         world.setBlock(i + 11, j + 1, k + 12, KMOD_Main.KetherCloud);
         world.setBlock(i + 11, j + 1, k + 13, KMOD_Main.KetherCloud);
         world.setBlock(i + 11, j + 1, k + 14, KMOD_Main.KetherCloud);
         world.setBlock(i + 11, j + 1, k + 15, KMOD_Main.KetherCloud);
         world.setBlock(i + 11, j + 1, k + 16, KMOD_Main.KetherCloud);
         world.setBlock(i + 11, j + 1, k + 17, KMOD_Main.KetherCloud);
         world.setBlock(i + 11, j + 1, k + 18, KMOD_Main.KetherCloud);
         world.setBlock(i + 11, j + 1, k + 19, KMOD_Main.KetherCloud);
         world.setBlock(i + 11, j + 2, k + 2, KMOD_Main.KetherCloud);
         world.setBlock(i + 11, j + 2, k + 3, KMOD_Main.KetherCloud);
         world.setBlock(i + 11, j + 2, k + 4, KMOD_Main.KetherCloud);
         world.setBlock(i + 11, j + 2, k + 5, KMOD_Main.KetherCloud);
         world.setBlock(i + 11, j + 2, k + 6, KMOD_Main.KetherCloud);
         world.setBlock(i + 11, j + 2, k + 7, KMOD_Main.KetherCloud);
         world.setBlock(i + 11, j + 2, k + 8, KMOD_Main.KetherCloud);
         world.setBlock(i + 11, j + 2, k + 9, KMOD_Main.KetherCloud);
         world.setBlock(i + 11, j + 2, k + 10, KMOD_Main.KetherCloud);
         world.setBlock(i + 11, j + 2, k + 11, KMOD_Main.KetherCloud);
         world.setBlock(i + 11, j + 2, k + 12, KMOD_Main.KetherCloud);
         world.setBlock(i + 11, j + 2, k + 13, KMOD_Main.KetherCloud);
         world.setBlock(i + 11, j + 2, k + 14, KMOD_Main.KetherCloud);
         world.setBlock(i + 11, j + 2, k + 15, KMOD_Main.KetherCloud);
         world.setBlock(i + 11, j + 2, k + 16, KMOD_Main.KetherCloud);
         world.setBlock(i + 11, j + 2, k + 17, KMOD_Main.KetherCloud);
         world.setBlock(i + 11, j + 2, k + 18, KMOD_Main.KetherCloud);
         world.setBlock(i + 11, j + 3, k + 6, KMOD_Main.KetherCloud);
         world.setBlock(i + 11, j + 3, k + 7, KMOD_Main.KetherCloud);
         world.setBlock(i + 11, j + 3, k + 8, KMOD_Main.KetherCloud);
         world.setBlock(i + 11, j + 3, k + 9, KMOD_Main.KetherCloud);
         world.setBlock(i + 11, j + 3, k + 10, KMOD_Main.KetherCloud);
         world.setBlock(i + 11, j + 3, k + 11, KMOD_Main.KetherCloud);
         world.setBlock(i + 11, j + 3, k + 12, KMOD_Main.KetherCloud);
         world.setBlock(i + 11, j + 3, k + 13, KMOD_Main.KetherCloud);
         world.setBlock(i + 11, j + 3, k + 14, KMOD_Main.KetherCloud);
         world.setBlock(i + 11, j + 4, k + 11, KMOD_Main.GiftsBlock);
         world.setBlock(i + 11, j + 9, k + 8, KMOD_Main.LifeLog);
         world.setBlock(i + 11, j + 9, k + 9, KMOD_Main.LifeLog);
         world.setBlock(i + 11, j + 9, k + 13, KMOD_Main.LifeLog);
         world.setBlock(i + 11, j + 9, k + 14, KMOD_Main.LifeLog);
         world.setBlock(i + 11, j + 10, k + 9, KMOD_Main.LifeLog);
         world.setBlock(i + 11, j + 10, k + 13, KMOD_Main.LifeLog);
         world.setBlock(i + 11, j + 11, k + 9, KMOD_Main.LifeLog);
         world.setBlock(i + 11, j + 11, k + 13, KMOD_Main.LifeLog);
         world.setBlock(i + 11, j + 12, k + 9, KMOD_Main.LifeLog);
         world.setBlock(i + 11, j + 12, k + 13, KMOD_Main.LifeLog);
         world.setBlock(i + 11, j + 13, k + 9, KMOD_Main.LifeLog);
         world.setBlock(i + 11, j + 13, k + 13, KMOD_Main.LifeLog);
         world.setBlock(i + 11, j + 14, k + 9, KMOD_Main.LifeLog);
         world.setBlock(i + 11, j + 14, k + 13, KMOD_Main.LifeLog);
         world.setBlock(i + 11, j + 15, k + 9, KMOD_Main.LifeLog);
         world.setBlock(i + 11, j + 15, k + 13, KMOD_Main.LifeLog);
         world.setBlock(i + 11, j + 16, k + 9, KMOD_Main.LifeLog);
         world.setBlock(i + 11, j + 16, k + 13, KMOD_Main.LifeLog);
         world.setBlock(i + 11, j + 17, k + 9, KMOD_Main.LifeLog);
         world.setBlock(i + 11, j + 17, k + 13, KMOD_Main.LifeLog);
         world.setBlock(i + 11, j + 18, k + 9, KMOD_Main.LifeLog);
         world.setBlock(i + 11, j + 18, k + 13, KMOD_Main.LifeLog);
         world.setBlock(i + 11, j + 19, k + 9, KMOD_Main.LifeLog);
         world.setBlock(i + 11, j + 19, k + 13, KMOD_Main.LifeLog);
         world.setBlock(i + 11, j + 20, k + 9, KMOD_Main.LifeLog);
         world.setBlock(i + 11, j + 20, k + 13, KMOD_Main.LifeLog);
         world.setBlock(i + 11, j + 21, k + 9, KMOD_Main.LifeLog);
         world.setBlock(i + 11, j + 21, k + 13, KMOD_Main.LifeLog);
         world.setBlock(i + 11, j + 22, k + 9, KMOD_Main.LifeLog);
         world.setBlock(i + 11, j + 22, k + 13, KMOD_Main.LifeLog);
         world.setBlock(i + 11, j + 23, k + 9, KMOD_Main.LifeLog);
         world.setBlock(i + 11, j + 23, k + 13, KMOD_Main.LifeLog);
         world.setBlock(i + 11, j + 24, k + 9, KMOD_Main.LifeLog);
         world.setBlock(i + 11, j + 24, k + 13, KMOD_Main.LifeLog);
         world.setBlock(i + 11, j + 25, k + 8, KMOD_Main.LifeLog);
         world.setBlock(i + 11, j + 25, k + 14, KMOD_Main.LifeLog);
         world.setBlock(i + 11, j + 26, k + 6, KMOD_Main.LifeLeaves);
         world.setBlock(i + 11, j + 26, k + 7, KMOD_Main.LifeLog);
         world.setBlock(i + 11, j + 26, k + 15, KMOD_Main.LifeLog);
         world.setBlock(i + 11, j + 26, k + 16, KMOD_Main.LifeLeaves);
         world.setBlock(i + 11, j + 27, k + 6, KMOD_Main.LifeLeaves);
         world.setBlock(i + 11, j + 27, k + 7, KMOD_Main.LifeLog);
         world.setBlock(i + 11, j + 27, k + 15, KMOD_Main.LifeLog);
         world.setBlock(i + 11, j + 27, k + 16, KMOD_Main.LifeLeaves);
         world.setBlock(i + 11, j + 28, k + 4, KMOD_Main.LifeLeaves);
         world.setBlock(i + 11, j + 28, k + 5, KMOD_Main.LifeLeaves);
         world.setBlock(i + 11, j + 28, k + 6, KMOD_Main.LifeLeaves);
         world.setBlock(i + 11, j + 28, k + 16, KMOD_Main.LifeLeaves);
         world.setBlock(i + 11, j + 28, k + 17, KMOD_Main.LifeLeaves);
         world.setBlock(i + 11, j + 29, k + 4, KMOD_Main.LifeLeaves);
         world.setBlock(i + 11, j + 29, k + 5, KMOD_Main.LifeLeaves);
         world.setBlock(i + 11, j + 29, k + 6, KMOD_Main.LifeLog);
         world.setBlock(i + 11, j + 29, k + 16, KMOD_Main.LifeLog);
         world.setBlock(i + 11, j + 29, k + 17, KMOD_Main.LifeLeaves);
         world.setBlock(i + 11, j + 29, k + 18, KMOD_Main.LifeLeaves);
         world.setBlock(i + 11, j + 30, k + 5, KMOD_Main.LifeLeaves);
         world.setBlock(i + 11, j + 30, k + 6, KMOD_Main.LifeLeaves);
         world.setBlock(i + 11, j + 30, k + 7, KMOD_Main.LifeLeaves);
         world.setBlock(i + 11, j + 30, k + 8, KMOD_Main.LifeLeaves);
         world.setBlock(i + 11, j + 30, k + 9, KMOD_Main.LifeLeaves);
         world.setBlock(i + 11, j + 30, k + 10, KMOD_Main.LifeLog);
         world.setBlock(i + 11, j + 30, k + 11, KMOD_Main.LifeLog);
         world.setBlock(i + 11, j + 30, k + 12, KMOD_Main.LifeLog);
         world.setBlock(i + 11, j + 30, k + 13, KMOD_Main.LifeLeaves);
         world.setBlock(i + 11, j + 30, k + 14, KMOD_Main.LifeLeaves);
         world.setBlock(i + 11, j + 30, k + 15, KMOD_Main.LifeLeaves);
         world.setBlock(i + 11, j + 30, k + 16, KMOD_Main.LifeLeaves);
         world.setBlock(i + 11, j + 30, k + 17, KMOD_Main.LifeLeaves);
         world.setBlock(i + 11, j + 31, k + 4, KMOD_Main.LifeLeaves);
         world.setBlock(i + 11, j + 31, k + 5, KMOD_Main.LifeLeaves);
         world.setBlock(i + 11, j + 31, k + 6, KMOD_Main.LifeLeaves);
         world.setBlock(i + 11, j + 31, k + 8, KMOD_Main.LifeLeaves);
         world.setBlock(i + 11, j + 31, k + 9, KMOD_Main.LifeLeaves);
         world.setBlock(i + 11, j + 31, k + 10, KMOD_Main.LifeLeaves);
         world.setBlock(i + 11, j + 31, k + 11, KMOD_Main.LifeLeaves);
         world.setBlock(i + 11, j + 31, k + 12, KMOD_Main.LifeLeaves);
         world.setBlock(i + 11, j + 31, k + 13, KMOD_Main.LifeLeaves);
         world.setBlock(i + 11, j + 31, k + 14, KMOD_Main.LifeLeaves);
         world.setBlock(i + 11, j + 31, k + 15, KMOD_Main.LifeLeaves);
         world.setBlock(i + 11, j + 31, k + 16, KMOD_Main.LifeLeaves);
         world.setBlock(i + 11, j + 31, k + 17, KMOD_Main.LifeLeaves);
         world.setBlock(i + 11, j + 31, k + 18, KMOD_Main.LifeLeaves);
         world.setBlock(i + 11, j + 32, k + 8, KMOD_Main.LifeLeaves);
         world.setBlock(i + 11, j + 32, k + 9, KMOD_Main.LifeLeaves);
         world.setBlock(i + 11, j + 32, k + 10, KMOD_Main.LifeLeaves);
         world.setBlock(i + 11, j + 32, k + 11, KMOD_Main.LifeLeaves);
         world.setBlock(i + 11, j + 32, k + 12, KMOD_Main.LifeLeaves);
         world.setBlock(i + 11, j + 32, k + 13, KMOD_Main.LifeLeaves);
         world.setBlock(i + 11, j + 32, k + 14, KMOD_Main.LifeLeaves);
         world.setBlock(i + 11, j + 32, k + 18, KMOD_Main.LifeLeaves);
         world.setBlock(i + 11, j + 33, k + 7, KMOD_Main.LifeLeaves);
         world.setBlock(i + 11, j + 33, k + 8, KMOD_Main.LifeLeaves);
         world.setBlock(i + 11, j + 33, k + 9, KMOD_Main.LifeLeaves);
         world.setBlock(i + 11, j + 33, k + 11, KMOD_Main.LifeLeaves);
         world.setBlock(i + 11, j + 33, k + 12, KMOD_Main.LifeLeaves);
         world.setBlock(i + 11, j + 33, k + 13, KMOD_Main.LifeLeaves);
         world.setBlock(i + 11, j + 34, k + 7, KMOD_Main.LifeLeaves);
         world.setBlock(i + 11, j + 34, k + 11, KMOD_Main.LifeLeaves);
         world.setBlock(i + 12, j + 0, k + 7, KMOD_Main.KetherCloud);
         world.setBlock(i + 12, j + 0, k + 8, KMOD_Main.KetherCloud);
         world.setBlock(i + 12, j + 0, k + 9, KMOD_Main.KetherCloud);
         world.setBlock(i + 12, j + 0, k + 10, KMOD_Main.KetherCloud);
         world.setBlock(i + 12, j + 0, k + 11, KMOD_Main.KetherCloud);
         world.setBlock(i + 12, j + 0, k + 12, KMOD_Main.KetherCloud);
         world.setBlock(i + 12, j + 0, k + 13, KMOD_Main.KetherCloud);
         world.setBlock(i + 12, j + 0, k + 14, KMOD_Main.KetherCloud);
         world.setBlock(i + 12, j + 0, k + 18, KMOD_Main.KetherCloud);
         world.setBlock(i + 12, j + 1, k + 1, KMOD_Main.KetherCloud);
         world.setBlock(i + 12, j + 1, k + 2, KMOD_Main.KetherCloud);
         world.setBlock(i + 12, j + 1, k + 3, KMOD_Main.KetherCloud);
         world.setBlock(i + 12, j + 1, k + 4, KMOD_Main.KetherCloud);
         world.setBlock(i + 12, j + 1, k + 5, KMOD_Main.KetherCloud);
         world.setBlock(i + 12, j + 1, k + 6, KMOD_Main.KetherCloud);
         world.setBlock(i + 12, j + 1, k + 7, KMOD_Main.KetherCloud);
         world.setBlock(i + 12, j + 1, k + 8, KMOD_Main.KetherCloud);
         world.setBlock(i + 12, j + 1, k + 9, KMOD_Main.KetherCloud);
         world.setBlock(i + 12, j + 1, k + 10, KMOD_Main.KetherCloud);
         world.setBlock(i + 12, j + 1, k + 11, KMOD_Main.KetherCloud);
         world.setBlock(i + 12, j + 1, k + 12, KMOD_Main.KetherCloud);
         world.setBlock(i + 12, j + 1, k + 13, KMOD_Main.KetherCloud);
         world.setBlock(i + 12, j + 1, k + 14, KMOD_Main.KetherCloud);
         world.setBlock(i + 12, j + 1, k + 15, KMOD_Main.KetherCloud);
         world.setBlock(i + 12, j + 1, k + 16, KMOD_Main.KetherCloud);
         world.setBlock(i + 12, j + 1, k + 17, KMOD_Main.KetherCloud);
         world.setBlock(i + 12, j + 1, k + 18, KMOD_Main.KetherCloud);
         world.setBlock(i + 12, j + 1, k + 19, KMOD_Main.KetherCloud);
         world.setBlock(i + 12, j + 2, k + 1, KMOD_Main.KetherCloud);
         world.setBlock(i + 12, j + 2, k + 2, KMOD_Main.KetherCloud);
         world.setBlock(i + 12, j + 2, k + 3, KMOD_Main.KetherCloud);
         world.setBlock(i + 12, j + 2, k + 4, KMOD_Main.KetherCloud);
         world.setBlock(i + 12, j + 2, k + 5, KMOD_Main.KetherCloud);
         world.setBlock(i + 12, j + 2, k + 6, KMOD_Main.KetherCloud);
         world.setBlock(i + 12, j + 2, k + 7, KMOD_Main.KetherCloud);
         world.setBlock(i + 12, j + 2, k + 8, KMOD_Main.KetherCloud);
         world.setBlock(i + 12, j + 2, k + 9, KMOD_Main.KetherCloud);
         world.setBlock(i + 12, j + 2, k + 10, KMOD_Main.KetherCloud);
         world.setBlock(i + 12, j + 2, k + 11, KMOD_Main.KetherCloud);
         world.setBlock(i + 12, j + 2, k + 12, KMOD_Main.KetherCloud);
         world.setBlock(i + 12, j + 2, k + 13, KMOD_Main.KetherCloud);
         world.setBlock(i + 12, j + 2, k + 14, KMOD_Main.KetherCloud);
         world.setBlock(i + 12, j + 2, k + 15, KMOD_Main.KetherCloud);
         world.setBlock(i + 12, j + 2, k + 16, KMOD_Main.KetherCloud);
         world.setBlock(i + 12, j + 2, k + 17, KMOD_Main.KetherCloud);
         world.setBlock(i + 12, j + 2, k + 18, KMOD_Main.KetherCloud);
         world.setBlock(i + 12, j + 2, k + 19, KMOD_Main.KetherCloud);
         world.setBlock(i + 12, j + 3, k + 5, KMOD_Main.KetherCloud);
         world.setBlock(i + 12, j + 3, k + 6, KMOD_Main.KetherCloud);
         world.setBlock(i + 12, j + 3, k + 7, KMOD_Main.KetherCloud);
         world.setBlock(i + 12, j + 3, k + 8, KMOD_Main.KetherCloud);
         world.setBlock(i + 12, j + 3, k + 9, KMOD_Main.KetherCloud);
         world.setBlock(i + 12, j + 3, k + 10, KMOD_Main.KetherCloud);
         world.setBlock(i + 12, j + 3, k + 11, KMOD_Main.KetherCloud);
         world.setBlock(i + 12, j + 3, k + 12, KMOD_Main.KetherCloud);
         world.setBlock(i + 12, j + 3, k + 13, KMOD_Main.KetherCloud);
         world.setBlock(i + 12, j + 3, k + 14, KMOD_Main.KetherCloud);
         world.setBlock(i + 12, j + 3, k + 15, KMOD_Main.KetherCloud);
         world.setBlock(i + 12, j + 7, k + 8, KMOD_Main.LifeLog);
         world.setBlock(i + 12, j + 7, k + 14, KMOD_Main.LifeLog);
         world.setBlock(i + 12, j + 8, k + 8, KMOD_Main.LifeLog);
         world.setBlock(i + 12, j + 8, k + 9, KMOD_Main.LifeLog);
         world.setBlock(i + 12, j + 8, k + 13, KMOD_Main.LifeLog);
         world.setBlock(i + 12, j + 8, k + 14, KMOD_Main.LifeLog);
         world.setBlock(i + 12, j + 9, k + 9, KMOD_Main.LifeLog);
         world.setBlock(i + 12, j + 9, k + 13, KMOD_Main.LifeLog);
         world.setBlock(i + 12, j + 10, k + 9, KMOD_Main.LifeLog);
         world.setBlock(i + 12, j + 10, k + 13, KMOD_Main.LifeLog);
         world.setBlock(i + 12, j + 11, k + 9, KMOD_Main.LifeLog);
         world.setBlock(i + 12, j + 11, k + 13, KMOD_Main.LifeLog);
         world.setBlock(i + 12, j + 12, k + 9, KMOD_Main.LifeLog);
         world.setBlock(i + 12, j + 12, k + 13, KMOD_Main.LifeLog);
         world.setBlock(i + 12, j + 13, k + 9, KMOD_Main.LifeLog);
         world.setBlock(i + 12, j + 13, k + 13, KMOD_Main.LifeLog);
         world.setBlock(i + 12, j + 14, k + 9, KMOD_Main.LifeLog);
         world.setBlock(i + 12, j + 14, k + 13, KMOD_Main.LifeLog);
         world.setBlock(i + 12, j + 15, k + 9, KMOD_Main.LifeLog);
         world.setBlock(i + 12, j + 15, k + 13, KMOD_Main.LifeLog);
         world.setBlock(i + 12, j + 16, k + 9, KMOD_Main.LifeLog);
         world.setBlock(i + 12, j + 16, k + 13, KMOD_Main.LifeLog);
         world.setBlock(i + 12, j + 17, k + 9, KMOD_Main.LifeLog);
         world.setBlock(i + 12, j + 17, k + 13, KMOD_Main.LifeLog);
         world.setBlock(i + 12, j + 18, k + 9, KMOD_Main.LifeLog);
         world.setBlock(i + 12, j + 18, k + 13, KMOD_Main.LifeLog);
         world.setBlock(i + 12, j + 19, k + 9, KMOD_Main.LifeLog);
         world.setBlock(i + 12, j + 19, k + 13, KMOD_Main.LifeLog);
         world.setBlock(i + 12, j + 20, k + 9, KMOD_Main.LifeLog);
         world.setBlock(i + 12, j + 20, k + 13, KMOD_Main.LifeLog);
         world.setBlock(i + 12, j + 21, k + 9, KMOD_Main.LifeLog);
         world.setBlock(i + 12, j + 21, k + 13, KMOD_Main.LifeLog);
         world.setBlock(i + 12, j + 22, k + 9, KMOD_Main.LifeLog);
         world.setBlock(i + 12, j + 22, k + 13, KMOD_Main.LifeLog);
         world.setBlock(i + 12, j + 23, k + 9, KMOD_Main.LifeLog);
         world.setBlock(i + 12, j + 23, k + 13, KMOD_Main.LifeLog);
         world.setBlock(i + 12, j + 24, k + 9, KMOD_Main.LifeLog);
         world.setBlock(i + 12, j + 24, k + 13, KMOD_Main.LifeLog);
         world.setBlock(i + 12, j + 25, k + 8, KMOD_Main.LifeLog);
         world.setBlock(i + 12, j + 25, k + 14, KMOD_Main.LifeLog);
         world.setBlock(i + 12, j + 26, k + 6, KMOD_Main.LifeLeaves);
         world.setBlock(i + 12, j + 26, k + 7, KMOD_Main.LifeLog);
         world.setBlock(i + 12, j + 26, k + 15, KMOD_Main.LifeLog);
         world.setBlock(i + 12, j + 26, k + 16, KMOD_Main.LifeLeaves);
         world.setBlock(i + 12, j + 27, k + 6, KMOD_Main.LifeLeaves);
         world.setBlock(i + 12, j + 27, k + 7, KMOD_Main.LifeLog);
         world.setBlock(i + 12, j + 27, k + 15, KMOD_Main.LifeLog);
         world.setBlock(i + 12, j + 27, k + 16, KMOD_Main.LifeLeaves);
         world.setBlock(i + 12, j + 27, k + 17, KMOD_Main.LifeLeaves);
         world.setBlock(i + 12, j + 28, k + 5, KMOD_Main.LifeLeaves);
         world.setBlock(i + 12, j + 28, k + 6, KMOD_Main.LifeLeaves);
         world.setBlock(i + 12, j + 28, k + 16, KMOD_Main.LifeLeaves);
         world.setBlock(i + 12, j + 28, k + 17, KMOD_Main.LifeLeaves);
         world.setBlock(i + 12, j + 29, k + 4, KMOD_Main.LifeLeaves);
         world.setBlock(i + 12, j + 29, k + 5, KMOD_Main.LifeLeaves);
         world.setBlock(i + 12, j + 29, k + 6, KMOD_Main.LifeLog);
         world.setBlock(i + 12, j + 29, k + 16, KMOD_Main.LifeLog);
         world.setBlock(i + 12, j + 29, k + 17, KMOD_Main.LifeLeaves);
         world.setBlock(i + 12, j + 29, k + 18, KMOD_Main.LifeLeaves);
         world.setBlock(i + 12, j + 30, k + 4, KMOD_Main.LifeLeaves);
         world.setBlock(i + 12, j + 30, k + 5, KMOD_Main.LifeLeaves);
         world.setBlock(i + 12, j + 30, k + 6, KMOD_Main.LifeLeaves);
         world.setBlock(i + 12, j + 30, k + 7, KMOD_Main.LifeLeaves);
         world.setBlock(i + 12, j + 30, k + 8, KMOD_Main.LifeLeaves);
         world.setBlock(i + 12, j + 30, k + 9, KMOD_Main.LifeLeaves);
         world.setBlock(i + 12, j + 30, k + 10, KMOD_Main.LifeLeaves);
         world.setBlock(i + 12, j + 30, k + 11, KMOD_Main.LifeLeaves);
         world.setBlock(i + 12, j + 30, k + 12, KMOD_Main.LifeLeaves);
         world.setBlock(i + 12, j + 30, k + 13, KMOD_Main.LifeLeaves);
         world.setBlock(i + 12, j + 30, k + 14, KMOD_Main.LifeLeaves);
         world.setBlock(i + 12, j + 30, k + 15, KMOD_Main.LifeLeaves);
         world.setBlock(i + 12, j + 30, k + 16, KMOD_Main.LifeLeaves);
         world.setBlock(i + 12, j + 30, k + 17, KMOD_Main.LifeLeaves);
         world.setBlock(i + 12, j + 31, k + 4, KMOD_Main.LifeLeaves);
         world.setBlock(i + 12, j + 31, k + 5, KMOD_Main.LifeLeaves);
         world.setBlock(i + 12, j + 31, k + 6, KMOD_Main.LifeLeaves);
         world.setBlock(i + 12, j + 31, k + 7, KMOD_Main.LifeLeaves);
         world.setBlock(i + 12, j + 31, k + 8, KMOD_Main.LifeLeaves);
         world.setBlock(i + 12, j + 31, k + 11, KMOD_Main.LifeLeaves);
         world.setBlock(i + 12, j + 31, k + 12, KMOD_Main.LifeLeaves);
         world.setBlock(i + 12, j + 31, k + 13, KMOD_Main.LifeLeaves);
         world.setBlock(i + 12, j + 31, k + 14, KMOD_Main.LifeLeaves);
         world.setBlock(i + 12, j + 31, k + 15, KMOD_Main.LifeLeaves);
         world.setBlock(i + 12, j + 31, k + 16, KMOD_Main.LifeLeaves);
         world.setBlock(i + 12, j + 32, k + 6, KMOD_Main.LifeLeaves);
         world.setBlock(i + 12, j + 32, k + 7, KMOD_Main.LifeLeaves);
         world.setBlock(i + 12, j + 32, k + 8, KMOD_Main.LifeLeaves);
         world.setBlock(i + 12, j + 32, k + 9, KMOD_Main.LifeLeaves);
         world.setBlock(i + 12, j + 32, k + 10, KMOD_Main.LifeLeaves);
         world.setBlock(i + 12, j + 32, k + 11, KMOD_Main.LifeLeaves);
         world.setBlock(i + 12, j + 32, k + 12, KMOD_Main.LifeLeaves);
         world.setBlock(i + 12, j + 32, k + 13, KMOD_Main.LifeLeaves);
         world.setBlock(i + 12, j + 32, k + 14, KMOD_Main.LifeLeaves);
         world.setBlock(i + 12, j + 32, k + 15, KMOD_Main.LifeLeaves);
         world.setBlock(i + 12, j + 33, k + 7, KMOD_Main.LifeLeaves);
         world.setBlock(i + 12, j + 33, k + 9, KMOD_Main.LifeLeaves);
         world.setBlock(i + 12, j + 33, k + 10, KMOD_Main.LifeLeaves);
         world.setBlock(i + 12, j + 33, k + 11, KMOD_Main.LifeLog);
         world.setBlock(i + 12, j + 33, k + 12, KMOD_Main.LifeLeaves);
         world.setBlock(i + 12, j + 33, k + 13, KMOD_Main.LifeLeaves);
         world.setBlock(i + 12, j + 33, k + 14, KMOD_Main.LifeLeaves);
         world.setBlock(i + 12, j + 34, k + 7, KMOD_Main.LifeLeaves);
         world.setBlock(i + 12, j + 34, k + 12, KMOD_Main.LifeLeaves);
         world.setBlock(i + 13, j + 0, k + 7, KMOD_Main.KetherCloud);
         world.setBlock(i + 13, j + 0, k + 8, KMOD_Main.KetherCloud);
         world.setBlock(i + 13, j + 0, k + 9, KMOD_Main.KetherCloud);
         world.setBlock(i + 13, j + 0, k + 10, KMOD_Main.KetherCloud);
         world.setBlock(i + 13, j + 0, k + 11, KMOD_Main.KetherCloud);
         world.setBlock(i + 13, j + 0, k + 12, KMOD_Main.KetherCloud);
         world.setBlock(i + 13, j + 0, k + 13, KMOD_Main.KetherCloud);
         world.setBlock(i + 13, j + 0, k + 14, KMOD_Main.KetherCloud);
         world.setBlock(i + 13, j + 1, k + 1, KMOD_Main.KetherCloud);
         world.setBlock(i + 13, j + 1, k + 2, KMOD_Main.KetherCloud);
         world.setBlock(i + 13, j + 1, k + 3, KMOD_Main.KetherCloud);
         world.setBlock(i + 13, j + 1, k + 4, KMOD_Main.KetherCloud);
         world.setBlock(i + 13, j + 1, k + 5, KMOD_Main.KetherCloud);
         world.setBlock(i + 13, j + 1, k + 7, KMOD_Main.KetherCloud);
         world.setBlock(i + 13, j + 1, k + 8, KMOD_Main.KetherCloud);
         world.setBlock(i + 13, j + 1, k + 9, KMOD_Main.KetherCloud);
         world.setBlock(i + 13, j + 1, k + 10, KMOD_Main.KetherCloud);
         world.setBlock(i + 13, j + 1, k + 11, KMOD_Main.KetherCloud);
         world.setBlock(i + 13, j + 1, k + 12, KMOD_Main.KetherCloud);
         world.setBlock(i + 13, j + 1, k + 13, KMOD_Main.KetherCloud);
         world.setBlock(i + 13, j + 1, k + 14, KMOD_Main.KetherCloud);
         world.setBlock(i + 13, j + 1, k + 15, KMOD_Main.KetherCloud);
         world.setBlock(i + 13, j + 1, k + 16, KMOD_Main.KetherCloud);
         world.setBlock(i + 13, j + 1, k + 17, KMOD_Main.KetherCloud);
         world.setBlock(i + 13, j + 1, k + 18, KMOD_Main.KetherCloud);
         world.setBlock(i + 13, j + 1, k + 19, KMOD_Main.KetherCloud);
         world.setBlock(i + 13, j + 2, k + 1, KMOD_Main.KetherCloud);
         world.setBlock(i + 13, j + 2, k + 2, KMOD_Main.KetherCloud);
         world.setBlock(i + 13, j + 2, k + 3, KMOD_Main.KetherCloud);
         world.setBlock(i + 13, j + 2, k + 4, KMOD_Main.KetherCloud);
         world.setBlock(i + 13, j + 2, k + 5, KMOD_Main.KetherCloud);
         world.setBlock(i + 13, j + 2, k + 6, KMOD_Main.KetherCloud);
         world.setBlock(i + 13, j + 2, k + 7, KMOD_Main.KetherCloud);
         world.setBlock(i + 13, j + 2, k + 8, KMOD_Main.KetherCloud);
         world.setBlock(i + 13, j + 2, k + 9, KMOD_Main.KetherCloud);
         world.setBlock(i + 13, j + 2, k + 10, KMOD_Main.KetherCloud);
         world.setBlock(i + 13, j + 2, k + 11, KMOD_Main.KetherCloud);
         world.setBlock(i + 13, j + 2, k + 12, KMOD_Main.KetherCloud);
         world.setBlock(i + 13, j + 2, k + 13, KMOD_Main.KetherCloud);
         world.setBlock(i + 13, j + 2, k + 14, KMOD_Main.KetherCloud);
         world.setBlock(i + 13, j + 2, k + 15, KMOD_Main.KetherCloud);
         world.setBlock(i + 13, j + 2, k + 16, KMOD_Main.KetherCloud);
         world.setBlock(i + 13, j + 2, k + 17, KMOD_Main.KetherCloud);
         world.setBlock(i + 13, j + 2, k + 18, KMOD_Main.KetherCloud);
         world.setBlock(i + 13, j + 2, k + 19, KMOD_Main.KetherCloud);
         world.setBlock(i + 13, j + 3, k + 4, KMOD_Main.KetherCloud);
         world.setBlock(i + 13, j + 3, k + 5, KMOD_Main.KetherCloud);
         world.setBlock(i + 13, j + 3, k + 6, KMOD_Main.KetherCloud);
         world.setBlock(i + 13, j + 3, k + 7, KMOD_Main.KetherCloud);
         world.setBlock(i + 13, j + 3, k + 8, KMOD_Main.KetherCloud);
         world.setBlock(i + 13, j + 3, k + 9, KMOD_Main.KetherCloud);
         world.setBlock(i + 13, j + 3, k + 10, KMOD_Main.KetherCloud);
         world.setBlock(i + 13, j + 3, k + 11, KMOD_Main.KetherCloud);
         world.setBlock(i + 13, j + 3, k + 12, KMOD_Main.KetherCloud);
         world.setBlock(i + 13, j + 3, k + 13, KMOD_Main.KetherCloud);
         world.setBlock(i + 13, j + 3, k + 14, KMOD_Main.KetherCloud);
         world.setBlock(i + 13, j + 3, k + 15, KMOD_Main.KetherCloud);
         world.setBlock(i + 13, j + 3, k + 16, KMOD_Main.KetherCloud);
         world.setBlock(i + 13, j + 4, k + 8, KMOD_Main.LifeLog);
         world.setBlock(i + 13, j + 4, k + 9, KMOD_Main.LifeLog);
         world.setBlock(i + 13, j + 4, k + 13, KMOD_Main.LifeLog);
         world.setBlock(i + 13, j + 4, k + 14, KMOD_Main.LifeLog);
         world.setBlock(i + 13, j + 5, k + 8, KMOD_Main.LifeLog);
         world.setBlock(i + 13, j + 5, k + 9, KMOD_Main.LifeLog);
         world.setBlock(i + 13, j + 5, k + 13, KMOD_Main.LifeLog);
         world.setBlock(i + 13, j + 5, k + 14, KMOD_Main.LifeLog);
         world.setBlock(i + 13, j + 6, k + 8, KMOD_Main.LifeLog);
         world.setBlock(i + 13, j + 6, k + 9, KMOD_Main.LifeLog);
         world.setBlock(i + 13, j + 6, k + 13, KMOD_Main.LifeLog);
         world.setBlock(i + 13, j + 6, k + 14, KMOD_Main.LifeLog);
         world.setBlock(i + 13, j + 7, k + 9, KMOD_Main.LifeLog);
         world.setBlock(i + 13, j + 7, k + 13, KMOD_Main.LifeLog);
         world.setBlock(i + 13, j + 7, k + 14, KMOD_Main.LifeLog);
         world.setBlock(i + 13, j + 8, k + 9, KMOD_Main.LifeLog);
         world.setBlock(i + 13, j + 8, k + 10, KMOD_Main.LifeLog);
         world.setBlock(i + 13, j + 8, k + 12, KMOD_Main.LifeLog);
         world.setBlock(i + 13, j + 8, k + 13, KMOD_Main.LifeLog);
         world.setBlock(i + 13, j + 9, k + 9, KMOD_Main.LifeLog);
         world.setBlock(i + 13, j + 9, k + 10, KMOD_Main.LifeLog);
         world.setBlock(i + 13, j + 9, k + 11, KMOD_Main.LifeLog);
         world.setBlock(i + 13, j + 9, k + 12, KMOD_Main.LifeLog);
         world.setBlock(i + 13, j + 9, k + 13, KMOD_Main.LifeLog);
         world.setBlock(i + 13, j + 10, k + 10, KMOD_Main.LifeLog);
         world.setBlock(i + 13, j + 10, k + 11, KMOD_Main.LifeLog);
         world.setBlock(i + 13, j + 10, k + 12, KMOD_Main.LifeLog);
         world.setBlock(i + 13, j + 11, k + 10, KMOD_Main.LifeLog);
         world.setBlock(i + 13, j + 11, k + 11, KMOD_Main.LifeLog);
         world.setBlock(i + 13, j + 11, k + 12, KMOD_Main.LifeLog);
         world.setBlock(i + 13, j + 12, k + 10, KMOD_Main.LifeLog);
         world.setBlock(i + 13, j + 12, k + 11, KMOD_Main.LifeLog);
         world.setBlock(i + 13, j + 12, k + 12, KMOD_Main.LifeLog);
         world.setBlock(i + 13, j + 13, k + 10, KMOD_Main.LifeLog);
         world.setBlock(i + 13, j + 13, k + 11, KMOD_Main.LifeLog);
         world.setBlock(i + 13, j + 13, k + 12, KMOD_Main.LifeLog);
         world.setBlock(i + 13, j + 14, k + 10, KMOD_Main.LifeLog);
         world.setBlock(i + 13, j + 14, k + 11, KMOD_Main.LifeLog);
         world.setBlock(i + 13, j + 14, k + 12, KMOD_Main.LifeLog);
         world.setBlock(i + 13, j + 15, k + 10, KMOD_Main.LifeLog);
         world.setBlock(i + 13, j + 15, k + 11, KMOD_Main.LifeLog);
         world.setBlock(i + 13, j + 15, k + 12, KMOD_Main.LifeLog);
         world.setBlock(i + 13, j + 16, k + 10, KMOD_Main.LifeLog);
         world.setBlock(i + 13, j + 16, k + 11, KMOD_Main.LifeLog);
         world.setBlock(i + 13, j + 16, k + 12, KMOD_Main.LifeLog);
         world.setBlock(i + 13, j + 17, k + 10, KMOD_Main.LifeLog);
         world.setBlock(i + 13, j + 17, k + 11, KMOD_Main.LifeLog);
         world.setBlock(i + 13, j + 17, k + 12, KMOD_Main.LifeLog);
         world.setBlock(i + 13, j + 18, k + 10, KMOD_Main.LifeLog);
         world.setBlock(i + 13, j + 18, k + 11, KMOD_Main.LifeLog);
         world.setBlock(i + 13, j + 18, k + 12, KMOD_Main.LifeLog);
         world.setBlock(i + 13, j + 19, k + 10, KMOD_Main.LifeLog);
         world.setBlock(i + 13, j + 19, k + 11, KMOD_Main.LifeLog);
         world.setBlock(i + 13, j + 19, k + 12, KMOD_Main.LifeLog);
         world.setBlock(i + 13, j + 20, k + 10, KMOD_Main.LifeLog);
         world.setBlock(i + 13, j + 20, k + 11, KMOD_Main.LifeLog);
         world.setBlock(i + 13, j + 20, k + 12, KMOD_Main.LifeLog);
         world.setBlock(i + 13, j + 21, k + 10, KMOD_Main.LifeLog);
         world.setBlock(i + 13, j + 21, k + 11, KMOD_Main.LifeLog);
         world.setBlock(i + 13, j + 21, k + 12, KMOD_Main.LifeLog);
         world.setBlock(i + 13, j + 22, k + 10, KMOD_Main.LifeLog);
         world.setBlock(i + 13, j + 22, k + 11, KMOD_Main.LifeLog);
         world.setBlock(i + 13, j + 22, k + 12, KMOD_Main.LifeLog);
         world.setBlock(i + 13, j + 23, k + 10, KMOD_Main.LifeLog);
         world.setBlock(i + 13, j + 23, k + 11, KMOD_Main.LifeLog);
         world.setBlock(i + 13, j + 23, k + 12, KMOD_Main.LifeLog);
         world.setBlock(i + 13, j + 24, k + 10, KMOD_Main.LifeLog);
         world.setBlock(i + 13, j + 24, k + 11, KMOD_Main.LifeLog);
         world.setBlock(i + 13, j + 24, k + 12, KMOD_Main.LifeLog);
         world.setBlock(i + 13, j + 25, k + 9, KMOD_Main.LifeLog);
         world.setBlock(i + 13, j + 25, k + 13, KMOD_Main.LifeLog);
         world.setBlock(i + 13, j + 26, k + 7, KMOD_Main.LifeLeaves);
         world.setBlock(i + 13, j + 26, k + 8, KMOD_Main.LifeLog);
         world.setBlock(i + 13, j + 26, k + 14, KMOD_Main.LifeLog);
         world.setBlock(i + 13, j + 26, k + 15, KMOD_Main.LifeLeaves);
         world.setBlock(i + 13, j + 26, k + 16, KMOD_Main.LifeLeaves);
         world.setBlock(i + 13, j + 27, k + 7, KMOD_Main.LifeLeaves);
         world.setBlock(i + 13, j + 27, k + 8, KMOD_Main.LifeLog);
         world.setBlock(i + 13, j + 27, k + 14, KMOD_Main.LifeLog);
         world.setBlock(i + 13, j + 27, k + 15, KMOD_Main.LifeLeaves);
         world.setBlock(i + 13, j + 28, k + 6, KMOD_Main.LifeLeaves);
         world.setBlock(i + 13, j + 28, k + 7, KMOD_Main.LifeLeaves);
         world.setBlock(i + 13, j + 28, k + 15, KMOD_Main.LifeLeaves);
         world.setBlock(i + 13, j + 28, k + 16, KMOD_Main.LifeLeaves);
         world.setBlock(i + 13, j + 28, k + 17, KMOD_Main.LifeLeaves);
         world.setBlock(i + 13, j + 28, k + 18, KMOD_Main.LifeLeaves);
         world.setBlock(i + 13, j + 28, k + 19, KMOD_Main.LifeLeaves);
         world.setBlock(i + 13, j + 29, k + 5, KMOD_Main.LifeLeaves);
         world.setBlock(i + 13, j + 29, k + 6, KMOD_Main.LifeLeaves);
         world.setBlock(i + 13, j + 29, k + 7, KMOD_Main.LifeLog);
         world.setBlock(i + 13, j + 29, k + 15, KMOD_Main.LifeLog);
         world.setBlock(i + 13, j + 29, k + 16, KMOD_Main.LifeLeaves);
         world.setBlock(i + 13, j + 29, k + 17, KMOD_Main.LifeLeaves);
         world.setBlock(i + 13, j + 29, k + 18, KMOD_Main.LifeLeaves);
         world.setBlock(i + 13, j + 29, k + 19, KMOD_Main.LifeLeaves);
         world.setBlock(i + 13, j + 30, k + 5, KMOD_Main.LifeLeaves);
         world.setBlock(i + 13, j + 30, k + 6, KMOD_Main.LifeLeaves);
         world.setBlock(i + 13, j + 30, k + 7, KMOD_Main.LifeLeaves);
         world.setBlock(i + 13, j + 30, k + 8, KMOD_Main.LifeLeaves);
         world.setBlock(i + 13, j + 30, k + 9, KMOD_Main.LifeLeaves);
         world.setBlock(i + 13, j + 30, k + 10, KMOD_Main.LifeLeaves);
         world.setBlock(i + 13, j + 30, k + 11, KMOD_Main.LifeLeaves);
         world.setBlock(i + 13, j + 30, k + 12, KMOD_Main.LifeLeaves);
         world.setBlock(i + 13, j + 30, k + 13, KMOD_Main.LifeLeaves);
         world.setBlock(i + 13, j + 30, k + 14, KMOD_Main.LifeLeaves);
         world.setBlock(i + 13, j + 30, k + 15, KMOD_Main.LifeLeaves);
         world.setBlock(i + 13, j + 30, k + 16, KMOD_Main.LifeLeaves);
         world.setBlock(i + 13, j + 31, k + 5, KMOD_Main.LifeLeaves);
         world.setBlock(i + 13, j + 31, k + 6, KMOD_Main.LifeLeaves);
         world.setBlock(i + 13, j + 31, k + 7, KMOD_Main.LifeLeaves);
         world.setBlock(i + 13, j + 31, k + 8, KMOD_Main.LifeLeaves);
         world.setBlock(i + 13, j + 31, k + 9, KMOD_Main.LifeLeaves);
         world.setBlock(i + 13, j + 31, k + 11, KMOD_Main.LifeLeaves);
         world.setBlock(i + 13, j + 31, k + 12, KMOD_Main.LifeLeaves);
         world.setBlock(i + 13, j + 31, k + 13, KMOD_Main.LifeLeaves);
         world.setBlock(i + 13, j + 31, k + 15, KMOD_Main.LifeLeaves);
         world.setBlock(i + 13, j + 32, k + 7, KMOD_Main.LifeLeaves);
         world.setBlock(i + 13, j + 32, k + 8, KMOD_Main.LifeLeaves);
         world.setBlock(i + 13, j + 32, k + 9, KMOD_Main.LifeLeaves);
         world.setBlock(i + 13, j + 32, k + 10, KMOD_Main.LifeLeaves);
         world.setBlock(i + 13, j + 32, k + 11, KMOD_Main.LifeLeaves);
         world.setBlock(i + 13, j + 32, k + 13, KMOD_Main.LifeLeaves);
         world.setBlock(i + 13, j + 32, k + 14, KMOD_Main.LifeLeaves);
         world.setBlock(i + 13, j + 32, k + 15, KMOD_Main.LifeLeaves);
         world.setBlock(i + 13, j + 33, k + 11, KMOD_Main.LifeLeaves);
         world.setBlock(i + 13, j + 33, k + 12, KMOD_Main.LifeLeaves);
         world.setBlock(i + 13, j + 33, k + 13, KMOD_Main.LifeLeaves);
         world.setBlock(i + 13, j + 33, k + 15, KMOD_Main.LifeLeaves);
         world.setBlock(i + 13, j + 34, k + 12, KMOD_Main.LifeLeaves);
         world.setBlock(i + 13, j + 35, k + 12, KMOD_Main.LifeLeaves);
         world.setBlock(i + 14, j + 0, k + 8, KMOD_Main.KetherCloud);
         world.setBlock(i + 14, j + 0, k + 9, KMOD_Main.KetherCloud);
         world.setBlock(i + 14, j + 0, k + 10, KMOD_Main.KetherCloud);
         world.setBlock(i + 14, j + 0, k + 11, KMOD_Main.KetherCloud);
         world.setBlock(i + 14, j + 0, k + 12, KMOD_Main.KetherCloud);
         world.setBlock(i + 14, j + 0, k + 13, KMOD_Main.KetherCloud);
         world.setBlock(i + 14, j + 1, k + 2, KMOD_Main.KetherCloud);
