package com.KMOD.WorldGens.NewTestTrees;

import com.KMOD.Main.KMOD_Main;
import cpw.mods.fml.common.IWorldGenerator;
import java.util.Random;
import net.minecraft.block.Block;
import net.minecraft.world.World;
import net.minecraft.world.chunk.IChunkProvider;
import net.minecraft.world.gen.feature.WorldGenerator;

public class KetherGenTree3 extends WorldGenerator implements IWorldGenerator {
   public void generate(Random random, int chunkX, int chunkZ, World world, IChunkProvider chunkGenerator, IChunkProvider chunkProvider) {
   }

   public static void setBlock(World world, int x, int y, int z, Block block) {
      Block b1 = world.getBlock(x, y, z);
      if (b1.isAir(world, x, y, z) || b1.isLeaves(world, x, y, z)) {
         world.setBlock(x, y, z, block);
      }

   }

   public boolean generate(World world, Random random, int x, int y, int z) {
      this.spawn(world, x, y, z);
      return true;
   }

   public void spawn(World world, int x, int y, int z) {
      if ((world.getBlock(x, y, z) == KMOD_Main.KetherGrass || world.getBlock(x, y - 1, z) == KMOD_Main.KetherGrass) && (world.getBlock(x + 16, y, z + 11) == KMOD_Main.KetherGrass || world.getBlock(x + 16, y - 1, z + 11) == KMOD_Main.KetherGrass || world.getBlock(x + 16, y, z + 11) == KMOD_Main.KetherDirt || world.getBlock(x + 16, y - 1, z + 11) == KMOD_Main.KetherDirt)) {
         setBlock(world, x + 16, y + 0, z + 11, KMOD_Main.KetherLog);
         world.setBlockMetadataWithNotify(x + 16, y + 0, z + 11, 12, 12);
         setBlock(world, x + 17, y + 0, z + 12, KMOD_Main.KetherLog);
         world.setBlockMetadataWithNotify(x + 17, y + 0, z + 12, 12, 12);
         setBlock(world, x + 17, y + 0, z + 13, KMOD_Main.KetherLog);
         world.setBlockMetadataWithNotify(x + 17, y + 0, z + 13, 12, 12);
         setBlock(world, x + 14, y + 0, z + 14, KMOD_Main.KetherLog);
         world.setBlockMetadataWithNotify(x + 14, y + 0, z + 14, 12, 12);
         setBlock(world, x + 17, y + 0, z + 14, KMOD_Main.KetherLog);
         world.setBlockMetadataWithNotify(x + 17, y + 0, z + 14, 12, 12);
         setBlock(world, x + 18, y + 0, z + 14, KMOD_Main.KetherLog);
         world.setBlockMetadataWithNotify(x + 18, y + 0, z + 14, 12, 12);
         setBlock(world, x + 15, y + 0, z + 15, KMOD_Main.KetherLog);
         world.setBlockMetadataWithNotify(x + 15, y + 0, z + 15, 12, 12);
         setBlock(world, x + 16, y + 0, z + 15, KMOD_Main.KetherLog);
         world.setBlockMetadataWithNotify(x + 16, y + 0, z + 15, 12, 12);
         setBlock(world, x + 17, y + 0, z + 15, KMOD_Main.KetherLog);
         world.setBlockMetadataWithNotify(x + 17, y + 0, z + 15, 12, 12);
         setBlock(world, x + 18, y + 0, z + 15, KMOD_Main.KetherLog);
         world.setBlockMetadataWithNotify(x + 18, y + 0, z + 15, 12, 12);
         setBlock(world, x + 19, y + 0, z + 15, KMOD_Main.KetherLog);
         world.setBlockMetadataWithNotify(x + 19, y + 0, z + 15, 12, 12);
         setBlock(world, x + 20, y + 0, z + 15, KMOD_Main.KetherLog);
         world.setBlockMetadataWithNotify(x + 20, y + 0, z + 15, 12, 12);
         setBlock(world, x + 17, y + 0, z + 16, KMOD_Main.KetherLog);
         world.setBlockMetadataWithNotify(x + 17, y + 0, z + 16, 12, 12);
         setBlock(world, x + 18, y + 0, z + 16, KMOD_Main.KetherLog);
         world.setBlockMetadataWithNotify(x + 18, y + 0, z + 16, 12, 12);
         setBlock(world, x + 19, y + 0, z + 16, KMOD_Main.KetherLog);
         world.setBlockMetadataWithNotify(x + 19, y + 0, z + 16, 12, 12);
         setBlock(world, x + 20, y + 0, z + 16, KMOD_Main.KetherLog);
         world.setBlockMetadataWithNotify(x + 20, y + 0, z + 16, 12, 12);
         setBlock(world, x + 23, y + 0, z + 16, KMOD_Main.KetherLog);
         setBlock(world, x + 17, y + 0, z + 17, KMOD_Main.KetherLog);
         world.setBlockMetadataWithNotify(x + 17, y + 0, z + 17, 12, 12);
         setBlock(world, x + 18, y + 0, z + 17, KMOD_Main.KetherLog);
         world.setBlockMetadataWithNotify(x + 18, y + 0, z + 17, 12, 12);
         setBlock(world, x + 21, y + 0, z + 17, KMOD_Main.KetherLog);
         setBlock(world, x + 22, y + 0, z + 17, KMOD_Main.KetherLog);
         setBlock(world, x + 18, y + 0, z + 18, KMOD_Main.KetherLog);
         world.setBlockMetadataWithNotify(x + 18, y + 0, z + 18, 12, 12);
         setBlock(world, x + 17, y + 0, z + 19, KMOD_Main.KetherLog);
         world.setBlockMetadataWithNotify(x + 17, y + 0, z + 19, 12, 12);
         setBlock(world, x + 16, y + 0, z + 20, KMOD_Main.KetherLog);
         world.setBlockMetadataWithNotify(x + 16, y + 0, z + 20, 12, 12);
         setBlock(world, x + 17, y + 1, z + 13, KMOD_Main.KetherLog);
         world.setBlockMetadataWithNotify(x + 17, y + 1, z + 13, 12, 12);
         setBlock(world, x + 17, y + 1, z + 14, KMOD_Main.KetherLog);
         world.setBlockMetadataWithNotify(x + 17, y + 1, z + 14, 12, 12);
         setBlock(world, x + 18, y + 1, z + 14, KMOD_Main.KetherLog);
         world.setBlockMetadataWithNotify(x + 18, y + 1, z + 14, 12, 12);
         setBlock(world, x + 17, y + 1, z + 15, KMOD_Main.KetherLog);
         world.setBlockMetadataWithNotify(x + 17, y + 1, z + 15, 12, 12);
         setBlock(world, x + 18, y + 1, z + 15, KMOD_Main.KetherLog);
         world.setBlockMetadataWithNotify(x + 18, y + 1, z + 15, 12, 12);
         setBlock(world, x + 19, y + 1, z + 15, KMOD_Main.KetherLog);
         world.setBlockMetadataWithNotify(x + 19, y + 1, z + 15, 12, 12);
         setBlock(world, x + 20, y + 1, z + 15, KMOD_Main.KetherLog);
         world.setBlockMetadataWithNotify(x + 20, y + 1, z + 15, 12, 12);
         setBlock(world, x + 17, y + 1, z + 16, KMOD_Main.KetherLog);
         world.setBlockMetadataWithNotify(x + 17, y + 1, z + 16, 12, 12);
         setBlock(world, x + 18, y + 1, z + 16, KMOD_Main.KetherLog);
         world.setBlockMetadataWithNotify(x + 18, y + 1, z + 16, 12, 12);
         setBlock(world, x + 19, y + 1, z + 16, KMOD_Main.KetherLog);
         world.setBlockMetadataWithNotify(x + 19, y + 1, z + 16, 12, 12);
         setBlock(world, x + 18, y + 1, z + 17, KMOD_Main.KetherLog);
         world.setBlockMetadataWithNotify(x + 18, y + 1, z + 17, 12, 12);
         setBlock(world, x + 17, y + 2, z + 14, KMOD_Main.KetherLog);
         world.setBlockMetadataWithNotify(x + 17, y + 2, z + 14, 12, 12);
         setBlock(world, x + 18, y + 2, z + 14, KMOD_Main.KetherLog);
         world.setBlockMetadataWithNotify(x + 18, y + 2, z + 14, 12, 12);
         setBlock(world, x + 19, y + 2, z + 14, KMOD_Main.KetherLog);
         world.setBlockMetadataWithNotify(x + 19, y + 2, z + 14, 12, 12);
         setBlock(world, x + 17, y + 2, z + 15, KMOD_Main.KetherLog);
         world.setBlockMetadataWithNotify(x + 17, y + 2, z + 15, 12, 12);
         setBlock(world, x + 18, y + 2, z + 15, KMOD_Main.KetherLog);
         world.setBlockMetadataWithNotify(x + 18, y + 2, z + 15, 12, 12);
         setBlock(world, x + 19, y + 2, z + 15, KMOD_Main.KetherLog);
         world.setBlockMetadataWithNotify(x + 19, y + 2, z + 15, 12, 12);
         setBlock(world, x + 18, y + 2, z + 16, KMOD_Main.KetherLog);
         world.setBlockMetadataWithNotify(x + 18, y + 2, z + 16, 12, 12);
         setBlock(world, x + 18, y + 3, z + 13, KMOD_Main.KetherLog);
         world.setBlockMetadataWithNotify(x + 18, y + 3, z + 13, 12, 12);
         setBlock(world, x + 17, y + 3, z + 14, KMOD_Main.KetherLog);
         world.setBlockMetadataWithNotify(x + 17, y + 3, z + 14, 12, 12);
         setBlock(world, x + 18, y + 3, z + 14, KMOD_Main.KetherLog);
         world.setBlockMetadataWithNotify(x + 18, y + 3, z + 14, 12, 12);
         setBlock(world, x + 19, y + 3, z + 14, KMOD_Main.KetherLog);
         world.setBlockMetadataWithNotify(x + 19, y + 3, z + 14, 12, 12);
         setBlock(world, x + 17, y + 3, z + 15, KMOD_Main.KetherLog);
         world.setBlockMetadataWithNotify(x + 17, y + 3, z + 15, 12, 12);
         setBlock(world, x + 18, y + 3, z + 15, KMOD_Main.KetherLog);
         world.setBlockMetadataWithNotify(x + 18, y + 3, z + 15, 12, 12);
         setBlock(world, x + 19, y + 3, z + 15, KMOD_Main.KetherLog);
         world.setBlockMetadataWithNotify(x + 19, y + 3, z + 15, 12, 12);
         setBlock(world, x + 18, y + 3, z + 16, KMOD_Main.KetherLog);
         world.setBlockMetadataWithNotify(x + 18, y + 3, z + 16, 12, 12);
         setBlock(world, x + 18, y + 4, z + 13, KMOD_Main.KetherLog);
         world.setBlockMetadataWithNotify(x + 18, y + 4, z + 13, 12, 12);
         setBlock(world, x + 19, y + 4, z + 13, KMOD_Main.KetherLog);
         world.setBlockMetadataWithNotify(x + 19, y + 4, z + 13, 12, 12);
         setBlock(world, x + 17, y + 4, z + 14, KMOD_Main.KetherLog);
         world.setBlockMetadataWithNotify(x + 17, y + 4, z + 14, 12, 12);
         setBlock(world, x + 18, y + 4, z + 14, KMOD_Main.KetherLog);
         world.setBlockMetadataWithNotify(x + 18, y + 4, z + 14, 12, 12);
         setBlock(world, x + 19, y + 4, z + 14, KMOD_Main.KetherLog);
         world.setBlockMetadataWithNotify(x + 19, y + 4, z + 14, 12, 12);
         setBlock(world, x + 17, y + 4, z + 15, KMOD_Main.KetherLog);
         world.setBlockMetadataWithNotify(x + 17, y + 4, z + 15, 12, 12);
         setBlock(world, x + 18, y + 4, z + 15, KMOD_Main.KetherLog);
         world.setBlockMetadataWithNotify(x + 18, y + 4, z + 15, 12, 12);
         setBlock(world, x + 19, y + 4, z + 15, KMOD_Main.KetherLog);
         world.setBlockMetadataWithNotify(x + 19, y + 4, z + 15, 12, 12);
         setBlock(world, x + 25, y + 5, z + 4, KMOD_Main.KetherLeaves);
         world.setBlockMetadataWithNotify(x + 25, y + 5, z + 4, 12, 12);
         setBlock(world, x + 23, y + 5, z + 5, KMOD_Main.KetherLeaves);
         world.setBlockMetadataWithNotify(x + 23, y + 5, z + 5, 12, 12);
         setBlock(world, x + 25, y + 5, z + 5, KMOD_Main.KetherLeaves);
         world.setBlockMetadataWithNotify(x + 25, y + 5, z + 5, 12, 12);
         setBlock(world, x + 24, y + 5, z + 6, KMOD_Main.KetherLeaves);
         world.setBlockMetadataWithNotify(x + 24, y + 5, z + 6, 12, 12);
         setBlock(world, x + 25, y + 5, z + 6, KMOD_Main.KetherLeaves);
         world.setBlockMetadataWithNotify(x + 25, y + 5, z + 6, 12, 12);
         setBlock(world, x + 30, y + 5, z + 8, KMOD_Main.KetherLeaves);
         world.setBlockMetadataWithNotify(x + 30, y + 5, z + 8, 12, 12);
         setBlock(world, x + 29, y + 5, z + 9, KMOD_Main.KetherLeaves);
         world.setBlockMetadataWithNotify(x + 29, y + 5, z + 9, 12, 12);
         setBlock(world, x + 30, y + 5, z + 10, KMOD_Main.KetherLeaves);
         world.setBlockMetadataWithNotify(x + 30, y + 5, z + 10, 12, 12);
         setBlock(world, x + 18, y + 5, z + 12, KMOD_Main.KetherLog);
         world.setBlockMetadataWithNotify(x + 18, y + 5, z + 12, 12, 12);
         setBlock(world, x + 17, y + 5, z + 13, KMOD_Main.KetherLog);
         world.setBlockMetadataWithNotify(x + 17, y + 5, z + 13, 12, 12);
         setBlock(world, x + 18, y + 5, z + 13, KMOD_Main.KetherLog);
         world.setBlockMetadataWithNotify(x + 18, y + 5, z + 13, 12, 12);
         setBlock(world, x + 19, y + 5, z + 13, KMOD_Main.KetherLog);
         world.setBlockMetadataWithNotify(x + 19, y + 5, z + 13, 12, 12);
         setBlock(world, x + 17, y + 5, z + 14, KMOD_Main.KetherLog);
         world.setBlockMetadataWithNotify(x + 17, y + 5, z + 14, 12, 12);
         setBlock(world, x + 18, y + 5, z + 14, KMOD_Main.KetherLog);
         world.setBlockMetadataWithNotify(x + 18, y + 5, z + 14, 12, 12);
         setBlock(world, x + 19, y + 5, z + 14, KMOD_Main.KetherLog);
         world.setBlockMetadataWithNotify(x + 19, y + 5, z + 14, 12, 12);
         setBlock(world, x + 18, y + 5, z + 15, KMOD_Main.KetherLog);
         world.setBlockMetadataWithNotify(x + 18, y + 5, z + 15, 12, 12);
         setBlock(world, x + 8, y + 5, z + 16, KMOD_Main.KetherLeaves);
         world.setBlockMetadataWithNotify(x + 8, y + 5, z + 16, 12, 12);
         setBlock(world, x + 29, y + 5, z + 16, KMOD_Main.KetherLeaves);
         world.setBlockMetadataWithNotify(x + 29, y + 5, z + 16, 12, 12);
         setBlock(world, x + 7, y + 5, z + 20, KMOD_Main.KetherLeaves);
         world.setBlockMetadataWithNotify(x + 7, y + 5, z + 20, 12, 12);
         setBlock(world, x + 10, y + 5, z + 21, KMOD_Main.KetherLeaves);
         world.setBlockMetadataWithNotify(x + 10, y + 5, z + 21, 12, 12);
         setBlock(world, x + 9, y + 5, z + 22, KMOD_Main.KetherLeaves);
         world.setBlockMetadataWithNotify(x + 9, y + 5, z + 22, 12, 12);
         setBlock(world, x + 10, y + 5, z + 23, KMOD_Main.KetherLeaves);
         world.setBlockMetadataWithNotify(x + 10, y + 5, z + 23, 12, 12);
         setBlock(world, x + 15, y + 5, z + 23, KMOD_Main.KetherLeaves);
         world.setBlockMetadataWithNotify(x + 15, y + 5, z + 23, 12, 12);
         setBlock(world, x + 14, y + 5, z + 24, KMOD_Main.KetherLeaves);
         world.setBlockMetadataWithNotify(x + 14, y + 5, z + 24, 12, 12);
         setBlock(world, x + 14, y + 5, z + 25, KMOD_Main.KetherLeaves);
         world.setBlockMetadataWithNotify(x + 14, y + 5, z + 25, 12, 12);
         setBlock(world, x + 18, y + 6, z + 2, KMOD_Main.KetherLeaves);
         world.setBlockMetadataWithNotify(x + 18, y + 6, z + 2, 12, 12);
         setBlock(world, x + 19, y + 6, z + 2, KMOD_Main.KetherLeaves);
         world.setBlockMetadataWithNotify(x + 19, y + 6, z + 2, 12, 12);
         setBlock(world, x + 22, y + 6, z + 3, KMOD_Main.KetherLeaves);
         world.setBlockMetadataWithNotify(x + 22, y + 6, z + 3, 12, 12);
         setBlock(world, x + 26, y + 6, z + 3, KMOD_Main.KetherLeaves);
         world.setBlockMetadataWithNotify(x + 26, y + 6, z + 3, 12, 12);
         setBlock(world, x + 15, y + 6, z + 4, KMOD_Main.KetherLeaves);
         world.setBlockMetadataWithNotify(x + 15, y + 6, z + 4, 12, 12);
         setBlock(world, x + 18, y + 6, z + 4, KMOD_Main.KetherLeaves);
         world.setBlockMetadataWithNotify(x + 18, y + 6, z + 4, 12, 12);
         setBlock(world, x + 23, y + 6, z + 4, KMOD_Main.KetherLeaves);
         world.setBlockMetadataWithNotify(x + 23, y + 6, z + 4, 12, 12);
         setBlock(world, x + 24, y + 6, z + 4, KMOD_Main.KetherLeaves);
         world.setBlockMetadataWithNotify(x + 24, y + 6, z + 4, 12, 12);
         setBlock(world, x + 15, y + 6, z + 5, KMOD_Main.KetherLeaves);
         world.setBlockMetadataWithNotify(x + 15, y + 6, z + 5, 12, 12);
         setBlock(world, x + 16, y + 6, z + 5, KMOD_Main.KetherLeaves);
         world.setBlockMetadataWithNotify(x + 16, y + 6, z + 5, 12, 12);
         setBlock(world, x + 22, y + 6, z + 5, KMOD_Main.KetherLeaves);
         world.setBlockMetadataWithNotify(x + 22, y + 6, z + 5, 12, 12);
         setBlock(world, x + 23, y + 6, z + 5, KMOD_Main.KetherLeaves);
         world.setBlockMetadataWithNotify(x + 23, y + 6, z + 5, 12, 12);
         setBlock(world, x + 26, y + 6, z + 5, KMOD_Main.KetherLeaves);
         world.setBlockMetadataWithNotify(x + 26, y + 6, z + 5, 12, 12);
         setBlock(world, x + 27, y + 6, z + 5, KMOD_Main.KetherLeaves);
         world.setBlockMetadataWithNotify(x + 27, y + 6, z + 5, 12, 12);
         setBlock(world, x + 23, y + 6, z + 6, KMOD_Main.KetherLeaves);
         world.setBlockMetadataWithNotify(x + 23, y + 6, z + 6, 12, 12);
         setBlock(world, x + 26, y + 6, z + 6, KMOD_Main.KetherLeaves);
         world.setBlockMetadataWithNotify(x + 26, y + 6, z + 6, 12, 12);
         setBlock(world, x + 27, y + 6, z + 6, KMOD_Main.KetherLeaves);
         world.setBlockMetadataWithNotify(x + 27, y + 6, z + 6, 12, 12);
         setBlock(world, x + 25, y + 6, z + 7, KMOD_Main.KetherLeaves);
         world.setBlockMetadataWithNotify(x + 25, y + 6, z + 7, 12, 12);
         setBlock(world, x + 30, y + 6, z + 7, KMOD_Main.KetherLeaves);
         world.setBlockMetadataWithNotify(x + 30, y + 6, z + 7, 12, 12);
         setBlock(world, x + 9, y + 6, z + 8, KMOD_Main.KetherLeaves);
         world.setBlockMetadataWithNotify(x + 9, y + 6, z + 8, 12, 12);
         setBlock(world, x + 10, y + 6, z + 8, KMOD_Main.KetherLeaves);
         world.setBlockMetadataWithNotify(x + 10, y + 6, z + 8, 12, 12);
         setBlock(world, x + 28, y + 6, z + 8, KMOD_Main.KetherLeaves);
         world.setBlockMetadataWithNotify(x + 28, y + 6, z + 8, 12, 12);
         setBlock(world, x + 30, y + 6, z + 8, KMOD_Main.KetherLeaves);
         world.setBlockMetadataWithNotify(x + 30, y + 6, z + 8, 12, 12);
         setBlock(world, x + 31, y + 6, z + 8, KMOD_Main.KetherLeaves);
         world.setBlockMetadataWithNotify(x + 31, y + 6, z + 8, 4, 4);
         setBlock(world, x + 28, y + 6, z + 9, KMOD_Main.KetherLeaves);
         world.setBlockMetadataWithNotify(x + 28, y + 6, z + 9, 12, 12);
         setBlock(world, x + 31, y + 6, z + 9, KMOD_Main.KetherLeaves);
         world.setBlockMetadataWithNotify(x + 31, y + 6, z + 9, 4, 4);
         setBlock(world, x + 8, y + 6, z + 10, KMOD_Main.KetherLeaves);
         world.setBlockMetadataWithNotify(x + 8, y + 6, z + 10, 12, 12);
         setBlock(world, x + 30, y + 6, z + 10, KMOD_Main.KetherLeaves);
         world.setBlockMetadataWithNotify(x + 30, y + 6, z + 10, 12, 12);
         setBlock(world, x + 31, y + 6, z + 10, KMOD_Main.KetherLeaves);
         world.setBlockMetadataWithNotify(x + 31, y + 6, z + 10, 4, 4);
         setBlock(world, x + 32, y + 6, z + 10, KMOD_Main.KetherLeaves);
         world.setBlockMetadataWithNotify(x + 32, y + 6, z + 10, 4, 4);
         setBlock(world, x + 30, y + 6, z + 11, KMOD_Main.KetherLeaves);
         world.setBlockMetadataWithNotify(x + 30, y + 6, z + 11, 12, 12);
         setBlock(world, x + 32, y + 6, z + 11, KMOD_Main.KetherLeaves);
         world.setBlockMetadataWithNotify(x + 32, y + 6, z + 11, 12, 12);
         setBlock(world, x + 8, y + 6, z + 12, KMOD_Main.KetherLeaves);
         world.setBlockMetadataWithNotify(x + 8, y + 6, z + 12, 12, 12);
         setBlock(world, x + 18, y + 6, z + 12, KMOD_Main.KetherLog);
         world.setBlockMetadataWithNotify(x + 18, y + 6, z + 12, 12, 12);
         setBlock(world, x + 19, y + 6, z + 12, KMOD_Main.KetherLog);
         world.setBlockMetadataWithNotify(x + 19, y + 6, z + 12, 8, 8);
         setBlock(world, x + 32, y + 6, z + 12, KMOD_Main.KetherLeaves);
         world.setBlockMetadataWithNotify(x + 32, y + 6, z + 12, 12, 12);
         setBlock(world, x + 17, y + 6, z + 13, KMOD_Main.KetherLog);
         world.setBlockMetadataWithNotify(x + 17, y + 6, z + 13, 12, 12);
         setBlock(world, x + 18, y + 6, z + 13, KMOD_Main.KetherLog);
         world.setBlockMetadataWithNotify(x + 18, y + 6, z + 13, 12, 12);
         setBlock(world, x + 19, y + 6, z + 13, KMOD_Main.KetherLog);
         world.setBlockMetadataWithNotify(x + 19, y + 6, z + 13, 12, 12);
         setBlock(world, x + 30, y + 6, z + 13, KMOD_Main.KetherLeaves);
         world.setBlockMetadataWithNotify(x + 30, y + 6, z + 13, 12, 12);
         setBlock(world, x + 31, y + 6, z + 13, KMOD_Main.KetherLeaves);
         world.setBlockMetadataWithNotify(x + 31, y + 6, z + 13, 4, 4);
         setBlock(world, x + 32, y + 6, z + 13, KMOD_Main.KetherLeaves);
         world.setBlockMetadataWithNotify(x + 32, y + 6, z + 13, 4, 4);
         setBlock(world, x + 9, y + 6, z + 14, KMOD_Main.KetherLeaves);
         world.setBlockMetadataWithNotify(x + 9, y + 6, z + 14, 12, 12);
         setBlock(world, x + 17, y + 6, z + 14, KMOD_Main.KetherLog);
         world.setBlockMetadataWithNotify(x + 17, y + 6, z + 14, 12, 12);
         setBlock(world, x + 18, y + 6, z + 14, KMOD_Main.KetherLog);
         world.setBlockMetadataWithNotify(x + 18, y + 6, z + 14, 12, 12);
         setBlock(world, x + 30, y + 6, z + 14, KMOD_Main.KetherLeaves);
         world.setBlockMetadataWithNotify(x + 30, y + 6, z + 14, 4, 4);
         setBlock(world, x + 6, y + 6, z + 15, KMOD_Main.KetherLeaves);
         world.setBlockMetadataWithNotify(x + 6, y + 6, z + 15, 12, 12);
         setBlock(world, x + 18, y + 6, z + 15, KMOD_Main.KetherLog);
         world.setBlockMetadataWithNotify(x + 18, y + 6, z + 15, 12, 12);
         setBlock(world, x + 28, y + 6, z + 15, KMOD_Main.KetherLeaves);
         world.setBlockMetadataWithNotify(x + 28, y + 6, z + 15, 12, 12);
         setBlock(world, x + 29, y + 6, z + 15, KMOD_Main.KetherLeaves);
         world.setBlockMetadataWithNotify(x + 29, y + 6, z + 15, 12, 12);
         setBlock(world, x + 30, y + 6, z + 15, KMOD_Main.KetherLeaves);
         world.setBlockMetadataWithNotify(x + 30, y + 6, z + 15, 12, 12);
         setBlock(world, x + 7, y + 6, z + 16, KMOD_Main.KetherLeaves);
         world.setBlockMetadataWithNotify(x + 7, y + 6, z + 16, 12, 12);
         setBlock(world, x + 9, y + 6, z + 16, KMOD_Main.KetherLeaves);
         world.setBlockMetadataWithNotify(x + 9, y + 6, z + 16, 12, 12);
         setBlock(world, x + 19, y + 6, z + 16, KMOD_Main.KetherLog);
         world.setBlockMetadataWithNotify(x + 19, y + 6, z + 16, 4, 4);
         setBlock(world, x + 28, y + 6, z + 16, KMOD_Main.KetherLeaves);
         world.setBlockMetadataWithNotify(x + 28, y + 6, z + 16, 12, 12);
         setBlock(world, x + 30, y + 6, z + 16, KMOD_Main.KetherLeaves);
         world.setBlockMetadataWithNotify(x + 30, y + 6, z + 16, 12, 12);
         setBlock(world, x + 31, y + 6, z + 16, KMOD_Main.KetherLeaves);
         world.setBlockMetadataWithNotify(x + 31, y + 6, z + 16, 4, 4);
         setBlock(world, x + 7, y + 6, z + 17, KMOD_Main.KetherLeaves);
         world.setBlockMetadataWithNotify(x + 7, y + 6, z + 17, 12, 12);
         setBlock(world, x + 30, y + 6, z + 17, KMOD_Main.KetherLeaves);
         world.setBlockMetadataWithNotify(x + 30, y + 6, z + 17, 12, 12);
         setBlock(world, x + 8, y + 6, z + 18, KMOD_Main.KetherLeaves);
         world.setBlockMetadataWithNotify(x + 8, y + 6, z + 18, 12, 12);
         setBlock(world, x + 30, y + 6, z + 18, KMOD_Main.KetherLeaves);
         world.setBlockMetadataWithNotify(x + 30, y + 6, z + 18, 12, 12);
         setBlock(world, x + 8, y + 6, z + 19, KMOD_Main.KetherLeaves);
         world.setBlockMetadataWithNotify(x + 8, y + 6, z + 19, 12, 12);
         setBlock(world, x + 9, y + 6, z + 19, KMOD_Main.KetherLeaves);
         world.setBlockMetadataWithNotify(x + 9, y + 6, z + 19, 12, 12);
         setBlock(world, x + 24, y + 6, z + 19, KMOD_Main.KetherLeaves);
         world.setBlockMetadataWithNotify(x + 24, y + 6, z + 19, 12, 12);
         setBlock(world, x + 27, y + 6, z + 19, KMOD_Main.KetherLeaves);
         world.setBlockMetadataWithNotify(x + 27, y + 6, z + 19, 12, 12);
         setBlock(world, x + 28, y + 6, z + 19, KMOD_Main.KetherLeaves);
         world.setBlockMetadataWithNotify(x + 28, y + 6, z + 19, 12, 12);
         setBlock(world, x + 7, y + 6, z + 20, KMOD_Main.KetherLeaves);
         world.setBlockMetadataWithNotify(x + 7, y + 6, z + 20, 12, 12);
         setBlock(world, x + 12, y + 6, z + 20, KMOD_Main.KetherLeaves);
         world.setBlockMetadataWithNotify(x + 12, y + 6, z + 20, 12, 12);
         setBlock(world, x + 7, y + 6, z + 21, KMOD_Main.KetherLeaves);
         world.setBlockMetadataWithNotify(x + 7, y + 6, z + 21, 12, 12);
         setBlock(world, x + 11, y + 6, z + 21, KMOD_Main.KetherLeaves);
         world.setBlockMetadataWithNotify(x + 11, y + 6, z + 21, 12, 12);
         setBlock(world, x + 14, y + 6, z + 21, KMOD_Main.KetherLeaves);
         world.setBlockMetadataWithNotify(x + 14, y + 6, z + 21, 12, 12);
         setBlock(world, x + 17, y + 6, z + 21, KMOD_Main.KetherLeaves);
         world.setBlockMetadataWithNotify(x + 17, y + 6, z + 21, 12, 12);
         setBlock(world, x + 18, y + 6, z + 21, KMOD_Main.KetherLeaves);
         world.setBlockMetadataWithNotify(x + 18, y + 6, z + 21, 12, 12);
         setBlock(world, x + 19, y + 6, z + 21, KMOD_Main.KetherLeaves);
         world.setBlockMetadataWithNotify(x + 19, y + 6, z + 21, 12, 12);
         setBlock(world, x + 20, y + 6, z + 21, KMOD_Main.KetherLeaves);
         world.setBlockMetadataWithNotify(x + 20, y + 6, z + 21, 12, 12);
         setBlock(world, x + 27, y + 6, z + 21, KMOD_Main.KetherLeaves);
         world.setBlockMetadataWithNotify(x + 27, y + 6, z + 21, 12, 12);
         setBlock(world, x + 7, y + 6, z + 22, KMOD_Main.KetherLeaves);
         world.setBlockMetadataWithNotify(x + 7, y + 6, z + 22, 12, 12);
         setBlock(world, x + 11, y + 6, z + 22, KMOD_Main.KetherLeaves);
         world.setBlockMetadataWithNotify(x + 11, y + 6, z + 22, 12, 12);
         setBlock(world, x + 13, y + 6, z + 22, KMOD_Main.KetherLeaves);
         world.setBlockMetadataWithNotify(x + 13, y + 6, z + 22, 12, 12);
         setBlock(world, x + 14, y + 6, z + 22, KMOD_Main.KetherLeaves);
         world.setBlockMetadataWithNotify(x + 14, y + 6, z + 22, 12, 12);
         setBlock(world, x + 16, y + 6, z + 22, KMOD_Main.KetherLeaves);
         world.setBlockMetadataWithNotify(x + 16, y + 6, z + 22, 12, 12);
         setBlock(world, x + 17, y + 6, z + 22, KMOD_Main.KetherLeaves);
         world.setBlockMetadataWithNotify(x + 17, y + 6, z + 22, 12, 12);
         setBlock(world, x + 18, y + 6, z + 22, KMOD_Main.KetherLeaves);
         world.setBlockMetadataWithNotify(x + 18, y + 6, z + 22, 12, 12);
         setBlock(world, x + 22, y + 6, z + 22, KMOD_Main.KetherLeaves);
         world.setBlockMetadataWithNotify(x + 22, y + 6, z + 22, 12, 12);
         setBlock(world, x + 28, y + 6, z + 22, KMOD_Main.KetherLeaves);
         world.setBlockMetadataWithNotify(x + 28, y + 6, z + 22, 12, 12);
         setBlock(world, x + 8, y + 6, z + 23, KMOD_Main.KetherLeaves);
         world.setBlockMetadataWithNotify(x + 8, y + 6, z + 23, 12, 12);
         setBlock(world, x + 10, y + 6, z + 23, KMOD_Main.KetherLeaves);
         world.setBlockMetadataWithNotify(x + 10, y + 6, z + 23, 12, 12);
         setBlock(world, x + 13, y + 6, z + 23, KMOD_Main.KetherLeaves);
         world.setBlockMetadataWithNotify(x + 13, y + 6, z + 23, 12, 12);
         setBlock(world, x + 14, y + 6, z + 23, KMOD_Main.KetherLeaves);
         world.setBlockMetadataWithNotify(x + 14, y + 6, z + 23, 12, 12);
         setBlock(world, x + 16, y + 6, z + 23, KMOD_Main.KetherLeaves);
         world.setBlockMetadataWithNotify(x + 16, y + 6, z + 23, 12, 12);
         setBlock(world, x + 17, y + 6, z + 23, KMOD_Main.KetherLeaves);
         world.setBlockMetadataWithNotify(x + 17, y + 6, z + 23, 12, 12);
         setBlock(world, x + 19, y + 6, z + 23, KMOD_Main.KetherLeaves);
         world.setBlockMetadataWithNotify(x + 19, y + 6, z + 23, 12, 12);
         setBlock(world, x + 21, y + 6, z + 23, KMOD_Main.KetherLeaves);
         world.setBlockMetadataWithNotify(x + 21, y + 6, z + 23, 12, 12);
         setBlock(world, x + 23, y + 6, z + 23, KMOD_Main.KetherLeaves);
         world.setBlockMetadataWithNotify(x + 23, y + 6, z + 23, 12, 12);
         setBlock(world, x + 27, y + 6, z + 23, KMOD_Main.KetherLeaves);
         world.setBlockMetadataWithNotify(x + 27, y + 6, z + 23, 12, 12);
         setBlock(world, x + 9, y + 6, z + 24, KMOD_Main.KetherLeaves);
         world.setBlockMetadataWithNotify(x + 9, y + 6, z + 24, 12, 12);
         setBlock(world, x + 14, y + 6, z + 24, KMOD_Main.KetherLeaves);
         world.setBlockMetadataWithNotify(x + 14, y + 6, z + 24, 12, 12);
         setBlock(world, x + 17, y + 6, z + 25, KMOD_Main.KetherLeaves);
         world.setBlockMetadataWithNotify(x + 17, y + 6, z + 25, 12, 12);
         setBlock(world, x + 17, y + 7, z + 1, KMOD_Main.KetherLeaves);
         world.setBlockMetadataWithNotify(x + 17, y + 7, z + 1, 12, 12);
         setBlock(world, x + 18, y + 7, z + 1, KMOD_Main.KetherLeaves);
         world.setBlockMetadataWithNotify(x + 18, y + 7, z + 1, 12, 12);
         setBlock(world, x + 20, y + 7, z + 2, KMOD_Main.KetherLeaves);
         world.setBlockMetadataWithNotify(x + 20, y + 7, z + 2, 12, 12);
         setBlock(world, x + 23, y + 7, z + 2, KMOD_Main.KetherLeaves);
         world.setBlockMetadataWithNotify(x + 23, y + 7, z + 2, 12, 12);
         setBlock(world, x + 14, y + 7, z + 3, KMOD_Main.KetherLeaves);
         world.setBlockMetadataWithNotify(x + 14, y + 7, z + 3, 12, 12);
         setBlock(world, x + 17, y + 7, z + 3, KMOD_Main.KetherLeaves);
         world.setBlockMetadataWithNotify(x + 17, y + 7, z + 3, 12, 12);
         setBlock(world, x + 22, y + 7, z + 3, KMOD_Main.KetherLeaves);
         world.setBlockMetadataWithNotify(x + 22, y + 7, z + 3, 12, 12);
         setBlock(world, x + 24, y + 7, z + 3, KMOD_Main.KetherLeaves);
         world.setBlockMetadataWithNotify(x + 24, y + 7, z + 3, 12, 12);
         setBlock(world, x + 16, y + 7, z + 4, KMOD_Main.KetherLeaves);
         world.setBlockMetadataWithNotify(x + 16, y + 7, z + 4, 12, 12);
         setBlock(world, x + 23, y + 7, z + 4, KMOD_Main.KetherLeaves);
         world.setBlockMetadataWithNotify(x + 23, y + 7, z + 4, 12, 12);
         setBlock(world, x + 28, y + 7, z + 4, KMOD_Main.KetherLeaves);
         world.setBlockMetadataWithNotify(x + 28, y + 7, z + 4, 12, 12);
         setBlock(world, x + 29, y + 7, z + 4, KMOD_Main.KetherLeaves);
         world.setBlockMetadataWithNotify(x + 29, y + 7, z + 4, 12, 12);
         setBlock(world, x + 17, y + 7, z + 5, KMOD_Main.KetherLeaves);
         world.setBlockMetadataWithNotify(x + 17, y + 7, z + 5, 12, 12);
         setBlock(world, x + 20, y + 7, z + 5, KMOD_Main.KetherLeaves);
         world.setBlockMetadataWithNotify(x + 20, y + 7, z + 5, 12, 12);
         setBlock(world, x + 25, y + 7, z + 5, KMOD_Main.KetherLeaves);
         world.setBlockMetadataWithNotify(x + 25, y + 7, z + 5, 12, 12);
         setBlock(world, x + 26, y + 7, z + 5, KMOD_Main.KetherLeaves);
         world.setBlockMetadataWithNotify(x + 26, y + 7, z + 5, 12, 12);
         setBlock(world, x + 28, y + 7, z + 5, KMOD_Main.KetherLeaves);
         world.setBlockMetadataWithNotify(x + 28, y + 7, z + 5, 12, 12);
         setBlock(world, x + 29, y + 7, z + 5, KMOD_Main.KetherLeaves);
         world.setBlockMetadataWithNotify(x + 29, y + 7, z + 5, 12, 12);
         setBlock(world, x + 15, y + 7, z + 6, KMOD_Main.KetherLeaves);
         world.setBlockMetadataWithNotify(x + 15, y + 7, z + 6, 12, 12);
         setBlock(world, x + 16, y + 7, z + 6, KMOD_Main.KetherLeaves);
         world.setBlockMetadataWithNotify(x + 16, y + 7, z + 6, 12, 12);
         setBlock(world, x + 29, y + 7, z + 6, KMOD_Main.KetherLeaves);
         world.setBlockMetadataWithNotify(x + 29, y + 7, z + 6, 12, 12);
         setBlock(world, x + 7, y + 7, z + 7, KMOD_Main.KetherLeaves);
         world.setBlockMetadataWithNotify(x + 7, y + 7, z + 7, 12, 12);
         setBlock(world, x + 10, y + 7, z + 7, KMOD_Main.KetherLeaves);
         world.setBlockMetadataWithNotify(x + 10, y + 7, z + 7, 12, 12);
         setBlock(world, x + 24, y + 7, z + 7, KMOD_Main.KetherLeaves);
         world.setBlockMetadataWithNotify(x + 24, y + 7, z + 7, 12, 12);
         setBlock(world, x + 27, y + 7, z + 7, KMOD_Main.KetherLeaves);
         world.setBlockMetadataWithNotify(x + 27, y + 7, z + 7, 12, 12);
         setBlock(world, x + 28, y + 7, z + 7, KMOD_Main.KetherLeaves);
         world.setBlockMetadataWithNotify(x + 28, y + 7, z + 7, 12, 12);
         setBlock(world, x + 8, y + 7, z + 8, KMOD_Main.KetherLeaves);
         world.setBlockMetadataWithNotify(x + 8, y + 7, z + 8, 12, 12);
         setBlock(world, x + 10, y + 7, z + 8, KMOD_Main.KetherLeaves);
         world.setBlockMetadataWithNotify(x + 10, y + 7, z + 8, 12, 12);
         setBlock(world, x + 23, y + 7, z + 8, KMOD_Main.KetherLeaves);
         world.setBlockMetadataWithNotify(x + 23, y + 7, z + 8, 12, 12);
         setBlock(world, x + 29, y + 7, z + 8, KMOD_Main.KetherLeaves);
         world.setBlockMetadataWithNotify(x + 29, y + 7, z + 8, 12, 12);
         setBlock(world, x + 7, y + 7, z + 9, KMOD_Main.KetherLeaves);
         world.setBlockMetadataWithNotify(x + 7, y + 7, z + 9, 12, 12);
         setBlock(world, x + 9, y + 7, z + 9, KMOD_Main.KetherLeaves);
         world.setBlockMetadataWithNotify(x + 9, y + 7, z + 9, 12, 12);
         setBlock(world, x + 11, y + 7, z + 9, KMOD_Main.KetherLeaves);
         world.setBlockMetadataWithNotify(x + 11, y + 7, z + 9, 12, 12);
         setBlock(world, x + 30, y + 7, z + 9, KMOD_Main.KetherLeaves);
         world.setBlockMetadataWithNotify(x + 30, y + 7, z + 9, 12, 12);
         setBlock(world, x + 8, y + 7, z + 10, KMOD_Main.KetherLeaves);
         world.setBlockMetadataWithNotify(x + 8, y + 7, z + 10, 12, 12);
         setBlock(world, x + 10, y + 7, z + 10, KMOD_Main.KetherLeaves);
         world.setBlockMetadataWithNotify(x + 10, y + 7, z + 10, 12, 12);
         setBlock(world, x + 28, y + 7, z + 10, KMOD_Main.KetherLeaves);
         world.setBlockMetadataWithNotify(x + 28, y + 7, z + 10, 12, 12);
         setBlock(world, x + 31, y + 7, z + 10, KMOD_Main.KetherLeaves);
         world.setBlockMetadataWithNotify(x + 31, y + 7, z + 10, 4, 4);
         setBlock(world, x + 8, y + 7, z + 11, KMOD_Main.KetherLeaves);
         world.setBlockMetadataWithNotify(x + 8, y + 7, z + 11, 12, 12);
         setBlock(world, x + 9, y + 7, z + 11, KMOD_Main.KetherLeaves);
         world.setBlockMetadataWithNotify(x + 9, y + 7, z + 11, 12, 12);
         setBlock(world, x + 10, y + 7, z + 11, KMOD_Main.KetherLeaves);
         world.setBlockMetadataWithNotify(x + 10, y + 7, z + 11, 12, 12);
         setBlock(world, x + 28, y + 7, z + 11, KMOD_Main.KetherLeaves);
         world.setBlockMetadataWithNotify(x + 28, y + 7, z + 11, 12, 12);
         setBlock(world, x + 30, y + 7, z + 11, KMOD_Main.KetherLeaves);
         world.setBlockMetadataWithNotify(x + 30, y + 7, z + 11, 12, 12);
         setBlock(world, x + 31, y + 7, z + 11, KMOD_Main.KetherLeaves);
         world.setBlockMetadataWithNotify(x + 31, y + 7, z + 11, 4, 4);
         setBlock(world, x + 5, y + 7, z + 12, KMOD_Main.KetherLeaves);
         world.setBlockMetadataWithNotify(x + 5, y + 7, z + 12, 12, 12);
         setBlock(world, x + 9, y + 7, z + 12, KMOD_Main.KetherLeaves);
         world.setBlockMetadataWithNotify(x + 9, y + 7, z + 12, 12, 12);
         setBlock(world, x + 17, y + 7, z + 12, KMOD_Main.KetherLog);
         world.setBlockMetadataWithNotify(x + 17, y + 7, z + 12, 12, 12);
         setBlock(world, x + 19, y + 7, z + 12, KMOD_Main.KetherLog);
         setBlock(world, x + 28, y + 7, z + 12, KMOD_Main.KetherLeaves);
         world.setBlockMetadataWithNotify(x + 28, y + 7, z + 12, 12, 12);
         setBlock(world, x + 30, y + 7, z + 12, KMOD_Main.KetherLeaves);
         world.setBlockMetadataWithNotify(x + 30, y + 7, z + 12, 12, 12);
         setBlock(world, x + 31, y + 7, z + 12, KMOD_Main.KetherLeaves);
         world.setBlockMetadataWithNotify(x + 31, y + 7, z + 12, 4, 4);
         setBlock(world, x + 10, y + 7, z + 13, KMOD_Main.KetherLeaves);
         world.setBlockMetadataWithNotify(x + 10, y + 7, z + 13, 12, 12);
         setBlock(world, x + 17, y + 7, z + 13, KMOD_Main.KetherLog);
         world.setBlockMetadataWithNotify(x + 17, y + 7, z + 13, 12, 12);
         setBlock(world, x + 18, y + 7, z + 13, KMOD_Main.KetherLog);
         world.setBlockMetadataWithNotify(x + 18, y + 7, z + 13, 12, 12);
         setBlock(world, x + 19, y + 7, z + 13, KMOD_Main.KetherLog);
         world.setBlockMetadataWithNotify(x + 19, y + 7, z + 13, 12, 12);
         setBlock(world, x + 20, y + 7, z + 13, KMOD_Main.KetherLog);
         world.setBlockMetadataWithNotify(x + 20, y + 7, z + 13, 12, 12);
         setBlock(world, x + 31, y + 7, z + 13, KMOD_Main.KetherLeaves);
         world.setBlockMetadataWithNotify(x + 31, y + 7, z + 13, 4, 4);
         setBlock(world, x + 7, y + 7, z + 14, KMOD_Main.KetherLeaves);
         world.setBlockMetadataWithNotify(x + 7, y + 7, z + 14, 12, 12);
         setBlock(world, x + 10, y + 7, z + 14, KMOD_Main.KetherLeaves);
         world.setBlockMetadataWithNotify(x + 10, y + 7, z + 14, 12, 12);
         setBlock(world, x + 17, y + 7, z + 14, KMOD_Main.KetherLog);
         world.setBlockMetadataWithNotify(x + 17, y + 7, z + 14, 12, 12);
         setBlock(world, x + 18, y + 7, z + 14, KMOD_Main.KetherLog);
         world.setBlockMetadataWithNotify(x + 18, y + 7, z + 14, 12, 12);
         setBlock(world, x + 28, y + 7, z + 14, KMOD_Main.KetherLeaves);
         world.setBlockMetadataWithNotify(x + 28, y + 7, z + 14, 12, 12);
         setBlock(world, x + 30, y + 7, z + 14, KMOD_Main.KetherLeaves);
         world.setBlockMetadataWithNotify(x + 30, y + 7, z + 14, 12, 12);
         setBlock(world, x + 31, y + 7, z + 14, KMOD_Main.KetherLeaves);
         world.setBlockMetadataWithNotify(x + 31, y + 7, z + 14, 4, 4);
         setBlock(world, x + 6, y + 7, z + 15, KMOD_Main.KetherLeaves);
         world.setBlockMetadataWithNotify(x + 6, y + 7, z + 15, 12, 12);
         setBlock(world, x + 7, y + 7, z + 15, KMOD_Main.KetherLeaves);
         world.setBlockMetadataWithNotify(x + 7, y + 7, z + 15, 12, 12);
         setBlock(world, x + 9, y + 7, z + 15, KMOD_Main.KetherLeaves);
         world.setBlockMetadataWithNotify(x + 9, y + 7, z + 15, 12, 12);
         setBlock(world, x + 8, y + 7, z + 16, KMOD_Main.KetherLeaves);
         world.setBlockMetadataWithNotify(x + 8, y + 7, z + 16, 12, 12);
         setBlock(world, x + 28, y + 7, z + 16, KMOD_Main.KetherLeaves);
         world.setBlockMetadataWithNotify(x + 28, y + 7, z + 16, 12, 12);
         setBlock(world, x + 5, y + 7, z + 17, KMOD_Main.KetherLeaves);
         world.setBlockMetadataWithNotify(x + 5, y + 7, z + 17, 12, 12);
         setBlock(world, x + 7, y + 7, z + 17, KMOD_Main.KetherLeaves);
         world.setBlockMetadataWithNotify(x + 7, y + 7, z + 17, 12, 12);
         setBlock(world, x + 8, y + 7, z + 17, KMOD_Main.KetherLeaves);
         world.setBlockMetadataWithNotify(x + 8, y + 7, z + 17, 12, 12);
         setBlock(world, x + 9, y + 7, z + 17, KMOD_Main.KetherLeaves);
         world.setBlockMetadataWithNotify(x + 9, y + 7, z + 17, 12, 12);
         setBlock(world, x + 19, y + 7, z + 17, KMOD_Main.KetherLog);
         world.setBlockMetadataWithNotify(x + 19, y + 7, z + 17, 8, 8);
         setBlock(world, x + 26, y + 7, z + 17, KMOD_Main.KetherLeaves);
         world.setBlockMetadataWithNotify(x + 26, y + 7, z + 17, 12, 12);
         setBlock(world, x + 30, y + 7, z + 17, KMOD_Main.KetherLeaves);
         world.setBlockMetadataWithNotify(x + 30, y + 7, z + 17, 12, 12);
         setBlock(world, x + 6, y + 7, z + 18, KMOD_Main.KetherLeaves);
         world.setBlockMetadataWithNotify(x + 6, y + 7, z + 18, 12, 12);
         setBlock(world, x + 9, y + 7, z + 18, KMOD_Main.KetherLeaves);
         world.setBlockMetadataWithNotify(x + 9, y + 7, z + 18, 12, 12);
         setBlock(world, x + 11, y + 7, z + 18, KMOD_Main.KetherLeaves);
         world.setBlockMetadataWithNotify(x + 11, y + 7, z + 18, 12, 12);
         setBlock(world, x + 28, y + 7, z + 18, KMOD_Main.KetherLeaves);
         world.setBlockMetadataWithNotify(x + 28, y + 7, z + 18, 12, 12);
         setBlock(world, x + 5, y + 7, z + 19, KMOD_Main.KetherLeaves);
         world.setBlockMetadataWithNotify(x + 5, y + 7, z + 19, 12, 12);
         setBlock(world, x + 6, y + 7, z + 19, KMOD_Main.KetherLeaves);
         world.setBlockMetadataWithNotify(x + 6, y + 7, z + 19, 12, 12);
         setBlock(world, x + 7, y + 7, z + 19, KMOD_Main.KetherLeaves);
         world.setBlockMetadataWithNotify(x + 7, y + 7, z + 19, 12, 12);
         setBlock(world, x + 11, y + 7, z + 19, KMOD_Main.KetherLeaves);
         world.setBlockMetadataWithNotify(x + 11, y + 7, z + 19, 12, 12);
         setBlock(world, x + 13, y + 7, z + 19, KMOD_Main.KetherLeaves);
         world.setBlockMetadataWithNotify(x + 13, y + 7, z + 19, 12, 12);
         setBlock(world, x + 25, y + 7, z + 19, KMOD_Main.KetherLeaves);
         world.setBlockMetadataWithNotify(x + 25, y + 7, z + 19, 12, 12);
         setBlock(world, x + 9, y + 7, z + 20, KMOD_Main.KetherLeaves);
         world.setBlockMetadataWithNotify(x + 9, y + 7, z + 20, 12, 12);
         setBlock(world, x + 10, y + 7, z + 20, KMOD_Main.KetherLeaves);
         world.setBlockMetadataWithNotify(x + 10, y + 7, z + 20, 12, 12);
         setBlock(world, x + 14, y + 7, z + 20, KMOD_Main.KetherLeaves);
         world.setBlockMetadataWithNotify(x + 14, y + 7, z + 20, 12, 12);
         setBlock(world, x + 16, y + 7, z + 20, KMOD_Main.KetherLeaves);
         world.setBlockMetadataWithNotify(x + 16, y + 7, z + 20, 12, 12);
         setBlock(world, x + 22, y + 7, z + 20, KMOD_Main.KetherLeaves);
         world.setBlockMetadataWithNotify(x + 22, y + 7, z + 20, 12, 12);
         setBlock(world, x + 23, y + 7, z + 20, KMOD_Main.KetherLeaves);
         world.setBlockMetadataWithNotify(x + 23, y + 7, z + 20, 12, 12);
         setBlock(world, x + 24, y + 7, z + 20, KMOD_Main.KetherLeaves);
         world.setBlockMetadataWithNotify(x + 24, y + 7, z + 20, 12, 12);
         setBlock(world, x + 27, y + 7, z + 20, KMOD_Main.KetherLeaves);
         world.setBlockMetadataWithNotify(x + 27, y + 7, z + 20, 12, 12);
         setBlock(world, x + 28, y + 7, z + 20, KMOD_Main.KetherLeaves);
         world.setBlockMetadataWithNotify(x + 28, y + 7, z + 20, 12, 12);
         setBlock(world, x + 8, y + 7, z + 21, KMOD_Main.KetherLeaves);
         world.setBlockMetadataWithNotify(x + 8, y + 7, z + 21, 12, 12);
         setBlock(world, x + 15, y + 7, z + 21, KMOD_Main.KetherLeaves);
         world.setBlockMetadataWithNotify(x + 15, y + 7, z + 21, 12, 12);
         setBlock(world, x + 17, y + 7, z + 21, KMOD_Main.KetherLeaves);
         world.setBlockMetadataWithNotify(x + 17, y + 7, z + 21, 12, 12);
         setBlock(world, x + 20, y + 7, z + 21, KMOD_Main.KetherLeaves);
         world.setBlockMetadataWithNotify(x + 20, y + 7, z + 21, 12, 12);
         setBlock(world, x + 21, y + 7, z + 21, KMOD_Main.KetherLeaves);
         world.setBlockMetadataWithNotify(x + 21, y + 7, z + 21, 12, 12);
         setBlock(world, x + 28, y + 7, z + 21, KMOD_Main.KetherLeaves);
         world.setBlockMetadataWithNotify(x + 28, y + 7, z + 21, 12, 12);
         setBlock(world, x + 7, y + 7, z + 22, KMOD_Main.KetherLeaves);
         world.setBlockMetadataWithNotify(x + 7, y + 7, z + 22, 12, 12);
         setBlock(world, x + 8, y + 7, z + 22, KMOD_Main.KetherLeaves);
         world.setBlockMetadataWithNotify(x + 8, y + 7, z + 22, 12, 12);
         setBlock(world, x + 10, y + 7, z + 22, KMOD_Main.KetherLeaves);
         world.setBlockMetadataWithNotify(x + 10, y + 7, z + 22, 12, 12);
         setBlock(world, x + 11, y + 7, z + 22, KMOD_Main.KetherLeaves);
         world.setBlockMetadataWithNotify(x + 11, y + 7, z + 22, 12, 12);
         setBlock(world, x + 12, y + 7, z + 22, KMOD_Main.KetherLeaves);
         world.setBlockMetadataWithNotify(x + 12, y + 7, z + 22, 12, 12);
         setBlock(world, x + 14, y + 7, z + 22, KMOD_Main.KetherLeaves);
         world.setBlockMetadataWithNotify(x + 14, y + 7, z + 22, 12, 12);
         setBlock(world, x + 15, y + 7, z + 22, KMOD_Main.KetherLeaves);
         world.setBlockMetadataWithNotify(x + 15, y + 7, z + 22, 12, 12);
         setBlock(world, x + 16, y + 7, z + 22, KMOD_Main.KetherLeaves);
         world.setBlockMetadataWithNotify(x + 16, y + 7, z + 22, 12, 12);
         setBlock(world, x + 17, y + 7, z + 22, KMOD_Main.KetherLeaves);
         world.setBlockMetadataWithNotify(x + 17, y + 7, z + 22, 12, 12);
         setBlock(world, x + 18, y + 7, z + 22, KMOD_Main.KetherLeaves);
         world.setBlockMetadataWithNotify(x + 18, y + 7, z + 22, 12, 12);
         setBlock(world, x + 20, y + 7, z + 22, KMOD_Main.KetherLeaves);
         world.setBlockMetadataWithNotify(x + 20, y + 7, z + 22, 12, 12);
         setBlock(world, x + 24, y + 7, z + 22, KMOD_Main.KetherLeaves);
         world.setBlockMetadataWithNotify(x + 24, y + 7, z + 22, 12, 12);
         setBlock(world, x + 25, y + 7, z + 22, KMOD_Main.KetherLeaves);
         world.setBlockMetadataWithNotify(x + 25, y + 7, z + 22, 12, 12);
         setBlock(world, x + 26, y + 7, z + 22, KMOD_Main.KetherLeaves);
         world.setBlockMetadataWithNotify(x + 26, y + 7, z + 22, 12, 12);
         setBlock(world, x + 28, y + 7, z + 22, KMOD_Main.KetherLeaves);
         world.setBlockMetadataWithNotify(x + 28, y + 7, z + 22, 12, 12);
         setBlock(world, x + 29, y + 7, z + 22, KMOD_Main.KetherLeaves);
         world.setBlockMetadataWithNotify(x + 29, y + 7, z + 22, 12, 12);
         setBlock(world, x + 15, y + 7, z + 23, KMOD_Main.KetherLeaves);
         world.setBlockMetadataWithNotify(x + 15, y + 7, z + 23, 12, 12);
         setBlock(world, x + 16, y + 7, z + 23, KMOD_Main.KetherLeaves);
         world.setBlockMetadataWithNotify(x + 16, y + 7, z + 23, 12, 12);
         setBlock(world, x + 17, y + 7, z + 23, KMOD_Main.KetherLeaves);
         world.setBlockMetadataWithNotify(x + 17, y + 7, z + 23, 12, 12);
         setBlock(world, x + 18, y + 7, z + 23, KMOD_Main.KetherLeaves);
         world.setBlockMetadataWithNotify(x + 18, y + 7, z + 23, 12, 12);
         setBlock(world, x + 19, y + 7, z + 23, KMOD_Main.KetherLeaves);
         world.setBlockMetadataWithNotify(x + 19, y + 7, z + 23, 12, 12);
         setBlock(world, x + 20, y + 7, z + 23, KMOD_Main.KetherLeaves);
         world.setBlockMetadataWithNotify(x + 20, y + 7, z + 23, 12, 12);
         setBlock(world, x + 23, y + 7, z + 23, KMOD_Main.KetherLeaves);
         world.setBlockMetadataWithNotify(x + 23, y + 7, z + 23, 12, 12);
         setBlock(world, x + 24, y + 7, z + 23, KMOD_Main.KetherLeaves);
         world.setBlockMetadataWithNotify(x + 24, y + 7, z + 23, 12, 12);
         setBlock(world, x + 9, y + 7, z + 24, KMOD_Main.KetherLeaves);
         world.setBlockMetadataWithNotify(x + 9, y + 7, z + 24, 12, 12);
         setBlock(world, x + 12, y + 7, z + 24, KMOD_Main.KetherLeaves);
         world.setBlockMetadataWithNotify(x + 12, y + 7, z + 24, 12, 12);
         setBlock(world, x + 16, y + 7, z + 24, KMOD_Main.KetherLeaves);
         world.setBlockMetadataWithNotify(x + 16, y + 7, z + 24, 12, 12);
         setBlock(world, x + 18, y + 7, z + 24, KMOD_Main.KetherLeaves);
         world.setBlockMetadataWithNotify(x + 18, y + 7, z + 24, 12, 12);
         setBlock(world, x + 20, y + 7, z + 24, KMOD_Main.KetherLeaves);
         world.setBlockMetadataWithNotify(x + 20, y + 7, z + 24, 12, 12);
         setBlock(world, x + 26, y + 7, z + 24, KMOD_Main.KetherLeaves);
         world.setBlockMetadataWithNotify(x + 26, y + 7, z + 24, 12, 12);
         setBlock(world, x + 12, y + 7, z + 25, KMOD_Main.KetherLeaves);
         world.setBlockMetadataWithNotify(x + 12, y + 7, z + 25, 12, 12);
         setBlock(world, x + 13, y + 7, z + 25, KMOD_Main.KetherLeaves);
         world.setBlockMetadataWithNotify(x + 13, y + 7, z + 25, 12, 12);
         setBlock(world, x + 17, y + 7, z + 26, KMOD_Main.KetherLeaves);
         world.setBlockMetadataWithNotify(x + 17, y + 7, z + 26, 12, 12);
         setBlock(world, x + 14, y + 7, z + 27, KMOD_Main.KetherLeaves);
         world.setBlockMetadataWithNotify(x + 14, y + 7, z + 27, 12, 12);
         setBlock(world, x + 16, y + 7, z + 27, KMOD_Main.KetherLeaves);
         world.setBlockMetadataWithNotify(x + 16, y + 7, z + 27, 12, 12);
         setBlock(world, x + 17, y + 8, z + 0, KMOD_Main.KetherLeaves);
         world.setBlockMetadataWithNotify(x + 17, y + 8, z + 0, 12, 12);
         setBlock(world, x + 18, y + 8, z + 0, KMOD_Main.KetherLeaves);
         world.setBlockMetadataWithNotify(x + 18, y + 8, z + 0, 12, 12);
         setBlock(world, x + 14, y + 8, z + 1, KMOD_Main.KetherLeaves);
         world.setBlockMetadataWithNotify(x + 14, y + 8, z + 1, 12, 12);
         setBlock(world, x + 16, y + 8, z + 1, KMOD_Main.KetherLeaves);
         world.setBlockMetadataWithNotify(x + 16, y + 8, z + 1, 12, 12);
         setBlock(world, x + 20, y + 8, z + 1, KMOD_Main.KetherLeaves);
         world.setBlockMetadataWithNotify(x + 20, y + 8, z + 1, 12, 12);
         setBlock(world, x + 13, y + 8, z + 2, KMOD_Main.KetherLeaves);
         world.setBlockMetadataWithNotify(x + 13, y + 8, z + 2, 12, 12);
         setBlock(world, x + 15, y + 8, z + 2, KMOD_Main.KetherLeaves);
         world.setBlockMetadataWithNotify(x + 15, y + 8, z + 2, 12, 12);
         setBlock(world, x + 21, y + 8, z + 2, KMOD_Main.KetherLeaves);
         world.setBlockMetadataWithNotify(x + 21, y + 8, z + 2, 12, 12);
         setBlock(world, x + 24, y + 8, z + 2, KMOD_Main.KetherLeaves);
         world.setBlockMetadataWithNotify(x + 24, y + 8, z + 2, 12, 12);
         setBlock(world, x + 18, y + 8, z + 3, KMOD_Main.KetherLeaves);
         world.setBlockMetadataWithNotify(x + 18, y + 8, z + 3, 12, 12);
         setBlock(world, x + 21, y + 8, z + 3, KMOD_Main.KetherLeaves);
         world.setBlockMetadataWithNotify(x + 21, y + 8, z + 3, 12, 12);
         setBlock(world, x + 24, y + 8, z + 3, KMOD_Main.KetherLeaves);
         world.setBlockMetadataWithNotify(x + 24, y + 8, z + 3, 12, 12);
         setBlock(world, x + 26, y + 8, z + 3, KMOD_Main.KetherLeaves);
         world.setBlockMetadataWithNotify(x + 26, y + 8, z + 3, 12, 12);
         setBlock(world, x + 12, y + 8, z + 4, KMOD_Main.KetherLeaves);
         world.setBlockMetadataWithNotify(x + 12, y + 8, z + 4, 12, 12);
         setBlock(world, x + 16, y + 8, z + 4, KMOD_Main.KetherLeaves);
         world.setBlockMetadataWithNotify(x + 16, y + 8, z + 4, 12, 12);
         setBlock(world, x + 17, y + 8, z + 4, KMOD_Main.KetherLeaves);
         world.setBlockMetadataWithNotify(x + 17, y + 8, z + 4, 12, 12);
         setBlock(world, x + 27, y + 8, z + 4, KMOD_Main.KetherLeaves);
         world.setBlockMetadataWithNotify(x + 27, y + 8, z + 4, 12, 12);
         setBlock(world, x + 12, y + 8, z + 5, KMOD_Main.KetherLeaves);
         world.setBlockMetadataWithNotify(x + 12, y + 8, z + 5, 12, 12);
         setBlock(world, x + 14, y + 8, z + 5, KMOD_Main.KetherLeaves);
         world.setBlockMetadataWithNotify(x + 14, y + 8, z + 5, 12, 12);
         setBlock(world, x + 22, y + 8, z + 5, KMOD_Main.KetherLeaves);
         world.setBlockMetadataWithNotify(x + 22, y + 8, z + 5, 12, 12);
         setBlock(world, x + 23, y + 8, z + 5, KMOD_Main.KetherLeaves);
         world.setBlockMetadataWithNotify(x + 23, y + 8, z + 5, 12, 12);
         setBlock(world, x + 27, y + 8, z + 5, KMOD_Main.KetherLeaves);
         world.setBlockMetadataWithNotify(x + 27, y + 8, z + 5, 12, 12);
         setBlock(world, x + 28, y + 8, z + 5, KMOD_Main.KetherLeaves);
         world.setBlockMetadataWithNotify(x + 28, y + 8, z + 5, 12, 12);
         setBlock(world, x + 29, y + 8, z + 5, KMOD_Main.KetherLeaves);
         world.setBlockMetadataWithNotify(x + 29, y + 8, z + 5, 12, 12);
         setBlock(world, x + 8, y + 8, z + 6, KMOD_Main.KetherLeaves);
         world.setBlockMetadataWithNotify(x + 8, y + 8, z + 6, 12, 12);
         setBlock(world, x + 16, y + 8, z + 6, KMOD_Main.KetherLeaves);
         world.setBlockMetadataWithNotify(x + 16, y + 8, z + 6, 12, 12);
         setBlock(world, x + 19, y + 8, z + 6, KMOD_Main.KetherLeaves);
         world.setBlockMetadataWithNotify(x + 19, y + 8, z + 6, 12, 12);
         setBlock(world, x + 24, y + 8, z + 6, KMOD_Main.KetherLeaves);
         world.setBlockMetadataWithNotify(x + 24, y + 8, z + 6, 12, 12);
         setBlock(world, x + 25, y + 8, z + 6, KMOD_Main.KetherLeaves);
         world.setBlockMetadataWithNotify(x + 25, y + 8, z + 6, 12, 12);
         setBlock(world, x + 27, y + 8, z + 6, KMOD_Main.KetherLeaves);
         world.setBlockMetadataWithNotify(x + 27, y + 8, z + 6, 12, 12);
         setBlock(world, x + 28, y + 8, z + 6, KMOD_Main.KetherLeaves);
         world.setBlockMetadataWithNotify(x + 28, y + 8, z + 6, 12, 12);
         setBlock(world, x + 14, y + 8, z + 7, KMOD_Main.KetherLeaves);
         world.setBlockMetadataWithNotify(x + 14, y + 8, z + 7, 12, 12);
         setBlock(world, x + 16, y + 8, z + 7, KMOD_Main.KetherLeaves);
         world.setBlockMetadataWithNotify(x + 16, y + 8, z + 7, 12, 12);
         setBlock(world, x + 22, y + 8, z + 7, KMOD_Main.KetherLeaves);
         world.setBlockMetadataWithNotify(x + 22, y + 8, z + 7, 12, 12);
         setBlock(world, x + 23, y + 8, z + 7, KMOD_Main.KetherLeaves);
         world.setBlockMetadataWithNotify(x + 23, y + 8, z + 7, 12, 12);
         setBlock(world, x + 26, y + 8, z + 7, KMOD_Main.KetherLeaves);
         world.setBlockMetadataWithNotify(x + 26, y + 8, z + 7, 12, 12);
         setBlock(world, x + 27, y + 8, z + 7, KMOD_Main.KetherLeaves);
         world.setBlockMetadataWithNotify(x + 27, y + 8, z + 7, 12, 12);
         setBlock(world, x + 28, y + 8, z + 7, KMOD_Main.KetherLeaves);
         world.setBlockMetadataWithNotify(x + 28, y + 8, z + 7, 12, 12);
         setBlock(world, x + 9, y + 8, z + 8, KMOD_Main.KetherLeaves);
         world.setBlockMetadataWithNotify(x + 9, y + 8, z + 8, 12, 12);
         setBlock(world, x + 10, y + 8, z + 8, KMOD_Main.KetherLeaves);
         world.setBlockMetadataWithNotify(x + 10, y + 8, z + 8, 12, 12);
         setBlock(world, x + 11, y + 8, z + 8, KMOD_Main.KetherLeaves);
         world.setBlockMetadataWithNotify(x + 11, y + 8, z + 8, 12, 12);
         setBlock(world, x + 12, y + 8, z + 8, KMOD_Main.KetherLeaves);
         world.setBlockMetadataWithNotify(x + 12, y + 8, z + 8, 12, 12);
         setBlock(world, x + 23, y + 8, z + 8, KMOD_Main.KetherLeaves);
         world.setBlockMetadataWithNotify(x + 23, y + 8, z + 8, 12, 12);
         setBlock(world, x + 25, y + 8, z + 8, KMOD_Main.KetherLeaves);
         world.setBlockMetadataWithNotify(x + 25, y + 8, z + 8, 12, 12);
         setBlock(world, x + 26, y + 8, z + 8, KMOD_Main.KetherLeaves);
         world.setBlockMetadataWithNotify(x + 26, y + 8, z + 8, 12, 12);
         setBlock(world, x + 27, y + 8, z + 8, KMOD_Main.KetherLeaves);
         world.setBlockMetadataWithNotify(x + 27, y + 8, z + 8, 12, 12);
         setBlock(world, x + 6, y + 8, z + 9, KMOD_Main.KetherLeaves);
         world.setBlockMetadataWithNotify(x + 6, y + 8, z + 9, 12, 12);
         setBlock(world, x + 10, y + 8, z + 9, KMOD_Main.KetherLeaves);
         world.setBlockMetadataWithNotify(x + 10, y + 8, z + 9, 12, 12);
         setBlock(world, x + 29, y + 8, z + 9, KMOD_Main.KetherLeaves);
         world.setBlockMetadataWithNotify(x + 29, y + 8, z + 9, 12, 12);
         setBlock(world, x + 30, y + 8, z + 9, KMOD_Main.KetherLeaves);
         world.setBlockMetadataWithNotify(x + 30, y + 8, z + 9, 12, 12);
         setBlock(world, x + 31, y + 8, z + 9, KMOD_Main.KetherLeaves);
         world.setBlockMetadataWithNotify(x + 31, y + 8, z + 9, 12, 12);
         setBlock(world, x + 6, y + 8, z + 10, KMOD_Main.KetherLeaves);
         world.setBlockMetadataWithNotify(x + 6, y + 8, z + 10, 12, 12);
         setBlock(world, x + 11, y + 8, z + 10, KMOD_Main.KetherLeaves);
         world.setBlockMetadataWithNotify(x + 11, y + 8, z + 10, 12, 12);
         setBlock(world, x + 28, y + 8, z + 10, KMOD_Main.KetherLeaves);
         world.setBlockMetadataWithNotify(x + 28, y + 8, z + 10, 12, 12);
         setBlock(world, x + 30, y + 8, z + 10, KMOD_Main.KetherLeaves);
         world.setBlockMetadataWithNotify(x + 30, y + 8, z + 10, 4, 4);
         setBlock(world, x + 31, y + 8, z + 10, KMOD_Main.KetherLeaves);
         world.setBlockMetadataWithNotify(x + 31, y + 8, z + 10, 12, 12);
         setBlock(world, x + 9, y + 8, z + 11, KMOD_Main.KetherLeaves);
         world.setBlockMetadataWithNotify(x + 9, y + 8, z + 11, 12, 12);
         setBlock(world, x + 10, y + 8, z + 11, KMOD_Main.KetherLeaves);
         world.setBlockMetadataWithNotify(x + 10, y + 8, z + 11, 12, 12);
         setBlock(world, x + 16, y + 8, z + 11, KMOD_Main.KetherLog);
         setBlock(world, x + 26, y + 8, z + 11, KMOD_Main.KetherLeaves);
         world.setBlockMetadataWithNotify(x + 26, y + 8, z + 11, 12, 12);
         setBlock(world, x + 27, y + 8, z + 11, KMOD_Main.KetherLeaves);
         world.setBlockMetadataWithNotify(x + 27, y + 8, z + 11, 12, 12);
         setBlock(world, x + 29, y + 8, z + 11, KMOD_Main.KetherLeaves);
         world.setBlockMetadataWithNotify(x + 29, y + 8, z + 11, 12, 12);
         setBlock(world, x + 30, y + 8, z + 11, KMOD_Main.KetherLeaves);
         world.setBlockMetadataWithNotify(x + 30, y + 8, z + 11, 12, 12);
         setBlock(world, x + 11, y + 8, z + 12, KMOD_Main.KetherLeaves);
         world.setBlockMetadataWithNotify(x + 11, y + 8, z + 12, 12, 12);
         setBlock(world, x + 20, y + 8, z + 12, KMOD_Main.KetherLog);
         world.setBlockMetadataWithNotify(x + 20, y + 8, z + 12, 12, 12);
         setBlock(world, x + 25, y + 8, z + 12, KMOD_Main.KetherLeaves);
         world.setBlockMetadataWithNotify(x + 25, y + 8, z + 12, 12, 12);
         setBlock(world, x + 28, y + 8, z + 12, KMOD_Main.KetherLeaves);
         world.setBlockMetadataWithNotify(x + 28, y + 8, z + 12, 12, 12);
         setBlock(world, x + 29, y + 8, z + 12, KMOD_Main.KetherLeaves);
         world.setBlockMetadataWithNotify(x + 29, y + 8, z + 12, 12, 12);
         setBlock(world, x + 4, y + 8, z + 13, KMOD_Main.KetherLeaves);
         world.setBlockMetadataWithNotify(x + 4, y + 8, z + 13, 12, 12);
         setBlock(world, x + 5, y + 8, z + 13, KMOD_Main.KetherLeaves);
         world.setBlockMetadataWithNotify(x + 5, y + 8, z + 13, 12, 12);
         setBlock(world, x + 6, y + 8, z + 13, KMOD_Main.KetherLeaves);
         world.setBlockMetadataWithNotify(x + 6, y + 8, z + 13, 12, 12);
         setBlock(world, x + 9, y + 8, z + 13, KMOD_Main.KetherLeaves);
         world.setBlockMetadataWithNotify(x + 9, y + 8, z + 13, 12, 12);
         setBlock(world, x + 11, y + 8, z + 13, KMOD_Main.KetherLeaves);
         world.setBlockMetadataWithNotify(x + 11, y + 8, z + 13, 12, 12);
         setBlock(world, x + 29, y + 8, z + 13, KMOD_Main.KetherLeaves);
         world.setBlockMetadataWithNotify(x + 29, y + 8, z + 13, 12, 12);
         setBlock(world, x + 30, y + 8, z + 13, KMOD_Main.KetherLeaves);
         world.setBlockMetadataWithNotify(x + 30, y + 8, z + 13, 12, 12);
         setBlock(world, x + 9, y + 8, z + 14, KMOD_Main.KetherLeaves);
         world.setBlockMetadataWithNotify(x + 9, y + 8, z + 14, 12, 12);
         setBlock(world, x + 17, y + 8, z + 14, KMOD_Main.KetherLog);
         world.setBlockMetadataWithNotify(x + 17, y + 8, z + 14, 12, 12);
         setBlock(world, x + 27, y + 8, z + 14, KMOD_Main.KetherLeaves);
         world.setBlockMetadataWithNotify(x + 27, y + 8, z + 14, 12, 12);
         setBlock(world, x + 28, y + 8, z + 14, KMOD_Main.KetherLeaves);
         world.setBlockMetadataWithNotify(x + 28, y + 8, z + 14, 12, 12);
         setBlock(world, x + 29, y + 8, z + 14, KMOD_Main.KetherLeaves);
         world.setBlockMetadataWithNotify(x + 29, y + 8, z + 14, 12, 12);
         setBlock(world, x + 30, y + 8, z + 14, KMOD_Main.KetherLeaves);
         world.setBlockMetadataWithNotify(x + 30, y + 8, z + 14, 12, 12);
         setBlock(world, x + 7, y + 8, z + 15, KMOD_Main.KetherLeaves);
         world.setBlockMetadataWithNotify(x + 7, y + 8, z + 15, 12, 12);
         setBlock(world, x + 16, y + 8, z + 15, KMOD_Main.KetherLog);
         world.setBlockMetadataWithNotify(x + 16, y + 8, z + 15, 12, 12);
         setBlock(world, x + 27, y + 8, z + 15, KMOD_Main.KetherLeaves);
         world.setBlockMetadataWithNotify(x + 27, y + 8, z + 15, 12, 12);
         setBlock(world, x + 6, y + 8, z + 16, KMOD_Main.KetherLeaves);
         world.setBlockMetadataWithNotify(x + 6, y + 8, z + 16, 12, 12);
         setBlock(world, x + 6, y + 8, z + 17, KMOD_Main.KetherLeaves);
         world.setBlockMetadataWithNotify(x + 6, y + 8, z + 17, 12, 12);
         setBlock(world, x + 7, y + 8, z + 17, KMOD_Main.KetherLeaves);
         world.setBlockMetadataWithNotify(x + 7, y + 8, z + 17, 12, 12);
         setBlock(world, x + 26, y + 8, z + 17, KMOD_Main.KetherLeaves);
         world.setBlockMetadataWithNotify(x + 26, y + 8, z + 17, 12, 12);
         setBlock(world, x + 27, y + 8, z + 17, KMOD_Main.KetherLeaves);
         world.setBlockMetadataWithNotify(x + 27, y + 8, z + 17, 12, 12);
         setBlock(world, x + 28, y + 8, z + 17, KMOD_Main.KetherLeaves);
         world.setBlockMetadataWithNotify(x + 28, y + 8, z + 17, 12, 12);
         setBlock(world, x + 29, y + 8, z + 17, KMOD_Main.KetherLeaves);
         world.setBlockMetadataWithNotify(x + 29, y + 8, z + 17, 12, 12);
         setBlock(world, x + 5, y + 8, z + 18, KMOD_Main.KetherLeaves);
         world.setBlockMetadataWithNotify(x + 5, y + 8, z + 18, 12, 12);
         setBlock(world, x + 6, y + 8, z + 18, KMOD_Main.KetherLeaves);
         world.setBlockMetadataWithNotify(x + 6, y + 8, z + 18, 12, 12);
         setBlock(world, x + 9, y + 8, z + 18, KMOD_Main.KetherLeaves);
         world.setBlockMetadataWithNotify(x + 9, y + 8, z + 18, 12, 12);
         setBlock(world, x + 10, y + 8, z + 18, KMOD_Main.KetherLeaves);
         world.setBlockMetadataWithNotify(x + 10, y + 8, z + 18, 12, 12);
         setBlock(world, x + 11, y + 8, z + 18, KMOD_Main.KetherLeaves);
         world.setBlockMetadataWithNotify(x + 11, y + 8, z + 18, 12, 12);
         setBlock(world, x + 19, y + 8, z + 18, KMOD_Main.KetherLog);
         world.setBlockMetadataWithNotify(x + 19, y + 8, z + 18, 8, 8);
         setBlock(world, x + 28, y + 8, z + 18, KMOD_Main.KetherLeaves);
         world.setBlockMetadataWithNotify(x + 28, y + 8, z + 18, 12, 12);
         setBlock(world, x + 29, y + 8, z + 18, KMOD_Main.KetherLeaves);
         world.setBlockMetadataWithNotify(x + 29, y + 8, z + 18, 12, 12);
         setBlock(world, x + 30, y + 8, z + 18, KMOD_Main.KetherLeaves);
         world.setBlockMetadataWithNotify(x + 30, y + 8, z + 18, 4, 4);
         setBlock(world, x + 5, y + 8, z + 19, KMOD_Main.KetherLeaves);
         world.setBlockMetadataWithNotify(x + 5, y + 8, z + 19, 12, 12);
         setBlock(world, x + 7, y + 8, z + 19, KMOD_Main.KetherLeaves);
         world.setBlockMetadataWithNotify(x + 7, y + 8, z + 19, 12, 12);
         setBlock(world, x + 9, y + 8, z + 19, KMOD_Main.KetherLeaves);
         world.setBlockMetadataWithNotify(x + 9, y + 8, z + 19, 12, 12);
         setBlock(world, x + 11, y + 8, z + 19, KMOD_Main.KetherLeaves);
         world.setBlockMetadataWithNotify(x + 11, y + 8, z + 19, 12, 12);
         setBlock(world, x + 16, y + 8, z + 19, KMOD_Main.KetherLeaves);
         world.setBlockMetadataWithNotify(x + 16, y + 8, z + 19, 12, 12);
         setBlock(world, x + 21, y + 8, z + 19, KMOD_Main.KetherLeaves);
         world.setBlockMetadataWithNotify(x + 21, y + 8, z + 19, 12, 12);
         setBlock(world, x + 22, y + 8, z + 19, KMOD_Main.KetherLeaves);
         world.setBlockMetadataWithNotify(x + 22, y + 8, z + 19, 12, 12);
         setBlock(world, x + 27, y + 8, z + 19, KMOD_Main.KetherLeaves);
         world.setBlockMetadataWithNotify(x + 27, y + 8, z + 19, 12, 12);
         setBlock(world, x + 29, y + 8, z + 19, KMOD_Main.KetherLeaves);
         world.setBlockMetadataWithNotify(x + 29, y + 8, z + 19, 12, 12);
         setBlock(world, x + 30, y + 8, z + 19, KMOD_Main.KetherLeaves);
         world.setBlockMetadataWithNotify(x + 30, y + 8, z + 19, 4, 4);
         setBlock(world, x + 31, y + 8, z + 19, KMOD_Main.KetherLeaves);
         world.setBlockMetadataWithNotify(x + 31, y + 8, z + 19, 4, 4);
         setBlock(world, x + 5, y + 8, z + 20, KMOD_Main.KetherLeaves);
         world.setBlockMetadataWithNotify(x + 5, y + 8, z + 20, 12, 12);
         setBlock(world, x + 8, y + 8, z + 20, KMOD_Main.KetherLeaves);
         world.setBlockMetadataWithNotify(x + 8, y + 8, z + 20, 12, 12);
         setBlock(world, x + 9, y + 8, z + 20, KMOD_Main.KetherLeaves);
         world.setBlockMetadataWithNotify(x + 9, y + 8, z + 20, 12, 12);
         setBlock(world, x + 10, y + 8, z + 20, KMOD_Main.KetherLeaves);
         world.setBlockMetadataWithNotify(x + 10, y + 8, z + 20, 12, 12);
         setBlock(world, x + 12, y + 8, z + 20, KMOD_Main.KetherLeaves);
         world.setBlockMetadataWithNotify(x + 12, y + 8, z + 20, 12, 12);
         setBlock(world, x + 15, y + 8, z + 20, KMOD_Main.KetherLeaves);
         world.setBlockMetadataWithNotify(x + 15, y + 8, z + 20, 12, 12);
         setBlock(world, x + 16, y + 8, z + 20, KMOD_Main.KetherLeaves);
         world.setBlockMetadataWithNotify(x + 16, y + 8, z + 20, 12, 12);
         setBlock(world, x + 17, y + 8, z + 20, KMOD_Main.KetherLeaves);
         world.setBlockMetadataWithNotify(x + 17, y + 8, z + 20, 12, 12);
         setBlock(world, x + 26, y + 8, z + 20, KMOD_Main.KetherLeaves);
         world.setBlockMetadataWithNotify(x + 26, y + 8, z + 20, 12, 12);
         setBlock(world, x + 29, y + 8, z + 20, KMOD_Main.KetherLeaves);
         world.setBlockMetadataWithNotify(x + 29, y + 8, z + 20, 4, 4);
         setBlock(world, x + 30, y + 8, z + 20, KMOD_Main.KetherLeaves);
         world.setBlockMetadataWithNotify(x + 30, y + 8, z + 20, 4, 4);
         setBlock(world, x + 5, y + 8, z + 21, KMOD_Main.KetherLeaves);
         world.setBlockMetadataWithNotify(x + 5, y + 8, z + 21, 12, 12);
         setBlock(world, x + 6, y + 8, z + 21, KMOD_Main.KetherLeaves);
         world.setBlockMetadataWithNotify(x + 6, y + 8, z + 21, 12, 12);
         setBlock(world, x + 8, y + 8, z + 21, KMOD_Main.KetherLeaves);
         world.setBlockMetadataWithNotify(x + 8, y + 8, z + 21, 12, 12);
         setBlock(world, x + 13, y + 8, z + 21, KMOD_Main.KetherLeaves);
         world.setBlockMetadataWithNotify(x + 13, y + 8, z + 21, 12, 12);
         setBlock(world, x + 16, y + 8, z + 21, KMOD_Main.KetherLeaves);
         world.setBlockMetadataWithNotify(x + 16, y + 8, z + 21, 12, 12);
         setBlock(world, x + 20, y + 8, z + 21, KMOD_Main.KetherLeaves);
         world.setBlockMetadataWithNotify(x + 20, y + 8, z + 21, 12, 12);
         setBlock(world, x + 21, y + 8, z + 21, KMOD_Main.KetherLeaves);
         world.setBlockMetadataWithNotify(x + 21, y + 8, z + 21, 12, 12);
         setBlock(world, x + 22, y + 8, z + 21, KMOD_Main.KetherLeaves);
         world.setBlockMetadataWithNotify(x + 22, y + 8, z + 21, 12, 12);
         setBlock(world, x + 27, y + 8, z + 21, KMOD_Main.KetherLeaves);
         world.setBlockMetadataWithNotify(x + 27, y + 8, z + 21, 12, 12);
         setBlock(world, x + 28, y + 8, z + 21, KMOD_Main.KetherLeaves);
         world.setBlockMetadataWithNotify(x + 28, y + 8, z + 21, 12, 12);
         setBlock(world, x + 29, y + 8, z + 21, KMOD_Main.KetherLeaves);
         world.setBlockMetadataWithNotify(x + 29, y + 8, z + 21, 4, 4);
         setBlock(world, x + 6, y + 8, z + 22, KMOD_Main.KetherLeaves);
         world.setBlockMetadataWithNotify(x + 6, y + 8, z + 22, 12, 12);
         setBlock(world, x + 8, y + 8, z + 22, KMOD_Main.KetherLeaves);
         world.setBlockMetadataWithNotify(x + 8, y + 8, z + 22, 12, 12);
         setBlock(world, x + 9, y + 8, z + 22, KMOD_Main.KetherLeaves);
         world.setBlockMetadataWithNotify(x + 9, y + 8, z + 22, 12, 12);
         setBlock(world, x + 10, y + 8, z + 22, KMOD_Main.KetherLeaves);
         world.setBlockMetadataWithNotify(x + 10, y + 8, z + 22, 12, 12);
         setBlock(world, x + 15, y + 8, z + 22, KMOD_Main.KetherLeaves);
         world.setBlockMetadataWithNotify(x + 15, y + 8, z + 22, 12, 12);
         setBlock(world, x + 19, y + 8, z + 22, KMOD_Main.KetherLeaves);
         world.setBlockMetadataWithNotify(x + 19, y + 8, z + 22, 12, 12);
         setBlock(world, x + 20, y + 8, z + 22, KMOD_Main.KetherLeaves);
         world.setBlockMetadataWithNotify(x + 20, y + 8, z + 22, 12, 12);
         setBlock(world, x + 24, y + 8, z + 22, KMOD_Main.KetherLeaves);
         world.setBlockMetadataWithNotify(x + 24, y + 8, z + 22, 12, 12);
         setBlock(world, x + 25, y + 8, z + 22, KMOD_Main.KetherLeaves);
         world.setBlockMetadataWithNotify(x + 25, y + 8, z + 22, 12, 12);
         setBlock(world, x + 26, y + 8, z + 22, KMOD_Main.KetherLeaves);
         world.setBlockMetadataWithNotify(x + 26, y + 8, z + 22, 12, 12);
         setBlock(world, x + 27, y + 8, z + 22, KMOD_Main.KetherLeaves);
         world.setBlockMetadataWithNotify(x + 27, y + 8, z + 22, 12, 12);
         setBlock(world, x + 28, y + 8, z + 22, KMOD_Main.KetherLeaves);
         world.setBlockMetadataWithNotify(x + 28, y + 8, z + 22, 12, 12);
         setBlock(world, x + 29, y + 8, z + 22, KMOD_Main.KetherLeaves);
         world.setBlockMetadataWithNotify(x + 29, y + 8, z + 22, 12, 12);
         setBlock(world, x + 6, y + 8, z + 23, KMOD_Main.KetherLeaves);
         world.setBlockMetadataWithNotify(x + 6, y + 8, z + 23, 12, 12);
         setBlock(world, x + 7, y + 8, z + 23, KMOD_Main.KetherLeaves);
         world.setBlockMetadataWithNotify(x + 7, y + 8, z + 23, 12, 12);
         setBlock(world, x + 8, y + 8, z + 23, KMOD_Main.KetherLeaves);
         world.setBlockMetadataWithNotify(x + 8, y + 8, z + 23, 12, 12);
         setBlock(world, x + 10, y + 8, z + 23, KMOD_Main.KetherLeaves);
         world.setBlockMetadataWithNotify(x + 10, y + 8, z + 23, 12, 12);
         setBlock(world, x + 12, y + 8, z + 23, KMOD_Main.KetherLeaves);
         world.setBlockMetadataWithNotify(x + 12, y + 8, z + 23, 12, 12);
         setBlock(world, x + 16, y + 8, z + 23, KMOD_Main.KetherLeaves);
         world.setBlockMetadataWithNotify(x + 16, y + 8, z + 23, 12, 12);
         setBlock(world, x + 18, y + 8, z + 23, KMOD_Main.KetherLeaves);
         world.setBlockMetadataWithNotify(x + 18, y + 8, z + 23, 12, 12);
         setBlock(world, x + 19, y + 8, z + 23, KMOD_Main.KetherLeaves);
         world.setBlockMetadataWithNotify(x + 19, y + 8, z + 23, 12, 12);
         setBlock(world, x + 22, y + 8, z + 23, KMOD_Main.KetherLeaves);
         world.setBlockMetadataWithNotify(x + 22, y + 8, z + 23, 12, 12);
         setBlock(world, x + 23, y + 8, z + 23, KMOD_Main.KetherLeaves);
         world.setBlockMetadataWithNotify(x + 23, y + 8, z + 23, 12, 12);
         setBlock(world, x + 26, y + 8, z + 23, KMOD_Main.KetherLeaves);
         world.setBlockMetadataWithNotify(x + 26, y + 8, z + 23, 12, 12);
         setBlock(world, x + 9, y + 8, z + 24, KMOD_Main.KetherLeaves);
         world.setBlockMetadataWithNotify(x + 9, y + 8, z + 24, 12, 12);
         setBlock(world, x + 14, y + 8, z + 24, KMOD_Main.KetherLeaves);
         world.setBlockMetadataWithNotify(x + 14, y + 8, z + 24, 12, 12);
         setBlock(world, x + 15, y + 8, z + 24, KMOD_Main.KetherLeaves);
         world.setBlockMetadataWithNotify(x + 15, y + 8, z + 24, 12, 12);
         setBlock(world, x + 18, y + 8, z + 24, KMOD_Main.KetherLeaves);
         world.setBlockMetadataWithNotify(x + 18, y + 8, z + 24, 12, 12);
         setBlock(world, x + 23, y + 8, z + 24, KMOD_Main.KetherLeaves);
         world.setBlockMetadataWithNotify(x + 23, y + 8, z + 24, 12, 12);
         setBlock(world, x + 26, y + 8, z + 24, KMOD_Main.KetherLeaves);
         world.setBlockMetadataWithNotify(x + 26, y + 8, z + 24, 12, 12);
         setBlock(world, x + 14, y + 8, z + 25, KMOD_Main.KetherLeaves);
         world.setBlockMetadataWithNotify(x + 14, y + 8, z + 25, 12, 12);
         setBlock(world, x + 15, y + 8, z + 25, KMOD_Main.KetherLeaves);
         world.setBlockMetadataWithNotify(x + 15, y + 8, z + 25, 12, 12);
         setBlock(world, x + 18, y + 8, z + 25, KMOD_Main.KetherLeaves);
         world.setBlockMetadataWithNotify(x + 18, y + 8, z + 25, 12, 12);
         setBlock(world, x + 19, y + 8, z + 25, KMOD_Main.KetherLeaves);
         world.setBlockMetadataWithNotify(x + 19, y + 8, z + 25, 12, 12);
         setBlock(world, x + 22, y + 8, z + 25, KMOD_Main.KetherLeaves);
         world.setBlockMetadataWithNotify(x + 22, y + 8, z + 25, 12, 12);
         setBlock(world, x + 23, y + 8, z + 25, KMOD_Main.KetherLeaves);
         world.setBlockMetadataWithNotify(x + 23, y + 8, z + 25, 12, 12);
         setBlock(world, x + 15, y + 8, z + 26, KMOD_Main.KetherLeaves);
         world.setBlockMetadataWithNotify(x + 15, y + 8, z + 26, 12, 12);
         setBlock(world, x + 16, y + 8, z + 26, KMOD_Main.KetherLeaves);
         world.setBlockMetadataWithNotify(x + 16, y + 8, z + 26, 12, 12);
         setBlock(world, x + 17, y + 8, z + 26, KMOD_Main.KetherLeaves);
         world.setBlockMetadataWithNotify(x + 17, y + 8, z + 26, 12, 12);
         setBlock(world, x + 15, y + 8, z + 27, KMOD_Main.KetherLeaves);
         world.setBlockMetadataWithNotify(x + 15, y + 8, z + 27, 12, 12);
         setBlock(world, x + 19, y + 9, z + 0, KMOD_Main.KetherLeaves);
         world.setBlockMetadataWithNotify(x + 19, y + 9, z + 0, 12, 12);
         setBlock(world, x + 18, y + 9, z + 1, KMOD_Main.KetherLeaves);
         world.setBlockMetadataWithNotify(x + 18, y + 9, z + 1, 12, 12);
         setBlock(world, x + 12, y + 9, z + 2, KMOD_Main.KetherLeaves);
         world.setBlockMetadataWithNotify(x + 12, y + 9, z + 2, 12, 12);
         setBlock(world, x + 16, y + 9, z + 2, KMOD_Main.KetherLeaves);
         world.setBlockMetadataWithNotify(x + 16, y + 9, z + 2, 12, 12);
         setBlock(world, x + 17, y + 9, z + 2, KMOD_Main.KetherLeaves);
         world.setBlockMetadataWithNotify(x + 17, y + 9, z + 2, 12, 12);
         setBlock(world, x + 22, y + 9, z + 2, KMOD_Main.KetherLeaves);
         world.setBlockMetadataWithNotify(x + 22, y + 9, z + 2, 12, 12);
         setBlock(world, x + 23, y + 9, z + 2, KMOD_Main.KetherLeaves);
         world.setBlockMetadataWithNotify(x + 23, y + 9, z + 2, 12, 12);
         setBlock(world, x + 24, y + 9, z + 2, KMOD_Main.KetherLeaves);
         world.setBlockMetadataWithNotify(x + 24, y + 9, z + 2, 12, 12);
         setBlock(world, x + 12, y + 9, z + 3, KMOD_Main.KetherLeaves);
         world.setBlockMetadataWithNotify(x + 12, y + 9, z + 3, 12, 12);
         setBlock(world, x + 16, y + 9, z + 3, KMOD_Main.KetherLeaves);
         world.setBlockMetadataWithNotify(x + 16, y + 9, z + 3, 12, 12);
         setBlock(world, x + 18, y + 9, z + 3, KMOD_Main.KetherLeaves);
         world.setBlockMetadataWithNotify(x + 18, y + 9, z + 3, 12, 12);
         setBlock(world, x + 28, y + 9, z + 3, KMOD_Main.KetherLeaves);
         world.setBlockMetadataWithNotify(x + 28, y + 9, z + 3, 12, 12);
         setBlock(world, x + 10, y + 9, z + 4, KMOD_Main.KetherLeaves);
         world.setBlockMetadataWithNotify(x + 10, y + 9, z + 4, 12, 12);
         setBlock(world, x + 11, y + 9, z + 4, KMOD_Main.KetherLeaves);
         world.setBlockMetadataWithNotify(x + 11, y + 9, z + 4, 12, 12);
         setBlock(world, x + 13, y + 9, z + 4, KMOD_Main.KetherLeaves);
         world.setBlockMetadataWithNotify(x + 13, y + 9, z + 4, 12, 12);
         setBlock(world, x + 16, y + 9, z + 4, KMOD_Main.KetherLeaves);
         world.setBlockMetadataWithNotify(x + 16, y + 9, z + 4, 12, 12);
         setBlock(world, x + 17, y + 9, z + 4, KMOD_Main.KetherLeaves);
         world.setBlockMetadataWithNotify(x + 17, y + 9, z + 4, 12, 12);
         setBlock(world, x + 18, y + 9, z + 4, KMOD_Main.KetherLeaves);
         world.setBlockMetadataWithNotify(x + 18, y + 9, z + 4, 12, 12);
         setBlock(world, x + 23, y + 9, z + 4, KMOD_Main.KetherLeaves);
         world.setBlockMetadataWithNotify(x + 23, y + 9, z + 4, 12, 12);
         setBlock(world, x + 24, y + 9, z + 4, KMOD_Main.KetherLeaves);
         world.setBlockMetadataWithNotify(x + 24, y + 9, z + 4, 12, 12);
         setBlock(world, x + 25, y + 9, z + 4, KMOD_Main.KetherLeaves);
         world.setBlockMetadataWithNotify(x + 25, y + 9, z + 4, 12, 12);
         setBlock(world, x + 26, y + 9, z + 4, KMOD_Main.KetherLeaves);
         world.setBlockMetadataWithNotify(x + 26, y + 9, z + 4, 12, 12);
         setBlock(world, x + 28, y + 9, z + 4, KMOD_Main.KetherLeaves);
         world.setBlockMetadataWithNotify(x + 28, y + 9, z + 4, 12, 12);
         setBlock(world, x + 29, y + 9, z + 4, KMOD_Main.KetherLeaves);
         world.setBlockMetadataWithNotify(x + 29, y + 9, z + 4, 12, 12);
         setBlock(world, x + 10, y + 9, z + 5, KMOD_Main.KetherLeaves);
         world.setBlockMetadataWithNotify(x + 10, y + 9, z + 5, 12, 12);
         setBlock(world, x + 11, y + 9, z + 5, KMOD_Main.KetherLeaves);
         world.setBlockMetadataWithNotify(x + 11, y + 9, z + 5, 12, 12);
         setBlock(world, x + 12, y + 9, z + 5, KMOD_Main.KetherLeaves);
         world.setBlockMetadataWithNotify(x + 12, y + 9, z + 5, 12, 12);
         setBlock(world, x + 16, y + 9, z + 5, KMOD_Main.KetherLeaves);
         world.setBlockMetadataWithNotify(x + 16, y + 9, z + 5, 12, 12);
         setBlock(world, x + 19, y + 9, z + 5, KMOD_Main.KetherLeaves);
         world.setBlockMetadataWithNotify(x + 19, y + 9, z + 5, 12, 12);
         setBlock(world, x + 21, y + 9, z + 5, KMOD_Main.KetherLeaves);
         world.setBlockMetadataWithNotify(x + 21, y + 9, z + 5, 12, 12);
         setBlock(world, x + 28, y + 9, z + 5, KMOD_Main.KetherLeaves);
         world.setBlockMetadataWithNotify(x + 28, y + 9, z + 5, 12, 12);
         setBlock(world, x + 30, y + 9, z + 5, KMOD_Main.KetherLeaves);
         world.setBlockMetadataWithNotify(x + 30, y + 9, z + 5, 12, 12);
         setBlock(world, x + 8, y + 9, z + 6, KMOD_Main.KetherLeaves);
         world.setBlockMetadataWithNotify(x + 8, y + 9, z + 6, 12, 12);
         setBlock(world, x + 15, y + 9, z + 6, KMOD_Main.KetherLeaves);
         world.setBlockMetadataWithNotify(x + 15, y + 9, z + 6, 12, 12);
         setBlock(world, x + 20, y + 9, z + 6, KMOD_Main.KetherLeaves);
         world.setBlockMetadataWithNotify(x + 20, y + 9, z + 6, 12, 12);
         setBlock(world, x + 24, y + 9, z + 6, KMOD_Main.KetherLeaves);
         world.setBlockMetadataWithNotify(x + 24, y + 9, z + 6, 12, 12);
         setBlock(world, x + 27, y + 9, z + 6, KMOD_Main.KetherLeaves);
         world.setBlockMetadataWithNotify(x + 27, y + 9, z + 6, 12, 12);
         setBlock(world, x + 30, y + 9, z + 6, KMOD_Main.KetherLeaves);
         world.setBlockMetadataWithNotify(x + 30, y + 9, z + 6, 12, 12);
         setBlock(world, x + 6, y + 9, z + 7, KMOD_Main.KetherLeaves);
         world.setBlockMetadataWithNotify(x + 6, y + 9, z + 7, 12, 12);
         setBlock(world, x + 9, y + 9, z + 7, KMOD_Main.KetherLeaves);
         world.setBlockMetadataWithNotify(x + 9, y + 9, z + 7, 12, 12);
         setBlock(world, x + 11, y + 9, z + 7, KMOD_Main.KetherLeaves);
         world.setBlockMetadataWithNotify(x + 11, y + 9, z + 7, 12, 12);
         setBlock(world, x + 14, y + 9, z + 7, KMOD_Main.KetherLeaves);
         world.setBlockMetadataWithNotify(x + 14, y + 9, z + 7, 12, 12);
         setBlock(world, x + 21, y + 9, z + 7, KMOD_Main.KetherLeaves);
         world.setBlockMetadataWithNotify(x + 21, y + 9, z + 7, 12, 12);
         setBlock(world, x + 24, y + 9, z + 7, KMOD_Main.KetherLeaves);
         world.setBlockMetadataWithNotify(x + 24, y + 9, z + 7, 12, 12);
         setBlock(world, x + 25, y + 9, z + 7, KMOD_Main.KetherLeaves);
         world.setBlockMetadataWithNotify(x + 25, y + 9, z + 7, 12, 12);
         setBlock(world, x + 5, y + 9, z + 8, KMOD_Main.KetherLeaves);
         world.setBlockMetadataWithNotify(x + 5, y + 9, z + 8, 12, 12);
         setBlock(world, x + 6, y + 9, z + 8, KMOD_Main.KetherLeaves);
         world.setBlockMetadataWithNotify(x + 6, y + 9, z + 8, 12, 12);
         setBlock(world, x + 7, y + 9, z + 8, KMOD_Main.KetherLeaves);
         world.setBlockMetadataWithNotify(x + 7, y + 9, z + 8, 12, 12);
         setBlock(world, x + 8, y + 9, z + 8, KMOD_Main.KetherLeaves);
         world.setBlockMetadataWithNotify(x + 8, y + 9, z + 8, 12, 12);
         setBlock(world, x + 22, y + 9, z + 8, KMOD_Main.KetherLeaves);
         world.setBlockMetadataWithNotify(x + 22, y + 9, z + 8, 12, 12);
         setBlock(world, x + 23, y + 9, z + 8, KMOD_Main.KetherLeaves);
         world.setBlockMetadataWithNotify(x + 23, y + 9, z + 8, 12, 12);
         setBlock(world, x + 24, y + 9, z + 8, KMOD_Main.KetherLeaves);
         world.setBlockMetadataWithNotify(x + 24, y + 9, z + 8, 12, 12);
         setBlock(world, x + 5, y + 9, z + 9, KMOD_Main.KetherLeaves);
         world.setBlockMetadataWithNotify(x + 5, y + 9, z + 9, 12, 12);
         setBlock(world, x + 8, y + 9, z + 9, KMOD_Main.KetherLeaves);
         world.setBlockMetadataWithNotify(x + 8, y + 9, z + 9, 12, 12);
         setBlock(world, x + 10, y + 9, z + 9, KMOD_Main.KetherLeaves);
         world.setBlockMetadataWithNotify(x + 10, y + 9, z + 9, 12, 12);
         setBlock(world, x + 25, y + 9, z + 9, KMOD_Main.KetherLeaves);
         world.setBlockMetadataWithNotify(x + 25, y + 9, z + 9, 12, 12);
         setBlock(world, x + 28, y + 9, z + 9, KMOD_Main.KetherLeaves);
         world.setBlockMetadataWithNotify(x + 28, y + 9, z + 9, 12, 12);
         setBlock(world, x + 4, y + 9, z + 10, KMOD_Main.KetherLeaves);
         world.setBlockMetadataWithNotify(x + 4, y + 9, z + 10, 12, 12);
         setBlock(world, x + 5, y + 9, z + 10, KMOD_Main.KetherLeaves);
         world.setBlockMetadataWithNotify(x + 5, y + 9, z + 10, 12, 12);
         setBlock(world, x + 7, y + 9, z + 10, KMOD_Main.KetherLeaves);
         world.setBlockMetadataWithNotify(x + 7, y + 9, z + 10, 12, 12);
         setBlock(world, x + 8, y + 9, z + 10, KMOD_Main.KetherLeaves);
         world.setBlockMetadataWithNotify(x + 8, y + 9, z + 10, 12, 12);
         setBlock(world, x + 9, y + 9, z + 10, KMOD_Main.KetherLeaves);
         world.setBlockMetadataWithNotify(x + 9, y + 9, z + 10, 12, 12);
         setBlock(world, x + 23, y + 9, z + 10, KMOD_Main.KetherLeaves);
         world.setBlockMetadataWithNotify(x + 23, y + 9, z + 10, 12, 12);
         setBlock(world, x + 25, y + 9, z + 10, KMOD_Main.KetherLeaves);
         world.setBlockMetadataWithNotify(x + 25, y + 9, z + 10, 12, 12);
         setBlock(world, x + 27, y + 9, z + 10, KMOD_Main.KetherLeaves);
         world.setBlockMetadataWithNotify(x + 27, y + 9, z + 10, 12, 12);
         setBlock(world, x + 29, y + 9, z + 10, KMOD_Main.KetherLeaves);
         world.setBlockMetadataWithNotify(x + 29, y + 9, z + 10, 12, 12);
         setBlock(world, x + 5, y + 9, z + 11, KMOD_Main.KetherLeaves);
         world.setBlockMetadataWithNotify(x + 5, y + 9, z + 11, 12, 12);
         setBlock(world, x + 8, y + 9, z + 11, KMOD_Main.KetherLeaves);
         world.setBlockMetadataWithNotify(x + 8, y + 9, z + 11, 12, 12);
         setBlock(world, x + 9, y + 9, z + 11, KMOD_Main.KetherLeaves);
         world.setBlockMetadataWithNotify(x + 9, y + 9, z + 11, 12, 12);
         setBlock(world, x + 16, y + 9, z + 11, KMOD_Main.KetherLog);
         world.setBlockMetadataWithNotify(x + 16, y + 9, z + 11, 12, 12);
         setBlock(world, x + 27, y + 9, z + 11, KMOD_Main.KetherLeaves);
         world.setBlockMetadataWithNotify(x + 27, y + 9, z + 11, 12, 12);
         setBlock(world, x + 29, y + 9, z + 11, KMOD_Main.KetherLeaves);
         world.setBlockMetadataWithNotify(x + 29, y + 9, z + 11, 12, 12);
         setBlock(world, x + 30, y + 9, z + 11, KMOD_Main.KetherLeaves);
         world.setBlockMetadataWithNotify(x + 30, y + 9, z + 11, 4, 4);
         setBlock(world, x + 31, y + 9, z + 11, KMOD_Main.KetherLeaves);
         world.setBlockMetadataWithNotify(x + 31, y + 9, z + 11, 4, 4);
         setBlock(world, x + 5, y + 9, z + 12, KMOD_Main.KetherLeaves);
         world.setBlockMetadataWithNotify(x + 5, y + 9, z + 12, 12, 12);
         setBlock(world, x + 8, y + 9, z + 12, KMOD_Main.KetherLeaves);
         world.setBlockMetadataWithNotify(x + 8, y + 9, z + 12, 12, 12);
         setBlock(world, x + 9, y + 9, z + 12, KMOD_Main.KetherLeaves);
         world.setBlockMetadataWithNotify(x + 9, y + 9, z + 12, 12, 12);
         setBlock(world, x + 10, y + 9, z + 12, KMOD_Main.KetherLeaves);
         world.setBlockMetadataWithNotify(x + 10, y + 9, z + 12, 12, 12);
         setBlock(world, x + 21, y + 9, z + 12, KMOD_Main.KetherLog);
         world.setBlockMetadataWithNotify(x + 21, y + 9, z + 12, 12, 12);
         setBlock(world, x + 24, y + 9, z + 12, KMOD_Main.KetherLeaves);
         world.setBlockMetadataWithNotify(x + 24, y + 9, z + 12, 12, 12);
         setBlock(world, x + 31, y + 9, z + 12, KMOD_Main.KetherLeaves);
         world.setBlockMetadataWithNotify(x + 31, y + 9, z + 12, 4, 4);
         setBlock(world, x + 32, y + 9, z + 12, KMOD_Main.KetherLeaves);
         world.setBlockMetadataWithNotify(x + 32, y + 9, z + 12, 4, 4);
         setBlock(world, x + 3, y + 9, z + 13, KMOD_Main.KetherLeaves);
         world.setBlockMetadataWithNotify(x + 3, y + 9, z + 13, 12, 12);
         setBlock(world, x + 5, y + 9, z + 13, KMOD_Main.KetherLeaves);
         world.setBlockMetadataWithNotify(x + 5, y + 9, z + 13, 12, 12);
         setBlock(world, x + 6, y + 9, z + 13, KMOD_Main.KetherLeaves);
         world.setBlockMetadataWithNotify(x + 6, y + 9, z + 13, 12, 12);
         setBlock(world, x + 9, y + 9, z + 13, KMOD_Main.KetherLeaves);
         world.setBlockMetadataWithNotify(x + 9, y + 9, z + 13, 12, 12);
         setBlock(world, x + 10, y + 9, z + 13, KMOD_Main.KetherLeaves);
         world.setBlockMetadataWithNotify(x + 10, y + 9, z + 13, 12, 12);
         setBlock(world, x + 23, y + 9, z + 13, KMOD_Main.KetherLeaves);
         world.setBlockMetadataWithNotify(x + 23, y + 9, z + 13, 12, 12);
         setBlock(world, x + 28, y + 9, z + 13, KMOD_Main.KetherLeaves);
         world.setBlockMetadataWithNotify(x + 28, y + 9, z + 13, 12, 12);
         setBlock(world, x + 4, y + 9, z + 14, KMOD_Main.KetherLeaves);
         world.setBlockMetadataWithNotify(x + 4, y + 9, z + 14, 12, 12);
         setBlock(world, x + 6, y + 9, z + 14, KMOD_Main.KetherLeaves);
         world.setBlockMetadataWithNotify(x + 6, y + 9, z + 14, 12, 12);
         setBlock(world, x + 9, y + 9, z + 14, KMOD_Main.KetherLeaves);
         world.setBlockMetadataWithNotify(x + 9, y + 9, z + 14, 12, 12);
         setBlock(world, x + 25, y + 9, z + 14, KMOD_Main.KetherLeaves);
         world.setBlockMetadataWithNotify(x + 25, y + 9, z + 14, 12, 12);
         setBlock(world, x + 28, y + 9, z + 14, KMOD_Main.KetherLeaves);
         world.setBlockMetadataWithNotify(x + 28, y + 9, z + 14, 12, 12);
         setBlock(world, x + 12, y + 9, z + 15, KMOD_Main.KetherLeaves);
         world.setBlockMetadataWithNotify(x + 12, y + 9, z + 15, 12, 12);
         setBlock(world, x + 15, y + 9, z + 15, KMOD_Main.KetherLog);
         world.setBlockMetadataWithNotify(x + 15, y + 9, z + 15, 4, 4);
         setBlock(world, x + 16, y + 9, z + 15, KMOD_Main.KetherLog);
         world.setBlockMetadataWithNotify(x + 16, y + 9, z + 15, 12, 12);
         setBlock(world, x + 24, y + 9, z + 15, KMOD_Main.KetherLeaves);
         world.setBlockMetadataWithNotify(x + 24, y + 9, z + 15, 12, 12);
         setBlock(world, x + 26, y + 9, z + 15, KMOD_Main.KetherLeaves);
         world.setBlockMetadataWithNotify(x + 26, y + 9, z + 15, 12, 12);
         setBlock(world, x + 28, y + 9, z + 15, KMOD_Main.KetherLeaves);
         world.setBlockMetadataWithNotify(x + 28, y + 9, z + 15, 12, 12);
         setBlock(world, x + 29, y + 9, z + 15, KMOD_Main.KetherLeaves);
         world.setBlockMetadataWithNotify(x + 29, y + 9, z + 15, 12, 12);
         setBlock(world, x + 4, y + 9, z + 16, KMOD_Main.KetherLeaves);
         world.setBlockMetadataWithNotify(x + 4, y + 9, z + 16, 12, 12);
         setBlock(world, x + 5, y + 9, z + 16, KMOD_Main.KetherLeaves);
         world.setBlockMetadataWithNotify(x + 5, y + 9, z + 16, 12, 12);
         setBlock(world, x + 7, y + 9, z + 16, KMOD_Main.KetherLeaves);
         world.setBlockMetadataWithNotify(x + 7, y + 9, z + 16, 12, 12);
         setBlock(world, x + 9, y + 9, z + 16, KMOD_Main.KetherLeaves);
         world.setBlockMetadataWithNotify(x + 9, y + 9, z + 16, 12, 12);
         setBlock(world, x + 10, y + 9, z + 16, KMOD_Main.KetherLeaves);
         world.setBlockMetadataWithNotify(x + 10, y + 9, z + 16, 12, 12);
         setBlock(world, x + 12, y + 9, z + 16, KMOD_Main.KetherLeaves);
         world.setBlockMetadataWithNotify(x + 12, y + 9, z + 16, 12, 12);
         setBlock(world, x + 25, y + 9, z + 16, KMOD_Main.KetherLeaves);
         world.setBlockMetadataWithNotify(x + 25, y + 9, z + 16, 12, 12);
         setBlock(world, x + 27, y + 9, z + 16, KMOD_Main.KetherLeaves);
         world.setBlockMetadataWithNotify(x + 27, y + 9, z + 16, 12, 12);
         setBlock(world, x + 28, y + 9, z + 16, KMOD_Main.KetherLeaves);
         world.setBlockMetadataWithNotify(x + 28, y + 9, z + 16, 12, 12);
         setBlock(world, x + 29, y + 9, z + 16, KMOD_Main.KetherLeaves);
         world.setBlockMetadataWithNotify(x + 29, y + 9, z + 16, 12, 12);
         setBlock(world, x + 30, y + 9, z + 16, KMOD_Main.KetherLeaves);
         world.setBlockMetadataWithNotify(x + 30, y + 9, z + 16, 12, 12);
         setBlock(world, x + 31, y + 9, z + 16, KMOD_Main.KetherLeaves);
         world.setBlockMetadataWithNotify(x + 31, y + 9, z + 16, 4, 4);
         setBlock(world, x + 6, y + 9, z + 17, KMOD_Main.KetherLeaves);
         world.setBlockMetadataWithNotify(x + 6, y + 9, z + 17, 12, 12);
         setBlock(world, x + 9, y + 9, z + 17, KMOD_Main.KetherLeaves);
         world.setBlockMetadataWithNotify(x + 9, y + 9, z + 17, 12, 12);
         setBlock(world, x + 10, y + 9, z + 17, KMOD_Main.KetherLeaves);
         world.setBlockMetadataWithNotify(x + 10, y + 9, z + 17, 12, 12);
         setBlock(world, x + 11, y + 9, z + 17, KMOD_Main.KetherLeaves);
         world.setBlockMetadataWithNotify(x + 11, y + 9, z + 17, 12, 12);
         setBlock(world, x + 12, y + 9, z + 17, KMOD_Main.KetherLeaves);
         world.setBlockMetadataWithNotify(x + 12, y + 9, z + 17, 12, 12);
         setBlock(world, x + 25, y + 9, z + 17, KMOD_Main.KetherLeaves);
         world.setBlockMetadataWithNotify(x + 25, y + 9, z + 17, 12, 12);
         setBlock(world, x + 29, y + 9, z + 17, KMOD_Main.KetherLeaves);
         world.setBlockMetadataWithNotify(x + 29, y + 9, z + 17, 12, 12);
         setBlock(world, x + 30, y + 9, z + 17, KMOD_Main.KetherLeaves);
         world.setBlockMetadataWithNotify(x + 30, y + 9, z + 17, 12, 12);
         setBlock(world, x + 6, y + 9, z + 18, KMOD_Main.KetherLeaves);
         world.setBlockMetadataWithNotify(x + 6, y + 9, z + 18, 12, 12);
         setBlock(world, x + 7, y + 9, z + 18, KMOD_Main.KetherLeaves);
         world.setBlockMetadataWithNotify(x + 7, y + 9, z + 18, 12, 12);
         setBlock(world, x + 10, y + 9, z + 18, KMOD_Main.KetherLeaves);
         world.setBlockMetadataWithNotify(x + 10, y + 9, z + 18, 12, 12);
         setBlock(world, x + 11, y + 9, z + 18, KMOD_Main.KetherLeaves);
         world.setBlockMetadataWithNotify(x + 11, y + 9, z + 18, 12, 12);
         setBlock(world, x + 13, y + 9, z + 18, KMOD_Main.KetherLeaves);
         world.setBlockMetadataWithNotify(x + 13, y + 9, z + 18, 12, 12);
         setBlock(world, x + 14, y + 9, z + 18, KMOD_Main.KetherLeaves);
         world.setBlockMetadataWithNotify(x + 14, y + 9, z + 18, 12, 12);
         setBlock(world, x + 18, y + 9, z + 18, KMOD_Main.KetherLeaves);
         world.setBlockMetadataWithNotify(x + 18, y + 9, z + 18, 12, 12);
         setBlock(world, x + 19, y + 9, z + 18, KMOD_Main.KetherLog);
         setBlock(world, x + 26, y + 9, z + 18, KMOD_Main.KetherLeaves);
         world.setBlockMetadataWithNotify(x + 26, y + 9, z + 18, 12, 12);
         setBlock(world, x + 27, y + 9, z + 18, KMOD_Main.KetherLeaves);
         world.setBlockMetadataWithNotify(x + 27, y + 9, z + 18, 12, 12);
         setBlock(world, x + 6, y + 9, z + 19, KMOD_Main.KetherLeaves);
         world.setBlockMetadataWithNotify(x + 6, y + 9, z + 19, 12, 12);
         setBlock(world, x + 7, y + 9, z + 19, KMOD_Main.KetherLeaves);
         world.setBlockMetadataWithNotify(x + 7, y + 9, z + 19, 12, 12);
         setBlock(world, x + 11, y + 9, z + 19, KMOD_Main.KetherLeaves);
         world.setBlockMetadataWithNotify(x + 11, y + 9, z + 19, 12, 12);
         setBlock(world, x + 13, y + 9, z + 19, KMOD_Main.KetherLeaves);
         world.setBlockMetadataWithNotify(x + 13, y + 9, z + 19, 12, 12);
         setBlock(world, x + 18, y + 9, z + 19, KMOD_Main.KetherLeaves);
         world.setBlockMetadataWithNotify(x + 18, y + 9, z + 19, 12, 12);
         setBlock(world, x + 19, y + 9, z + 19, KMOD_Main.KetherLeaves);
         world.setBlockMetadataWithNotify(x + 19, y + 9, z + 19, 12, 12);
         setBlock(world, x + 21, y + 9, z + 19, KMOD_Main.KetherLeaves);
         world.setBlockMetadataWithNotify(x + 21, y + 9, z + 19, 12, 12);
         setBlock(world, x + 22, y + 9, z + 19, KMOD_Main.KetherLeaves);
         world.setBlockMetadataWithNotify(x + 22, y + 9, z + 19, 12, 12);
         setBlock(world, x + 26, y + 9, z + 19, KMOD_Main.KetherLeaves);
         world.setBlockMetadataWithNotify(x + 26, y + 9, z + 19, 12, 12);
         setBlock(world, x + 27, y + 9, z + 19, KMOD_Main.KetherLeaves);
         world.setBlockMetadataWithNotify(x + 27, y + 9, z + 19, 12, 12);
         setBlock(world, x + 9, y + 9, z + 20, KMOD_Main.KetherLeaves);
         world.setBlockMetadataWithNotify(x + 9, y + 9, z + 20, 12, 12);
         setBlock(world, x + 14, y + 9, z + 20, KMOD_Main.KetherLeaves);
         world.setBlockMetadataWithNotify(x + 14, y + 9, z + 20, 12, 12);
         setBlock(world, x + 15, y + 9, z + 20, KMOD_Main.KetherLeaves);
         world.setBlockMetadataWithNotify(x + 15, y + 9, z + 20, 12, 12);
         setBlock(world, x + 18, y + 9, z + 20, KMOD_Main.KetherLeaves);
         world.setBlockMetadataWithNotify(x + 18, y + 9, z + 20, 12, 12);
         setBlock(world, x + 23, y + 9, z + 20, KMOD_Main.KetherLeaves);
         world.setBlockMetadataWithNotify(x + 23, y + 9, z + 20, 12, 12);
         setBlock(world, x + 27, y + 9, z + 20, KMOD_Main.KetherLeaves);
         world.setBlockMetadataWithNotify(x + 27, y + 9, z + 20, 12, 12);
         setBlock(world, x + 29, y + 9, z + 20, KMOD_Main.KetherLeaves);
         world.setBlockMetadataWithNotify(x + 29, y + 9, z + 20, 12, 12);
         setBlock(world, x + 6, y + 9, z + 21, KMOD_Main.KetherLeaves);
         world.setBlockMetadataWithNotify(x + 6, y + 9, z + 21, 12, 12);
         setBlock(world, x + 8, y + 9, z + 21, KMOD_Main.KetherLeaves);
         world.setBlockMetadataWithNotify(x + 8, y + 9, z + 21, 12, 12);
         setBlock(world, x + 12, y + 9, z + 21, KMOD_Main.KetherLeaves);
         world.setBlockMetadataWithNotify(x + 12, y + 9, z + 21, 12, 12);
         setBlock(world, x + 16, y + 9, z + 21, KMOD_Main.KetherLeaves);
         world.setBlockMetadataWithNotify(x + 16, y + 9, z + 21, 12, 12);
         setBlock(world, x + 24, y + 9, z + 21, KMOD_Main.KetherLeaves);
         world.setBlockMetadataWithNotify(x + 24, y + 9, z + 21, 12, 12);
         setBlock(world, x + 6, y + 9, z + 22, KMOD_Main.KetherLeaves);
         world.setBlockMetadataWithNotify(x + 6, y + 9, z + 22, 12, 12);
         setBlock(world, x + 7, y + 9, z + 22, KMOD_Main.KetherLeaves);
         world.setBlockMetadataWithNotify(x + 7, y + 9, z + 22, 12, 12);
         setBlock(world, x + 8, y + 9, z + 22, KMOD_Main.KetherLeaves);
         world.setBlockMetadataWithNotify(x + 8, y + 9, z + 22, 12, 12);
         setBlock(world, x + 21, y + 9, z + 22, KMOD_Main.KetherLeaves);
         world.setBlockMetadataWithNotify(x + 21, y + 9, z + 22, 12, 12);
         setBlock(world, x + 25, y + 9, z + 22, KMOD_Main.KetherLeaves);
         world.setBlockMetadataWithNotify(x + 25, y + 9, z + 22, 12, 12);
         setBlock(world, x + 29, y + 9, z + 22, KMOD_Main.KetherLeaves);
         world.setBlockMetadataWithNotify(x + 29, y + 9, z + 22, 12, 12);
         setBlock(world, x + 9, y + 9, z + 23, KMOD_Main.KetherLeaves);
         world.setBlockMetadataWithNotify(x + 9, y + 9, z + 23, 12, 12);
         setBlock(world, x + 10, y + 9, z + 23, KMOD_Main.KetherLeaves);
         world.setBlockMetadataWithNotify(x + 10, y + 9, z + 23, 12, 12);
         setBlock(world, x + 11, y + 9, z + 23, KMOD_Main.KetherLeaves);
         world.setBlockMetadataWithNotify(x + 11, y + 9, z + 23, 12, 12);
         setBlock(world, x + 17, y + 9, z + 23, KMOD_Main.KetherLeaves);
         world.setBlockMetadataWithNotify(x + 17, y + 9, z + 23, 12, 12);
         setBlock(world, x + 18, y + 9, z + 23, KMOD_Main.KetherLeaves);
         world.setBlockMetadataWithNotify(x + 18, y + 9, z + 23, 12, 12);
         setBlock(world, x + 20, y + 9, z + 23, KMOD_Main.KetherLeaves);
         world.setBlockMetadataWithNotify(x + 20, y + 9, z + 23, 12, 12);
         setBlock(world, x + 24, y + 9, z + 23, KMOD_Main.KetherLeaves);
         world.setBlockMetadataWithNotify(x + 24, y + 9, z + 23, 12, 12);
         setBlock(world, x + 26, y + 9, z + 23, KMOD_Main.KetherLeaves);
         world.setBlockMetadataWithNotify(x + 26, y + 9, z + 23, 12, 12);
         setBlock(world, x + 27, y + 9, z + 23, KMOD_Main.KetherLeaves);
         world.setBlockMetadataWithNotify(x + 27, y + 9, z + 23, 12, 12);
         setBlock(world, x + 9, y + 9, z + 24, KMOD_Main.KetherLeaves);
         world.setBlockMetadataWithNotify(x + 9, y + 9, z + 24, 12, 12);
         setBlock(world, x + 24, y + 9, z + 24, KMOD_Main.KetherLeaves);
         world.setBlockMetadataWithNotify(x + 24, y + 9, z + 24, 12, 12);
         setBlock(world, x + 26, y + 9, z + 24, KMOD_Main.KetherLeaves);
         world.setBlockMetadataWithNotify(x + 26, y + 9, z + 24, 12, 12);
         setBlock(world, x + 22, y + 9, z + 25, KMOD_Main.KetherLeaves);
         world.setBlockMetadataWithNotify(x + 22, y + 9, z + 25, 12, 12);
         setBlock(world, x + 13, y + 9, z + 26, KMOD_Main.KetherLeaves);
         world.setBlockMetadataWithNotify(x + 13, y + 9, z + 26, 12, 12);
         setBlock(world, x + 14, y + 9, z + 26, KMOD_Main.KetherLeaves);
         world.setBlockMetadataWithNotify(x + 14, y + 9, z + 26, 12, 12);
         setBlock(world, x + 15, y + 9, z + 26, KMOD_Main.KetherLeaves);
         world.setBlockMetadataWithNotify(x + 15, y + 9, z + 26, 12, 12);
         setBlock(world, x + 17, y + 9, z + 26, KMOD_Main.KetherLeaves);
         world.setBlockMetadataWithNotify(x + 17, y + 9, z + 26, 12, 12);
         setBlock(world, x + 18, y + 9, z + 26, KMOD_Main.KetherLeaves);
         world.setBlockMetadataWithNotify(x + 18, y + 9, z + 26, 12, 12);
         setBlock(world, x + 14, y + 9, z + 27, KMOD_Main.KetherLeaves);
         world.setBlockMetadataWithNotify(x + 14, y + 9, z + 27, 12, 12);
         setBlock(world, x + 16, y + 9, z + 27, KMOD_Main.KetherLeaves);
         world.setBlockMetadataWithNotify(x + 16, y + 9, z + 27, 12, 12);
         setBlock(world, x + 15, y + 10, z + 1, KMOD_Main.KetherLeaves);
         world.setBlockMetadataWithNotify(x + 15, y + 10, z + 1, 12, 12);
         setBlock(world, x + 16, y + 10, z + 1, KMOD_Main.KetherLeaves);
         world.setBlockMetadataWithNotify(x + 16, y + 10, z + 1, 12, 12);
         setBlock(world, x + 17, y + 10, z + 1, KMOD_Main.KetherLeaves);
         world.setBlockMetadataWithNotify(x + 17, y + 10, z + 1, 12, 12);
         setBlock(world, x + 21, y + 10, z + 1, KMOD_Main.KetherLeaves);
         world.setBlockMetadataWithNotify(x + 21, y + 10, z + 1, 12, 12);
         setBlock(world, x + 15, y + 10, z + 2, KMOD_Main.KetherLeaves);
         world.setBlockMetadataWithNotify(x + 15, y + 10, z + 2, 12, 12);
         setBlock(world, x + 17, y + 10, z + 2, KMOD_Main.KetherLeaves);
         world.setBlockMetadataWithNotify(x + 17, y + 10, z + 2, 12, 12);
         setBlock(world, x + 18, y + 10, z + 2, KMOD_Main.KetherLeaves);
         world.setBlockMetadataWithNotify(x + 18, y + 10, z + 2, 12, 12);
         setBlock(world, x + 19, y + 10, z + 2, KMOD_Main.KetherLeaves);
         world.setBlockMetadataWithNotify(x + 19, y + 10, z + 2, 12, 12);
         setBlock(world, x + 22, y + 10, z + 2, KMOD_Main.KetherLeaves);
         world.setBlockMetadataWithNotify(x + 22, y + 10, z + 2, 12, 12);
         setBlock(world, x + 9, y + 10, z + 3, KMOD_Main.KetherLeaves);
         world.setBlockMetadataWithNotify(x + 9, y + 10, z + 3, 12, 12);
         setBlock(world, x + 11, y + 10, z + 3, KMOD_Main.KetherLeaves);
         world.setBlockMetadataWithNotify(x + 11, y + 10, z + 3, 12, 12);
