package com.KMOD.WorldGens.NewTestTrees;

import com.KMOD.Main.KMOD_Main;
import cpw.mods.fml.common.IWorldGenerator;
import java.util.Random;
import net.minecraft.block.Block;
import net.minecraft.world.World;
import net.minecraft.world.chunk.IChunkProvider;
import net.minecraft.world.gen.feature.WorldGenerator;

public class KetherGenTree1 extends WorldGenerator implements IWorldGenerator {
   public void generate(Random random, int chunkX, int chunkZ, World world, IChunkProvider chunkGenerator, IChunkProvider chunkProvider) {
   }

   public void setBlock(World world, int x, int y, int z, Block block) {
      Block b1 = world.getBlock(x, y, z);
      if (b1.isAir(world, x, y, z) || b1.isLeaves(world, x, y, z)) {
         world.setBlock(x, y, z, block);
      }

   }

   public boolean generate(World world, Random random, int x, int y, int z) {
      this.spawn(world, x, y, z);
      return true;
   }

   public void spawn(World world, int x, int y, int z) {
      if ((world.getBlock(x, y, z) == KMOD_Main.KetherGrass || world.getBlock(x, y - 1, z) == KMOD_Main.KetherGrass) && (world.getBlock(x + 13, y, z + 11) == KMOD_Main.KetherGrass || world.getBlock(x + 13, y - 1, z + 11) == KMOD_Main.KetherGrass || world.getBlock(x + 13, y, z + 11) == KMOD_Main.KetherDirt || world.getBlock(x + 13, y - 1, z + 11) == KMOD_Main.KetherDirt)) {
         this.setBlock(world, x + 13, y + 0, z + 11, KMOD_Main.KetherLog);
         world.setBlockMetadataWithNotify(x + 13, y + 0, z + 11, 15, 15);
         this.setBlock(world, x + 14, y + 0, z + 11, KMOD_Main.KetherLog);
         world.setBlockMetadataWithNotify(x + 14, y + 0, z + 11, 15, 15);
         this.setBlock(world, x + 15, y + 0, z + 11, KMOD_Main.KetherLog);
         world.setBlockMetadataWithNotify(x + 15, y + 0, z + 11, 15, 15);
         this.setBlock(world, x + 16, y + 0, z + 11, KMOD_Main.KetherLog);
         world.setBlockMetadataWithNotify(x + 16, y + 0, z + 11, 15, 15);
         this.setBlock(world, x + 13, y + 0, z + 12, KMOD_Main.KetherLog);
         world.setBlockMetadataWithNotify(x + 13, y + 0, z + 12, 15, 15);
         this.setBlock(world, x + 14, y + 0, z + 12, KMOD_Main.KetherLog);
         world.setBlockMetadataWithNotify(x + 14, y + 0, z + 12, 15, 15);
         this.setBlock(world, x + 15, y + 0, z + 12, KMOD_Main.KetherLog);
         world.setBlockMetadataWithNotify(x + 15, y + 0, z + 12, 15, 15);
         this.setBlock(world, x + 16, y + 0, z + 12, KMOD_Main.KetherLog);
         world.setBlockMetadataWithNotify(x + 16, y + 0, z + 12, 15, 15);
         this.setBlock(world, x + 17, y + 0, z + 12, KMOD_Main.KetherLog);
         world.setBlockMetadataWithNotify(x + 17, y + 0, z + 12, 15, 15);
         this.setBlock(world, x + 15, y + 0, z + 13, KMOD_Main.KetherLog);
         world.setBlockMetadataWithNotify(x + 15, y + 0, z + 13, 15, 15);
         this.setBlock(world, x + 16, y + 0, z + 13, KMOD_Main.KetherLog);
         world.setBlockMetadataWithNotify(x + 16, y + 0, z + 13, 15, 15);
         this.setBlock(world, x + 14, y + 1, z + 11, KMOD_Main.KetherLog);
         world.setBlockMetadataWithNotify(x + 14, y + 1, z + 11, 15, 15);
         this.setBlock(world, x + 14, y + 1, z + 12, KMOD_Main.KetherLog);
         world.setBlockMetadataWithNotify(x + 14, y + 1, z + 12, 15, 15);
         this.setBlock(world, x + 15, y + 1, z + 12, KMOD_Main.KetherLog);
         world.setBlockMetadataWithNotify(x + 15, y + 1, z + 12, 15, 15);
         this.setBlock(world, x + 16, y + 1, z + 12, KMOD_Main.KetherLog);
         world.setBlockMetadataWithNotify(x + 16, y + 1, z + 12, 15, 15);
         this.setBlock(world, x + 14, y + 1, z + 13, KMOD_Main.KetherLog);
         world.setBlockMetadataWithNotify(x + 14, y + 1, z + 13, 3, 3);
         this.setBlock(world, x + 15, y + 1, z + 13, KMOD_Main.KetherLog);
         world.setBlockMetadataWithNotify(x + 15, y + 1, z + 13, 15, 15);
         this.setBlock(world, x + 13, y + 2, z + 12, KMOD_Main.KetherLog);
         world.setBlockMetadataWithNotify(x + 13, y + 2, z + 12, 15, 15);
         this.setBlock(world, x + 14, y + 2, z + 12, KMOD_Main.KetherLog);
         world.setBlockMetadataWithNotify(x + 14, y + 2, z + 12, 15, 15);
         this.setBlock(world, x + 15, y + 2, z + 12, KMOD_Main.KetherLog);
         world.setBlockMetadataWithNotify(x + 15, y + 2, z + 12, 15, 15);
         this.setBlock(world, x + 14, y + 2, z + 13, KMOD_Main.KetherLog);
         world.setBlockMetadataWithNotify(x + 14, y + 2, z + 13, 15, 15);
         this.setBlock(world, x + 13, y + 3, z + 12, KMOD_Main.KetherLog);
         world.setBlockMetadataWithNotify(x + 13, y + 3, z + 12, 15, 15);
         this.setBlock(world, x + 14, y + 3, z + 12, KMOD_Main.KetherLog);
         world.setBlockMetadataWithNotify(x + 14, y + 3, z + 12, 15, 15);
         this.setBlock(world, x + 13, y + 3, z + 13, KMOD_Main.KetherLog);
         world.setBlockMetadataWithNotify(x + 13, y + 3, z + 13, 15, 15);
         this.setBlock(world, x + 12, y + 4, z + 12, KMOD_Main.KetherLog);
         world.setBlockMetadataWithNotify(x + 12, y + 4, z + 12, 15, 15);
         this.setBlock(world, x + 13, y + 4, z + 12, KMOD_Main.KetherLog);
         world.setBlockMetadataWithNotify(x + 13, y + 4, z + 12, 15, 15);
         this.setBlock(world, x + 12, y + 4, z + 13, KMOD_Main.KetherLog);
         world.setBlockMetadataWithNotify(x + 12, y + 4, z + 13, 15, 15);
         this.setBlock(world, x + 11, y + 5, z + 12, KMOD_Main.KetherLog);
         world.setBlockMetadataWithNotify(x + 11, y + 5, z + 12, 15, 15);
         this.setBlock(world, x + 12, y + 5, z + 12, KMOD_Main.KetherLog);
         world.setBlockMetadataWithNotify(x + 12, y + 5, z + 12, 15, 15);
         this.setBlock(world, x + 11, y + 5, z + 13, KMOD_Main.KetherLog);
         world.setBlockMetadataWithNotify(x + 11, y + 5, z + 13, 15, 15);
         this.setBlock(world, x + 11, y + 6, z + 11, KMOD_Main.KetherLog);
         world.setBlockMetadataWithNotify(x + 11, y + 6, z + 11, 15, 15);
         this.setBlock(world, x + 10, y + 6, z + 12, KMOD_Main.KetherLog);
         world.setBlockMetadataWithNotify(x + 10, y + 6, z + 12, 15, 15);
         this.setBlock(world, x + 11, y + 6, z + 12, KMOD_Main.KetherLog);
         world.setBlockMetadataWithNotify(x + 11, y + 6, z + 12, 15, 15);
         this.setBlock(world, x + 12, y + 6, z + 12, KMOD_Main.KetherLog);
         world.setBlockMetadataWithNotify(x + 12, y + 6, z + 12, 15, 15);
         this.setBlock(world, x + 12, y + 6, z + 13, KMOD_Main.KetherLog);
         world.setBlockMetadataWithNotify(x + 12, y + 6, z + 13, 15, 15);
         this.setBlock(world, x + 9, y + 7, z + 11, KMOD_Main.KetherLog);
         world.setBlockMetadataWithNotify(x + 9, y + 7, z + 11, 15, 15);
         this.setBlock(world, x + 11, y + 7, z + 11, KMOD_Main.KetherLog);
         world.setBlockMetadataWithNotify(x + 11, y + 7, z + 11, 15, 15);
         this.setBlock(world, x + 12, y + 7, z + 14, KMOD_Main.KetherLog);
         world.setBlockMetadataWithNotify(x + 12, y + 7, z + 14, 15, 15);
         this.setBlock(world, x + 8, y + 7, z + 23, KMOD_Main.KetherLeaves);
         world.setBlockMetadataWithNotify(x + 8, y + 7, z + 23, 15, 15);
         this.setBlock(world, x + 9, y + 7, z + 23, KMOD_Main.KetherLeaves);
         world.setBlockMetadataWithNotify(x + 9, y + 7, z + 23, 15, 15);
         this.setBlock(world, x + 10, y + 7, z + 23, KMOD_Main.KetherLeaves);
         world.setBlockMetadataWithNotify(x + 10, y + 7, z + 23, 15, 15);
         this.setBlock(world, x + 10, y + 7, z + 24, KMOD_Main.KetherLeaves);
         world.setBlockMetadataWithNotify(x + 10, y + 7, z + 24, 15, 15);
         this.setBlock(world, x + 7, y + 8, z + 9, KMOD_Main.KetherLeaves);
         world.setBlockMetadataWithNotify(x + 7, y + 8, z + 9, 15, 15);
         this.setBlock(world, x + 7, y + 8, z + 10, KMOD_Main.KetherLog);
         world.setBlockMetadataWithNotify(x + 7, y + 8, z + 10, 15, 15);
         this.setBlock(world, x + 8, y + 8, z + 10, KMOD_Main.KetherLog);
         world.setBlockMetadataWithNotify(x + 8, y + 8, z + 10, 15, 15);
         this.setBlock(world, x + 11, y + 8, z + 10, KMOD_Main.KetherLog);
         world.setBlockMetadataWithNotify(x + 11, y + 8, z + 10, 15, 15);
         this.setBlock(world, x + 12, y + 8, z + 14, KMOD_Main.KetherLog);
         world.setBlockMetadataWithNotify(x + 12, y + 8, z + 14, 15, 15);
         this.setBlock(world, x + 13, y + 8, z + 14, KMOD_Main.KetherLog);
         world.setBlockMetadataWithNotify(x + 13, y + 8, z + 14, 15, 15);
         this.setBlock(world, x + 13, y + 8, z + 15, KMOD_Main.KetherLeaves);
         world.setBlockMetadataWithNotify(x + 13, y + 8, z + 15, 15, 15);
         this.setBlock(world, x + 14, y + 8, z + 15, KMOD_Main.KetherLog);
         world.setBlockMetadataWithNotify(x + 14, y + 8, z + 15, 15, 15);
         this.setBlock(world, x + 13, y + 8, z + 17, KMOD_Main.KetherLeaves);
         world.setBlockMetadataWithNotify(x + 13, y + 8, z + 17, 15, 15);
         this.setBlock(world, x + 5, y + 8, z + 19, KMOD_Main.KetherLeaves);
         world.setBlockMetadataWithNotify(x + 5, y + 8, z + 19, 15, 15);
         this.setBlock(world, x + 6, y + 8, z + 19, KMOD_Main.KetherLeaves);
         world.setBlockMetadataWithNotify(x + 6, y + 8, z + 19, 15, 15);
         this.setBlock(world, x + 4, y + 8, z + 20, KMOD_Main.KetherLeaves);
         world.setBlockMetadataWithNotify(x + 4, y + 8, z + 20, 15, 15);
         this.setBlock(world, x + 7, y + 8, z + 20, KMOD_Main.KetherLeaves);
         world.setBlockMetadataWithNotify(x + 7, y + 8, z + 20, 15, 15);
         this.setBlock(world, x + 8, y + 8, z + 20, KMOD_Main.KetherLeaves);
         world.setBlockMetadataWithNotify(x + 8, y + 8, z + 20, 15, 15);
         this.setBlock(world, x + 11, y + 8, z + 20, KMOD_Main.KetherLeaves);
         world.setBlockMetadataWithNotify(x + 11, y + 8, z + 20, 15, 15);
         this.setBlock(world, x + 5, y + 8, z + 21, KMOD_Main.KetherLeaves);
         world.setBlockMetadataWithNotify(x + 5, y + 8, z + 21, 15, 15);
         this.setBlock(world, x + 9, y + 8, z + 21, KMOD_Main.KetherLeaves);
         world.setBlockMetadataWithNotify(x + 9, y + 8, z + 21, 15, 15);
         this.setBlock(world, x + 10, y + 8, z + 21, KMOD_Main.KetherLeaves);
         world.setBlockMetadataWithNotify(x + 10, y + 8, z + 21, 15, 15);
         this.setBlock(world, x + 12, y + 8, z + 21, KMOD_Main.KetherLeaves);
         world.setBlockMetadataWithNotify(x + 12, y + 8, z + 21, 15, 15);
         this.setBlock(world, x + 7, y + 8, z + 22, KMOD_Main.KetherLeaves);
         world.setBlockMetadataWithNotify(x + 7, y + 8, z + 22, 15, 15);
         this.setBlock(world, x + 11, y + 8, z + 22, KMOD_Main.KetherLeaves);
         world.setBlockMetadataWithNotify(x + 11, y + 8, z + 22, 15, 15);
         this.setBlock(world, x + 12, y + 8, z + 22, KMOD_Main.KetherLeaves);
         world.setBlockMetadataWithNotify(x + 12, y + 8, z + 22, 15, 15);
         this.setBlock(world, x + 7, y + 8, z + 23, KMOD_Main.KetherLeaves);
         world.setBlockMetadataWithNotify(x + 7, y + 8, z + 23, 15, 15);
         this.setBlock(world, x + 8, y + 9, z + 0, KMOD_Main.KetherLeaves);
         world.setBlockMetadataWithNotify(x + 8, y + 9, z + 0, 15, 15);
         this.setBlock(world, x + 10, y + 9, z + 1, KMOD_Main.KetherLeaves);
         world.setBlockMetadataWithNotify(x + 10, y + 9, z + 1, 15, 15);
         this.setBlock(world, x + 4, y + 9, z + 2, KMOD_Main.KetherLeaves);
         world.setBlockMetadataWithNotify(x + 4, y + 9, z + 2, 15, 15);
         this.setBlock(world, x + 9, y + 9, z + 2, KMOD_Main.KetherLeaves);
         world.setBlockMetadataWithNotify(x + 9, y + 9, z + 2, 15, 15);
         this.setBlock(world, x + 4, y + 9, z + 3, KMOD_Main.KetherLeaves);
         world.setBlockMetadataWithNotify(x + 4, y + 9, z + 3, 15, 15);
         this.setBlock(world, x + 7, y + 9, z + 3, KMOD_Main.KetherLeaves);
         world.setBlockMetadataWithNotify(x + 7, y + 9, z + 3, 15, 15);
         this.setBlock(world, x + 8, y + 9, z + 3, KMOD_Main.KetherLeaves);
         world.setBlockMetadataWithNotify(x + 8, y + 9, z + 3, 15, 15);
         this.setBlock(world, x + 9, y + 9, z + 3, KMOD_Main.KetherLeaves);
         world.setBlockMetadataWithNotify(x + 9, y + 9, z + 3, 15, 15);
         this.setBlock(world, x + 10, y + 9, z + 3, KMOD_Main.KetherLeaves);
         world.setBlockMetadataWithNotify(x + 10, y + 9, z + 3, 15, 15);
         this.setBlock(world, x + 11, y + 9, z + 3, KMOD_Main.KetherLeaves);
         world.setBlockMetadataWithNotify(x + 11, y + 9, z + 3, 15, 15);
         this.setBlock(world, x + 1, y + 9, z + 4, KMOD_Main.KetherLeaves);
         world.setBlockMetadataWithNotify(x + 1, y + 9, z + 4, 15, 15);
         this.setBlock(world, x + 2, y + 9, z + 4, KMOD_Main.KetherLeaves);
         world.setBlockMetadataWithNotify(x + 2, y + 9, z + 4, 15, 15);
         this.setBlock(world, x + 5, y + 9, z + 4, KMOD_Main.KetherLeaves);
         world.setBlockMetadataWithNotify(x + 5, y + 9, z + 4, 15, 15);
         this.setBlock(world, x + 9, y + 9, z + 5, KMOD_Main.KetherLeaves);
         world.setBlockMetadataWithNotify(x + 9, y + 9, z + 5, 15, 15);
         this.setBlock(world, x + 15, y + 9, z + 5, KMOD_Main.KetherLeaves);
         world.setBlockMetadataWithNotify(x + 15, y + 9, z + 5, 15, 15);
         this.setBlock(world, x + 3, y + 9, z + 6, KMOD_Main.KetherLeaves);
         world.setBlockMetadataWithNotify(x + 3, y + 9, z + 6, 15, 15);
         this.setBlock(world, x + 14, y + 9, z + 6, KMOD_Main.KetherLeaves);
         world.setBlockMetadataWithNotify(x + 14, y + 9, z + 6, 15, 15);
         this.setBlock(world, x + 17, y + 9, z + 6, KMOD_Main.KetherLeaves);
         world.setBlockMetadataWithNotify(x + 17, y + 9, z + 6, 15, 15);
         this.setBlock(world, x + 3, y + 9, z + 7, KMOD_Main.KetherLeaves);
         world.setBlockMetadataWithNotify(x + 3, y + 9, z + 7, 15, 15);
         this.setBlock(world, x + 7, y + 9, z + 7, KMOD_Main.KetherLeaves);
         world.setBlockMetadataWithNotify(x + 7, y + 9, z + 7, 15, 15);
         this.setBlock(world, x + 15, y + 9, z + 7, KMOD_Main.KetherLeaves);
         world.setBlockMetadataWithNotify(x + 15, y + 9, z + 7, 15, 15);
         this.setBlock(world, x + 6, y + 9, z + 8, KMOD_Main.KetherLeaves);
         world.setBlockMetadataWithNotify(x + 6, y + 9, z + 8, 15, 15);
         this.setBlock(world, x + 7, y + 9, z + 8, KMOD_Main.KetherLeaves);
         world.setBlockMetadataWithNotify(x + 7, y + 9, z + 8, 15, 15);
         this.setBlock(world, x + 8, y + 9, z + 8, KMOD_Main.KetherLeaves);
         world.setBlockMetadataWithNotify(x + 8, y + 9, z + 8, 15, 15);
         this.setBlock(world, x + 16, y + 9, z + 8, KMOD_Main.KetherLeaves);
         world.setBlockMetadataWithNotify(x + 16, y + 9, z + 8, 15, 15);
         this.setBlock(world, x + 5, y + 9, z + 9, KMOD_Main.KetherLeaves);
         world.setBlockMetadataWithNotify(x + 5, y + 9, z + 9, 15, 15);
         this.setBlock(world, x + 6, y + 9, z + 9, KMOD_Main.KetherLeaves);
         world.setBlockMetadataWithNotify(x + 6, y + 9, z + 9, 15, 15);
         this.setBlock(world, x + 7, y + 9, z + 9, KMOD_Main.KetherLog);
         world.setBlockMetadataWithNotify(x + 7, y + 9, z + 9, 15, 15);
         this.setBlock(world, x + 6, y + 9, z + 10, KMOD_Main.KetherLog);
         world.setBlockMetadataWithNotify(x + 6, y + 9, z + 10, 15, 15);
         this.setBlock(world, x + 11, y + 9, z + 10, KMOD_Main.KetherLog);
         world.setBlockMetadataWithNotify(x + 11, y + 9, z + 10, 15, 15);
         this.setBlock(world, x + 15, y + 9, z + 11, KMOD_Main.KetherLeaves);
         world.setBlockMetadataWithNotify(x + 15, y + 9, z + 11, 15, 15);
         this.setBlock(world, x + 2, y + 9, z + 12, KMOD_Main.KetherLeaves);
         world.setBlockMetadataWithNotify(x + 2, y + 9, z + 12, 15, 15);
         this.setBlock(world, x + 4, y + 9, z + 12, KMOD_Main.KetherLeaves);
         world.setBlockMetadataWithNotify(x + 4, y + 9, z + 12, 15, 15);
         this.setBlock(world, x + 6, y + 9, z + 13, KMOD_Main.KetherLeaves);
         world.setBlockMetadataWithNotify(x + 6, y + 9, z + 13, 15, 15);
         this.setBlock(world, x + 4, y + 9, z + 14, KMOD_Main.KetherLeaves);
         world.setBlockMetadataWithNotify(x + 4, y + 9, z + 14, 15, 15);
         this.setBlock(world, x + 14, y + 9, z + 14, KMOD_Main.KetherLeaves);
         world.setBlockMetadataWithNotify(x + 14, y + 9, z + 14, 15, 15);
         this.setBlock(world, x + 15, y + 9, z + 14, KMOD_Main.KetherLeaves);
         world.setBlockMetadataWithNotify(x + 15, y + 9, z + 14, 15, 15);
         this.setBlock(world, x + 4, y + 9, z + 15, KMOD_Main.KetherLeaves);
         world.setBlockMetadataWithNotify(x + 4, y + 9, z + 15, 15, 15);
         this.setBlock(world, x + 11, y + 9, z + 15, KMOD_Main.KetherLog);
         world.setBlockMetadataWithNotify(x + 11, y + 9, z + 15, 15, 15);
         this.setBlock(world, x + 12, y + 9, z + 15, KMOD_Main.KetherLog);
         world.setBlockMetadataWithNotify(x + 12, y + 9, z + 15, 15, 15);
         this.setBlock(world, x + 14, y + 9, z + 15, KMOD_Main.KetherLog);
         world.setBlockMetadataWithNotify(x + 14, y + 9, z + 15, 15, 15);
         this.setBlock(world, x + 16, y + 9, z + 15, KMOD_Main.KetherLeaves);
         world.setBlockMetadataWithNotify(x + 16, y + 9, z + 15, 15, 15);
         this.setBlock(world, x + 5, y + 9, z + 16, KMOD_Main.KetherLeaves);
         world.setBlockMetadataWithNotify(x + 5, y + 9, z + 16, 15, 15);
         this.setBlock(world, x + 15, y + 9, z + 16, KMOD_Main.KetherLeaves);
         world.setBlockMetadataWithNotify(x + 15, y + 9, z + 16, 15, 15);
         this.setBlock(world, x + 16, y + 9, z + 16, KMOD_Main.KetherLeaves);
         world.setBlockMetadataWithNotify(x + 16, y + 9, z + 16, 15, 15);
         this.setBlock(world, x + 6, y + 9, z + 17, KMOD_Main.KetherLeaves);
         world.setBlockMetadataWithNotify(x + 6, y + 9, z + 17, 15, 15);
         this.setBlock(world, x + 12, y + 9, z + 17, KMOD_Main.KetherLeaves);
         world.setBlockMetadataWithNotify(x + 12, y + 9, z + 17, 15, 15);
         this.setBlock(world, x + 14, y + 9, z + 17, KMOD_Main.KetherLeaves);
         world.setBlockMetadataWithNotify(x + 14, y + 9, z + 17, 15, 15);
         this.setBlock(world, x + 15, y + 9, z + 17, KMOD_Main.KetherLeaves);
         world.setBlockMetadataWithNotify(x + 15, y + 9, z + 17, 15, 15);
         this.setBlock(world, x + 16, y + 9, z + 17, KMOD_Main.KetherLeaves);
         world.setBlockMetadataWithNotify(x + 16, y + 9, z + 17, 15, 15);
         this.setBlock(world, x + 7, y + 9, z + 18, KMOD_Main.KetherLeaves);
         world.setBlockMetadataWithNotify(x + 7, y + 9, z + 18, 15, 15);
         this.setBlock(world, x + 12, y + 9, z + 18, KMOD_Main.KetherLeaves);
         world.setBlockMetadataWithNotify(x + 12, y + 9, z + 18, 15, 15);
         this.setBlock(world, x + 16, y + 9, z + 18, KMOD_Main.KetherLeaves);
         world.setBlockMetadataWithNotify(x + 16, y + 9, z + 18, 15, 15);
         this.setBlock(world, x + 5, y + 9, z + 19, KMOD_Main.KetherLeaves);
         world.setBlockMetadataWithNotify(x + 5, y + 9, z + 19, 15, 15);
         this.setBlock(world, x + 10, y + 9, z + 19, KMOD_Main.KetherLeaves);
         world.setBlockMetadataWithNotify(x + 10, y + 9, z + 19, 15, 15);
         this.setBlock(world, x + 11, y + 9, z + 19, KMOD_Main.KetherLeaves);
         world.setBlockMetadataWithNotify(x + 11, y + 9, z + 19, 15, 15);
         this.setBlock(world, x + 12, y + 9, z + 19, KMOD_Main.KetherLeaves);
         world.setBlockMetadataWithNotify(x + 12, y + 9, z + 19, 15, 15);
         this.setBlock(world, x + 17, y + 9, z + 19, KMOD_Main.KetherLeaves);
         world.setBlockMetadataWithNotify(x + 17, y + 9, z + 19, 15, 15);
         this.setBlock(world, x + 4, y + 9, z + 20, KMOD_Main.KetherLeaves);
         world.setBlockMetadataWithNotify(x + 4, y + 9, z + 20, 15, 15);
         this.setBlock(world, x + 6, y + 9, z + 20, KMOD_Main.KetherLeaves);
         world.setBlockMetadataWithNotify(x + 6, y + 9, z + 20, 15, 15);
         this.setBlock(world, x + 7, y + 9, z + 20, KMOD_Main.KetherLeaves);
         world.setBlockMetadataWithNotify(x + 7, y + 9, z + 20, 15, 15);
         this.setBlock(world, x + 14, y + 9, z + 20, KMOD_Main.KetherLeaves);
         world.setBlockMetadataWithNotify(x + 14, y + 9, z + 20, 15, 15);
         this.setBlock(world, x + 16, y + 9, z + 20, KMOD_Main.KetherLeaves);
         world.setBlockMetadataWithNotify(x + 16, y + 9, z + 20, 15, 15);
         this.setBlock(world, x + 4, y + 9, z + 21, KMOD_Main.KetherLeaves);
         world.setBlockMetadataWithNotify(x + 4, y + 9, z + 21, 15, 15);
         this.setBlock(world, x + 6, y + 9, z + 21, KMOD_Main.KetherLeaves);
         world.setBlockMetadataWithNotify(x + 6, y + 9, z + 21, 15, 15);
         this.setBlock(world, x + 9, y + 9, z + 21, KMOD_Main.KetherLeaves);
         world.setBlockMetadataWithNotify(x + 9, y + 9, z + 21, 15, 15);
         this.setBlock(world, x + 12, y + 9, z + 21, KMOD_Main.KetherLeaves);
         world.setBlockMetadataWithNotify(x + 12, y + 9, z + 21, 15, 15);
         this.setBlock(world, x + 15, y + 9, z + 21, KMOD_Main.KetherLeaves);
         world.setBlockMetadataWithNotify(x + 15, y + 9, z + 21, 15, 15);
         this.setBlock(world, x + 5, y + 9, z + 22, KMOD_Main.KetherLeaves);
         world.setBlockMetadataWithNotify(x + 5, y + 9, z + 22, 15, 15);
         this.setBlock(world, x + 8, y + 9, z + 22, KMOD_Main.KetherLeaves);
         world.setBlockMetadataWithNotify(x + 8, y + 9, z + 22, 15, 15);
         this.setBlock(world, x + 9, y + 9, z + 22, KMOD_Main.KetherLeaves);
         world.setBlockMetadataWithNotify(x + 9, y + 9, z + 22, 15, 15);
         this.setBlock(world, x + 9, y + 9, z + 23, KMOD_Main.KetherLeaves);
         world.setBlockMetadataWithNotify(x + 9, y + 9, z + 23, 15, 15);
         this.setBlock(world, x + 10, y + 9, z + 23, KMOD_Main.KetherLeaves);
         world.setBlockMetadataWithNotify(x + 10, y + 9, z + 23, 15, 15);
         this.setBlock(world, x + 9, y + 9, z + 24, KMOD_Main.KetherLeaves);
         world.setBlockMetadataWithNotify(x + 9, y + 9, z + 24, 15, 15);
         this.setBlock(world, x + 5, y + 10, z + 0, KMOD_Main.KetherLeaves);
         world.setBlockMetadataWithNotify(x + 5, y + 10, z + 0, 15, 15);
         this.setBlock(world, x + 6, y + 10, z + 0, KMOD_Main.KetherLeaves);
         world.setBlockMetadataWithNotify(x + 6, y + 10, z + 0, 15, 15);
         this.setBlock(world, x + 6, y + 10, z + 1, KMOD_Main.KetherLeaves);
         world.setBlockMetadataWithNotify(x + 6, y + 10, z + 1, 15, 15);
         this.setBlock(world, x + 7, y + 10, z + 1, KMOD_Main.KetherLeaves);
         world.setBlockMetadataWithNotify(x + 7, y + 10, z + 1, 15, 15);
         this.setBlock(world, x + 11, y + 10, z + 1, KMOD_Main.KetherLeaves);
         world.setBlockMetadataWithNotify(x + 11, y + 10, z + 1, 15, 15);
         this.setBlock(world, x + 4, y + 10, z + 2, KMOD_Main.KetherLeaves);
         world.setBlockMetadataWithNotify(x + 4, y + 10, z + 2, 15, 15);
         this.setBlock(world, x + 5, y + 10, z + 2, KMOD_Main.KetherLeaves);
         world.setBlockMetadataWithNotify(x + 5, y + 10, z + 2, 15, 15);
         this.setBlock(world, x + 10, y + 10, z + 2, KMOD_Main.KetherLeaves);
         world.setBlockMetadataWithNotify(x + 10, y + 10, z + 2, 15, 15);
         this.setBlock(world, x + 3, y + 10, z + 3, KMOD_Main.KetherLeaves);
         world.setBlockMetadataWithNotify(x + 3, y + 10, z + 3, 15, 15);
         this.setBlock(world, x + 7, y + 10, z + 3, KMOD_Main.KetherLeaves);
         world.setBlockMetadataWithNotify(x + 7, y + 10, z + 3, 15, 15);
         this.setBlock(world, x + 8, y + 10, z + 3, KMOD_Main.KetherLeaves);
         world.setBlockMetadataWithNotify(x + 8, y + 10, z + 3, 15, 15);
         this.setBlock(world, x + 10, y + 10, z + 3, KMOD_Main.KetherLeaves);
         world.setBlockMetadataWithNotify(x + 10, y + 10, z + 3, 15, 15);
         this.setBlock(world, x + 2, y + 10, z + 4, KMOD_Main.KetherLeaves);
         world.setBlockMetadataWithNotify(x + 2, y + 10, z + 4, 15, 15);
         this.setBlock(world, x + 4, y + 10, z + 4, KMOD_Main.KetherLeaves);
         world.setBlockMetadataWithNotify(x + 4, y + 10, z + 4, 15, 15);
         this.setBlock(world, x + 8, y + 10, z + 4, KMOD_Main.KetherLeaves);
         world.setBlockMetadataWithNotify(x + 8, y + 10, z + 4, 15, 15);
         this.setBlock(world, x + 9, y + 10, z + 4, KMOD_Main.KetherLeaves);
         world.setBlockMetadataWithNotify(x + 9, y + 10, z + 4, 15, 15);
         this.setBlock(world, x + 11, y + 10, z + 4, KMOD_Main.KetherLeaves);
         world.setBlockMetadataWithNotify(x + 11, y + 10, z + 4, 15, 15);
         this.setBlock(world, x + 15, y + 10, z + 4, KMOD_Main.KetherLeaves);
         world.setBlockMetadataWithNotify(x + 15, y + 10, z + 4, 15, 15);
         this.setBlock(world, x + 3, y + 10, z + 5, KMOD_Main.KetherLeaves);
         world.setBlockMetadataWithNotify(x + 3, y + 10, z + 5, 15, 15);
         this.setBlock(world, x + 4, y + 10, z + 5, KMOD_Main.KetherLeaves);
         world.setBlockMetadataWithNotify(x + 4, y + 10, z + 5, 15, 15);
         this.setBlock(world, x + 7, y + 10, z + 5, KMOD_Main.KetherLeaves);
         world.setBlockMetadataWithNotify(x + 7, y + 10, z + 5, 15, 15);
         this.setBlock(world, x + 15, y + 10, z + 5, KMOD_Main.KetherLeaves);
         world.setBlockMetadataWithNotify(x + 15, y + 10, z + 5, 15, 15);
         this.setBlock(world, x + 3, y + 10, z + 6, KMOD_Main.KetherLeaves);
         world.setBlockMetadataWithNotify(x + 3, y + 10, z + 6, 15, 15);
         this.setBlock(world, x + 4, y + 10, z + 6, KMOD_Main.KetherLeaves);
         world.setBlockMetadataWithNotify(x + 4, y + 10, z + 6, 15, 15);
         this.setBlock(world, x + 5, y + 10, z + 6, KMOD_Main.KetherLeaves);
         world.setBlockMetadataWithNotify(x + 5, y + 10, z + 6, 15, 15);
         this.setBlock(world, x + 6, y + 10, z + 6, KMOD_Main.KetherLeaves);
         world.setBlockMetadataWithNotify(x + 6, y + 10, z + 6, 15, 15);
         this.setBlock(world, x + 7, y + 10, z + 6, KMOD_Main.KetherLeaves);
         world.setBlockMetadataWithNotify(x + 7, y + 10, z + 6, 15, 15);
         this.setBlock(world, x + 8, y + 10, z + 6, KMOD_Main.KetherLeaves);
         world.setBlockMetadataWithNotify(x + 8, y + 10, z + 6, 15, 15);
         this.setBlock(world, x + 15, y + 10, z + 6, KMOD_Main.KetherLeaves);
         world.setBlockMetadataWithNotify(x + 15, y + 10, z + 6, 15, 15);
         this.setBlock(world, x + 16, y + 10, z + 6, KMOD_Main.KetherLeaves);
         world.setBlockMetadataWithNotify(x + 16, y + 10, z + 6, 15, 15);
         this.setBlock(world, x + 18, y + 10, z + 6, KMOD_Main.KetherLeaves);
         world.setBlockMetadataWithNotify(x + 18, y + 10, z + 6, 15, 15);
         this.setBlock(world, x + 5, y + 10, z + 7, KMOD_Main.KetherLeaves);
         world.setBlockMetadataWithNotify(x + 5, y + 10, z + 7, 15, 15);
         this.setBlock(world, x + 9, y + 10, z + 7, KMOD_Main.KetherLeaves);
         world.setBlockMetadataWithNotify(x + 9, y + 10, z + 7, 15, 15);
         this.setBlock(world, x + 10, y + 10, z + 7, KMOD_Main.KetherLeaves);
         world.setBlockMetadataWithNotify(x + 10, y + 10, z + 7, 15, 15);
         this.setBlock(world, x + 16, y + 10, z + 7, KMOD_Main.KetherLeaves);
         world.setBlockMetadataWithNotify(x + 16, y + 10, z + 7, 15, 15);
         this.setBlock(world, x + 18, y + 10, z + 7, KMOD_Main.KetherLeaves);
         world.setBlockMetadataWithNotify(x + 18, y + 10, z + 7, 15, 15);
         this.setBlock(world, x + 4, y + 10, z + 8, KMOD_Main.KetherLeaves);
         world.setBlockMetadataWithNotify(x + 4, y + 10, z + 8, 15, 15);
         this.setBlock(world, x + 6, y + 10, z + 8, KMOD_Main.KetherLeaves);
         world.setBlockMetadataWithNotify(x + 6, y + 10, z + 8, 15, 15);
         this.setBlock(world, x + 7, y + 10, z + 8, KMOD_Main.KetherLeaves);
         world.setBlockMetadataWithNotify(x + 7, y + 10, z + 8, 15, 15);
         this.setBlock(world, x + 9, y + 10, z + 8, KMOD_Main.KetherLeaves);
         world.setBlockMetadataWithNotify(x + 9, y + 10, z + 8, 15, 15);
         this.setBlock(world, x + 10, y + 10, z + 8, KMOD_Main.KetherLeaves);
         world.setBlockMetadataWithNotify(x + 10, y + 10, z + 8, 15, 15);
         this.setBlock(world, x + 12, y + 10, z + 8, KMOD_Main.KetherLeaves);
         world.setBlockMetadataWithNotify(x + 12, y + 10, z + 8, 15, 15);
         this.setBlock(world, x + 13, y + 10, z + 8, KMOD_Main.KetherLeaves);
         world.setBlockMetadataWithNotify(x + 13, y + 10, z + 8, 15, 15);
         this.setBlock(world, x + 5, y + 10, z + 9, KMOD_Main.KetherLeaves);
         world.setBlockMetadataWithNotify(x + 5, y + 10, z + 9, 15, 15);
         this.setBlock(world, x + 7, y + 10, z + 9, KMOD_Main.KetherLeaves);
         world.setBlockMetadataWithNotify(x + 7, y + 10, z + 9, 15, 15);
         this.setBlock(world, x + 11, y + 10, z + 9, KMOD_Main.KetherLog);
         world.setBlockMetadataWithNotify(x + 11, y + 10, z + 9, 15, 15);
         this.setBlock(world, x + 13, y + 10, z + 9, KMOD_Main.KetherLeaves);
         world.setBlockMetadataWithNotify(x + 13, y + 10, z + 9, 15, 15);
         this.setBlock(world, x + 2, y + 10, z + 10, KMOD_Main.KetherLeaves);
         world.setBlockMetadataWithNotify(x + 2, y + 10, z + 10, 15, 15);
         this.setBlock(world, x + 3, y + 10, z + 10, KMOD_Main.KetherLeaves);
         world.setBlockMetadataWithNotify(x + 3, y + 10, z + 10, 15, 15);
         this.setBlock(world, x + 4, y + 10, z + 10, KMOD_Main.KetherLeaves);
         world.setBlockMetadataWithNotify(x + 4, y + 10, z + 10, 15, 15);
         this.setBlock(world, x + 5, y + 10, z + 10, KMOD_Main.KetherLog);
         world.setBlockMetadataWithNotify(x + 5, y + 10, z + 10, 15, 15);
         this.setBlock(world, x + 6, y + 10, z + 10, KMOD_Main.KetherLeaves);
         world.setBlockMetadataWithNotify(x + 6, y + 10, z + 10, 15, 15);
         this.setBlock(world, x + 13, y + 10, z + 10, KMOD_Main.KetherLeaves);
         world.setBlockMetadataWithNotify(x + 13, y + 10, z + 10, 15, 15);
         this.setBlock(world, x + 1, y + 10, z + 11, KMOD_Main.KetherLeaves);
         world.setBlockMetadataWithNotify(x + 1, y + 10, z + 11, 15, 15);
         this.setBlock(world, x + 14, y + 10, z + 11, KMOD_Main.KetherLeaves);
         world.setBlockMetadataWithNotify(x + 14, y + 10, z + 11, 15, 15);
         this.setBlock(world, x + 2, y + 10, z + 12, KMOD_Main.KetherLeaves);
         world.setBlockMetadataWithNotify(x + 2, y + 10, z + 12, 15, 15);
         this.setBlock(world, x + 8, y + 10, z + 12, KMOD_Main.KetherLeaves);
         world.setBlockMetadataWithNotify(x + 8, y + 10, z + 12, 15, 15);
         this.setBlock(world, x + 11, y + 10, z + 12, KMOD_Main.KetherLeaves);
         world.setBlockMetadataWithNotify(x + 11, y + 10, z + 12, 15, 15);
         this.setBlock(world, x + 6, y + 10, z + 13, KMOD_Main.KetherLeaves);
         world.setBlockMetadataWithNotify(x + 6, y + 10, z + 13, 15, 15);
         this.setBlock(world, x + 7, y + 10, z + 13, KMOD_Main.KetherLeaves);
         world.setBlockMetadataWithNotify(x + 7, y + 10, z + 13, 15, 15);
         this.setBlock(world, x + 15, y + 10, z + 13, KMOD_Main.KetherLeaves);
         world.setBlockMetadataWithNotify(x + 15, y + 10, z + 13, 15, 15);
         this.setBlock(world, x + 16, y + 10, z + 13, KMOD_Main.KetherLeaves);
         world.setBlockMetadataWithNotify(x + 16, y + 10, z + 13, 15, 15);
         this.setBlock(world, x + 3, y + 10, z + 14, KMOD_Main.KetherLeaves);
         world.setBlockMetadataWithNotify(x + 3, y + 10, z + 14, 15, 15);
         this.setBlock(world, x + 9, y + 10, z + 14, KMOD_Main.KetherLeaves);
         world.setBlockMetadataWithNotify(x + 9, y + 10, z + 14, 15, 15);
         this.setBlock(world, x + 10, y + 10, z + 14, KMOD_Main.KetherLeaves);
         world.setBlockMetadataWithNotify(x + 10, y + 10, z + 14, 15, 15);
         this.setBlock(world, x + 13, y + 10, z + 14, KMOD_Main.KetherLeaves);
         world.setBlockMetadataWithNotify(x + 13, y + 10, z + 14, 15, 15);
         this.setBlock(world, x + 16, y + 10, z + 14, KMOD_Main.KetherLeaves);
         world.setBlockMetadataWithNotify(x + 16, y + 10, z + 14, 15, 15);
         this.setBlock(world, x + 4, y + 10, z + 15, KMOD_Main.KetherLeaves);
         world.setBlockMetadataWithNotify(x + 4, y + 10, z + 15, 15, 15);
         this.setBlock(world, x + 13, y + 10, z + 15, KMOD_Main.KetherLeaves);
         world.setBlockMetadataWithNotify(x + 13, y + 10, z + 15, 15, 15);
         this.setBlock(world, x + 4, y + 10, z + 16, KMOD_Main.KetherLeaves);
         world.setBlockMetadataWithNotify(x + 4, y + 10, z + 16, 15, 15);
         this.setBlock(world, x + 7, y + 10, z + 16, KMOD_Main.KetherLeaves);
         world.setBlockMetadataWithNotify(x + 7, y + 10, z + 16, 15, 15);
         this.setBlock(world, x + 11, y + 10, z + 16, KMOD_Main.KetherLog);
         world.setBlockMetadataWithNotify(x + 11, y + 10, z + 16, 15, 15);
         this.setBlock(world, x + 14, y + 10, z + 16, KMOD_Main.KetherLeaves);
         world.setBlockMetadataWithNotify(x + 14, y + 10, z + 16, 15, 15);
         this.setBlock(world, x + 15, y + 10, z + 16, KMOD_Main.KetherLeaves);
         world.setBlockMetadataWithNotify(x + 15, y + 10, z + 16, 15, 15);
         this.setBlock(world, x + 16, y + 10, z + 16, KMOD_Main.KetherLeaves);
         world.setBlockMetadataWithNotify(x + 16, y + 10, z + 16, 15, 15);
         this.setBlock(world, x + 17, y + 10, z + 16, KMOD_Main.KetherLeaves);
         world.setBlockMetadataWithNotify(x + 17, y + 10, z + 16, 15, 15);
         this.setBlock(world, x + 5, y + 10, z + 17, KMOD_Main.KetherLeaves);
         world.setBlockMetadataWithNotify(x + 5, y + 10, z + 17, 15, 15);
         this.setBlock(world, x + 6, y + 10, z + 17, KMOD_Main.KetherLeaves);
         world.setBlockMetadataWithNotify(x + 6, y + 10, z + 17, 15, 15);
         this.setBlock(world, x + 8, y + 10, z + 17, KMOD_Main.KetherLeaves);
         world.setBlockMetadataWithNotify(x + 8, y + 10, z + 17, 15, 15);
         this.setBlock(world, x + 10, y + 10, z + 17, KMOD_Main.KetherLeaves);
         world.setBlockMetadataWithNotify(x + 10, y + 10, z + 17, 15, 15);
         this.setBlock(world, x + 12, y + 10, z + 17, KMOD_Main.KetherLeaves);
         world.setBlockMetadataWithNotify(x + 12, y + 10, z + 17, 15, 15);
         this.setBlock(world, x + 15, y + 10, z + 17, KMOD_Main.KetherLeaves);
         world.setBlockMetadataWithNotify(x + 15, y + 10, z + 17, 15, 15);
         this.setBlock(world, x + 16, y + 10, z + 17, KMOD_Main.KetherLeaves);
         world.setBlockMetadataWithNotify(x + 16, y + 10, z + 17, 15, 15);
         this.setBlock(world, x + 5, y + 10, z + 18, KMOD_Main.KetherLeaves);
         world.setBlockMetadataWithNotify(x + 5, y + 10, z + 18, 15, 15);
         this.setBlock(world, x + 9, y + 10, z + 18, KMOD_Main.KetherLeaves);
         world.setBlockMetadataWithNotify(x + 9, y + 10, z + 18, 15, 15);
         this.setBlock(world, x + 17, y + 10, z + 18, KMOD_Main.KetherLeaves);
         world.setBlockMetadataWithNotify(x + 17, y + 10, z + 18, 15, 15);
         this.setBlock(world, x + 18, y + 10, z + 18, KMOD_Main.KetherLeaves);
         world.setBlockMetadataWithNotify(x + 18, y + 10, z + 18, 15, 15);
         this.setBlock(world, x + 5, y + 10, z + 19, KMOD_Main.KetherLeaves);
         world.setBlockMetadataWithNotify(x + 5, y + 10, z + 19, 15, 15);
         this.setBlock(world, x + 10, y + 10, z + 19, KMOD_Main.KetherLeaves);
         world.setBlockMetadataWithNotify(x + 10, y + 10, z + 19, 15, 15);
         this.setBlock(world, x + 14, y + 10, z + 19, KMOD_Main.KetherLeaves);
         world.setBlockMetadataWithNotify(x + 14, y + 10, z + 19, 15, 15);
         this.setBlock(world, x + 15, y + 10, z + 19, KMOD_Main.KetherLeaves);
         world.setBlockMetadataWithNotify(x + 15, y + 10, z + 19, 15, 15);
         this.setBlock(world, x + 5, y + 10, z + 20, KMOD_Main.KetherLeaves);
         world.setBlockMetadataWithNotify(x + 5, y + 10, z + 20, 15, 15);
         this.setBlock(world, x + 6, y + 10, z + 20, KMOD_Main.KetherLeaves);
         world.setBlockMetadataWithNotify(x + 6, y + 10, z + 20, 15, 15);
         this.setBlock(world, x + 11, y + 10, z + 20, KMOD_Main.KetherLeaves);
         world.setBlockMetadataWithNotify(x + 11, y + 10, z + 20, 15, 15);
         this.setBlock(world, x + 13, y + 10, z + 20, KMOD_Main.KetherLeaves);
         world.setBlockMetadataWithNotify(x + 13, y + 10, z + 20, 15, 15);
         this.setBlock(world, x + 16, y + 10, z + 20, KMOD_Main.KetherLeaves);
         world.setBlockMetadataWithNotify(x + 16, y + 10, z + 20, 15, 15);
         this.setBlock(world, x + 6, y + 10, z + 21, KMOD_Main.KetherLeaves);
         world.setBlockMetadataWithNotify(x + 6, y + 10, z + 21, 15, 15);
         this.setBlock(world, x + 8, y + 10, z + 21, KMOD_Main.KetherLeaves);
         world.setBlockMetadataWithNotify(x + 8, y + 10, z + 21, 15, 15);
         this.setBlock(world, x + 9, y + 10, z + 21, KMOD_Main.KetherLeaves);
         world.setBlockMetadataWithNotify(x + 9, y + 10, z + 21, 15, 15);
         this.setBlock(world, x + 10, y + 10, z + 21, KMOD_Main.KetherLeaves);
         world.setBlockMetadataWithNotify(x + 10, y + 10, z + 21, 15, 15);
         this.setBlock(world, x + 13, y + 10, z + 21, KMOD_Main.KetherLeaves);
         world.setBlockMetadataWithNotify(x + 13, y + 10, z + 21, 15, 15);
         this.setBlock(world, x + 14, y + 10, z + 21, KMOD_Main.KetherLeaves);
         world.setBlockMetadataWithNotify(x + 14, y + 10, z + 21, 15, 15);
         this.setBlock(world, x + 15, y + 10, z + 21, KMOD_Main.KetherLeaves);
         world.setBlockMetadataWithNotify(x + 15, y + 10, z + 21, 15, 15);
         this.setBlock(world, x + 8, y + 10, z + 22, KMOD_Main.KetherLeaves);
         world.setBlockMetadataWithNotify(x + 8, y + 10, z + 22, 15, 15);
         this.setBlock(world, x + 11, y + 10, z + 22, KMOD_Main.KetherLeaves);
         world.setBlockMetadataWithNotify(x + 11, y + 10, z + 22, 15, 15);
         this.setBlock(world, x + 8, y + 10, z + 23, KMOD_Main.KetherLeaves);
         world.setBlockMetadataWithNotify(x + 8, y + 10, z + 23, 15, 15);
         this.setBlock(world, x + 6, y + 11, z + 2, KMOD_Main.KetherLeaves);
         world.setBlockMetadataWithNotify(x + 6, y + 11, z + 2, 15, 15);
         this.setBlock(world, x + 7, y + 11, z + 2, KMOD_Main.KetherLeaves);
         world.setBlockMetadataWithNotify(x + 7, y + 11, z + 2, 15, 15);
         this.setBlock(world, x + 9, y + 11, z + 2, KMOD_Main.KetherLeaves);
         world.setBlockMetadataWithNotify(x + 9, y + 11, z + 2, 15, 15);
         this.setBlock(world, x + 10, y + 11, z + 2, KMOD_Main.KetherLeaves);
         world.setBlockMetadataWithNotify(x + 10, y + 11, z + 2, 15, 15);
         this.setBlock(world, x + 11, y + 11, z + 2, KMOD_Main.KetherLeaves);
         world.setBlockMetadataWithNotify(x + 11, y + 11, z + 2, 15, 15);
         this.setBlock(world, x + 5, y + 11, z + 3, KMOD_Main.KetherLeaves);
         world.setBlockMetadataWithNotify(x + 5, y + 11, z + 3, 15, 15);
         this.setBlock(world, x + 8, y + 11, z + 3, KMOD_Main.KetherLeaves);
         world.setBlockMetadataWithNotify(x + 8, y + 11, z + 3, 15, 15);
         this.setBlock(world, x + 10, y + 11, z + 3, KMOD_Main.KetherLeaves);
         world.setBlockMetadataWithNotify(x + 10, y + 11, z + 3, 15, 15);
         this.setBlock(world, x + 13, y + 11, z + 3, KMOD_Main.KetherLeaves);
         world.setBlockMetadataWithNotify(x + 13, y + 11, z + 3, 15, 15);
         this.setBlock(world, x + 4, y + 11, z + 4, KMOD_Main.KetherLeaves);
         world.setBlockMetadataWithNotify(x + 4, y + 11, z + 4, 15, 15);
         this.setBlock(world, x + 6, y + 11, z + 4, KMOD_Main.KetherLeaves);
         world.setBlockMetadataWithNotify(x + 6, y + 11, z + 4, 15, 15);
         this.setBlock(world, x + 9, y + 11, z + 4, KMOD_Main.KetherLeaves);
         world.setBlockMetadataWithNotify(x + 9, y + 11, z + 4, 15, 15);
         this.setBlock(world, x + 12, y + 11, z + 4, KMOD_Main.KetherLeaves);
         world.setBlockMetadataWithNotify(x + 12, y + 11, z + 4, 15, 15);
         this.setBlock(world, x + 3, y + 11, z + 5, KMOD_Main.KetherLeaves);
         world.setBlockMetadataWithNotify(x + 3, y + 11, z + 5, 15, 15);
         this.setBlock(world, x + 5, y + 11, z + 5, KMOD_Main.KetherLeaves);
         world.setBlockMetadataWithNotify(x + 5, y + 11, z + 5, 15, 15);
         this.setBlock(world, x + 9, y + 11, z + 5, KMOD_Main.KetherLeaves);
         world.setBlockMetadataWithNotify(x + 9, y + 11, z + 5, 15, 15);
         this.setBlock(world, x + 10, y + 11, z + 5, KMOD_Main.KetherLeaves);
         world.setBlockMetadataWithNotify(x + 10, y + 11, z + 5, 15, 15);
         this.setBlock(world, x + 8, y + 11, z + 6, KMOD_Main.KetherLeaves);
         world.setBlockMetadataWithNotify(x + 8, y + 11, z + 6, 15, 15);
         this.setBlock(world, x + 11, y + 11, z + 6, KMOD_Main.KetherLeaves);
         world.setBlockMetadataWithNotify(x + 11, y + 11, z + 6, 15, 15);
         this.setBlock(world, x + 12, y + 11, z + 6, KMOD_Main.KetherLeaves);
         world.setBlockMetadataWithNotify(x + 12, y + 11, z + 6, 15, 15);
         this.setBlock(world, x + 13, y + 11, z + 6, KMOD_Main.KetherLeaves);
         world.setBlockMetadataWithNotify(x + 13, y + 11, z + 6, 15, 15);
         this.setBlock(world, x + 17, y + 11, z + 6, KMOD_Main.KetherLeaves);
         world.setBlockMetadataWithNotify(x + 17, y + 11, z + 6, 15, 15);
         this.setBlock(world, x + 5, y + 11, z + 7, KMOD_Main.KetherLeaves);
         world.setBlockMetadataWithNotify(x + 5, y + 11, z + 7, 15, 15);
         this.setBlock(world, x + 6, y + 11, z + 7, KMOD_Main.KetherLeaves);
         world.setBlockMetadataWithNotify(x + 6, y + 11, z + 7, 15, 15);
         this.setBlock(world, x + 8, y + 11, z + 7, KMOD_Main.KetherLeaves);
         world.setBlockMetadataWithNotify(x + 8, y + 11, z + 7, 15, 15);
         this.setBlock(world, x + 10, y + 11, z + 7, KMOD_Main.KetherLeaves);
         world.setBlockMetadataWithNotify(x + 10, y + 11, z + 7, 15, 15);
         this.setBlock(world, x + 14, y + 11, z + 7, KMOD_Main.KetherLeaves);
         world.setBlockMetadataWithNotify(x + 14, y + 11, z + 7, 15, 15);
         this.setBlock(world, x + 15, y + 11, z + 7, KMOD_Main.KetherLeaves);
         world.setBlockMetadataWithNotify(x + 15, y + 11, z + 7, 15, 15);
         this.setBlock(world, x + 16, y + 11, z + 7, KMOD_Main.KetherLeaves);
         world.setBlockMetadataWithNotify(x + 16, y + 11, z + 7, 15, 15);
         this.setBlock(world, x + 3, y + 11, z + 8, KMOD_Main.KetherLeaves);
         world.setBlockMetadataWithNotify(x + 3, y + 11, z + 8, 15, 15);
         this.setBlock(world, x + 4, y + 11, z + 8, KMOD_Main.KetherLeaves);
         world.setBlockMetadataWithNotify(x + 4, y + 11, z + 8, 15, 15);
         this.setBlock(world, x + 9, y + 11, z + 8, KMOD_Main.KetherLeaves);
         world.setBlockMetadataWithNotify(x + 9, y + 11, z + 8, 15, 15);
         this.setBlock(world, x + 13, y + 11, z + 8, KMOD_Main.KetherLeaves);
         world.setBlockMetadataWithNotify(x + 13, y + 11, z + 8, 15, 15);
         this.setBlock(world, x + 2, y + 11, z + 9, KMOD_Main.KetherLeaves);
         world.setBlockMetadataWithNotify(x + 2, y + 11, z + 9, 15, 15);
         this.setBlock(world, x + 5, y + 11, z + 9, KMOD_Main.KetherLog);
         world.setBlockMetadataWithNotify(x + 5, y + 11, z + 9, 15, 15);
         this.setBlock(world, x + 8, y + 11, z + 9, KMOD_Main.KetherLeaves);
         world.setBlockMetadataWithNotify(x + 8, y + 11, z + 9, 15, 15);
         this.setBlock(world, x + 11, y + 11, z + 9, KMOD_Main.KetherLeaves);
         world.setBlockMetadataWithNotify(x + 11, y + 11, z + 9, 15, 15);
         this.setBlock(world, x + 13, y + 11, z + 9, KMOD_Main.KetherLeaves);
         world.setBlockMetadataWithNotify(x + 13, y + 11, z + 9, 15, 15);
         this.setBlock(world, x + 16, y + 11, z + 9, KMOD_Main.KetherLeaves);
         world.setBlockMetadataWithNotify(x + 16, y + 11, z + 9, 15, 15);
         this.setBlock(world, x + 17, y + 11, z + 9, KMOD_Main.KetherLeaves);
         world.setBlockMetadataWithNotify(x + 17, y + 11, z + 9, 15, 15);
         this.setBlock(world, x + 18, y + 11, z + 9, KMOD_Main.KetherLeaves);
         world.setBlockMetadataWithNotify(x + 18, y + 11, z + 9, 15, 15);
         this.setBlock(world, x + 3, y + 11, z + 10, KMOD_Main.KetherLeaves);
         world.setBlockMetadataWithNotify(x + 3, y + 11, z + 10, 15, 15);
         this.setBlock(world, x + 5, y + 11, z + 10, KMOD_Main.KetherLog);
         world.setBlockMetadataWithNotify(x + 5, y + 11, z + 10, 15, 15);
         this.setBlock(world, x + 10, y + 11, z + 10, KMOD_Main.KetherLeaves);
         world.setBlockMetadataWithNotify(x + 10, y + 11, z + 10, 15, 15);
         this.setBlock(world, x + 13, y + 11, z + 10, KMOD_Main.KetherLeaves);
         world.setBlockMetadataWithNotify(x + 13, y + 11, z + 10, 15, 15);
         this.setBlock(world, x + 14, y + 11, z + 10, KMOD_Main.KetherLeaves);
         world.setBlockMetadataWithNotify(x + 14, y + 11, z + 10, 15, 15);
         this.setBlock(world, x + 17, y + 11, z + 10, KMOD_Main.KetherLeaves);
         world.setBlockMetadataWithNotify(x + 17, y + 11, z + 10, 15, 15);
         this.setBlock(world, x + 5, y + 11, z + 11, KMOD_Main.KetherLeaves);
         world.setBlockMetadataWithNotify(x + 5, y + 11, z + 11, 15, 15);
         this.setBlock(world, x + 8, y + 11, z + 11, KMOD_Main.KetherLeaves);
         world.setBlockMetadataWithNotify(x + 8, y + 11, z + 11, 15, 15);
         this.setBlock(world, x + 10, y + 11, z + 11, KMOD_Main.KetherLeaves);
         world.setBlockMetadataWithNotify(x + 10, y + 11, z + 11, 15, 15);
         this.setBlock(world, x + 11, y + 11, z + 11, KMOD_Main.KetherLeaves);
         world.setBlockMetadataWithNotify(x + 11, y + 11, z + 11, 15, 15);
         this.setBlock(world, x + 13, y + 11, z + 11, KMOD_Main.KetherLeaves);
         world.setBlockMetadataWithNotify(x + 13, y + 11, z + 11, 15, 15);
         this.setBlock(world, x + 16, y + 11, z + 11, KMOD_Main.KetherLeaves);
         world.setBlockMetadataWithNotify(x + 16, y + 11, z + 11, 15, 15);
         this.setBlock(world, x + 17, y + 11, z + 11, KMOD_Main.KetherLeaves);
         world.setBlockMetadataWithNotify(x + 17, y + 11, z + 11, 15, 15);
         this.setBlock(world, x + 4, y + 11, z + 12, KMOD_Main.KetherLeaves);
         world.setBlockMetadataWithNotify(x + 4, y + 11, z + 12, 15, 15);
         this.setBlock(world, x + 12, y + 11, z + 12, KMOD_Main.KetherLeaves);
         world.setBlockMetadataWithNotify(x + 12, y + 11, z + 12, 15, 15);
         this.setBlock(world, x + 17, y + 11, z + 12, KMOD_Main.KetherLeaves);
         world.setBlockMetadataWithNotify(x + 17, y + 11, z + 12, 15, 15);
         this.setBlock(world, x + 2, y + 11, z + 13, KMOD_Main.KetherLeaves);
         world.setBlockMetadataWithNotify(x + 2, y + 11, z + 13, 15, 15);
         this.setBlock(world, x + 4, y + 11, z + 13, KMOD_Main.KetherLeaves);
         world.setBlockMetadataWithNotify(x + 4, y + 11, z + 13, 15, 15);
         this.setBlock(world, x + 6, y + 11, z + 13, KMOD_Main.KetherLeaves);
         world.setBlockMetadataWithNotify(x + 6, y + 11, z + 13, 15, 15);
         this.setBlock(world, x + 8, y + 11, z + 13, KMOD_Main.KetherLeaves);
         world.setBlockMetadataWithNotify(x + 8, y + 11, z + 13, 15, 15);
         this.setBlock(world, x + 9, y + 11, z + 13, KMOD_Main.KetherLeaves);
         world.setBlockMetadataWithNotify(x + 9, y + 11, z + 13, 15, 15);
         this.setBlock(world, x + 14, y + 11, z + 13, KMOD_Main.KetherLeaves);
         world.setBlockMetadataWithNotify(x + 14, y + 11, z + 13, 15, 15);
         this.setBlock(world, x + 16, y + 11, z + 13, KMOD_Main.KetherLeaves);
         world.setBlockMetadataWithNotify(x + 16, y + 11, z + 13, 15, 15);
         this.setBlock(world, x + 2, y + 11, z + 14, KMOD_Main.KetherLeaves);
         world.setBlockMetadataWithNotify(x + 2, y + 11, z + 14, 15, 15);
         this.setBlock(world, x + 3, y + 11, z + 14, KMOD_Main.KetherLeaves);
         world.setBlockMetadataWithNotify(x + 3, y + 11, z + 14, 15, 15);
         this.setBlock(world, x + 5, y + 11, z + 14, KMOD_Main.KetherLeaves);
         world.setBlockMetadataWithNotify(x + 5, y + 11, z + 14, 15, 15);
         this.setBlock(world, x + 6, y + 11, z + 14, KMOD_Main.KetherLeaves);
         world.setBlockMetadataWithNotify(x + 6, y + 11, z + 14, 15, 15);
         this.setBlock(world, x + 10, y + 11, z + 14, KMOD_Main.KetherLeaves);
         world.setBlockMetadataWithNotify(x + 10, y + 11, z + 14, 15, 15);
         this.setBlock(world, x + 14, y + 11, z + 14, KMOD_Main.KetherLeaves);
         world.setBlockMetadataWithNotify(x + 14, y + 11, z + 14, 15, 15);
         this.setBlock(world, x + 15, y + 11, z + 14, KMOD_Main.KetherLeaves);
         world.setBlockMetadataWithNotify(x + 15, y + 11, z + 14, 15, 15);
         this.setBlock(world, x + 17, y + 11, z + 14, KMOD_Main.KetherLeaves);
         world.setBlockMetadataWithNotify(x + 17, y + 11, z + 14, 15, 15);
         this.setBlock(world, x + 3, y + 11, z + 15, KMOD_Main.KetherLeaves);
         world.setBlockMetadataWithNotify(x + 3, y + 11, z + 15, 15, 15);
         this.setBlock(world, x + 8, y + 11, z + 15, KMOD_Main.KetherLeaves);
         world.setBlockMetadataWithNotify(x + 8, y + 11, z + 15, 15, 15);
         this.setBlock(world, x + 10, y + 11, z + 15, KMOD_Main.KetherLeaves);
         world.setBlockMetadataWithNotify(x + 10, y + 11, z + 15, 15, 15);
         this.setBlock(world, x + 17, y + 11, z + 15, KMOD_Main.KetherLeaves);
         world.setBlockMetadataWithNotify(x + 17, y + 11, z + 15, 15, 15);
         this.setBlock(world, x + 4, y + 11, z + 16, KMOD_Main.KetherLeaves);
         world.setBlockMetadataWithNotify(x + 4, y + 11, z + 16, 15, 15);
         this.setBlock(world, x + 5, y + 11, z + 16, KMOD_Main.KetherLeaves);
         world.setBlockMetadataWithNotify(x + 5, y + 11, z + 16, 15, 15);
         this.setBlock(world, x + 8, y + 11, z + 16, KMOD_Main.KetherLeaves);
         world.setBlockMetadataWithNotify(x + 8, y + 11, z + 16, 15, 15);
         this.setBlock(world, x + 10, y + 11, z + 16, KMOD_Main.KetherLeaves);
         world.setBlockMetadataWithNotify(x + 10, y + 11, z + 16, 15, 15);
         this.setBlock(world, x + 11, y + 11, z + 16, KMOD_Main.KetherLog);
         world.setBlockMetadataWithNotify(x + 11, y + 11, z + 16, 15, 15);
         this.setBlock(world, x + 14, y + 11, z + 16, KMOD_Main.KetherLeaves);
         world.setBlockMetadataWithNotify(x + 14, y + 11, z + 16, 15, 15);
         this.setBlock(world, x + 5, y + 11, z + 17, KMOD_Main.KetherLeaves);
         world.setBlockMetadataWithNotify(x + 5, y + 11, z + 17, 15, 15);
         this.setBlock(world, x + 6, y + 11, z + 17, KMOD_Main.KetherLeaves);
         world.setBlockMetadataWithNotify(x + 6, y + 11, z + 17, 15, 15);
         this.setBlock(world, x + 8, y + 11, z + 17, KMOD_Main.KetherLeaves);
         world.setBlockMetadataWithNotify(x + 8, y + 11, z + 17, 15, 15);
         this.setBlock(world, x + 9, y + 11, z + 17, KMOD_Main.KetherLeaves);
         world.setBlockMetadataWithNotify(x + 9, y + 11, z + 17, 15, 15);
         this.setBlock(world, x + 14, y + 11, z + 17, KMOD_Main.KetherLeaves);
         world.setBlockMetadataWithNotify(x + 14, y + 11, z + 17, 15, 15);
         this.setBlock(world, x + 15, y + 11, z + 17, KMOD_Main.KetherLeaves);
         world.setBlockMetadataWithNotify(x + 15, y + 11, z + 17, 15, 15);
         this.setBlock(world, x + 4, y + 11, z + 18, KMOD_Main.KetherLeaves);
         world.setBlockMetadataWithNotify(x + 4, y + 11, z + 18, 15, 15);
         this.setBlock(world, x + 5, y + 11, z + 18, KMOD_Main.KetherLeaves);
         world.setBlockMetadataWithNotify(x + 5, y + 11, z + 18, 15, 15);
         this.setBlock(world, x + 7, y + 11, z + 18, KMOD_Main.KetherLeaves);
         world.setBlockMetadataWithNotify(x + 7, y + 11, z + 18, 15, 15);
         this.setBlock(world, x + 8, y + 11, z + 18, KMOD_Main.KetherLeaves);
         world.setBlockMetadataWithNotify(x + 8, y + 11, z + 18, 15, 15);
         this.setBlock(world, x + 9, y + 11, z + 18, KMOD_Main.KetherLeaves);
         world.setBlockMetadataWithNotify(x + 9, y + 11, z + 18, 15, 15);
         this.setBlock(world, x + 14, y + 11, z + 18, KMOD_Main.KetherLeaves);
         world.setBlockMetadataWithNotify(x + 14, y + 11, z + 18, 15, 15);
         this.setBlock(world, x + 18, y + 11, z + 18, KMOD_Main.KetherLeaves);
         world.setBlockMetadataWithNotify(x + 18, y + 11, z + 18, 15, 15);
         this.setBlock(world, x + 5, y + 11, z + 19, KMOD_Main.KetherLeaves);
         world.setBlockMetadataWithNotify(x + 5, y + 11, z + 19, 15, 15);
         this.setBlock(world, x + 13, y + 11, z + 19, KMOD_Main.KetherLeaves);
         world.setBlockMetadataWithNotify(x + 13, y + 11, z + 19, 15, 15);
         this.setBlock(world, x + 16, y + 11, z + 19, KMOD_Main.KetherLeaves);
         world.setBlockMetadataWithNotify(x + 16, y + 11, z + 19, 15, 15);
         this.setBlock(world, x + 17, y + 11, z + 19, KMOD_Main.KetherLeaves);
         world.setBlockMetadataWithNotify(x + 17, y + 11, z + 19, 15, 15);
         this.setBlock(world, x + 7, y + 11, z + 20, KMOD_Main.KetherLeaves);
         world.setBlockMetadataWithNotify(x + 7, y + 11, z + 20, 15, 15);
         this.setBlock(world, x + 9, y + 11, z + 20, KMOD_Main.KetherLeaves);
         world.setBlockMetadataWithNotify(x + 9, y + 11, z + 20, 15, 15);
         this.setBlock(world, x + 11, y + 11, z + 20, KMOD_Main.KetherLeaves);
         world.setBlockMetadataWithNotify(x + 11, y + 11, z + 20, 15, 15);
         this.setBlock(world, x + 13, y + 11, z + 20, KMOD_Main.KetherLeaves);
         world.setBlockMetadataWithNotify(x + 13, y + 11, z + 20, 15, 15);
         this.setBlock(world, x + 14, y + 11, z + 20, KMOD_Main.KetherLeaves);
         world.setBlockMetadataWithNotify(x + 14, y + 11, z + 20, 15, 15);
         this.setBlock(world, x + 15, y + 11, z + 20, KMOD_Main.KetherLeaves);
         world.setBlockMetadataWithNotify(x + 15, y + 11, z + 20, 15, 15);
         this.setBlock(world, x + 16, y + 11, z + 20, KMOD_Main.KetherLeaves);
         world.setBlockMetadataWithNotify(x + 16, y + 11, z + 20, 15, 15);
         this.setBlock(world, x + 7, y + 11, z + 21, KMOD_Main.KetherLeaves);
         world.setBlockMetadataWithNotify(x + 7, y + 11, z + 21, 15, 15);
         this.setBlock(world, x + 8, y + 11, z + 21, KMOD_Main.KetherLeaves);
         world.setBlockMetadataWithNotify(x + 8, y + 11, z + 21, 15, 15);
         this.setBlock(world, x + 12, y + 11, z + 21, KMOD_Main.KetherLeaves);
         world.setBlockMetadataWithNotify(x + 12, y + 11, z + 21, 15, 15);
         this.setBlock(world, x + 13, y + 11, z + 21, KMOD_Main.KetherLeaves);
         world.setBlockMetadataWithNotify(x + 13, y + 11, z + 21, 15, 15);
         this.setBlock(world, x + 9, y + 11, z + 22, KMOD_Main.KetherLeaves);
         world.setBlockMetadataWithNotify(x + 9, y + 11, z + 22, 15, 15);
         this.setBlock(world, x + 11, y + 11, z + 22, KMOD_Main.KetherLeaves);
         world.setBlockMetadataWithNotify(x + 11, y + 11, z + 22, 15, 15);
         this.setBlock(world, x + 9, y + 12, z + 2, KMOD_Main.KetherLeaves);
         world.setBlockMetadataWithNotify(x + 9, y + 12, z + 2, 15, 15);
         this.setBlock(world, x + 5, y + 12, z + 3, KMOD_Main.KetherLeaves);
         world.setBlockMetadataWithNotify(x + 5, y + 12, z + 3, 15, 15);
         this.setBlock(world, x + 11, y + 12, z + 3, KMOD_Main.KetherLeaves);
         world.setBlockMetadataWithNotify(x + 11, y + 12, z + 3, 15, 15);
         this.setBlock(world, x + 3, y + 12, z + 4, KMOD_Main.KetherLeaves);
         world.setBlockMetadataWithNotify(x + 3, y + 12, z + 4, 15, 15);
         this.setBlock(world, x + 4, y + 12, z + 4, KMOD_Main.KetherLeaves);
         world.setBlockMetadataWithNotify(x + 4, y + 12, z + 4, 15, 15);
         this.setBlock(world, x + 5, y + 12, z + 4, KMOD_Main.KetherLeaves);
         world.setBlockMetadataWithNotify(x + 5, y + 12, z + 4, 15, 15);
         this.setBlock(world, x + 6, y + 12, z + 4, KMOD_Main.KetherLeaves);
         world.setBlockMetadataWithNotify(x + 6, y + 12, z + 4, 15, 15);
         this.setBlock(world, x + 7, y + 12, z + 4, KMOD_Main.KetherLeaves);
         world.setBlockMetadataWithNotify(x + 7, y + 12, z + 4, 15, 15);
         this.setBlock(world, x + 8, y + 12, z + 4, KMOD_Main.KetherLeaves);
         world.setBlockMetadataWithNotify(x + 8, y + 12, z + 4, 15, 15);
         this.setBlock(world, x + 9, y + 12, z + 4, KMOD_Main.KetherLeaves);
         world.setBlockMetadataWithNotify(x + 9, y + 12, z + 4, 15, 15);
         this.setBlock(world, x + 6, y + 12, z + 5, KMOD_Main.KetherLeaves);
         world.setBlockMetadataWithNotify(x + 6, y + 12, z + 5, 15, 15);
         this.setBlock(world, x + 10, y + 12, z + 5, KMOD_Main.KetherLeaves);
         world.setBlockMetadataWithNotify(x + 10, y + 12, z + 5, 15, 15);
         this.setBlock(world, x + 11, y + 12, z + 5, KMOD_Main.KetherLeaves);
         world.setBlockMetadataWithNotify(x + 11, y + 12, z + 5, 15, 15);
         this.setBlock(world, x + 12, y + 12, z + 5, KMOD_Main.KetherLeaves);
         world.setBlockMetadataWithNotify(x + 12, y + 12, z + 5, 15, 15);
         this.setBlock(world, x + 14, y + 12, z + 5, KMOD_Main.KetherLeaves);
         world.setBlockMetadataWithNotify(x + 14, y + 12, z + 5, 15, 15);
         this.setBlock(world, x + 10, y + 12, z + 6, KMOD_Main.KetherLeaves);
         world.setBlockMetadataWithNotify(x + 10, y + 12, z + 6, 15, 15);
         this.setBlock(world, x + 7, y + 12, z + 7, KMOD_Main.KetherLeaves);
         world.setBlockMetadataWithNotify(x + 7, y + 12, z + 7, 15, 15);
         this.setBlock(world, x + 15, y + 12, z + 7, KMOD_Main.KetherLeaves);
         world.setBlockMetadataWithNotify(x + 15, y + 12, z + 7, 15, 15);
         this.setBlock(world, x + 17, y + 12, z + 7, KMOD_Main.KetherLeaves);
         world.setBlockMetadataWithNotify(x + 17, y + 12, z + 7, 15, 15);
         this.setBlock(world, x + 6, y + 12, z + 8, KMOD_Main.KetherLeaves);
         world.setBlockMetadataWithNotify(x + 6, y + 12, z + 8, 15, 15);
         this.setBlock(world, x + 7, y + 12, z + 8, KMOD_Main.KetherLeaves);
         world.setBlockMetadataWithNotify(x + 7, y + 12, z + 8, 15, 15);
         this.setBlock(world, x + 10, y + 12, z + 8, KMOD_Main.KetherLeaves);
         world.setBlockMetadataWithNotify(x + 10, y + 12, z + 8, 15, 15);
         this.setBlock(world, x + 13, y + 12, z + 8, KMOD_Main.KetherLeaves);
         world.setBlockMetadataWithNotify(x + 13, y + 12, z + 8, 15, 15);
         this.setBlock(world, x + 14, y + 12, z + 8, KMOD_Main.KetherLeaves);
         world.setBlockMetadataWithNotify(x + 14, y + 12, z + 8, 15, 15);
         this.setBlock(world, x + 17, y + 12, z + 8, KMOD_Main.KetherLeaves);
         world.setBlockMetadataWithNotify(x + 17, y + 12, z + 8, 15, 15);
         this.setBlock(world, x + 4, y + 12, z + 9, KMOD_Main.KetherLeaves);
         world.setBlockMetadataWithNotify(x + 4, y + 12, z + 9, 15, 15);
         this.setBlock(world, x + 5, y + 12, z + 9, KMOD_Main.KetherLeaves);
         world.setBlockMetadataWithNotify(x + 5, y + 12, z + 9, 15, 15);
         this.setBlock(world, x + 7, y + 12, z + 9, KMOD_Main.KetherLeaves);
         world.setBlockMetadataWithNotify(x + 7, y + 12, z + 9, 15, 15);
         this.setBlock(world, x + 8, y + 12, z + 9, KMOD_Main.KetherLeaves);
         world.setBlockMetadataWithNotify(x + 8, y + 12, z + 9, 15, 15);
         this.setBlock(world, x + 13, y + 12, z + 9, KMOD_Main.KetherLeaves);
         world.setBlockMetadataWithNotify(x + 13, y + 12, z + 9, 15, 15);
         this.setBlock(world, x + 15, y + 12, z + 9, KMOD_Main.KetherLeaves);
         world.setBlockMetadataWithNotify(x + 15, y + 12, z + 9, 15, 15);
         this.setBlock(world, x + 17, y + 12, z + 9, KMOD_Main.KetherLeaves);
         world.setBlockMetadataWithNotify(x + 17, y + 12, z + 9, 15, 15);
         this.setBlock(world, x + 18, y + 12, z + 9, KMOD_Main.KetherLeaves);
         world.setBlockMetadataWithNotify(x + 18, y + 12, z + 9, 15, 15);
         this.setBlock(world, x + 2, y + 12, z + 10, KMOD_Main.KetherLeaves);
         world.setBlockMetadataWithNotify(x + 2, y + 12, z + 10, 15, 15);
         this.setBlock(world, x + 3, y + 12, z + 10, KMOD_Main.KetherLeaves);
         world.setBlockMetadataWithNotify(x + 3, y + 12, z + 10, 15, 15);
         this.setBlock(world, x + 4, y + 12, z + 10, KMOD_Main.KetherLeaves);
         world.setBlockMetadataWithNotify(x + 4, y + 12, z + 10, 15, 15);
         this.setBlock(world, x + 5, y + 12, z + 10, KMOD_Main.KetherLeaves);
         world.setBlockMetadataWithNotify(x + 5, y + 12, z + 10, 15, 15);
         this.setBlock(world, x + 6, y + 12, z + 10, KMOD_Main.KetherLeaves);
         world.setBlockMetadataWithNotify(x + 6, y + 12, z + 10, 15, 15);
         this.setBlock(world, x + 9, y + 12, z + 10, KMOD_Main.KetherLeaves);
         world.setBlockMetadataWithNotify(x + 9, y + 12, z + 10, 15, 15);
         this.setBlock(world, x + 11, y + 12, z + 10, KMOD_Main.KetherLeaves);
         world.setBlockMetadataWithNotify(x + 11, y + 12, z + 10, 15, 15);
         this.setBlock(world, x + 17, y + 12, z + 10, KMOD_Main.KetherLeaves);
         world.setBlockMetadataWithNotify(x + 17, y + 12, z + 10, 15, 15);
         this.setBlock(world, x + 2, y + 12, z + 11, KMOD_Main.KetherLeaves);
         world.setBlockMetadataWithNotify(x + 2, y + 12, z + 11, 15, 15);
         this.setBlock(world, x + 5, y + 12, z + 11, KMOD_Main.KetherLeaves);
         world.setBlockMetadataWithNotify(x + 5, y + 12, z + 11, 15, 15);
         this.setBlock(world, x + 8, y + 12, z + 11, KMOD_Main.KetherLeaves);
         world.setBlockMetadataWithNotify(x + 8, y + 12, z + 11, 15, 15);
         this.setBlock(world, x + 9, y + 12, z + 11, KMOD_Main.KetherLeaves);
         world.setBlockMetadataWithNotify(x + 9, y + 12, z + 11, 15, 15);
         this.setBlock(world, x + 12, y + 12, z + 11, KMOD_Main.KetherLeaves);
         world.setBlockMetadataWithNotify(x + 12, y + 12, z + 11, 15, 15);
         this.setBlock(world, x + 14, y + 12, z + 11, KMOD_Main.KetherLeaves);
         world.setBlockMetadataWithNotify(x + 14, y + 12, z + 11, 15, 15);
         this.setBlock(world, x + 18, y + 12, z + 11, KMOD_Main.KetherLeaves);
         world.setBlockMetadataWithNotify(x + 18, y + 12, z + 11, 15, 15);
         this.setBlock(world, x + 9, y + 12, z + 12, KMOD_Main.KetherLeaves);
         world.setBlockMetadataWithNotify(x + 9, y + 12, z + 12, 15, 15);
         this.setBlock(world, x + 12, y + 12, z + 12, KMOD_Main.KetherLeaves);
         world.setBlockMetadataWithNotify(x + 12, y + 12, z + 12, 15, 15);
         this.setBlock(world, x + 9, y + 12, z + 13, KMOD_Main.KetherLeaves);
         world.setBlockMetadataWithNotify(x + 9, y + 12, z + 13, 15, 15);
         this.setBlock(world, x + 12, y + 12, z + 13, KMOD_Main.KetherLeaves);
         world.setBlockMetadataWithNotify(x + 12, y + 12, z + 13, 15, 15);
         this.setBlock(world, x + 14, y + 12, z + 13, KMOD_Main.KetherLeaves);
         world.setBlockMetadataWithNotify(x + 14, y + 12, z + 13, 15, 15);
         this.setBlock(world, x + 16, y + 12, z + 13, KMOD_Main.KetherLeaves);
         world.setBlockMetadataWithNotify(x + 16, y + 12, z + 13, 15, 15);
         this.setBlock(world, x + 7, y + 12, z + 14, KMOD_Main.KetherLeaves);
         world.setBlockMetadataWithNotify(x + 7, y + 12, z + 14, 15, 15);
         this.setBlock(world, x + 13, y + 12, z + 14, KMOD_Main.KetherLeaves);
         world.setBlockMetadataWithNotify(x + 13, y + 12, z + 14, 15, 15);
         this.setBlock(world, x + 15, y + 12, z + 14, KMOD_Main.KetherLeaves);
         world.setBlockMetadataWithNotify(x + 15, y + 12, z + 14, 15, 15);
         this.setBlock(world, x + 4, y + 12, z + 15, KMOD_Main.KetherLeaves);
         world.setBlockMetadataWithNotify(x + 4, y + 12, z + 15, 15, 15);
         this.setBlock(world, x + 9, y + 12, z + 15, KMOD_Main.KetherLeaves);
         world.setBlockMetadataWithNotify(x + 9, y + 12, z + 15, 15, 15);
         this.setBlock(world, x + 13, y + 12, z + 15, KMOD_Main.KetherLeaves);
         world.setBlockMetadataWithNotify(x + 13, y + 12, z + 15, 15, 15);
         this.setBlock(world, x + 15, y + 12, z + 15, KMOD_Main.KetherLeaves);
         world.setBlockMetadataWithNotify(x + 15, y + 12, z + 15, 15, 15);
         this.setBlock(world, x + 16, y + 12, z + 15, KMOD_Main.KetherLeaves);
         world.setBlockMetadataWithNotify(x + 16, y + 12, z + 15, 15, 15);
         this.setBlock(world, x + 4, y + 12, z + 16, KMOD_Main.KetherLeaves);
         world.setBlockMetadataWithNotify(x + 4, y + 12, z + 16, 15, 15);
         this.setBlock(world, x + 9, y + 12, z + 16, KMOD_Main.KetherLeaves);
         world.setBlockMetadataWithNotify(x + 9, y + 12, z + 16, 15, 15);
         this.setBlock(world, x + 10, y + 12, z + 16, KMOD_Main.KetherLeaves);
         world.setBlockMetadataWithNotify(x + 10, y + 12, z + 16, 15, 15);
         this.setBlock(world, x + 11, y + 12, z + 16, KMOD_Main.KetherLog);
         world.setBlockMetadataWithNotify(x + 11, y + 12, z + 16, 15, 15);
         this.setBlock(world, x + 12, y + 12, z + 16, KMOD_Main.KetherLeaves);
         world.setBlockMetadataWithNotify(x + 12, y + 12, z + 16, 15, 15);
         this.setBlock(world, x + 15, y + 12, z + 16, KMOD_Main.KetherLeaves);
         world.setBlockMetadataWithNotify(x + 15, y + 12, z + 16, 15, 15);
         this.setBlock(world, x + 16, y + 12, z + 16, KMOD_Main.KetherLeaves);
         world.setBlockMetadataWithNotify(x + 16, y + 12, z + 16, 15, 15);
         this.setBlock(world, x + 17, y + 12, z + 16, KMOD_Main.KetherLeaves);
         world.setBlockMetadataWithNotify(x + 17, y + 12, z + 16, 15, 15);
         this.setBlock(world, x + 8, y + 12, z + 17, KMOD_Main.KetherLeaves);
         world.setBlockMetadataWithNotify(x + 8, y + 12, z + 17, 15, 15);
         this.setBlock(world, x + 9, y + 12, z + 18, KMOD_Main.KetherLeaves);
         world.setBlockMetadataWithNotify(x + 9, y + 12, z + 18, 15, 15);
         this.setBlock(world, x + 11, y + 12, z + 18, KMOD_Main.KetherLeaves);
         world.setBlockMetadataWithNotify(x + 11, y + 12, z + 18, 15, 15);
         this.setBlock(world, x + 13, y + 12, z + 18, KMOD_Main.KetherLeaves);
         world.setBlockMetadataWithNotify(x + 13, y + 12, z + 18, 15, 15);
         this.setBlock(world, x + 14, y + 12, z + 18, KMOD_Main.KetherLeaves);
         world.setBlockMetadataWithNotify(x + 14, y + 12, z + 18, 15, 15);
         this.setBlock(world, x + 7, y + 12, z + 19, KMOD_Main.KetherLeaves);
         world.setBlockMetadataWithNotify(x + 7, y + 12, z + 19, 15, 15);
         this.setBlock(world, x + 8, y + 12, z + 19, KMOD_Main.KetherLeaves);
         world.setBlockMetadataWithNotify(x + 8, y + 12, z + 19, 15, 15);
         this.setBlock(world, x + 13, y + 12, z + 19, KMOD_Main.KetherLeaves);
         world.setBlockMetadataWithNotify(x + 13, y + 12, z + 19, 15, 15);
         this.setBlock(world, x + 14, y + 12, z + 19, KMOD_Main.KetherLeaves);
         world.setBlockMetadataWithNotify(x + 14, y + 12, z + 19, 15, 15);
         this.setBlock(world, x + 15, y + 12, z + 19, KMOD_Main.KetherLeaves);
         world.setBlockMetadataWithNotify(x + 15, y + 12, z + 19, 15, 15);
         this.setBlock(world, x + 5, y + 12, z + 20, KMOD_Main.KetherLeaves);
         world.setBlockMetadataWithNotify(x + 5, y + 12, z + 20, 15, 15);
         this.setBlock(world, x + 10, y + 12, z + 20, KMOD_Main.KetherLeaves);
         world.setBlockMetadataWithNotify(x + 10, y + 12, z + 20, 15, 15);
         this.setBlock(world, x + 13, y + 12, z + 20, KMOD_Main.KetherLeaves);
         world.setBlockMetadataWithNotify(x + 13, y + 12, z + 20, 15, 15);
         this.setBlock(world, x + 7, y + 12, z + 21, KMOD_Main.KetherLeaves);
         world.setBlockMetadataWithNotify(x + 7, y + 12, z + 21, 15, 15);
         this.setBlock(world, x + 10, y + 12, z + 21, KMOD_Main.KetherLeaves);
         world.setBlockMetadataWithNotify(x + 10, y + 12, z + 21, 15, 15);
         this.setBlock(world, x + 12, y + 12, z + 21, KMOD_Main.KetherLeaves);
         world.setBlockMetadataWithNotify(x + 12, y + 12, z + 21, 15, 15);
         this.setBlock(world, x + 10, y + 13, z + 3, KMOD_Main.KetherLeaves);
         world.setBlockMetadataWithNotify(x + 10, y + 13, z + 3, 15, 15);
         this.setBlock(world, x + 5, y + 13, z + 4, KMOD_Main.KetherLeaves);
         world.setBlockMetadataWithNotify(x + 5, y + 13, z + 4, 15, 15);
         this.setBlock(world, x + 11, y + 13, z + 4, KMOD_Main.KetherLeaves);
         world.setBlockMetadataWithNotify(x + 11, y + 13, z + 4, 15, 15);
         this.setBlock(world, x + 13, y + 13, z + 4, KMOD_Main.KetherLeaves);
         world.setBlockMetadataWithNotify(x + 13, y + 13, z + 4, 15, 15);
         this.setBlock(world, x + 6, y + 13, z + 5, KMOD_Main.KetherLeaves);
         world.setBlockMetadataWithNotify(x + 6, y + 13, z + 5, 15, 15);
         this.setBlock(world, x + 8, y + 13, z + 5, KMOD_Main.KetherLeaves);
         world.setBlockMetadataWithNotify(x + 8, y + 13, z + 5, 15, 15);
         this.setBlock(world, x + 11, y + 13, z + 5, KMOD_Main.KetherLeaves);
         world.setBlockMetadataWithNotify(x + 11, y + 13, z + 5, 15, 15);
         this.setBlock(world, x + 12, y + 13, z + 5, KMOD_Main.KetherLeaves);
         world.setBlockMetadataWithNotify(x + 12, y + 13, z + 5, 15, 15);
         this.setBlock(world, x + 6, y + 13, z + 6, KMOD_Main.KetherLeaves);
         world.setBlockMetadataWithNotify(x + 6, y + 13, z + 6, 15, 15);
         this.setBlock(world, x + 8, y + 13, z + 6, KMOD_Main.KetherLeaves);
         world.setBlockMetadataWithNotify(x + 8, y + 13, z + 6, 15, 15);
         this.setBlock(world, x + 9, y + 13, z + 6, KMOD_Main.KetherLeaves);
         world.setBlockMetadataWithNotify(x + 9, y + 13, z + 6, 15, 15);
         this.setBlock(world, x + 12, y + 13, z + 6, KMOD_Main.KetherLeaves);
         world.setBlockMetadataWithNotify(x + 12, y + 13, z + 6, 15, 15);
         this.setBlock(world, x + 13, y + 13, z + 6, KMOD_Main.KetherLeaves);
         world.setBlockMetadataWithNotify(x + 13, y + 13, z + 6, 15, 15);
         this.setBlock(world, x + 14, y + 13, z + 6, KMOD_Main.KetherLeaves);
         world.setBlockMetadataWithNotify(x + 14, y + 13, z + 6, 15, 15);
         this.setBlock(world, x + 5, y + 13, z + 7, KMOD_Main.KetherLeaves);
         world.setBlockMetadataWithNotify(x + 5, y + 13, z + 7, 15, 15);
         this.setBlock(world, x + 6, y + 13, z + 7, KMOD_Main.KetherLeaves);
         world.setBlockMetadataWithNotify(x + 6, y + 13, z + 7, 15, 15);
         this.setBlock(world, x + 9, y + 13, z + 7, KMOD_Main.KetherLeaves);
         world.setBlockMetadataWithNotify(x + 9, y + 13, z + 7, 15, 15);
         this.setBlock(world, x + 14, y + 13, z + 7, KMOD_Main.KetherLeaves);
         world.setBlockMetadataWithNotify(x + 14, y + 13, z + 7, 15, 15);
         this.setBlock(world, x + 4, y + 13, z + 8, KMOD_Main.KetherLeaves);
         world.setBlockMetadataWithNotify(x + 4, y + 13, z + 8, 15, 15);
         this.setBlock(world, x + 8, y + 13, z + 8, KMOD_Main.KetherLeaves);
         world.setBlockMetadataWithNotify(x + 8, y + 13, z + 8, 15, 15);
         this.setBlock(world, x + 11, y + 13, z + 8, KMOD_Main.KetherLeaves);
         world.setBlockMetadataWithNotify(x + 11, y + 13, z + 8, 15, 15);
         this.setBlock(world, x + 4, y + 13, z + 9, KMOD_Main.KetherLeaves);
         world.setBlockMetadataWithNotify(x + 4, y + 13, z + 9, 15, 15);
         this.setBlock(world, x + 5, y + 13, z + 9, KMOD_Main.KetherLeaves);
         world.setBlockMetadataWithNotify(x + 5, y + 13, z + 9, 15, 15);
         this.setBlock(world, x + 8, y + 13, z + 9, KMOD_Main.KetherLeaves);
         world.setBlockMetadataWithNotify(x + 8, y + 13, z + 9, 15, 15);
         this.setBlock(world, x + 12, y + 13, z + 9, KMOD_Main.KetherLeaves);
         world.setBlockMetadataWithNotify(x + 12, y + 13, z + 9, 15, 15);
         this.setBlock(world, x + 14, y + 13, z + 9, KMOD_Main.KetherLeaves);
         world.setBlockMetadataWithNotify(x + 14, y + 13, z + 9, 15, 15);
         this.setBlock(world, x + 6, y + 13, z + 10, KMOD_Main.KetherLeaves);
         world.setBlockMetadataWithNotify(x + 6, y + 13, z + 10, 15, 15);
         this.setBlock(world, x + 7, y + 13, z + 10, KMOD_Main.KetherLeaves);
         world.setBlockMetadataWithNotify(x + 7, y + 13, z + 10, 15, 15);
         this.setBlock(world, x + 15, y + 13, z + 10, KMOD_Main.KetherLeaves);
         world.setBlockMetadataWithNotify(x + 15, y + 13, z + 10, 15, 15);
         this.setBlock(world, x + 18, y + 13, z + 10, KMOD_Main.KetherLeaves);
         world.setBlockMetadataWithNotify(x + 18, y + 13, z + 10, 15, 15);
         this.setBlock(world, x + 5, y + 13, z + 11, KMOD_Main.KetherLeaves);
         world.setBlockMetadataWithNotify(x + 5, y + 13, z + 11, 15, 15);
         this.setBlock(world, x + 13, y + 13, z + 11, KMOD_Main.KetherLeaves);
         world.setBlockMetadataWithNotify(x + 13, y + 13, z + 11, 15, 15);
         this.setBlock(world, x + 14, y + 13, z + 11, KMOD_Main.KetherLeaves);
         world.setBlockMetadataWithNotify(x + 14, y + 13, z + 11, 15, 15);
         this.setBlock(world, x + 17, y + 13, z + 11, KMOD_Main.KetherLeaves);
         world.setBlockMetadataWithNotify(x + 17, y + 13, z + 11, 15, 15);
         this.setBlock(world, x + 2, y + 13, z + 12, KMOD_Main.KetherLeaves);
         world.setBlockMetadataWithNotify(x + 2, y + 13, z + 12, 15, 15);
         this.setBlock(world, x + 5, y + 13, z + 12, KMOD_Main.KetherLeaves);
         world.setBlockMetadataWithNotify(x + 5, y + 13, z + 12, 15, 15);
         this.setBlock(world, x + 6, y + 13, z + 12, KMOD_Main.KetherLeaves);
         world.setBlockMetadataWithNotify(x + 6, y + 13, z + 12, 15, 15);
         this.setBlock(world, x + 10, y + 13, z + 12, KMOD_Main.KetherLeaves);
         world.setBlockMetadataWithNotify(x + 10, y + 13, z + 12, 15, 15);
         this.setBlock(world, x + 13, y + 13, z + 12, KMOD_Main.KetherLeaves);
         world.setBlockMetadataWithNotify(x + 13, y + 13, z + 12, 15, 15);
         this.setBlock(world, x + 14, y + 13, z + 12, KMOD_Main.KetherLeaves);
         world.setBlockMetadataWithNotify(x + 14, y + 13, z + 12, 15, 15);
         this.setBlock(world, x + 15, y + 13, z + 12, KMOD_Main.KetherLeaves);
         world.setBlockMetadataWithNotify(x + 15, y + 13, z + 12, 15, 15);
         this.setBlock(world, x + 16, y + 13, z + 12, KMOD_Main.KetherLeaves);
         world.setBlockMetadataWithNotify(x + 16, y + 13, z + 12, 15, 15);
         this.setBlock(world, x + 2, y + 13, z + 13, KMOD_Main.KetherLeaves);
         world.setBlockMetadataWithNotify(x + 2, y + 13, z + 13, 15, 15);
         this.setBlock(world, x + 3, y + 13, z + 13, KMOD_Main.KetherLeaves);
         world.setBlockMetadataWithNotify(x + 3, y + 13, z + 13, 15, 15);
         this.setBlock(world, x + 6, y + 13, z + 13, KMOD_Main.KetherLeaves);
         world.setBlockMetadataWithNotify(x + 6, y + 13, z + 13, 15, 15);
         this.setBlock(world, x + 8, y + 13, z + 13, KMOD_Main.KetherLeaves);
         world.setBlockMetadataWithNotify(x + 8, y + 13, z + 13, 15, 15);
         this.setBlock(world, x + 10, y + 13, z + 13, KMOD_Main.KetherLeaves);
         world.setBlockMetadataWithNotify(x + 10, y + 13, z + 13, 15, 15);
         this.setBlock(world, x + 16, y + 13, z + 13, KMOD_Main.KetherLeaves);
         world.setBlockMetadataWithNotify(x + 16, y + 13, z + 13, 15, 15);
         this.setBlock(world, x + 7, y + 13, z + 14, KMOD_Main.KetherLeaves);
         world.setBlockMetadataWithNotify(x + 7, y + 13, z + 14, 15, 15);
         this.setBlock(world, x + 12, y + 13, z + 14, KMOD_Main.KetherLeaves);
         world.setBlockMetadataWithNotify(x + 12, y + 13, z + 14, 15, 15);
         this.setBlock(world, x + 13, y + 13, z + 14, KMOD_Main.KetherLeaves);
         world.setBlockMetadataWithNotify(x + 13, y + 13, z + 14, 15, 15);
         this.setBlock(world, x + 16, y + 13, z + 14, KMOD_Main.KetherLeaves);
         world.setBlockMetadataWithNotify(x + 16, y + 13, z + 14, 15, 15);
         this.setBlock(world, x + 4, y + 13, z + 15, KMOD_Main.KetherLeaves);
         world.setBlockMetadataWithNotify(x + 4, y + 13, z + 15, 15, 15);
         this.setBlock(world, x + 5, y + 13, z + 15, KMOD_Main.KetherLeaves);
         world.setBlockMetadataWithNotify(x + 5, y + 13, z + 15, 15, 15);
         this.setBlock(world, x + 6, y + 13, z + 15, KMOD_Main.KetherLeaves);
         world.setBlockMetadataWithNotify(x + 6, y + 13, z + 15, 15, 15);
         this.setBlock(world, x + 8, y + 13, z + 15, KMOD_Main.KetherLeaves);
         world.setBlockMetadataWithNotify(x + 8, y + 13, z + 15, 15, 15);
         this.setBlock(world, x + 11, y + 13, z + 15, KMOD_Main.KetherLeaves);
         world.setBlockMetadataWithNotify(x + 11, y + 13, z + 15, 15, 15);
         this.setBlock(world, x + 13, y + 13, z + 15, KMOD_Main.KetherLeaves);
         world.setBlockMetadataWithNotify(x + 13, y + 13, z + 15, 15, 15);
         this.setBlock(world, x + 17, y + 13, z + 15, KMOD_Main.KetherLeaves);
         world.setBlockMetadataWithNotify(x + 17, y + 13, z + 15, 15, 15);
         this.setBlock(world, x + 6, y + 13, z + 16, KMOD_Main.KetherLeaves);
         world.setBlockMetadataWithNotify(x + 6, y + 13, z + 16, 15, 15);
         this.setBlock(world, x + 7, y + 13, z + 16, KMOD_Main.KetherLeaves);
         world.setBlockMetadataWithNotify(x + 7, y + 13, z + 16, 15, 15);
         this.setBlock(world, x + 8, y + 13, z + 16, KMOD_Main.KetherLeaves);
         world.setBlockMetadataWithNotify(x + 8, y + 13, z + 16, 15, 15);
         this.setBlock(world, x + 13, y + 13, z + 16, KMOD_Main.KetherLeaves);
         world.setBlockMetadataWithNotify(x + 13, y + 13, z + 16, 15, 15);
         this.setBlock(world, x + 14, y + 13, z + 16, KMOD_Main.KetherLeaves);
         world.setBlockMetadataWithNotify(x + 14, y + 13, z + 16, 15, 15);
         this.setBlock(world, x + 15, y + 13, z + 16, KMOD_Main.KetherLeaves);
         world.setBlockMetadataWithNotify(x + 15, y + 13, z + 16, 15, 15);
         this.setBlock(world, x + 7, y + 13, z + 17, KMOD_Main.KetherLeaves);
         world.setBlockMetadataWithNotify(x + 7, y + 13, z + 17, 15, 15);
         this.setBlock(world, x + 12, y + 13, z + 17, KMOD_Main.KetherLeaves);
         world.setBlockMetadataWithNotify(x + 12, y + 13, z + 17, 15, 15);
         this.setBlock(world, x + 13, y + 13, z + 17, KMOD_Main.KetherLeaves);
         world.setBlockMetadataWithNotify(x + 13, y + 13, z + 17, 15, 15);
         this.setBlock(world, x + 14, y + 13, z + 17, KMOD_Main.KetherLeaves);
         world.setBlockMetadataWithNotify(x + 14, y + 13, z + 17, 15, 15);
         this.setBlock(world, x + 16, y + 13, z + 17, KMOD_Main.KetherLeaves);
         world.setBlockMetadataWithNotify(x + 16, y + 13, z + 17, 15, 15);
         this.setBlock(world, x + 9, y + 13, z + 18, KMOD_Main.KetherLeaves);
         world.setBlockMetadataWithNotify(x + 9, y + 13, z + 18, 15, 15);
         this.setBlock(world, x + 13, y + 13, z + 18, KMOD_Main.KetherLeaves);
         world.setBlockMetadataWithNotify(x + 13, y + 13, z + 18, 15, 15);
         this.setBlock(world, x + 14, y + 13, z + 18, KMOD_Main.KetherLeaves);
         world.setBlockMetadataWithNotify(x + 14, y + 13, z + 18, 15, 15);
         this.setBlock(world, x + 6, y + 13, z + 19, KMOD_Main.KetherLeaves);
         world.setBlockMetadataWithNotify(x + 6, y + 13, z + 19, 15, 15);
         this.setBlock(world, x + 8, y + 13, z + 19, KMOD_Main.KetherLeaves);
         world.setBlockMetadataWithNotify(x + 8, y + 13, z + 19, 15, 15);
         this.setBlock(world, x + 9, y + 13, z + 19, KMOD_Main.KetherLeaves);
         world.setBlockMetadataWithNotify(x + 9, y + 13, z + 19, 15, 15);
         this.setBlock(world, x + 12, y + 13, z + 19, KMOD_Main.KetherLeaves);
         world.setBlockMetadataWithNotify(x + 12, y + 13, z + 19, 15, 15);
         this.setBlock(world, x + 13, y + 13, z + 19, KMOD_Main.KetherLeaves);
         world.setBlockMetadataWithNotify(x + 13, y + 13, z + 19, 15, 15);
         this.setBlock(world, x + 6, y + 13, z + 20, KMOD_Main.KetherLeaves);
         world.setBlockMetadataWithNotify(x + 6, y + 13, z + 20, 15, 15);
         this.setBlock(world, x + 7, y + 13, z + 20, KMOD_Main.KetherLeaves);
         world.setBlockMetadataWithNotify(x + 7, y + 13, z + 20, 15, 15);
         this.setBlock(world, x + 10, y + 13, z + 20, KMOD_Main.KetherLeaves);
         world.setBlockMetadataWithNotify(x + 10, y + 13, z + 20, 15, 15);
         this.setBlock(world, x + 11, y + 13, z + 20, KMOD_Main.KetherLeaves);
         world.setBlockMetadataWithNotify(x + 11, y + 13, z + 20, 15, 15);
         this.setBlock(world, x + 9, y + 14, z + 5, KMOD_Main.KetherLeaves);
         world.setBlockMetadataWithNotify(x + 9, y + 14, z + 5, 15, 15);
         this.setBlock(world, x + 8, y + 14, z + 6, KMOD_Main.KetherLeaves);
         world.setBlockMetadataWithNotify(x + 8, y + 14, z + 6, 15, 15);
         this.setBlock(world, x + 14, y + 14, z + 6, KMOD_Main.KetherLeaves);
         world.setBlockMetadataWithNotify(x + 14, y + 14, z + 6, 15, 15);
         this.setBlock(world, x + 7, y + 14, z + 7, KMOD_Main.KetherLeaves);
         world.setBlockMetadataWithNotify(x + 7, y + 14, z + 7, 15, 15);
         this.setBlock(world, x + 11, y + 14, z + 7, KMOD_Main.KetherLeaves);
         world.setBlockMetadataWithNotify(x + 11, y + 14, z + 7, 15, 15);
         this.setBlock(world, x + 14, y + 14, z + 7, KMOD_Main.KetherLeaves);
         world.setBlockMetadataWithNotify(x + 14, y + 14, z + 7, 15, 15);
         this.setBlock(world, x + 5, y + 14, z + 8, KMOD_Main.KetherLeaves);
         world.setBlockMetadataWithNotify(x + 5, y + 14, z + 8, 15, 15);
         this.setBlock(world, x + 7, y + 14, z + 8, KMOD_Main.KetherLeaves);
         world.setBlockMetadataWithNotify(x + 7, y + 14, z + 8, 15, 15);
         this.setBlock(world, x + 8, y + 14, z + 8, KMOD_Main.KetherLeaves);
         world.setBlockMetadataWithNotify(x + 8, y + 14, z + 8, 15, 15);
         this.setBlock(world, x + 10, y + 14, z + 8, KMOD_Main.KetherLeaves);
         world.setBlockMetadataWithNotify(x + 10, y + 14, z + 8, 15, 15);
         this.setBlock(world, x + 11, y + 14, z + 9, KMOD_Main.KetherLeaves);
         world.setBlockMetadataWithNotify(x + 11, y + 14, z + 9, 15, 15);
         this.setBlock(world, x + 15, y + 14, z + 9, KMOD_Main.KetherLeaves);
         world.setBlockMetadataWithNotify(x + 15, y + 14, z + 9, 15, 15);
         this.setBlock(world, x + 9, y + 14, z + 10, KMOD_Main.KetherLeaves);
         world.setBlockMetadataWithNotify(x + 9, y + 14, z + 10, 15, 15);
         this.setBlock(world, x + 10, y + 14, z + 10, KMOD_Main.KetherLeaves);
         world.setBlockMetadataWithNotify(x + 10, y + 14, z + 10, 15, 15);
         this.setBlock(world, x + 5, y + 14, z + 11, KMOD_Main.KetherLeaves);
         world.setBlockMetadataWithNotify(x + 5, y + 14, z + 11, 15, 15);
         this.setBlock(world, x + 9, y + 14, z + 11, KMOD_Main.KetherLeaves);
         world.setBlockMetadataWithNotify(x + 9, y + 14, z + 11, 15, 15);
         this.setBlock(world, x + 10, y + 14, z + 11, KMOD_Main.KetherLeaves);
         world.setBlockMetadataWithNotify(x + 10, y + 14, z + 11, 15, 15);
         this.setBlock(world, x + 9, y + 14, z + 12, KMOD_Main.KetherLeaves);
         world.setBlockMetadataWithNotify(x + 9, y + 14, z + 12, 15, 15);
         this.setBlock(world, x + 10, y + 14, z + 12, KMOD_Main.KetherLeaves);
         world.setBlockMetadataWithNotify(x + 10, y + 14, z + 12, 15, 15);
         this.setBlock(world, x + 12, y + 14, z + 12, KMOD_Main.KetherLeaves);
         world.setBlockMetadataWithNotify(x + 12, y + 14, z + 12, 15, 15);
         this.setBlock(world, x + 5, y + 14, z + 13, KMOD_Main.KetherLeaves);
         world.setBlockMetadataWithNotify(x + 5, y + 14, z + 13, 15, 15);
         this.setBlock(world, x + 6, y + 14, z + 13, KMOD_Main.KetherLeaves);
         world.setBlockMetadataWithNotify(x + 6, y + 14, z + 13, 15, 15);
         this.setBlock(world, x + 9, y + 14, z + 13, KMOD_Main.KetherLeaves);
         world.setBlockMetadataWithNotify(x + 9, y + 14, z + 13, 15, 15);
         this.setBlock(world, x + 11, y + 14, z + 13, KMOD_Main.KetherLeaves);
         world.setBlockMetadataWithNotify(x + 11, y + 14, z + 13, 15, 15);
         this.setBlock(world, x + 13, y + 14, z + 13, KMOD_Main.KetherLeaves);
         world.setBlockMetadataWithNotify(x + 13, y + 14, z + 13, 15, 15);
         this.setBlock(world, x + 14, y + 14, z + 13, KMOD_Main.KetherLeaves);
         world.setBlockMetadataWithNotify(x + 14, y + 14, z + 13, 15, 15);
         this.setBlock(world, x + 9, y + 14, z + 14, KMOD_Main.KetherLeaves);
         world.setBlockMetadataWithNotify(x + 9, y + 14, z + 14, 15, 15);
         this.setBlock(world, x + 5, y + 14, z + 15, KMOD_Main.KetherLeaves);
         world.setBlockMetadataWithNotify(x + 5, y + 14, z + 15, 15, 15);
         this.setBlock(world, x + 9, y + 14, z + 15, KMOD_Main.KetherLeaves);
         world.setBlockMetadataWithNotify(x + 9, y + 14, z + 15, 15, 15);
         this.setBlock(world, x + 10, y + 14, z + 15, KMOD_Main.KetherLeaves);
         world.setBlockMetadataWithNotify(x + 10, y + 14, z + 15, 15, 15);
         this.setBlock(world, x + 12, y + 14, z + 15, KMOD_Main.KetherLeaves);
         world.setBlockMetadataWithNotify(x + 12, y + 14, z + 15, 15, 15);
         this.setBlock(world, x + 13, y + 14, z + 15, KMOD_Main.KetherLeaves);
         world.setBlockMetadataWithNotify(x + 13, y + 14, z + 15, 15, 15);
         this.setBlock(world, x + 14, y + 14, z + 15, KMOD_Main.KetherLeaves);
         world.setBlockMetadataWithNotify(x + 14, y + 14, z + 15, 15, 15);
         this.setBlock(world, x + 16, y + 14, z + 15, KMOD_Main.KetherLeaves);
         world.setBlockMetadataWithNotify(x + 16, y + 14, z + 15, 15, 15);
         this.setBlock(world, x + 5, y + 14, z + 16, KMOD_Main.KetherLeaves);
         world.setBlockMetadataWithNotify(x + 5, y + 14, z + 16, 15, 15);
         this.setBlock(world, x + 6, y + 14, z + 16, KMOD_Main.KetherLeaves);
         world.setBlockMetadataWithNotify(x + 6, y + 14, z + 16, 15, 15);
         this.setBlock(world, x + 9, y + 14, z + 16, KMOD_Main.KetherLeaves);
         world.setBlockMetadataWithNotify(x + 9, y + 14, z + 16, 15, 15);
         this.setBlock(world, x + 14, y + 14, z + 16, KMOD_Main.KetherLeaves);
         world.setBlockMetadataWithNotify(x + 14, y + 14, z + 16, 15, 15);
         this.setBlock(world, x + 6, y + 14, z + 17, KMOD_Main.KetherLeaves);
         world.setBlockMetadataWithNotify(x + 6, y + 14, z + 17, 15, 15);
         this.setBlock(world, x + 7, y + 14, z + 17, KMOD_Main.KetherLeaves);
         world.setBlockMetadataWithNotify(x + 7, y + 14, z + 17, 15, 15);
         this.setBlock(world, x + 12, y + 14, z + 17, KMOD_Main.KetherLeaves);
         world.setBlockMetadataWithNotify(x + 12, y + 14, z + 17, 15, 15);
         this.setBlock(world, x + 7, y + 14, z + 18, KMOD_Main.KetherLeaves);
         world.setBlockMetadataWithNotify(x + 7, y + 14, z + 18, 15, 15);
         this.setBlock(world, x + 8, y + 14, z + 18, KMOD_Main.KetherLeaves);
         world.setBlockMetadataWithNotify(x + 8, y + 14, z + 18, 15, 15);
         this.setBlock(world, x + 9, y + 14, z + 18, KMOD_Main.KetherLeaves);
         world.setBlockMetadataWithNotify(x + 9, y + 14, z + 18, 15, 15);
         this.setBlock(world, x + 12, y + 14, z + 18, KMOD_Main.KetherLeaves);
         world.setBlockMetadataWithNotify(x + 12, y + 14, z + 18, 15, 15);
         this.setBlock(world, x + 10, y + 14, z + 19, KMOD_Main.KetherLeaves);
         world.setBlockMetadataWithNotify(x + 10, y + 14, z + 19, 15, 15);
         this.setBlock(world, x + 7, y + 15, z + 7, KMOD_Main.KetherLeaves);
         world.setBlockMetadataWithNotify(x + 7, y + 15, z + 7, 15, 15);
         this.setBlock(world, x + 9, y + 15, z + 7, KMOD_Main.KetherLeaves);
         world.setBlockMetadataWithNotify(x + 9, y + 15, z + 7, 15, 15);
         this.setBlock(world, x + 11, y + 15, z + 7, KMOD_Main.KetherLeaves);
         world.setBlockMetadataWithNotify(x + 11, y + 15, z + 7, 15, 15);
         this.setBlock(world, x + 12, y + 15, z + 7, KMOD_Main.KetherLeaves);
         world.setBlockMetadataWithNotify(x + 12, y + 15, z + 7, 15, 15);
         this.setBlock(world, x + 6, y + 15, z + 8, KMOD_Main.KetherLeaves);
         world.setBlockMetadataWithNotify(x + 6, y + 15, z + 8, 15, 15);
         this.setBlock(world, x + 8, y + 15, z + 8, KMOD_Main.KetherLeaves);
         world.setBlockMetadataWithNotify(x + 8, y + 15, z + 8, 15, 15);
         this.setBlock(world, x + 9, y + 15, z + 8, KMOD_Main.KetherLeaves);
         world.setBlockMetadataWithNotify(x + 9, y + 15, z + 8, 15, 15);
         this.setBlock(world, x + 11, y + 15, z + 8, KMOD_Main.KetherLeaves);
         world.setBlockMetadataWithNotify(x + 11, y + 15, z + 8, 15, 15);
         this.setBlock(world, x + 10, y + 15, z + 9, KMOD_Main.KetherLeaves);
         world.setBlockMetadataWithNotify(x + 10, y + 15, z + 9, 15, 15);
         this.setBlock(world, x + 11, y + 15, z + 9, KMOD_Main.KetherLeaves);
         world.setBlockMetadataWithNotify(x + 11, y + 15, z + 9, 15, 15);
         this.setBlock(world, x + 7, y + 15, z + 10, KMOD_Main.KetherLeaves);
         world.setBlockMetadataWithNotify(x + 7, y + 15, z + 10, 15, 15);
         this.setBlock(world, x + 8, y + 15, z + 10, KMOD_Main.KetherLeaves);
         world.setBlockMetadataWithNotify(x + 8, y + 15, z + 10, 15, 15);
         this.setBlock(world, x + 10, y + 15, z + 10, KMOD_Main.KetherLeaves);
         world.setBlockMetadataWithNotify(x + 10, y + 15, z + 10, 15, 15);
         this.setBlock(world, x + 11, y + 15, z + 10, KMOD_Main.KetherLeaves);
         world.setBlockMetadataWithNotify(x + 11, y + 15, z + 10, 15, 15);
         this.setBlock(world, x + 8, y + 15, z + 11, KMOD_Main.KetherLeaves);
         world.setBlockMetadataWithNotify(x + 8, y + 15, z + 11, 15, 15);
         this.setBlock(world, x + 9, y + 15, z + 11, KMOD_Main.KetherLeaves);
         world.setBlockMetadataWithNotify(x + 9, y + 15, z + 11, 15, 15);
         this.setBlock(world, x + 10, y + 15, z + 11, KMOD_Main.KetherLeaves);
         world.setBlockMetadataWithNotify(x + 10, y + 15, z + 11, 15, 15);
         this.setBlock(world, x + 12, y + 15, z + 11, KMOD_Main.KetherLeaves);
         world.setBlockMetadataWithNotify(x + 12, y + 15, z + 11, 15, 15);
         this.setBlock(world, x + 8, y + 15, z + 12, KMOD_Main.KetherLeaves);
         world.setBlockMetadataWithNotify(x + 8, y + 15, z + 12, 15, 15);
         this.setBlock(world, x + 8, y + 15, z + 13, KMOD_Main.KetherLeaves);
         world.setBlockMetadataWithNotify(x + 8, y + 15, z + 13, 15, 15);
         this.setBlock(world, x + 12, y + 15, z + 13, KMOD_Main.KetherLeaves);
         world.setBlockMetadataWithNotify(x + 12, y + 15, z + 13, 15, 15);
         this.setBlock(world, x + 15, y + 15, z + 13, KMOD_Main.KetherLeaves);
         world.setBlockMetadataWithNotify(x + 15, y + 15, z + 13, 15, 15);
         this.setBlock(world, x + 14, y + 15, z + 14, KMOD_Main.KetherLeaves);
         world.setBlockMetadataWithNotify(x + 14, y + 15, z + 14, 15, 15);
         this.setBlock(world, x + 15, y + 15, z + 15, KMOD_Main.KetherLeaves);
         world.setBlockMetadataWithNotify(x + 15, y + 15, z + 15, 15, 15);
         this.setBlock(world, x + 7, y + 15, z + 16, KMOD_Main.KetherLeaves);
         world.setBlockMetadataWithNotify(x + 7, y + 15, z + 16, 15, 15);
         this.setBlock(world, x + 8, y + 15, z + 16, KMOD_Main.KetherLeaves);
         world.setBlockMetadataWithNotify(x + 8, y + 15, z + 16, 15, 15);
         this.setBlock(world, x + 10, y + 15, z + 16, KMOD_Main.KetherLeaves);
         world.setBlockMetadataWithNotify(x + 10, y + 15, z + 16, 15, 15);
         this.setBlock(world, x + 7, y + 15, z + 17, KMOD_Main.KetherLeaves);
         world.setBlockMetadataWithNotify(x + 7, y + 15, z + 17, 15, 15);
         this.setBlock(world, x + 8, y + 15, z + 17, KMOD_Main.KetherLeaves);
         world.setBlockMetadataWithNotify(x + 8, y + 15, z + 17, 15, 15);
         this.setBlock(world, x + 7, y + 15, z + 18, KMOD_Main.KetherLeaves);
         world.setBlockMetadataWithNotify(x + 7, y + 15, z + 18, 15, 15);
         this.setBlock(world, x + 9, y + 15, z + 18, KMOD_Main.KetherLeaves);
         world.setBlockMetadataWithNotify(x + 9, y + 15, z + 18, 15, 15);
      }

   }
}
